Workbook

Sheet Summary
B2: Report summary
B4: Report period | C4: =HSummary!E2 -> #REF!
B5: Res id | C5: =HSummary!F2 -> #REF!
B6: MID | C6: =HSummary!G2 -> #REF!
B7: Legal entity | C7: =HSummary!H2 -> #REF!
B8: Res name | C8: =HSummary!I2 -> #REF!
B9: Address | C9: =HSummary!J2 -> #REF!
B10: PAN | C10: =HSummary!K2 -> #REF!
B11: GSTIN | C11: =HSummary!L2 -> #REF!
B12: TAN | C12: =HSummary!M2 -> #REF!
B13: Pay-out cycle | C13: =HSummary!N2 -> #REF!
B14: Zomato GSTIN - TCS | C14: =HSummary!O2 -> #REF!
B15: Zomato GSTIN - Regular | C15: =HSummary!P2 -> #REF!
B16: Total Orders (Delivered + Cancelled/ Rejected) | C16: ='Payout Breakup'!F4 -> 0
B17: Net Payout (Settled + Unsettled) | C17: ='Payout Breakup'!F64 -> 0
B18: Bank UTR | C18: =IF(RIGHT(HSummary!S2,1)=",",LEFT(HSummary!S2,LEN(HSummary!S2)-1),HSummary!S2) -> #REF!
B22: Report - detailed breakdown
B23: This report comprises the following detailed tabs regarding your pay-out:
B24: Tab Name | C24: Description
B25: Payout Breakup | C25: Breakup of your total earnings during this report period
B26: Order Level | C26: Detailed view of your order level earnings, deductions, pay-outs and UTRs for settled orders.
B27: Addition/Deductions Details | C27: Summarized view on : 1. Res id level additions like 194 H, etc 2. Res id level deductions like pay later, etc
B28: Discounts Summary | C28: View of the different discounts running on your restaurant during this report period
B29: Glossary | C29: Descriptions of the terms used in the Order Level tab

Sheet Payout Breakup
B2: Payout breakup
B3: S.no. | C3: Particular | D3: Delivered Orders | E3: Cancelled/ Rejected Orders | F3: Total
C4: Number of orders | D4: =IFERROR(COUNTIF('Order Level'!I:I,"Delivered"),0) -> 0 | E4: =IFERROR(COUNTIF('Order Level'!I:I,"CANCELLED")+COUNTIF('Order Level'!I:I,"REJECTED")+COUNTIF('Order Level'!I:I,"TIMEDOUT"),0) -> 0 | F4: =SUM(D4:E4) -> 0
B6: A | C6: Net order value ( 1 + 2 + 3 - 4 - 5 + 6 - 7 + 8 ) | D6: =D7+D8+D9-D10-D11+D14+D12-D13 -> 0 | E6: =E7+E8+E9-E10-E11+E12+E14-E13 -> 0 | F6: =F7+F8+F9-F10-F11+F14+F12-F13 -> 0
B7: 1 | C7: ='Order Level'!O7 -> Subtotal (items total) | D7: =SUMIFS('Order Level'!$O:$O,'Order Level'!$I:$I,"DELIVERED") -> 0 | E7: =IFERROR(SUMIFS('Order Level'!$O:$O,'Order Level'!$I:$I,"CANCELLED")+SUMIFS('Order Level'!$O:$O,'Order Level'!$I:$I,"REJECTED")+SUMIFS('Order Level'!$O:$O,'Order Level'!$I:$I,"TIMEDOUT"),0) -> 0 | F7: =SUM(D7:E7) -> 0
B8: 2 | C8: ='Order Level'!P7 -> Packaging charge | D8: =IFERROR(SUMIFS('Order Level'!$P:$P,'Order Level'!$I:$I,"DELIVERED"),0) -> 0 | E8: =IFERROR(SUMIFS('Order Level'!$P:$P,'Order Level'!$I:$I,"CANCELLED")+SUMIFS('Order Level'!$P:$P,'Order Level'!$I:$I,"REJECTED")+SUMIFS('Order Level'!$P:$P,'Order Level'!$I:$I,"TIMEDOUT"),0) -> 0 | F8: =SUM(D8:E8) -> 0
B9: 3 | C9: ='Order Level'!Q7 -> Delivery charge for restaurants on self logistics | D9: =IFERROR(SUMIFS('Order Level'!$Q:$Q,'Order Level'!$I:$I,"DELIVERED"),0) -> 0 | E9: =IFERROR(SUMIFS('Order Level'!$Q:$Q,'Order Level'!$I:$I,"CANCELLED")+SUMIFS('Order Level'!$Q:$Q,'Order Level'!$I:$I,"REJECTED")+SUMIFS('Order Level'!$Q:$Q,'Order Level'!$I:$I,"TIMEDOUT"),0) -> 0 | F9: =SUM(D9:E9) -> 0
B10: 4 | C10: ='Order Level'!R7 -> Restaurant discount (Promo) | D10: =IFERROR(SUMIFS('Order Level'!$R:$R,'Order Level'!$I:$I,"DELIVERED"),0) -> 0 | E10: =IFERROR(SUMIFS('Order Level'!$R:$R,'Order Level'!$I:$I,"CANCELLED")+SUMIFS('Order Level'!$R:$R,'Order Level'!$I:$I,"REJECTED")+SUMIFS('Order Level'!$R:$R,'Order Level'!$I:$I,"TIMEDOUT"),0) -> 0 | F10: =SUM(D10:E10) -> 0
B11: 5 | C11: ='Order Level'!S7 -> Restaurant discount (BOGO, Freebies, Gold, Brand pack & others) | D11: =IFERROR(SUMIFS('Order Level'!$S:$S,'Order Level'!$I:$I,"DELIVERED"),0) -> 0 | E11: =IFERROR(SUMIFS('Order Level'!$S:$S,'Order Level'!$I:$I,"CANCELLED")+SUMIFS('Order Level'!$S:$S,'Order Level'!$I:$I,"REJECTED")+SUMIFS('Order Level'!$S:$S,'Order Level'!$I:$I,"TIMEDOUT"),0) -> 0 | F11: =SUM(D11:E11) -> 0
B12: 6 | C12: ='Order Level'!T7 -> Brand pack subscription fee | D12: =IFERROR(SUMIFS('Order Level'!$T:$T,'Order Level'!$I:$I,"DELIVERED"),0) -> 0 | E12: =IFERROR(SUMIFS('Order Level'!$T:$T,'Order Level'!$I:$I,"CANCELLED")+SUMIFS('Order Level'!$T:$T,'Order Level'!$I:$I,"REJECTED")+SUMIFS('Order Level'!$T:$T,'Order Level'!$I:$I,"TIMEDOUT"),0) -> 0 | F12: =SUM(D12:E12) -> 0
B13: 7 | C13: ='Order Level'!U7 -> Delivery charge discount/ Relisting discount | D13: =IFERROR(SUMIFS('Order Level'!$U:$U,'Order Level'!$I:$I,"DELIVERED"),0) -> 0 | E13: =IFERROR(SUMIFS('Order Level'!$U:$U,'Order Level'!$I:$I,"CANCELLED")+SUMIFS('Order Level'!$U:$U,'Order Level'!$I:$I,"REJECTED")+SUMIFS('Order Level'!$U:$U,'Order Level'!$I:$I,"TIMEDOUT"),0) -> 0 | F13: =SUM(D13:E13) -> 0
B14: 8 | C14: ='Order Level'!V7 -> Total GST collected from customers | D14: =IFERROR(SUMIFS('Order Level'!$V:$V,'Order Level'!$I:$I,"DELIVERED"),0) -> 0 | E14: =IFERROR(SUMIFS('Order Level'!$V:$V,'Order Level'!$I:$I,"CANCELLED")+SUMIFS('Order Level'!$V:$V,'Order Level'!$I:$I,"REJECTED")+SUMIFS('Order Level'!$V:$V,'Order Level'!$I:$I,"TIMEDOUT"),0) -> 0 | F14: =SUM(D14:E14) -> 0
B16: B | C16: Total commissionable value ( 9 + 10 + 11 ) | D16: =D17+D18+D19 -> 0 | E16: =E17+E18+E19 -> 0 | F16: =F17+F18+F19 -> 0
B17: 9 | C17: Commissionable value of Subtotal, excluding restuarant discounts ( 1 - 4 - 5 ) | D17: =IFERROR(SUMIFS('Order Level'!$X:$X,'Order Level'!$I:$I,"DELIVERED"),0) -> 0 | E17: =IFERROR(SUMIFS('Order Level'!$X:$X,'Order Level'!$I:$I,"CANCELLED")+SUMIFS('Order Level'!$X:$X,'Order Level'!$I:$I,"REJECTED")+SUMIFS('Order Level'!$X:$X,'Order Level'!$I:$I,"TIMEDOUT"),0) -> 0 | F17: =sum(D17:E17) -> 0
B18: 10 | C18: Commissionable value of Packaging charge | D18: =IFERROR(SUMIFS('Order Level'!$Y:$Y,'Order Level'!$I:$I,"DELIVERED"),0) -> 0 | E18: =IFERROR(SUMIFS('Order Level'!$Y:$Y,'Order Level'!$I:$I,"CANCELLED")+SUMIFS('Order Level'!$Y:$Y,'Order Level'!$I:$I,"REJECTED")+SUMIFS('Order Level'!$Y:$Y,'Order Level'!$I:$I,"TIMEDOUT"),0) -> 0 | F18: =sum(D18:E18) -> 0
B19: 11 | C19: Commissionable value of Total GST collected from customers | D19: =IFERROR(SUMIFS('Order Level'!$Z:$Z,'Order Level'!$I:$I,"DELIVERED"),0) -> 0 | E19: =IFERROR(SUMIFS('Order Level'!$Z:$Z,'Order Level'!$I:$I,"CANCELLED")+SUMIFS('Order Level'!$Z:$Z,'Order Level'!$I:$I,"REJECTED")+SUMIFS('Order Level'!$Z:$Z,'Order Level'!$I:$I,"TIMEDOUT"),0) -> 0 | F19: =sum(D19:E19) -> 0
B21: C | C21: Service fees & payment mechanism fees ( 12 + 13 - 14 - 15 + 16 ) | D21: =D22+D23-D24-D25+D26 -> 0 | E21: =E22+E23-E24-E25+E26 -> 0 | F21: =F22+F23-F24-F25+F26 -> 0
B22: 12 | C22: =LEFT('Order Level'!AC7,FIND("[",'Order Level'!AC7)-2) -> Base service fee | D22: =IFERROR(SUMIFS('Order Level'!$AC:$AC,'Order Level'!$I:$I,"DELIVERED"),0) -> 0 | E22: =IFERROR(SUMIFS('Order Level'!$AC:$AC,'Order Level'!$I:$I,"CANCELLED")+SUMIFS('Order Level'!$AC:$AC,'Order Level'!$I:$I,"REJECTED")+SUMIFS('Order Level'!$AC:$AC,'Order Level'!$I:$I,"TIMEDOUT"),0) -> 0 | F22: =SUM(D22:E22) -> 0
B23: 13 | C23: ='Order Level'!AE7 -> Long distance enablement fee | D23: =IFERROR(SUMIFS('Order Level'!$AE:$AE,'Order Level'!$I:$I,"DELIVERED"),0) -> 0 | E23: =IFERROR(SUMIFS('Order Level'!$AE:$AE,'Order Level'!$I:$I,"CANCELLED")+SUMIFS('Order Level'!$AE:$AE,'Order Level'!$I:$I,"REJECTED")+SUMIFS('Order Level'!$AE:$AE,'Order Level'!$I:$I,"TIMEDOUT"),0) -> 0 | F23: =SUM(D23:E23) -> 0
B24: 14 | C24: ='Order Level'!AF7 -> Discount on long distance enablement fee | D24: =IFERROR(SUMIFS('Order Level'!$AF:$AF,'Order Level'!$I:$I,"DELIVERED"),0) -> 0 | E24: =IFERROR(SUMIFS('Order Level'!$AF:$AF,'Order Level'!$I:$I,"CANCELLED")+SUMIFS('Order Level'!$AF:$AF,'Order Level'!$I:$I,"REJECTED")+SUMIFS('Order Level'!$AF:$AF,'Order Level'!$I:$I,"TIMEDOUT"),0) -> 0 | F24: =SUM(D24:E24) -> 0
B25: 15 | C25: Discount on service fee due to 30% capping (Service fees capped at 30% of commissionable value) | D25: =IFERROR(SUMIFS('Order Level'!$AG:$AG,'Order Level'!$I:$I,"DELIVERED"),0) -> 0 | E25: =IFERROR(SUMIFS('Order Level'!$AG:$AG,'Order Level'!$I:$I,"CANCELLED")+SUMIFS('Order Level'!$AG:$AG,'Order Level'!$I:$I,"REJECTED")+SUMIFS('Order Level'!$AG:$AG,'Order Level'!$I:$I,"TIMEDOUT"),0) -> 0 | F25: =SUM(D25:E25) -> 0
B26: 16 | C26: ='Order Level'!AH7 -> Payment mechanism fee | D26: =IFERROR(SUMIFS('Order Level'!$AH:$AH,'Order Level'!$I:$I,"DELIVERED"),0) -> 0 | E26: =IFERROR(SUMIFS('Order Level'!$AH:$AH,'Order Level'!$I:$I,"CANCELLED")+SUMIFS('Order Level'!$AH:$AH,'Order Level'!$I:$I,"REJECTED")+SUMIFS('Order Level'!$AH:$AH,'Order Level'!$I:$I,"TIMEDOUT"),0) -> 0 | F26: =SUM(D26:E26) -> 0
B28: D | C28: Government charges ( 12 + 13 + 14 + 15 ) | D28: =SUM(D29:D32) -> 0 | E28: =SUM(E29:E32) -> 0 | F28: =SUM(F29:F32) -> 0
B29: 17 | C29: =LEFT('Order Level'!AJ7,FIND("(",'Order Level'!AJ7)-2) -> Taxes on service fee & payment mechanism fee | D29: =IFERROR(SUMIFS('Order Level'!$AJ:$AJ,'Order Level'!$I:$I,"DELIVERED"),0) -> 0 | E29: =SUMIFS('Order Level'!$AJ:$AJ,'Order Level'!$I:$I,"CANCELLED")+SUMIFS('Order Level'!$AJ:$AJ,'Order Level'!$I:$I,"REJECTED")+SUMIFS('Order Level'!$AJ:$AJ,'Order Level'!$I:$I,"TIMEDOUT") -> 0 | F29: =SUM(D29:E29) -> 0
B30: 18 | C30: ='Order Level'!AM7&" + "&'Order Level'!AN7 -> Tax collected at source + TCS IGST amount | D30: =IFERROR(SUMIFS('Order Level'!$AM:$AM,'Order Level'!$I:$I,"DELIVERED")+SUMIFS('Order Level'!$AN:$AN,'Order Level'!$I:$I,"DELIVERED"),0) -> 0 | E30: =SUMIFS('Order Level'!$AM:$AM,'Order Level'!$I:$I,"CANCELLED")+SUMIFS('Order Level'!$AN:$AN,'Order Level'!$I:$I,"CANCELLED")+SUMIFS('Order Level'!$AM:$AM,'Order Level'!$I:$I,"REJECTED")+SUMIFS('Order Level'!$AN:$AN,'Order Level'!$I:$I,"REJECTED")+SUMIFS('Order Level'!$AM:$AM,'Order Level'!$I:$I,"TIMEDOUT")+SUMIFS('Order Level'!$AN:$AN,'Order Level'!$I:$I,"TIMEDOUT") -> 0 | F30: =SUM(D30:E30) -> 0
B31: 19 | C31: ='Order Level'!AO7 -> TDS 194O amount | D31: =IFERROR(SUMIFS('Order Level'!$AO:$AO,'Order Level'!$I:$I,"DELIVERED"),0) -> 0 | E31: =IFERROR(SUMIFS('Order Level'!$AO:$AO,'Order Level'!$I:$I,"CANCELLED")+SUMIFS('Order Level'!$AO:$AO,'Order Level'!$I:$I,"REJECTED")+SUMIFS('Order Level'!$AO:$AO,'Order Level'!$I:$I,"TIMEDOUT"),0) -> 0 | F31: =SUM(D31:E31) -> 0
B32: 20 | C32: ='Order Level'!AP7 -> GST paid by Zomato on behalf of restaurant - under section 9(5) | D32: =IFERROR(SUMIFS('Order Level'!$AP:$AP,'Order Level'!$I:$I,"DELIVERED"),0) -> 0 | E32: =SUMIFS('Order Level'!$AP:$AP,'Order Level'!$I:$I,"CANCELLED")+SUMIFS('Order Level'!$AP:$AP,'Order Level'!$I:$I,"REJECTED")+SUMIFS('Order Level'!$AP:$AP,'Order Level'!$I:$I,"TIMEDOUT") -> 0 | F32: =SUM(D32:E32) -> 0
B34: E | C34: Other order level deductions ( 16 + 17 + 18 ) | D34: =D35+SUM(D44:D45) -> 0 | E34: =E35+SUM(E44:E45) -> 0 | F34: =F35+SUM(F44:F45) -> 0
B35: 21 | C35: Other Order level deductions | D35: =SUM(D36:D43) -> 0 | E35: =SUM(E36:E43) -> 0 | F35: =SUM(D35:E35) -> 0
C36: ='Order Level'!AS7 -> Customer compensation/ recoupment | D36: =IFERROR(SUMIFS('Order Level'!$AS:$AS,'Order Level'!$I:$I,"DELIVERED"),0) -> 0 | E36: =IFERROR(SUMIFS('Order Level'!$AS:$AS,'Order Level'!$I:$I,"CANCELLED"),0) -> 0 | F36: =SUM(D36:E36) -> 0
C37: Rejection penalty | D37: 0 | E37: =IFERROR(SUMIFS('Order Level'!$AS:$AS,'Order Level'!$I:$I,"REJECTED")+SUMIFS('Order Level'!$AS:$AS,'Order Level'!$I:$I,"TIMEDOUT"),0) -> 0 | F37: =SUM(D37:E37) -> 0
C38: ='Order Level'!AT7 -> Delivery charges recovery | D38: =IFERROR(SUMIFS('Order Level'!$AT:$AT,'Order Level'!$I:$I,"DELIVERED"),0) -> 0 | E38: =IFERROR(SUMIFS('Order Level'!$AT:$AT,'Order Level'!$I:$I,"CANCELLED")+SUMIFS('Order Level'!$AT:$AT,'Order Level'!$I:$I,"REJECTED")+SUMIFS('Order Level'!$AT:$AT,'Order Level'!$I:$I,"TIMEDOUT"),0) -> 0 | F38: =SUM(D38:E38) -> 0
C39: ='Order Level'!AV7 -> Credit note/ (Debit note) adjustment | D39: =IFERROR(SUMIFS('Order Level'!$AV:$AV,'Order Level'!$I:$I,"DELIVERED"),0) -> 0 | E39: =IFERROR(SUMIFS('Order Level'!$AV:$AV,'Order Level'!$I:$I,"CANCELLED")+SUMIFS('Order Level'!$AV:$AV,'Order Level'!$I:$I,"REJECTED")+SUMIFS('Order Level'!$AV:$AV,'Order Level'!$I:$I,"TIMEDOUT"),0) -> 0 | F39: =SUM(D39:E39) -> 0
C40: ='Order Level'!AW7 -> Promo recovery adjustment | D40: =IFERROR(SUMIFS('Order Level'!$AW:$AW,'Order Level'!$I:$I,"DELIVERED"),0) -> 0 | E40: =IFERROR(SUMIFS('Order Level'!$AW:$AW,'Order Level'!$I:$I,"CANCELLED")+SUMIFS('Order Level'!$AW:$AW,'Order Level'!$I:$I,"REJECTED")+SUMIFS('Order Level'!$AW:$AW,'Order Level'!$I:$I,"TIMEDOUT"),0) -> 0 | F40: =SUM(D40:E40) -> 0
C41: ='Order Level'!AX7 -> Extra inventory ads (order level deduction) | D41: =IFERROR(SUMIFS('Order Level'!$AX:$AX,'Order Level'!$I:$I,"DELIVERED"),0) -> 0 | E41: =IFERROR(SUMIFS('Order Level'!$AX:$AX,'Order Level'!$I:$I,"CANCELLED")+SUMIFS('Order Level'!$AX:$AX,'Order Level'!$I:$I,"REJECTED")+SUMIFS('Order Level'!$AX:$AX,'Order Level'!$I:$I,"TIMEDOUT"),0) -> 0 | F41: =SUM(D41:E41) -> 0
C42: ='Order Level'!AY7 -> Brand loyalty points redemption | D42: =IFERROR(SUMIFS('Order Level'!$AY:$AY,'Order Level'!$I:$I,"DELIVERED"),0) -> 0 | E42: =IFERROR(SUMIFS('Order Level'!$AY:$AY,'Order Level'!$I:$I,"CANCELLED")+SUMIFS('Order Level'!$AY:$AY,'Order Level'!$I:$I,"REJECTED")+SUMIFS('Order Level'!$AY:$AY,'Order Level'!$I:$I,"TIMEDOUT"),0) -> 0 | F42: =SUM(D42:E42) -> 0
C43: ='Order Level'!AZ7 -> Express order fee | D43: =IFERROR(SUMIFS('Order Level'!$AZ:$AZ,'Order Level'!$I:$I,"DELIVERED"),0) -> 0 | E43: =IFERROR(SUMIFS('Order Level'!$AZ:$AZ,'Order Level'!$I:$I,"CANCELLED")+SUMIFS('Order Level'!$AZ:$AZ,'Order Level'!$I:$I,"REJECTED")+SUMIFS('Order Level'!$AZ:$AZ,'Order Level'!$I:$I,"TIMEDOUT"),0) -> 0 | F43: =SUM(D43:E43) -> 0
B44: 22 | C44: ='Order Level'!AU7 -> Amount received in cash (on self delivery orders) | D44: =IFERROR(SUMIFS('Order Level'!$AU:$AU,'Order Level'!$I:$I,"DELIVERED"),0) -> 0 | E44: =IFERROR(SUMIFS('Order Level'!$AU:$AU,'Order Level'!$I:$I,"CANCELLED")+SUMIFS('Order Level'!$AU:$AU,'Order Level'!$I:$I,"REJECTED")+SUMIFS('Order Level'!$AU:$AU,'Order Level'!$I:$I,"TIMEDOUT"),0) -> 0 | F44: =SUM(D44:E44) -> 0
B45: 23 | C45: Adjustments from previous weeks (Refer to Annexure : "Addition/ Deduction Details") | D45: =IFERROR(SUMIFS('Addition Deductions Details'!G:G,'Addition Deductions Details'!B:B,"Total adjustments from previous weeks"),0) -> 0 | E45: - | F45: =SUM(D45:E45) -> 0
B47: F | C47: Investment in growth services (24 + 25 + 26) | D47: =SUM(D48:D50) -> 0 | E47: - | F47: =SUM(F48:F49) -> 0
...

Sheet Order Level
A1: Order level breakup
A2: =Summary!C26 -> Detailed view of your order level earnings, deductions, pay-outs and UTRs for settled orders.
A3: Get definition of terms used in this sheet in the 'Glossary' tab
A5: RESTAURANT DETAILS > | O5: CUSTOMER PAYABLE | X5: COMMISSIONABLE VALUE | AB5: TOTAL DEDUCTIONS & ADDITIONS | BE5: SETTLEMENT DETAILS
O6: (1) | P6: (2) | Q6: (3) | R6: (4) | S6: (5) | T6: (6) | U6: (7) | V6: (8) | W6: (A) | X6: (9) | Y6: (10) | Z6: (11) | AA6: (B) | AB6: (12) | AC6: (13) | AD6: (14) | AE6: (15) | AF6: (16) | AG6: (17) | AH6: (18) | AI6: (C) | AJ6: (19) | AK6: (20) | AL6: (21) | AM6: (22) | AN6: (23) | AO6: (24) | AP6: (25) | AQ6: (26) | AR6: (D) | AS6: (27) | AT6: (28) | AU6: (29) | AV6: (30) | AW6: (31) | AX6: (32) | AY6: (33) | AZ6: (34) | BA6: (E) | BB6: (F) | BC6: (G) | BD6: (H) | BE6: (35) | BF6: (36) | BG6: (37) | BH6: (38)
A7: S.no. | B7: Order ID | C7: Order date | D7: Week no. | E7: Res. name | F7: Res. ID | G7: Discount construct | H7: Mode of payment | I7: Order status (Delivered/ Cancelled/ Rejected) | J7: Cancellation policy (% Amount refunded back to restaurant partner) | K7: Cancellation/ Rejection reason | L7: Cancelled/ Rejected state (Order status at the time it was cancelled/ rejected) | M7: Order type | N7: Delivery state code | O7: Subtotal (items total) | P7: Packaging charge | Q7: Delivery charge for restaurants on self logistics | R7: Restaurant discount (Promo) | S7: Restaurant discount (BOGO, Freebies, Gold, Brand pack & others) | T7: Brand pack subscription fee | U7: Delivery charge discount/ Relisting discount | V7: Total GST collected from customers | W7: Net order value [(1) + (2) + (3) - (4) - (5) + (6) - (7) + (8)] | X7: Commissionable value of Subtotal, excluding restuarant discounts [(1) - (4) - (5)] | Y7: Commissionable value of Packaging charge | Z7: Commissionable value of Total GST collected from customers | AA7: Total commissionable value [(9) + (10) + (11)] | AB7: Base service fee % | AC7: Base service fee [(12)% * (B)] | AD7: Actual order distance (km) | AE7: Long distance enablement fee | AF7: Discount on long distance enablement fee | AG7: Discount on service fee due to 30% capping Service fees capped at 30% of commissionable value (B) | AH7: Payment mechanism fee | AI7: Service fee & payment mechanism fee [(13) + (15) - (16) - (17) + (18)] | AJ7: Taxes on service fee & payment mechanism fee [(C) * 18%] | AK7: Applicable amount for TCS | AL7: Applicable amount for 9(5) | AM7: Tax collected at source | AN7: TCS IGST amount | AO7: TDS 194O amount | AP7: GST paid by Zomato on behalf of restaurant - under section 9(5) | AQ7: GST to be paid by Restaurant partner to Govt. | AR7: Government charges [(19) + (22) + (23) + (24) + (25)] | AS7: Customer compensation/ recoupment | AT7: Delivery charges recovery | AU7: Amount received in cash (on self delivery orders) | AV7: Credit note/ (Debit note) adjustment | AW7: Promo recovery adjustment | AX7: Extra inventory ads (order level deduction) | AY7: Brand loyalty points redemption | AZ7: Express order fee | BA7: Other order-level deductions [(27) + (28) + (29) + (30) + (31) + (32) + (33) + (34)] | BB7: Net Deductions [(C) + (D) + (E)] | BC7: Net Additions (cancellation refund for cancelled orders/ tip for kitchen staff for delivered orders) | BD7: Order level Payout (A) - (F) + (G) | BE7: Settlement status | BF7: Settlement date | BG7: Bank UTR | BH7: Unsettled amount | BI7: Customer ID
A8: #REF! | B8: #REF! | C8: #REF!
A9: 1 | B9: 7552660112 | C9: 2025-12-08 12:42:40 | D9: 50 | E9: Bawarchi Baba- By Posh Foods | F9: 20415473 | G9: NA | H9: ONLINE | I9: DELIVERED | J9: NA | K9: NA | L9: NA | M9: O2 | N9: 9 | O9: 751 | P9: 0 | Q9: 0 | R9: 0 | S9: 0 | T9: 0 | U9: 0 | V9: 37.55 | W9: 788.55 | X9: 751 | Y9: 0 | Z9: 0 | AA9: 751 | AB9: 23 | AC9: 172.73 | AD9: 1.49 | AE9: 0 | AF9: 0 | AG9: 0 | AH9: 14.51 | AI9: 187.24 | AJ9: 33.7 | AK9: 0 | AL9: 751 | AM9: 0 | AN9: 0 | AO9: 0.75 | AP9: 37.55 | AQ9: 0 | AR9: 72 | AS9: 0 | AT9: 0 | AU9: 0 | AV9: 0 | AW9: 0 | AX9: 0 | AY9: 0 | AZ9: 0 | BA9: 0 | BB9: 259.24 | BC9: 0 | BD9: 529.31 | BE9: settled | BF9: 2025-12-17 05:30:00 | BG9: CITIN25671235852 | BH9: 0 | BI9: cb35c5eea46990d77471d7446ceb503f5dccd4c464f34b8967937e6f99fa8a1c
A10: 2 | B10: 7560170806 | C10: 2025-12-08 13:00:47 | D10: 50 | E10: Bawarchi Baba- By Posh Foods | F10: 20415473 | G10: Flat ₹150 off (2025-12-03 - 2031-01-01) | H10: ONLINE | I10: DELIVERED | J10: NA | K10: NA | L10: NA | M10: O2 | N10: 9 | O10: 602 | P10: 0 | Q10: 0 | R10: 150 | S10: 0 | T10: 0 | U10: 0 | V10: 22.6 | W10: 474.6 | X10: 452 | Y10: 0 | Z10: 0 | AA10: 452 | AB10: 23 | AC10: 103.96 | AD10: 3.94 | AE10: 0 | AF10: 0 | AG10: 0 | AH10: 8.73 | AI10: 112.69 | AJ10: 20.28 | AK10: 0 | AL10: 452 | AM10: 0 | AN10: 0 | AO10: 0.45 | AP10: 22.6 | AQ10: 0 | AR10: 43.33 | AS10: 0 | AT10: 0 | AU10: 0 | AV10: 0 | AW10: 0 | AX10: 0 | AY10: 0 | AZ10: 0 | BA10: 0 | BB10: 156.02 | BC10: 0 | BD10: 318.58 | BE10: settled | BF10: 2025-12-17 05:30:00 | BG10: CITIN25671235852 | BH10: 0 | BI10: c41a75f085e7c6e4c98d1bf0f3d1fc65320c600b0f7c5c8ab4118203ba64f127
A11: 3 | B11: 7557546844 | C11: 2025-12-08 14:30:09 | D11: 50 | E11: Bawarchi Baba- By Posh Foods | F11: 20415473 | G11: Flat ₹125 off (2025-12-03 - 2031-01-01) | H11: ONLINE | I11: DELIVERED | J11: NA | K11: NA | L11: NA | M11: O2 | N11: 9 | O11: 381 | P11: 0 | Q11: 0 | R11: 87 | S11: 0 | T11: 0 | U11: 0 | V11: 14.7 | W11: 308.7 | X11: 294 | Y11: 0 | Z11: 0 | AA11: 294 | AB11: 23 | AC11: 67.62 | AD11: 4.91 | AE11: 20 | AF11: 0 | AG11: 0 | AH11: 5.68 | AI11: 93.3 | AJ11: 16.79 | AK11: 0 | AL11: 294 | AM11: 0 | AN11: 0 | AO11: 0.29 | AP11: 14.7 | AQ11: 0 | AR11: 31.78 | AS11: 0 | AT11: 0 | AU11: 0 | AV11: 0 | AW11: 0 | AX11: 0 | AY11: 0 | AZ11: 0 | BA11: 0 | BB11: 125.08 | BC11: 0 | BD11: 183.62 | BE11: settled | BF11: 2025-12-17 05:30:00 | BG11: CITIN25671235852 | BH11: 0 | BI11: 2db5cd9dba2dd6d0d4f9ebbd62a61959ee0a5989de1abe74e935951629652deb
A12: 4 | B12: 7562450177 | C12: 2025-12-08 15:18:57 | D12: 50 | E12: Bawarchi Baba- By Posh Foods | F12: 20415473 | G12: Flat ₹150 off (2025-12-03 - 2031-01-01) | H12: ONLINE | I12: DELIVERED | J12: NA | K12: NA | L12: NA | M12: O2 | N12: 9 | O12: 490 | P12: 0 | Q12: 0 | R12: 105 | S12: 0 | T12: 0 | U12: 0 | V12: 19.25 | W12: 404.25 | X12: 385 | Y12: 0 | Z12: 0 | AA12: 385 | AB12: 23 | AC12: 88.55 | AD12: 5.99 | AE12: 20 | AF12: 0 | AG12: 0 | AH12: 7.44 | AI12: 115.99 | AJ12: 20.88 | AK12: 0 | AL12: 385 | AM12: 0 | AN12: 0 | AO12: 0.38 | AP12: 19.25 | AQ12: 0 | AR12: 40.51 | AS12: 0 | AT12: 0 | AU12: 0 | AV12: 0 | AW12: 0 | AX12: 0 | AY12: 0 | AZ12: 0 | BA12: 0 | BB12: 156.5 | BC12: 0 | BD12: 247.75 | BE12: settled | BF12: 2025-12-17 05:30:00 | BG12: CITIN25671235852 | BH12: 0 | BI12: edbc0734e8d40cbb942dc5d2da9219ca3805078547a3dcbc1be08de4d560499a
A13: 5 | B13: 7562487134 | C13: 2025-12-08 17:44:34 | D13: 50 | E13: Bawarchi Baba- By Posh Foods | F13: 20415473 | G13: Flat ₹175 off (2025-12-03 - 2025-12-08) | H13: ONLINE | I13: DELIVERED | J13: NA | K13: NA | L13: NA | M13: O2 | N13: 9 | O13: 907 | P13: 0 | Q13: 0 | R13: 175 | S13: 0 | T13: 0 | U13: 0 | V13: 36.6 | W13: 768.6 | X13: 732 | Y13: 0 | Z13: 0 | AA13: 732 | AB13: 23 | AC13: 168.36 | AD13: 5.65 | AE13: 20 | AF13: 0 | AG13: 0 | AH13: 14.14 | AI13: 202.5 | AJ13: 36.45 | AK13: 0 | AL13: 732 | AM13: 0 | AN13: 0 | AO13: 0.73 | AP13: 36.6 | AQ13: 0 | AR13: 73.78 | AS13: 0 | AT13: 0 | AU13: 0 | AV13: 0 | AW13: 0 | AX13: 0 | AY13: 0 | AZ13: 0 | BA13: 0 | BB13: 276.28 | BC13: 0 | BD13: 492.32 | BE13: settled | BF13: 2025-12-17 05:30:00 | BG13: CITIN25671235852 | BH13: 0 | BI13: cecb45147239b1ed9a4c33970a3d2217df7c0ed88b2cf60944a30562ce8d78f4
A14: 6 | B14: 7559445870 | C14: 2025-12-08 18:29:26 | D14: 50 | E14: Bawarchi Baba- By Posh Foods | F14: 20415473 | G14: NA | H14: ONLINE | I14: DELIVERED | J14: NA | K14: NA | L14: NA | M14: O2 | N14: 6 | O14: 490 | P14: 0 | Q14: 0 | R14: 0 | S14: 0 | T14: 0 | U14: 0 | V14: 24.5 | W14: 514.5 | X14: 490 | Y14: 0 | Z14: 0 | AA14: 490 | AB14: 23 | AC14: 112.7 | AD14: 13.54 | AE14: 40 | AF14: 0 | AG14: 5.7 | AH14: 9.47 | AI14: 156.47 | AJ14: 28.16 | AK14: 0 | AL14: 490 | AM14: 0 | AN14: 0 | AO14: 0.49 | AP14: 24.5 | AQ14: 0 | AR14: 53.15 | AS14: 0 | AT14: 0 | AU14: 0 | AV14: 0 | AW14: 0 | AX14: 0 | AY14: 0 | AZ14: 0 | BA14: 0 | BB14: 209.62 | BC14: 0 | BD14: 304.88 | BE14: settled | BF14: 2025-12-17 05:30:00 | BG14: CITIN25671235852 | BH14: 0 | BI14: a361917a88f59dcd3a1edcf93ecccc12998bd335b1cea92cef36d93c53b559c2
A15: 7 | B15: 7562608999 | C15: 2025-12-08 19:10:22 | D15: 50 | E15: Bawarchi Baba- By Posh Foods | F15: 20415473 | G15: NA | H15: ONLINE | I15: DELIVERED | J15: NA | K15: NA | L15: NA | M15: O2 | N15: 9 | O15: 325 | P15: 0 | Q15: 0 | R15: 0 | S15: 32.5 | T15: 0 | U15: 0 | V15: 14.63 | W15: 307.13 | X15: 292.5 | Y15: 0 | Z15: 0 | AA15: 292.5 | AB15: 23 | AC15: 67.28 | AD15: 2.61 | AE15: 0 | AF15: 0 | AG15: 0 | AH15: 5.65 | AI15: 72.93 | AJ15: 13.13 | AK15: 0 | AL15: 292.5 | AM15: 0 | AN15: 0 | AO15: 0.29 | AP15: 14.63 | AQ15: 0 | AR15: 28.05 | AS15: 0 | AT15: 0 | AU15: 0 | AV15: 0 | AW15: 0 | AX15: 0 | AY15: 0 | AZ15: 0 | BA15: 0 | BB15: 100.98 | BC15: 0 | BD15: 206.15 | BE15: settled | BF15: 2025-12-17 05:30:00 | BG15: CITIN25671235852 | BH15: 0 | BI15: 621fad13401bb5d6646e7cea0a351a197872da77b3ba2a2dd6959d54d6c72f98
A16: 8 | B16: 7561484332 | C16: 2025-12-08 19:12:38 | D16: 50 | E16: Bawarchi Baba- By Posh Foods | F16: 20415473 | G16: NA | H16: ONLINE | I16: DELIVERED | J16: NA | K16: NA | L16: NA | M16: O2 | N16: 9 | O16: 590 | P16: 0 | Q16: 0 | R16: 0 | S16: 59 | T16: 0 | U16: 0 | V16: 26.55 | W16: 557.55 | X16: 531 | Y16: 0 | Z16: 0 | AA16: 531 | AB16: 23 | AC16: 122.13 | AD16: 0.99 | AE16: 0 | AF16: 0 | AG16: 0 | AH16: 10.26 | AI16: 132.39 | AJ16: 23.83 | AK16: 0 | AL16: 531 | AM16: 0 | AN16: 0 | AO16: 0.53 | AP16: 26.55 | AQ16: 0 | AR16: 50.91 | AS16: 0 | AT16: 0 | AU16: 0 | AV16: 0 | AW16: 0 | AX16: 0 | AY16: 0 | AZ16: 0 | BA16: 0 | BB16: 183.3 | BC16: 0 | BD16: 374.25 | BE16: settled | BF16: 2025-12-17 05:30:00 | BG16: CITIN25671235852 | BH16: 0 | BI16: bfd7222db6761f7b6e19ffa558a574c02831304a52f5397e91709ee714f0b64b
A17: 9 | B17: 7551968276 | C17: 2025-12-08 19:21:25 | D17: 50 | E17: Bawarchi Baba- By Posh Foods | F17: 20415473 | G17: NA | H17: ONLINE | I17: DELIVERED | J17: NA | K17: NA | L17: NA | M17: O2 | N17: 9 | O17: 539 | P17: 0 | Q17: 0 | R17: 0 | S17: 53.9 | T17: 0 | U17: 0 | V17: 24.26 | W17: 509.36 | X17: 485.1 | Y17: 0 | Z17: 0 | AA17: 485.1 | AB17: 23 | AC17: 111.57 | AD17: 0.61 | AE17: 0 | AF17: 0 | AG17: 0 | AH17: 9.37 | AI17: 120.94 | AJ17: 21.77 | AK17: 0 | AL17: 485.1 | AM17: 0 | AN17: 0 | AO17: 0.49 | AP17: 24.26 | AQ17: 0 | AR17: 46.52 | AS17: 0 | AT17: 0 | AU17: 0 | AV17: 0 | AW17: 0 | AX17: 0 | AY17: 0 | AZ17: 0 | BA17: 0 | BB17: 167.46 | BC17: 0 | BD17: 341.9 | BE17: settled | BF17: 2025-12-17 05:30:00 | BG17: CITIN25671235852 | BH17: 0 | BI17: d3cf32bfc12742075a230d6155099807b7225a6de7f03bfe3ee36776938e9bd1
A18: 10 | B18: 7560870809 | C18: 2025-12-08 20:04:36 | D18: 50 | E18: Bawarchi Baba- By Posh Foods | F18: 20415473 | G18: NA | H18: ONLINE | I18: DELIVERED | J18: NA | K18: NA | L18: NA | M18: O2 | N18: 9 | O18: 300 | P18: 0 | Q18: 0 | R18: 0 | S18: 30 | T18: 0 | U18: 0 | V18: 13.5 | W18: 283.5 | X18: 270 | Y18: 0 | Z18: 0 | AA18: 270 | AB18: 23 | AC18: 62.1 | AD18: 3.18 | AE18: 0 | AF18: 0 | AG18: 0 | AH18: 5.22 | AI18: 67.32 | AJ18: 12.12 | AK18: 0 | AL18: 270 | AM18: 0 | AN18: 0 | AO18: 0.27 | AP18: 13.5 | AQ18: 0 | AR18: 25.89 | AS18: 0 | AT18: 0 | AU18: 0 | AV18: 0 | AW18: 0 | AX18: 0 | AY18: 0 | AZ18: 0 | BA18: 0 | BB18: 93.21 | BC18: 0 | BD18: 190.29 | BE18: settled | BF18: 2025-12-17 05:30:00 | BG18: CITIN25671235852 | BH18: 0 | BI18: cdcec16cbc5de97435cef34fd6582f75f34f0bedefd4a29c2da78ef8640f3356
A19: 11 | B19: 7562163978 | C19: 2025-12-08 21:09:18 | D19: 50 | E19: Bawarchi Baba- By Posh Foods | F19: 20415473 | G19: NA | H19: ONLINE | I19: DELIVERED | J19: NA | K19: NA | L19: NA | M19: O2 | N19: 9 | O19: 396 | P19: 0 | Q19: 0 | R19: 0 | S19: 39.6 | T19: 0 | U19: 0 | V19: 17.82 | W19: 374.22 | X19: 356.4 | Y19: 0 | Z19: 0 | AA19: 356.4 | AB19: 23 | AC19: 81.97 | AD19: 5.65 | AE19: 20 | AF19: 0 | AG19: 0 | AH19: 6.89 | AI19: 108.86 | AJ19: 19.59 | AK19: 0 | AL19: 356.4 | AM19: 0 | AN19: 0 | AO19: 0.36 | AP19: 17.82 | AQ19: 0 | AR19: 37.77 | AS19: 0 | AT19: 0 | AU19: 0 | AV19: 0 | AW19: 0 | AX19: 0 | AY19: 0 | AZ19: 0 | BA19: 0 | BB19: 146.63 | BC19: 0 | BD19: 227.59 | BE19: settled | BF19: 2025-12-17 05:30:00 | BG19: CITIN25671235852 | BH19: 0 | BI19: 37a022bed0da614004a7c558e4f12c870d7c637b327ed11407091764109e7c37
A20: 12 | B20: 7561048586 | C20: 2025-12-08 21:13:38 | D20: 50 | E20: Bawarchi Baba- By Posh Foods | F20: 20415473 | G20: NA | H20: ONLINE | I20: DELIVERED | J20: NA | K20: NA | L20: NA | M20: O2 | N20: 9 | O20: 320 | P20: 0 | Q20: 0 | R20: 0 | S20: 32 | T20: 0 | U20: 0 | V20: 14.4 | W20: 302.4 | X20: 288 | Y20: 0 | Z20: 0 | AA20: 288 | AB20: 23 | AC20: 66.24 | AD20: 2.34 | AE20: 0 | AF20: 0 | AG20: 0 | AH20: 5.56 | AI20: 71.8 | AJ20: 12.92 | AK20: 0 | AL20: 288 | AM20: 0 | AN20: 0 | AO20: 0.29 | AP20: 14.4 | AQ20: 0 | AR20: 27.61 | AS20: 0 | AT20: 0 | AU20: 0 | AV20: 0 | AW20: 0 | AX20: 0 | AY20: 0 | AZ20: 0 | BA20: 0 | BB20: 99.41 | BC20: 0 | BD20: 202.99 | BE20: settled | BF20: 2025-12-17 05:30:00 | BG20: CITIN25671235852 | BH20: 0 | BI20: aa5be29e94b463f92498aeb9190fa54a04d4f14492c5ae6b8bbb1e492596ddc2
... A137: 129 | B137: 7584633679 | C137: 2025-12-14 23:17:45 | D137: 50 | E137: Bawarchi Baba- By Posh Foods | F137: 20415473 | G137: NA | H137: ONLINE | I137: DELIVERED | J137: NA | K137: NA | L137: NA | M137: O2 | N137: 9 | O137: 115 | P137: 0 | Q137: 0 | R137: 0 | S137: 0 | T137: 0 | U137: 0 | V137: 5.75 | W137: 120.75 | X137: 115 | Y137: 0 | Z137: 0 | AA137: 115 | AB137: 23 | AC137: 26.45 | AD137: 4.03 | AE137: 0 | AF137: 0 | AG137: 0 | AH137: 2.22 | AI137: 28.67 | AJ137: 5.16 | AK137: 0 | AL137: 115 | AM137: 0 | AN137: 0 | AO137: 0.12 | AP137: 5.75 | AQ137: 0 | AR137: 11.03 | AS137: 0 | AT137: 0 | AU137: 0 | AV137: 0 | AW137: 0 | AX137: 0 | AY137: 0 | AZ137: 0 | BA137: 0 | BB137: 39.7 | BC137: 0 | BD137: 81.05 | BE137: settled | BF137: 2025-12-17 05:30:00 | BG137: CITIN25671235852 | BH137: 0 | BI137: b454dd20cfe3618fe388d600aa7430f494b58f5156ba1b8cc8e4f5b4f6a9721a

Sheet Addition Deductions Details
B1: Addition/ Deduction details (non order-level additions & deductions and adjustments from previous weeks)
B2: Summarized view on : 1. Res id level additions like 194 H, etc 2. Res id level deductions like pay later, etc
B5: Addition Type
B6: Type | C6: NA | D6: Invoice No/Order id | E6: Order date | F6: Settlement status | G6: Total amount | H6: Adjusted amount | I6: Outstanding amount
B7: ADS | D7: 31888686 | E7: 2025-12-17 05:30:00,2025-12-17 05:30:00 | F7: settled | G7: 0 | H7: 0 | I7: 0
B8: ADS | D8: 31888686 | E8: 2025-12-17 05:30:00 | F8: settled | G8: 1063.13 | H8: 1063.13 | I8: 0
B9: Total Additions | G9: 1063.13 | H9: 1063.13 | I9: 0
B12: Deduction Type
B13: A) Investments in growth services
B14: Type | C14: Res id for which deduction created | D14: Invoice No/Campaign id | E14: Deduction time period | F14: Settlement Status | G14: Total amount | H14: Adjusted amount | I14: Outstanding amount
B15: ADS | C15: 20415473 | D15: 31659259 | E15: 08 December 25 - 14 December 25 | F15: settled | G15: 7246.38 | H15: 7246.38 | I15: 0
B16: ADS | C16: 21552679 | D16: 31786480 | E16: 09 December 25 - 11 December 25 | F16: settled | G16: 84.96 | H16: 84.96 | I16: 0
B17: ADS | C17: 20415473 | D17: 32022899 | E17: 08 December 25 - 14 December 25 | F17: settled | G17: 4906.44 | H17: 4906.44 | I17: 0
B18: ADS | C18: 20415473 | D18: 31800199 | E18: 08 December 25 - 14 December 25 | F18: settled | G18: 1465.56 | H18: 1465.56 | I18: 0
B19: Total Ads & miscellaneous services | G19: 13703.34 | H19: 13703.34 | I19: 0
B21: B) Investments in Hyperpure
B22: Type | C22: Res id for which deduction created | D22: OrderId | E22: Deduction time period | F22: Settlement Status | G22: Total amount | H22: Adjusted amount | I22: Outstanding amount
B23: Hyperpure | C23: 20828753 | D23: 22040544 | E23: 11 December 25 - 11 December 25 | F23: settled | G23: 2438.25 | H23: 2438.25 | I23: 0
B24: Total Hyperpure | G24: 2438.25 | H24: 2438.25 | I24: 0
B26: C) Other deductions
B27: D) Adjustments from previous weeks
B28: Total Deductions (A) + (B) + (C) | G28: 16141.59 | H28: 16141.59 | I28: 0

Sheet Discounts Summary
C1: Offers and Discounts summary
C2: =Summary!C28 -> View of the different discounts running on your restaurant during this report period
C4: Discount Construct | D4: Orders | E4: ='Order Level'!O7 -> Subtotal (items total) | F4: Discount given | G4: Discount given per order | H4: Effective Discount %
C5: {=UNIQUE('Order Level'!G9:G1025760)} -> #REF! | D5: =IF(COUNTIFS('Order Level'!$I:$I,"delivered",'Order Level'!$G:$G,'Discounts Summary'!$C5)=0,"",COUNTIFS('Order Level'!$I:$I,"delivered",'Order Level'!$G:$G,'Discounts Summary'!$C5)) | E5: =IF(SUMIFS('Order Level'!$O:$O,'Order Level'!$I:$I,"Delivered",'Order Level'!$G:$G,'Discounts Summary'!$C5)=0,"",SUMIFS('Order Level'!$O:$O,'Order Level'!$I:$I,"Delivered",'Order Level'!$G:$G,'Discounts Summary'!$C5)) | F5: =IF(SUMIF('Order Level'!$G:$G,$C5,'Order Level'!R:R)=0,"",SUMIF('Order Level'!$G:$G,$C5,'Order Level'!R:R)) | G5: =IFERROR(F5/D5,"") | H5: =IFERROR(F5/E5,"")
D6: =IF(COUNTIFS('Order Level'!$I:$I,"delivered",'Order Level'!$G:$G,'Discounts Summary'!$C6)=0,"",COUNTIFS('Order Level'!$I:$I,"delivered",'Order Level'!$G:$G,'Discounts Summary'!$C6)) | E6: =IF(SUMIFS('Order Level'!$O:$O,'Order Level'!$I:$I,"Delivered",'Order Level'!$G:$G,'Discounts Summary'!$C6)=0,"",SUMIFS('Order Level'!$O:$O,'Order Level'!$I:$I,"Delivered",'Order Level'!$G:$G,'Discounts Summary'!$C6)) | F6: =IF(SUMIF('Order Level'!$G:$G,$C6,'Order Level'!R:R)=0,"",SUMIF('Order Level'!$G:$G,$C6,'Order Level'!R:R)) | G6: =IFERROR(F6/D6,"") | H6: =IFERROR(F6/E6,"")
D7: =IF(COUNTIFS('Order Level'!$I:$I,"delivered",'Order Level'!$G:$G,'Discounts Summary'!$C7)=0,"",COUNTIFS('Order Level'!$I:$I,"delivered",'Order Level'!$G:$G,'Discounts Summary'!$C7)) | E7: =IF(SUMIFS('Order Level'!$O:$O,'Order Level'!$I:$I,"Delivered",'Order Level'!$G:$G,'Discounts Summary'!$C7)=0,"",SUMIFS('Order Level'!$O:$O,'Order Level'!$I:$I,"Delivered",'Order Level'!$G:$G,'Discounts Summary'!$C7)) | F7: =IF(SUMIF('Order Level'!$G:$G,$C7,'Order Level'!R:R)=0,"",SUMIF('Order Level'!$G:$G,$C7,'Order Level'!R:R)) | G7: =IFERROR(F7/D7,"") | H7: =IFERROR(F7/E7,"")
D8: =IF(COUNTIFS('Order Level'!$I:$I,"delivered",'Order Level'!$G:$G,'Discounts Summary'!$C8)=0,"",COUNTIFS('Order Level'!$I:$I,"delivered",'Order Level'!$G:$G,'Discounts Summary'!$C8)) | E8: =IF(SUMIFS('Order Level'!$O:$O,'Order Level'!$I:$I,"Delivered",'Order Level'!$G:$G,'Discounts Summary'!$C8)=0,"",SUMIFS('Order Level'!$O:$O,'Order Level'!$I:$I,"Delivered",'Order Level'!$G:$G,'Discounts Summary'!$C8)) | F8: =IF(SUMIF('Order Level'!$G:$G,$C8,'Order Level'!R:R)=0,"",SUMIF('Order Level'!$G:$G,$C8,'Order Level'!R:R)) | G8: =IFERROR(F8/D8,"") | H8: =IFERROR(F8/E8,"")
D9: =IF(COUNTIFS('Order Level'!$I:$I,"delivered",'Order Level'!$G:$G,'Discounts Summary'!$C9)=0,"",COUNTIFS('Order Level'!$I:$I,"delivered",'Order Level'!$G:$G,'Discounts Summary'!$C9)) | E9: =IF(SUMIFS('Order Level'!$O:$O,'Order Level'!$I:$I,"Delivered",'Order Level'!$G:$G,'Discounts Summary'!$C9)=0,"",SUMIFS('Order Level'!$O:$O,'Order Level'!$I:$I,"Delivered",'Order Level'!$G:$G,'Discounts Summary'!$C9)) | F9: =IF(SUMIF('Order Level'!$G:$G,$C9,'Order Level'!R:R)=0,"",SUMIF('Order Level'!$G:$G,$C9,'Order Level'!R:R)) | G9: =IFERROR(F9/D9,"") | H9: =IFERROR(F9/E9,"")
D10: =IF(COUNTIFS('Order Level'!$I:$I,"delivered",'Order Level'!$G:$G,'Discounts Summary'!$C10)=0,"",COUNTIFS('Order Level'!$I:$I,"delivered",'Order Level'!$G:$G,'Discounts Summary'!$C10)) | E10: =IF(SUMIFS('Order Level'!$O:$O,'Order Level'!$I:$I,"Delivered",'Order Level'!$G:$G,'Discounts Summary'!$C10)=0,"",SUMIFS('Order Level'!$O:$O,'Order Level'!$I:$I,"Delivered",'Order Level'!$G:$G,'Discounts Summary'!$C10)) | F10: =IF(SUMIF('Order Level'!$G:$G,$C10,'Order Level'!R:R)=0,"",SUMIF('Order Level'!$G:$G,$C10,'Order Level'!R:R)) | G10: =IFERROR(F10/D10,"") | H10: =IFERROR(F10/E10,"")
D11: =IF(COUNTIFS('Order Level'!$I:$I,"delivered",'Order Level'!$G:$G,'Discounts Summary'!$C11)=0,"",COUNTIFS('Order Level'!$I:$I,"delivered",'Order Level'!$G:$G,'Discounts Summary'!$C11)) | E11: =IF(SUMIFS('Order Level'!$O:$O,'Order Level'!$I:$I,"Delivered",'Order Level'!$G:$G,'Discounts Summary'!$C11)=0,"",SUMIFS('Order Level'!$O:$O,'Order Level'!$I:$I,"Delivered",'Order Level'!$G:$G,'Discounts Summary'!$C11)) | F11: =IF(SUMIF('Order Level'!$G:$G,$C11,'Order Level'!R:R)=0,"",SUMIF('Order Level'!$G:$G,$C11,'Order Level'!R:R)) | G11: =IFERROR(F11/D11,"") | H11: =IFERROR(F11/E11,"")
D12: =IF(COUNTIFS('Order Level'!$I:$I,"delivered",'Order Level'!$G:$G,'Discounts Summary'!$C12)=0,"",COUNTIFS('Order Level'!$I:$I,"delivered",'Order Level'!$G:$G,'Discounts Summary'!$C12)) | E12: =IF(SUMIFS('Order Level'!$O:$O,'Order Level'!$I:$I,"Delivered",'Order Level'!$G:$G,'Discounts Summary'!$C12)=0,"",SUMIFS('Order Level'!$O:$O,'Order Level'!$I:$I,"Delivered",'Order Level'!$G:$G,'Discounts Summary'!$C12)) | F12: =IF(SUMIF('Order Level'!$G:$G,$C12,'Order Level'!R:R)=0,"",SUMIF('Order Level'!$G:$G,$C12,'Order Level'!R:R)) | G12: =IFERROR(F12/D12,"") | H12: =IFERROR(F12/E12,"")
D13: =IF(COUNTIFS('Order Level'!$I:$I,"delivered",'Order Level'!$G:$G,'Discounts Summary'!$C13)=0,"",COUNTIFS('Order Level'!$I:$I,"delivered",'Order Level'!$G:$G,'Discounts Summary'!$C13)) | E13: =IF(SUMIFS('Order Level'!$O:$O,'Order Level'!$I:$I,"Delivered",'Order Level'!$G:$G,'Discounts Summary'!$C13)=0,"",SUMIFS('Order Level'!$O:$O,'Order Level'!$I:$I,"Delivered",'Order Level'!$G:$G,'Discounts Summary'!$C13)) | F13: =IF(SUMIF('Order Level'!$G:$G,$C13,'Order Level'!R:R)=0,"",SUMIF('Order Level'!$G:$G,$C13,'Order Level'!R:R)) | G13: =IFERROR(F13/D13,"") | H13: =IFERROR(F13/E13,"")
D14: =IF(COUNTIFS('Order Level'!$I:$I,"delivered",'Order Level'!$G:$G,'Discounts Summary'!$C14)=0,"",COUNTIFS('Order Level'!$I:$I,"delivered",'Order Level'!$G:$G,'Discounts Summary'!$C14)) | E14: =IF(SUMIFS('Order Level'!$O:$O,'Order Level'!$I:$I,"Delivered",'Order Level'!$G:$G,'Discounts Summary'!$C14)=0,"",SUMIFS('Order Level'!$O:$O,'Order Level'!$I:$I,"Delivered",'Order Level'!$G:$G,'Discounts Summary'!$C14)) | F14: =IF(SUMIF('Order Level'!$G:$G,$C14,'Order Level'!R:R)=0,"",SUMIF('Order Level'!$G:$G,$C14,'Order Level'!R:R)) | G14: =IFERROR(F14/D14,"") | H14: =IFERROR(F14/E14,"")
D15: =IF(COUNTIFS('Order Level'!$I:$I,"delivered",'Order Level'!$G:$G,'Discounts Summary'!$C15)=0,"",COUNTIFS('Order Level'!$I:$I,"delivered",'Order Level'!$G:$G,'Discounts Summary'!$C15)) | E15: =IF(SUMIFS('Order Level'!$O:$O,'Order Level'!$I:$I,"Delivered",'Order Level'!$G:$G,'Discounts Summary'!$C15)=0,"",SUMIFS('Order Level'!$O:$O,'Order Level'!$I:$I,"Delivered",'Order Level'!$G:$G,'Discounts Summary'!$C15)) | F15: =IF(SUMIF('Order Level'!$G:$G,$C15,'Order Level'!R:R)=0,"",SUMIF('Order Level'!$G:$G,$C15,'Order Level'!R:R)) | G15: =IFERROR(F15/D15,"") | H15: =IFERROR(F15/E15,"")
D16: =IF(COUNTIFS('Order Level'!$I:$I,"delivered",'Order Level'!$G:$G,'Discounts Summary'!$C16)=0,"",COUNTIFS('Order Level'!$I:$I,"delivered",'Order Level'!$G:$G,'Discounts Summary'!$C16)) | E16: =IF(SUMIFS('Order Level'!$O:$O,'Order Level'!$I:$I,"Delivered",'Order Level'!$G:$G,'Discounts Summary'!$C16)=0,"",SUMIFS('Order Level'!$O:$O,'Order Level'!$I:$I,"Delivered",'Order Level'!$G:$G,'Discounts Summary'!$C16)) | F16: =IF(SUMIF('Order Level'!$G:$G,$C16,'Order Level'!R:R)=0,"",SUMIF('Order Level'!$G:$G,$C16,'Order Level'!R:R)) | G16: =IFERROR(F16/D16,"") | H16: =IFERROR(F16/E16,"")
D17: =IF(COUNTIFS('Order Level'!$I:$I,"delivered",'Order Level'!$G:$G,'Discounts Summary'!$C17)=0,"",COUNTIFS('Order Level'!$I:$I,"delivered",'Order Level'!$G:$G,'Discounts Summary'!$C17)) | E17: =IF(SUMIFS('Order Level'!$O:$O,'Order Level'!$I:$I,"Delivered",'Order Level'!$G:$G,'Discounts Summary'!$C17)=0,"",SUMIFS('Order Level'!$O:$O,'Order Level'!$I:$I,"Delivered",'Order Level'!$G:$G,'Discounts Summary'!$C17)) | F17: =IF(SUMIF('Order Level'!$G:$G,$C17,'Order Level'!R:R)=0,"",SUMIF('Order Level'!$G:$G,$C17,'Order Level'!R:R)) | G17: =IFERROR(F17/D17,"") | H17: =IFERROR(F17/E17,"")
... D48: =IF(COUNTIFS('Order Level'!$I:$I,"delivered",'Order Level'!$G:$G,'Discounts Summary'!$C48)=0,"",COUNTIFS('Order Level'!$I:$I,"delivered",'Order Level'!$G:$G,'Discounts Summary'!$C48)) | E48: =IF(SUMIFS('Order Level'!$O:$O,'Order Level'!$I:$I,"Delivered",'Order Level'!$G:$G,'Discounts Summary'!$C48)=0,"",SUMIFS('Order Level'!$O:$O,'Order Level'!$I:$I,"Delivered",'Order Level'!$G:$G,'Discounts Summary'!$C48)) | F48: =IF(SUMIF('Order Level'!$G:$G,$C48,'Order Level'!R:R)=0,"",SUMIF('Order Level'!$G:$G,$C48,'Order Level'!R:R)) | G48: =IFERROR(F48/D48,"") | H48: =IFERROR(F48/E48,"")

Sheet Glossary
A1: Glossary
A2: =Summary!C29 -> Descriptions of the terms used in the Order Level tab
A3: S.no | B3: Particulars | C3: Definition
A4: 1 | B4: Subtotal (items total) | C4: Gross total of dishes/items ordered by the customer before discount
A5: 2 | B5: Packaging charge | C5: Cost set by the restaurant partner for the packaging material of whatever nature, including containers and coverings
A6: 3 | B6: Delivery charge for restaurants on self logistics | C6: Cost charged by restaurant partner when the delivery of order is undertaken by the restaurant partner themselves
A7: 4 | B7: Restaurant discount (Promo) | C7: Offer or promo discounts borne by the restaurant partner on the order
A8: 5 | B8: Restaurant discount (BOGO, Freebies, Gold & others) | C8: BOGO/Freebie/Gold or any other discounts borne by the restaurant partner on the order
A9: 6 | B9: Brand pack subscription fee | C9: Revenue generated for the restaurant through brand pack subscriptions
A10: 7 | B10: Delivery charge discount | C10: Delivery charge discount borne by the resturant partner on the order
A11: 8 | B11: Total GST collected from customers | C11: Total tax amount paid by the customer on the order. It include GST on food items, packaging charge and delivery charge (for orders delivered by the restaurant partners themselves) after adjusting restaurant partner discount
A12: A | B12: Net order value | C12: This means the subtotal value received, including the packaging charge, delivery charge (for orders delivered by the restaurant partners themselves) and less restaurant partner discounts
A13: 9 | B13: Commissionable value of Subtotal, excluding restuarant discounts | C13: This is the commission-applicable amount of the subtotal value, excluding restaurant discounts
A14: 10 | B14: Commissionable value of Packaging charge | C14: This is the commission-applicable amount of the packaging charge
A15: 11 | B15: Commissionable value of Total GST collected from customers (if applicable) | C15: This is the commission-applicable amount of the total GST collected from customers
A16: B | B16: Total commissionable value | C16: It is total amount on which Zomato commission will be applied
A17: 12 | B17: Base service fee % | C17: This means the amount payable by the restaurant partner to Zomato, being a % of commissionable value
A18: 13 | B18: Base service fee | C18: Derived value after multiplying total commissionable value with base service fee %
A19: 14 | B19: Actual order distance | C19: This is the shortest distance between the restaurant and the customer as per Google maps.
A20: 15 | B20: Long distance enablement fee (if applicable) | C20: Amount payable to Zomato for facilitating long distance orders, charged per order basis delivery distance
A21: 16 | B21: Discount on long distance enablement fee (if applicable) | C21: Discount on long distance fee to adjust for set distance cap
A22: 17 | B22: Discount on service fee due to 30% capping | C22: This is a discount on service fee given by Zomato on orders where the sum of all types of service fees exceeds 30% of the commissionable value. The discount is equal to whatever amount exceeds 30% of the commissionable value.
A23: 18 | B23: Payment mechanism fee | C23: Payment mechanism fee is the amount payable by the Restaurant Partner to Zomato, being a % of Order Value including taxes less any charge not levied by restaurant but collected by Zomato, as more specifically set out in the Form
A24: C | B24: Service fee & payment mechanism fee | C24: Total service fee, including payment mechanism fee, net of any discounts
A25: 19 | B25: Taxes on service fee & payment mechanism fee | C25: Tax charged on service fee & payment mechanism fee
A26: 20 | B26: Applicable amount for TCS | C26: It is gross sales amount (less applicable taxes) on which Tax Collected at Source under CGST Act 2017. It is applicable on items other than supply of Restaurant Service.
A27: 21 | B27: Applicable amount for 9(5) | C27: It is gross sales amount (less applicable taxes) of items under Restaurant Service category as per Section 9(5) of Central Goods and Services Tax Act, 2017, with effect from 1 January 2022
A28: 22 | B28: Tax collected at source (TCS) | C28: TCS is amount collected at source by Zomato on items other than Restaurant Services in terms of provisions of Section 52 of the CGST Act, 2017. The said amount will be deposited to Government upon filing of TCS return {GSTR-8} at GSTIN level.
A29: 23 | B29: TCS IGST amount | C29: If TCS is deducted on interstate supply, same will be updated here
A30: 24 | B30: TDS 194O | C30: Zomato is required to deduct taxes at source from the amount for all orders that are settled via Zomato’s platform. TDS u/s 194-O shall be applied on gross sales (less applicable taxes charged by the Restaurant) as per the applicable tax law on the rate as applicable and amended from time to time
A31: 25 | B31: GST paid by Zomato on behalf of restaurant - under section 9(5) | C31: Tax amount retained by Zomato for restaurant services as per Section 9(5) of Central Goods and Services Tax Act 2017, with effect from 1 January 2022. Zomato deposits this tax amount with authorities on behalf of the restaurant
A32: 26 | B32: GST to be paid by restaurant partner to Govt. | C32: This amount is residual value of total GST collected from user and deposited by Zomato under section 9(5) of GST Act. This amount need to deposited to Govt by restaurant partners
A33: D | B33: Government charges | C33: Sum of all the taxes charged on the order as per the government guidelines
A34: 27 | B34: Customer compensation/recoupment | C34: The amount recovered/recouped against customer refunds made by Zomato, from the restaurant partners
A35: 28 | B35: Delivery charges recovery | C35: Amount of discount offers by merchant on the delivery fee charged by the delivery partner, where the restaurant partner is availing logistics services from Zomato
A36: 29 | B36: Amount received in cash (on self delivery orders) | C36: Amount received by restaurant partner from customers for cash on delivery orders where the restaurant partner provided logistics services
A37: 30 | B37: Credit note/(Debit note) adjustment | C37: CN/DN raised to adjust commission/convenience fee or other revenue
A38: 31 | B38: Promo recovery adjustment | C38: Manual promo recovery from the restaurant partner where automated recovery was not made
A39: 32 | B39: Extra inventory ads (order level deduction) | C39: The amount deducted against Extra inventory ads campaign
A40: E | B40: Other order-level deductions | C40: Sum of all deductions at an order level other than the service fee, payment mechanism fee, and government charges
...

Sheet HSummary
E2: 08 Dec 2025 - 14 Dec 2025 | F2: 20415473 | G2: 262096 | H2: Posh Foods | I2: Bawarchi Baba- By Posh Foods | J2: Shop No,- LG-18,ICON LEISURE VELLEY,GREATER NOIDA WEST,Gautam Buddha Nagar,Uttar Pradesh, Noida, Uttar Pradesh | K2: AAXFP3903C | L2: 09AAXFP3903C1Z2 | M2: MRTP11755C | N2: Weekly (Every Wednesday) | O2: 09AADCD4946L1CJ | P2: 09AADCD4946L1Z8 | S2: CITIN25671235852,

Sheet HDiscount
C6: Flat ₹175 off (2025-12-03 - 2025-12-08)
C7: Flat ₹125 off (2025-12-08 - 2031-01-01)
C8: Flat ₹100 off (2025-12-08 - 2031-01-01)
C9: Flat 30% off (2025-10-17 - 2031-01-01)
C10: Flat ₹125 off (2025-12-03 - 2031-01-01)
C11: Flat ₹150 off (2025-12-03 - 2031-01-01)
C12: Flat ₹80 off (2025-12-08 - 2031-01-01)
C13: Flat ₹150 off (2025-12-08 - 2031-01-01)
C14: Flat ₹175 off (2025-12-08 - 2031-01-01)
