Workbook

Sheet Summary
B1: Posh Foods - Bawarchi Baba ( Sector 28 )
B2: Zomato Summary - January - 2026
B4: Details | C4: 1st to 4th | D4: 5th to 11th | E4: 12th to 18th | F4: 19th to 25th | G4: 26th to 31st | H4: Total
B6: No.of orders | C6: 196 | D6: 326 | E6: 283 | F6: 280 | G6: 231 | H6: =SUM(C6:G6)
B8: Total Income (Number that you see on Zomato dashboard) | C8: =Cashflow!C10 | D8: =Cashflow!D10 | E8: =Cashflow!E10 | F8: =Cashflow!F10 | G8: =Cashflow!G10 | H8: =SUM(C8:G8)
B10: Avg. order value | C10: =IFERROR(C8/C6,) | D10: =IFERROR(D8/D6,) | E10: =IFERROR(E8/E6,) | F10: =IFERROR(F8/F6,) | G10: =IFERROR(G8/G6,) | H10: =IFERROR(H8/H6,)
B12: No of disputed orders | C12: 0 | D12: 0 | E12: 0 | F12: 0 | G12: 0 | H12: =SUM(C12:G12)
B14: Refund amount for disputed orders | C14: =Cashflow!C18 | D14: =Cashflow!D18 | E14: =Cashflow!E18 | F14: =Cashflow!F18 | G14: =Cashflow!G18 | H14: =SUM(C14:G14)
B16: Discounts | C16: =Cashflow!C8 | D16: =Cashflow!D8 | E16: =Cashflow!E8 | F16: =Cashflow!F8 | G16: =Cashflow!G8 | H16: =SUM(C16:G16)
C17: =IFERROR(C16/C8,) | D17: =IFERROR(D16/D8,) | E17: =IFERROR(E16/E8,) | F17: =IFERROR(F16/F8,) | G17: =IFERROR(G16/G8,) | H17: =IFERROR(H16/H8,)
B19: Commisonable Amount | C19: 46804.5 | D19: 77643.05 | E19: 68111.95 | F19: 67820.6 | G19: 57569.5 | H19: =SUM(C19:G19)
B20: Commission | C20: =Cashflow!C11 | D20: =Cashflow!D11 | E20: =Cashflow!E11 | F20: =Cashflow!F11 | G20: =Cashflow!G11 | H20: =SUM(C20:G20)
B21: (Calculated on Sales + GST) | C21: =IFERROR(C20/C19,) | D21: =IFERROR(D20/D19,) | E21: =IFERROR(E20/E19,) | F21: =IFERROR(F20/F19,) | G21: =IFERROR(G20/G19,) | H21: =IFERROR(H20/H19,)
B23: Marketing & Ads | C23: =Cashflow!C21 | D23: =Cashflow!D21 | E23: =Cashflow!E21 | F23: =Cashflow!F21 | G23: =Cashflow!G21 | H23: =SUM(C23:G23)
C24: =IFERROR(C23/C8,) | D24: =IFERROR(D23/D8,) | E24: =IFERROR(E23/E8,) | F24: =IFERROR(F23/F8,) | G24: =IFERROR(G23/G8,) | H24: =IFERROR(H23/H8,)
B27: Other charges & Tax Adjustments | C27: =Cashflow!C13+Cashflow!C26 | D27: =Cashflow!D13+Cashflow!D26 | E27: =Cashflow!E13+Cashflow!E26 | F27: =Cashflow!F13+Cashflow!F26 | G27: =Cashflow!G13+Cashflow!G26 | H27: =SUM(C27:G27)
C28: =IFERROR(C27/C8,) | D28: =IFERROR(D27/D8,) | E28: =IFERROR(E27/E8,) | F28: =IFERROR(F27/F8,) | G28: =IFERROR(G27/G8,) | H28: =IFERROR(H27/H8,)
B32: Zomato Hyperpure Adjustments | C32: =Cashflow!C36 | D32: =Cashflow!D36 | E32: =Cashflow!E36 | F32: =Cashflow!F36 | G32: =Cashflow!G36 | H32: =SUM(C32:G32)
B35: Money received | C35: =C8-C14-C20-C23-C27-C32 | D35: =D8-D14-D20-D23-D27-D32 | E35: =E8-E14-E20-E23-E27-E32 | F35: =F8-F14-F20-F23-F27-F32+Cashflow!F31 | G35: =G8-G14-G20-G23-G27-G32 | H35: =SUM(C35:G35)
C36: =IFERROR(C35/$C$8,) | D36: =IFERROR(D35/$D$8,) | E36: =IFERROR(E35/$E$8,) | F36: =IFERROR(F35/F8,) | G36: =IFERROR(G35/G8,) | H36: =IFERROR(H35/H8,)

Sheet Cashflow
A1: =Summary!B1
A2: Zomato Cash Flow - January - 2026
A4: S.No | B4: Details | C4: =Summary!C4 | D4: =Summary!D4 | E4: =Summary!E4 | F4: =Summary!F4 | G4: =Summary!G4 | H4: Total
A5: 1 | B5: Item sales (Delivered orders) | C5: ='D1W1'!O2 | D5: ='D1W2'!O2 | E5: ='D1W3'!O2 | F5: ='D1W4'!O2 | G5: ='D1W5'!O2 | H5: =SUM(C5:G5)
B6: Add:- Packing charges | C6: ='D1W1'!P2 | D6: ='D1W2'!P2 | E6: ='D1W3'!P2 | F6: ='D1W4'!P2 | G6: ='D1W5'!P2 | H6: =SUM(C6:G6)
B7: Add:- Compensation paid for cancelled orders | C7: ='D1W1'!AV1 | D7: ='D1W2'!AV1 | E7: ='D1W3'!AV1 | F7: ='D1W4'!AV1 | G7: ='D1W5'!AV1 | H7: =SUM(C7:G7)
B8: Less:- Discount | C8: ='D1W1'!R2+'D1W1'!S2+'D1W1'!U2 | D8: ='D1W2'!R2+'D1W2'!S2+'D1W2'!U2 | E8: ='D1W3'!R2+'D1W3'!S2+'D1W3'!U2 | F8: ='D1W4'!R2+'D1W4'!S2+'D1W4'!U2 | G8: ='D1W5'!R2+'D1W5'!S2+'D1W5'!U2 | H8: =SUM(C8:G8)
B9: Add:- GST | C9: ='D1W1'!V2 | D9: ='D1W2'!V2 | E9: ='D1W3'!V2 | F9: ='D1W4'!V2 | G9: ='D1W5'!V2 | H9: =SUM(C9:G9) | M9: Gst | N9: Tds
B10: Net Sales | C10: =C5+C6+C9+C7-C8 | D10: =D5+D6+D9+D7-D8 | E10: =E5+E6+E9+E7-E8 | F10: =F5+F6+F9+F7-F8 | G10: =G5+G6+G9+G7-G8 | H10: =H5+H6+H9+H7-H8 | M10: =H10-H29 | N10: =H12*100/118
A11: 2 | B11: Less:- Commission | C11: =C12 | D11: =D12 | E11: =E12 | F11: =F12 | G11: =G12 | H11: =H12
B12: Platform Fee | C12: ='D1W1'!Z3 | D12: ='D1W2'!Z3 | E12: ='D1W3'!Z3 | F12: ='D1W4'!Z3 | G12: ='D1W5'!Z3 | H12: =SUM(C12:G12)
A13: 3 | B13: Less:- Other Charges | C13: =C14+C16-C15+C17 | D13: =D14+D16-D15+D17 | E13: =E14+E16-E15+E17 | F13: =F14+F16-F15+F17 | G13: =G14+G16-G15+G17 | H13: =H14+H16-H15+H17
B14: Convenience Fee | C14: ='D1W1'!AA3 | D14: ='D1W2'!AA3 | E14: ='D1W3'!AA3 | F14: ='D1W4'!AA3 | G14: ='D1W5'!AA3 | H14: =SUM(C14:G14)
B15: Discount on Service Fee | H15: =SUM(C15:G15) | L15: netsales | M15: =C10+C8-C29 | N15: =D10+D8-D29 | O15: =E10+E8-E29 | P15: =F10+F8-F29 | Q15: =G10+G8-G29
B16: Long Distance Fee | H16: =SUM(C16:G16) | L16: disc | M16: =C8 | N16: =D8 | O16: =E8 | P16: =F8 | Q16: =G8
A17: 4 | B17: Merchant Cancellation Charges | C17: 0 | D17: 0 | E17: 0 | F17: 0 | G17: 0 | H17: =SUM(C17:G17) | L17: comm | M17: =C12-C15 | N17: =D12-D15 | O17: =E12-E15 | P17: =F12-F15 | Q17: =G12-G15
B18: Less:- Refunds | C18: =SUM(C19:C20) | D18: =SUM(D19:D20) | E18: =SUM(E19:E20) | F18: =SUM(F19:F20) | G18: =SUM(G19:G20) | H18: =H19+H20 | L18: tds ecom | M18: =C27 | N18: =D27 | O18: =E27 | P18: =F27 | Q18: =G27
B19: Paid by Restaurant | C19: ='D1W1'!AL4 | D19: ='D1W2'!AL4 | E19: ='D1W3'!AL4 | F19: ='D1W4'!AL4 | G19: ='D1W5'!AL4 | H19: =SUM(C19:G19) | L19: conve | M19: =C14 | N19: =D14 | O19: =E14 | P19: =F14 | Q19: =G14
A20: 5 | B20: Received by Restaurant | C20: 0 | D20: 0 | E20: 0 | F20: 0 | G20: 0 | H20: =SUM(C20:G20) | L20: othe cha | M20: =C16 | N20: =D16 | O20: =E16 | P20: =F16 | Q20: =G16
B21: Less:- Marketing Charges | C21: =C22+C23+C24 | D21: =D22+D23+D24 | E21: =E22+E23+E24 | F21: =F22+F23+F24 | G21: =G22+G23+G24 | H21: =H22+H23+H24 | L21: tds | M21: =(C12*100/118)*2% | N21: =(D12*100/118)*2% | O21: =(E12*100/118)*2% | P21: =(F12*100/118)*2% | Q21: =(G12*100/118)*2%
B22: High Priority | C22: ='D2W1'!G15-'D2W1'!G7 | D22: ='D2W2'!G15-'D2W2'!G7 | E22: ='D2W3'!G15-'D2W3'!G7 | F22: ='D2W4'!G15-'D2W4'!G7 | G22: ='D2W5'!G15-'D2W5'!G7 | H22: =SUM(C22:G22)
B23: Call Center Service Fees | C23: 0 | D23: 0 | E23: 0 | F23: 0 | G23: 0 | H23: =SUM(C23:G23)
B24: PocketHero Fee | C24: 0 | D24: 0 | E24: 0 | F24: 0 | G24: 0 | H24: =SUM(C24:G24)
A25: 6 | B25: Profit from Zomato | C25: =C10-C11-C18-C21-C13-C29 | D25: =D10-D11-D18-D21-D13-D29 | E25: =E10-E11-E18-E21-E13-E29 | F25: =F10-F11-F18-F21-F13-F29 | G25: =G10-G11-G18-G21-G13-G29 | H25: =H10-H11-H18-H21-H13-H29
B26: Less:- Tax Adjustments | C26: =SUM(C27:C29) | D26: =SUM(D27:D29) | E26: =SUM(E27:E29) | F26: =SUM(F27:F29) | G26: =SUM(G27:G29) | H26: =SUM(H27:H29)
B27: TDS deduction for aggrigators | C27: ='D1W1'!AH4 | D27: ='D1W2'!AH4 | E27: ='D1W3'!AH4 | F27: ='D1W4'!AH4 | G27: ='D1W5'!AH4 | H27: =SUM(C27:G27)
B28: TCS | C28: ='D1W1'!AF4+'D1W1'!AG4 | D28: ='D1W2'!AF4+'D1W2'!AG4 | E28: ='D1W3'!AF4+'D1W3'!AG4 | F28: ='D1W4'!AF4+'D1W4'!AG4 | G28: ='D1W5'!AF4+'D1W5'!AG4 | H28: =SUM(C28:G28)
A29: 7 | B29: GST collected and paid by Zomato | C29: ='D1W1'!AI4 | D29: ='D1W2'!AI4 | E29: ='D1W3'!AI4 | F29: ='D1W4'!AI4 | G29: ='D1W5'!AI4 | H29: =SUM(C29:G29)
B30: Expected Receipts | C30: =C25-C27-C28-C34 | D30: =D25-D27-D28-D34 | E30: =E25-E27-E28-E34 | F30: =F25-F27-F28-F34 | G30: =G25-G27-G28-G34 | H30: =H25-H27-H28-H34
B31: Service Fee Reversal | C31: 0 | D31: 0 | E31: 0 | F31: 0 | G31: 0 | H31: =SUM(C31:G31)
B32: Interim payments | C32: 0 | D32: 0 | E32: 0 | F32: 0 | G32: 0 | H32: =SUM(C32:G32)
B33: Opening Week Adjustments | C33: 20136.95 | D33: 0 | E33: 0 | F33: 0 | G33: 0 | H33: =SUM(C33:G33)
B34: Following Week Adjustments | C34: 0 | D34: 0 | E34: 0 | F34: 0 | G34: 0 | H34: =SUM(C34:G34)
B35: Closing Week Adjustments | C35: 0 | D35: 0 | E35: 0 | F35: 0 | G35: 6428.56 | H35: =SUM(C35:G35)
B36: Zomato hyperpure Payment Adjustments | C36: ='D2W1'!G20 | D36: ='D2W2'!G19 | E36: ='D2W3'!G19 | F36: ='D2W4'!G19 | G36: ='D2W5'!G19 | H36: =SUM(C36:G36)
B37: EMI Loan deductions | C37: 0 | D37: 0 | E37: 0 | F37: 0 | G37: 0 | H37: =SUM(C37:G37)
A38: 8 | B38: Actual receipts | C38: 0 | D38: 0 | E38: 0 | F38: 0 | G38: 0 | H38: =SUM(C38:G38)
B39: Difference | C39: =C30-C38-C36+C33+C35 | D39: =D30-D38-D36-D33+D35 | E39: =E30-E38-E36-E33+E35 | F39: =F30-F38-F36-F33+F35-F34-F32 | G39: =G30-G38-G36-G33+G35 | H39: =H30-H38-H36+H33+H35-H34-H32
B41: Note :

Sheet Profit statement
A1: =Summary!B1
A2: Zomato Profit Statement - January - 2026
A4: Details | B4: =Summary!C4 | C4: =Summary!D4 | D4: =Summary!E4 | E4: =Summary!F4 | F4: =Summary!G4 | G4: =Summary!H4
A5: A. Net Sales
A6: Total Income | B6: =Cashflow!C5+Cashflow!C6+Cashflow!C9-Cashflow!C8-Cashflow!C29 | C6: =Cashflow!D5+Cashflow!D6+Cashflow!D9-Cashflow!D8-Cashflow!D29 | D6: =Cashflow!E5+Cashflow!E6+Cashflow!E9-Cashflow!E8-Cashflow!E29 | E6: =Cashflow!F5+Cashflow!F6+Cashflow!F9-Cashflow!F8-Cashflow!F29 | F6: =Cashflow!G5+Cashflow!G6+Cashflow!G9-Cashflow!G8-Cashflow!G29 | G6: =SUM(B6:F6)
A7: Add- Adjust: Cancelled orders (By Zomato) | B7: =Cashflow!C7 | C7: =Cashflow!D7 | D7: =Cashflow!E7 | E7: =Cashflow!F7 | F7: =Cashflow!G7 | G7: =SUM(B7:F7)
A8: Net Sales (Number that you see on Numerize app) | B8: =B6+B7 | C8: =C6+C7 | D8: =D6+D7 | E8: =E6+E7 | F8: =F6+F7 | G8: =G6+G7
A10: B. Less:- Commission | B10: =Cashflow!C11 | C10: =Cashflow!D11 | D10: =Cashflow!E11 | E10: =Cashflow!F11 | F10: =Cashflow!G11 | G10: =SUM(B10:F10)
A12: C. Less:- Marketing & Ads | B12: =Cashflow!C21 | C12: =Cashflow!D21 | D12: =Cashflow!E21 | E12: =Cashflow!F21 | F12: =Cashflow!G21 | G12: =SUM(B12:F12)
A14: D. Less:- Refund on disputed orders | B14: =Cashflow!C18 | C14: =Cashflow!D18 | D14: =Cashflow!E18 | E14: =Cashflow!F18 | F14: =Cashflow!G18 | G14: =SUM(B14:F14)
A16: E. Other charges | B16: =Cashflow!C13 | C16: =Cashflow!D13 | D16: =Cashflow!E13 | E16: =Cashflow!F13 | F16: =Cashflow!G13 | G16: =SUM(B16:F16)
A18: F. Profit | B18: =B8-B10-B12-B14-B16 | C18: =C8-C10-C12-C14-C16 | D18: =D8-D10-D12-D14-D16 | E18: =E8-E10-E12-E14-E16 | F18: =F8-F10-F12-F14-F16 | G18: =G8-G10-G12-G14-G16
A19: Percentage | B19: =IFERROR(B18/B8,0) | C19: =IFERROR(C18/C8,0) | D19: =IFERROR(D18/D8,0) | E19: =IFERROR(E18/E8,0) | F19: =IFERROR(F18/F8,0) | G19: =G18/G8

Sheet Discrepancies
A1: =Summary!B1
A2: Zomato Discrepancies - January - 2026
A4: Details | B4: =Summary!C4 | C4: =Summary!D4 | D4: =Summary!E4 | E4: =Summary!F4 | F4: =Summary!G4 | G4: =Summary!H4
A5: A. POS discrepancies
A6: Sales as per Zomato | B6: =Cashflow!C10 | C6: =Cashflow!D10 | D6: =Cashflow!E10 | E6: =Cashflow!F10 | F6: =Cashflow!G10 | G6: =SUM(B6:F6)
A7: Sale as per POS | G7: =SUM(B7:F7)
A8: Difference | B8: =B7-B6 | C8: =C7-C6 | D8: =D7-D6 | E8: =E7-E6 | F8: =F7-F6 | G8: =G7-G6
B9: =IFERROR(B8/B6,) | C9: =IFERROR(C8/C6,0) | D9: =IFERROR(D8/D6,0) | E9: =IFERROR(E8/E6,0) | F9: =IFERROR(F8/F6,0) | G9: =IFERROR(G8/G6,0)
A11: B. Order discrepancies
A12: No.of delivered orders for which payment isn't received | B12: 0 | C12: 0 | D12: 0 | E12: 0 | F12: 0 | G12: =SUM(B12:F12)
A13: Value of such orders | B13: 0 | C13: 0 | D13: 0 | E13: 0 | F13: 0 | G13: =SUM(B13:F13)
A16: C. Payment discrepancies
A17: Expected receipts in the bank account | B17: =Cashflow!C30 | C17: =Cashflow!D30 | D17: =Cashflow!E30 | E17: =Cashflow!F30 | F17: =Cashflow!G30 | G17: =SUM(B17:F17)
A18: Investment in Hyperpure | B18: =Cashflow!C36 | C18: =Cashflow!D36 | D18: =Cashflow!E36 | E18: =Cashflow!F36 | F18: =Cashflow!G36 | G18: =SUM(B18:F18)
A19: Following Week Adjustment | B19: =Cashflow!C34 | C19: =Cashflow!D34 | D19: =Cashflow!E34 | E19: =Cashflow!F34 | F19: =Cashflow!G34 | G19: =SUM(B19:F19)
A20: Opening Week Adjustment | B20: =Cashflow!C33 | C20: =Cashflow!D33 | D20: =Cashflow!E33 | E20: =Cashflow!F33 | F20: 0 | G20: =SUM(B20:F20)
A21: Closing Week Adjustment | B21: =Cashflow!C35 | C21: =Cashflow!D35 | D21: =Cashflow!E35 | E21: =Cashflow!F35 | F21: =Cashflow!G35 | G21: =SUM(B21:F21)
A22: Actual receipts in the bank | B22: =Cashflow!C38 | C22: =Cashflow!D38 | D22: =Cashflow!E38 | E22: =Cashflow!F38 | F22: =Cashflow!G38 | G22: =SUM(B22:F22)
A23: Difference | B23: =B17-B22-B18+B20 | C23: =C17-C22-C18 | D23: =D17-D22-D18 | E23: =E17-E22-E18-E19 | F23: =F17-F22-F18+F21 | G23: =G17-G22-G18+G20-G19
A25: Note:

Sheet POS

Sheet BANK
B5: 1 | C5: 2 | D5: 3 | E5: 4 | F5: 5
A10: Date | B10: Narration | C10: Chq./Ref.No. | D10: Value Dt | E10: Withdrawal Amt. | F10: Deposit Amt. | G10: Closing Balance
A11: 01/10/25 | B11: NEFT CR-YESB0000001-ONE 97 COMMUNICATIONS LIMITED SETTL-ROCKTAIL HOSPITALITY SERVICES-YESBN12025100101816795 | C11: YESBN12025100101816795 | D11: 01/10/25 | F11: 28308.11 | G11: 369938.81
A12: 01/10/25 | B12: NEFT CR-RATN0000999-PINE LABS LIMITED-ROCKTAIL HOSPITALITY SERVICES-RATNN52025100142548753 | C12: RATNN52025100142548753 | D12: 01/10/25 | F12: 988.02 | G12: 370926.83
A13: 01/10/25 | B13: 42552394TERMINAL 1 CARDS SETTL. 01/10/25 | C13: 000000000000000 | D13: 01/10/25 | F13: 4135.06 | G13: 375061.89
A14: 01/10/25 | B14: UPI-8978287178PTYES-8978287178@PTYES-UBIN0813567-564035906635-UPI | C14: 0000564035906635 | D14: 01/10/25 | E14: 165 | G14: 374896.89
A15: 01/10/25 | B15: 50200069817641-TPT-NBLCVTK6KLDPDJXS-WOLFFPACK VENTURES PRIVATE LIMITED | C15: 0000000223256296 | D15: 01/10/25 | F15: 200000 | G15: 574896.89
A16: 01/10/25 | B16: VENDOR PAYMENTS - ROCKTAIL HOSPITALITY DR - 57500000326520 - NEFT TRANSITORY ACCOUNT | C16: 0000000000000188 | D16: 01/10/25 | E16: 390734 | G16: 184162.89
A17: 01/10/25 | B17: UPI-SHREY SINGH-SHREYSINGH0501-1@OKHDFCBANK-HDFC0004216-564012927870-REGISTRATION | C17: 0000564012927870 | D17: 01/10/25 | E17: 8700 | G17: 175462.89
A18: 01/10/25 | B18: NEFT RETURN-INCORRECT ACCOUNT NUMBER-LAXMI AGENCIES-IBKLN92025100194760959 | C18: HDFCN52025100104276617 | D18: 01/10/25 | F18: 8322 | G18: 183784.89
A19: 01/10/25 | B19: NEFT RETURN-INCORRECT ACCOUNT NUMBER-LAXMI AGENCIES-IBKLN92025100194760962 | C19: HDFCN52025100104276606 | D19: 01/10/25 | F19: 8316 | G19: 192100.89
A20: 01/10/25 | B20: NEFT CR-CITI0000002-ETERNAL LIMITED-ROCKTAIL HOSPITALITY SERVICES-CITIN52025100134584901 | C20: CITIN52025100134584901 | D20: 01/10/25 | F20: 22470.51 | G20: 214571.4
A21: 01/10/25 | B21: NEFT CR-UTIB0000052-BUNDL TECHNOLOGIES PRIVATE LIMITED-ROCKTAIL HOSPITALITY SERVICES-UTIBN62025100172850989 | C21: UTIBN62025100172850989 | D21: 01/10/25 | F21: 28624.05 | G21: 243195.45
A22: 01/10/25 | B22: FT - DR - 50200086201346 - SRI CHAKRA ENTERPRISES | C22: 0000000000000187 | D22: 01/10/25 | E22: 68400 | G22: 174795.45
A23: 01/10/25 | B23: CQ NO-000187 AMOUNT-100323 TRANSFERS 4 DR - 50200088485779 - NSP ENTERPRISES | C23: 000000000000000 | D23: 01/10/25 | E23: 12843 | G23: 161952.45
A24: 01/10/25 | B24: CQ NO-000187 AMOUNT-100323 TRANSFERS 4 DR - 50200082063860 - AAMODHA ENTERPRISES | C24: 000000000000000 | D24: 01/10/25 | E24: 16560 | G24: 145392.45
A25: 01/10/25 | B25: CQ NO-000187 AMOUNT-100323 TRANSFERS 4 DR - 50200034371828 - SRIHITHA DISTRIBUTORS | C25: 000000000000000 | D25: 01/10/25 | E25: 2520 | G25: 142872.45
A26: 01/10/25 | B26: UPI-SRI LAXMI CHENNAKESA-Q560982817@YBL-YESB0YBLUPI-112039563850-POOJA | C26: 0000112039563850 | D26: 01/10/25 | E26: 1651 | G26: 141221.45
A27: 01/10/25 | B27: NEFT CR-YESB0000001-SWIGGY LIMITED-ROCKTAIL HOSPITALITY SERVICES-YESBN12025100106534132 | C27: YESBN12025100106534132 | D27: 01/10/25 | F27: 37494.72 | G27: 178716.17
A28: 02/10/25 | B28: NEFT CR-YESB0000001-ONE 97 COMMUNICATIONS LIMITED SETTL-ROCKTAIL HOSPITALITY SERVICES-YESBN12025100202440556 | C28: YESBN12025100202440556 | D28: 02/10/25 | F28: 28924.86 | G28: 207641.03
A29: 02/10/25 | B29: 42552394TERMINAL 1 CARDS SETTL. 02/10/25 | C29: 000000000000000 | D29: 02/10/25 | F29: 6676.28 | G29: 214317.31
A30: 03/10/25 | B30: NEFT CR-YESB0000001-ONE 97 COMMUNICATIONS LIMITED SETTL-ROCKTAIL HOSPITALITY SERVICES-YESBN12025100302342936 | C30: YESBN12025100302342936 | D30: 03/10/25 | F30: 38471.91 | G30: 252789.22
A31: 03/10/25 | B31: 42552394TERMINAL 1 CARDS SETTL. 03/10/25 | C31: 000000000000000 | D31: 03/10/25 | F31: 13411.99 | G31: 266201.21
A32: 03/10/25 | B32: UPI-BHANWRA RAM-BHANWARJATCHOUDHARY251@OKSBI-SBIN0011306-564239417166-FURNITURE | C32: 0000564239417166 | D32: 03/10/25 | E32: 35000 | G32: 231201.21
A33: 03/10/25 | B33: NEFT CR-UTIB0000052-BUNDL TECHNOLOGIES PRIVATE LIMITED-ROCKTAIL HOSPITALITY SERVICES-UTIBN62025100395892591 | C33: UTIBN62025100395892591 | D33: 03/10/25 | F33: 13038.51 | G33: 244239.72
A34: 04/10/25 | B34: NEFT CR-YESB0000001-ONE 97 COMMUNICATIONS LIMITED SETTL-ROCKTAIL HOSPITALITY SERVICES-YESBN12025100403632181 | C34: YESBN12025100403632181 | D34: 04/10/25 | F34: 53035 | G34: 297274.72
A35: 04/10/25 | B35: 42552394TERMINAL 1 CARDS SETTL. 04/10/25 | C35: 000000000000000 | D35: 04/10/25 | F35: 10812.69 | G35: 308087.41
A36: 04/10/25 | B36: UPI-SWIGGY LIMITED-SWIGGY.STORES@AXB-UTIB0000100-527751059928-PAY FOR INTENT | C36: 0000527751059928 | D36: 04/10/25 | E36: 856 | G36: 307231.41
A37: 05/10/25 | B37: NEFT CR-YESB0000001-ONE 97 COMMUNICATIONS LIMITED SETTL-ROCKTAIL HOSPITALITY SERVICES-YESBN12025100501829191 | C37: YESBN12025100501829191 | D37: 05/10/25 | F37: 72645.73 | G37: 379877.14
A38: 05/10/25 | B38: 42552394TERMINAL 1 CARDS SETTL. 05/10/25 | C38: 000000000000000 | D38: 05/10/25 | F38: 17370.83 | G38: 397247.97
A39: 05/10/25 | B39: SETTLEMENT CHARGE-SEP25-CPY597 | C39: 000000000000000 | D39: 05/10/25 | E39: 37.76 | G39: 397210.21
A40: 06/10/25 | B40: NEFT CR-YESB0000001-ONE 97 COMMUNICATIONS LIMITED SETTL-ROCKTAIL HOSPITALITY SERVICES-YESBN12025100601953902 | C40: YESBN12025100601953902 | D40: 06/10/25 | F40: 65856.98 | G40: 463067.19
A41: 06/10/25 | B41: EMI 162047443 CHQ S16204744314 1025162047443 | C41: 000000000000000 | D41: 06/10/25 | E41: 70666 | G41: 392401.19
A42: 06/10/25 | B42: 42552394TERMINAL 1 CARDS SETTL. 06/10/25 | C42: 000000000000000 | D42: 06/10/25 | F42: 1635.17 | G42: 394036.36
A43: 06/10/25 | B43: NEFT CR-CITI0000002-ETERNAL LIMITED-ROCKTAIL HOSPITALITY SERVICES-CITIN52025100636240957 | C43: CITIN52025100636240957 | D43: 06/10/25 | F43: 61201.16 | G43: 455237.52
A44: 07/10/25 | B44: NEFT CR-YESB0000001-ONE 97 COMMUNICATIONS LIMITED SETTL-ROCKTAIL HOSPITALITY SERVICES-YESBN12025100701113506 | C44: YESBN12025100701113506 | D44: 07/10/25 | F44: 24613.36 | G44: 479850.88
A45: 07/10/25 | B45: 42552394TERMINAL 1 CARDS SETTL. 07/10/25 | C45: 000000000000000 | D45: 07/10/25 | F45: 9641.79 | G45: 489492.67
A46: 07/10/25 | B46: NEFT CR-YESB0000001-SWIGGY LIMITED-ROCKTAIL HOSPITALITY SERVICES-YESBN12025100705709842 | C46: YESBN12025100705709842 | D46: 07/10/25 | F46: 83057.26 | G46: 572549.93
A47: 08/10/25 | B47: NEFT CR-YESB0000001-ONE 97 COMMUNICATIONS LIMITED SETTL-ROCKTAIL HOSPITALITY SERVICES-YESBN12025100800862936 | C47: YESBN12025100800862936 | D47: 08/10/25 | F47: 17786 | G47: 590335.93
A48: 08/10/25 | B48: 42552394TERMINAL 1 CARDS SETTL. 08/10/25 | C48: 000000000000000 | D48: 08/10/25 | F48: 5938.15 | G48: 596274.08
...

Sheet D1W1
O1: 0 | P1: 0 | Q1: 0 | R1: 0 | S1: 0 | T1: 0 | U1: 0 | V1: 0 | W1: 0 | X1: 0 | Y1: 0 | Z1: 0 | AA1: 0 | AB1: 0 | AC1: 0 | AD1: 0 | AE1: 0 | AF1: 0 | AG1: 0 | AH1: 0 | AI1: 0 | AJ1: 0 | AK1: 0 | AL1: 0 | AM1: 0 | AN1: 0 | AO1: 0 | AP1: 0 | AQ1: 0 | AR1: 0 | AS1: 0 | AT1: 0 | AU1: 0 | AV1: 0 | AW1: 0 | AX1: 0 | AY1: 0 | AZ1: 0 | BA1: 0 | BB1: 0
O2: 58501 | P2: 686 | Q2: 0 | R2: 12382.5 | S2: 0 | T2: 0 | U2: 0 | V2: 2340.58 | W2: 49145.08 | X2: 46804.5 | Y2: 3724 | Z2: 8892.81 | AA2: 903.86 | AB2: 9796.67 | AC2: 1763.39 | AD2: 0 | AE2: 46804.5 | AF2: 0 | AG2: 0 | AH2: 46.59 | AI2: 2341.83 | AJ2: -1.25 | AK2: 4151.81 | AL2: 0 | AM2: 0 | AN2: 0 | AO2: 0 | AP2: 0 | AQ2: 0 | AR2: 0 | AS2: 0 | AT2: 0 | AU2: 13948.48 | AV2: 0 | AW2: 35196.6 | AX2: 0 | AY2: 0 | AZ2: 0 | BA2: 0 | BB2: 0
O3: 69031.18 | P3: 809.48 | Q3: 0 | R3: 14611.35 | S3: 0 | T3: 0 | U3: 0 | V3: 2761.8844 | W3: 57991.194 | X3: 55229.31 | Y3: 4394.32 | Z3: 10493.516 | AA3: 1066.5548 | AB3: 11560.071 | AC3: 2080.8002 | AD3: 0 | AE3: 55229.31 | AF3: 0 | AG3: 0 | AH3: 54.9762 | AI3: 2763.3594 | AJ3: -1.475 | AK3: 4899.1358 | AL3: 0 | AM3: 0 | AN3: 0 | AO3: 0 | AP3: 0 | AQ3: 0 | AR3: 0 | AS3: 0 | AT3: 0 | AU3: 16459.206 | AV3: 0 | AW3: 41531.988 | AX3: 0 | AY3: 0 | AZ3: 0 | BA3: 0 | BB3: 0
O4: 58501 | P4: 686 | Q4: 0 | R4: 12382.5 | S4: 0 | T4: 0 | U4: 0 | V4: 2340.58 | W4: 49145.08 | X4: 46804.5 | Y4: 3724 | Z4: 8892.81 | AA4: 903.86 | AB4: 9796.67 | AC4: 1763.39 | AD4: 0 | AE4: 46804.5 | AF4: 0 | AG4: 0 | AH4: 46.59 | AI4: 2341.83 | AJ4: -1.25 | AK4: 4151.81 | AL4: 0 | AM4: 0 | AN4: 0 | AO4: 0 | AP4: 0 | AQ4: 0 | AR4: 0 | AS4: 0 | AT4: 0 | AU4: 13948.48 | AV4: 0 | AW4: 35196.6 | AX4: 0 | AY4: 0 | AZ4: 0 | BA4: 0 | BB4: 0
A5: S.No. | B5: Order ID | C5: Order Date | D5: Week No. | E5: Res. name | F5: Res. ID | G5: Discount Construct | H5: Mode of payment | I5: Order status (Delivered/ Cancelled/ Rejected) | J5: Cancellation policy (% Amount refunded back to restaurant partner) | K5: Cancellation/ Rejection Reason | L5: Cancelled/ Rejected State (Order status at the time it was cancelled/ rejected) | M5: Order type | N5: Delivery State code | O5: Subtotal (items total) | P5: Packaging charge | Q5: Delivery charge for restaurants on self logistics | R5: Restaurant discount [Promo] | S5: Restaurant Discount [BOGO, Freebies, Gold, Brand pack & others] | T5: Brand pack subscription fee | U5: Delivery charge discount / Relisting discount | V5: Total GST collected from customers | W5: Net order value [(1) + (2) + (3) - (4) - (5) + (6) - (7) + (8)] | X5: Commissionable value (excludes customer GST) [(A) + (7) - (8) - (6) - (3)] | Y5: Service fees % | Z5: Service fee [ (9) * (10) ] | AA5: Payment mechanism fee | AB5: Service fee & payment mechanism fees [(11) + (12)] | AC5: Taxes on service & payment mechanism fees (B) * 18% | AD5: Applicable amount for TCS | AE5: Applicable amount for 9(5) | AF5: Tax collected at source | AG5: TCS IGST amount | AH5: TDS 194O amount | AI5: GST paid by Zomato on behalf of restaurant - under section 9(5) | AJ5: GST to be paid by Restaurant partner to Govt. | AK5: Government charges [(13) + (16) + (17) + (18) + (19)] | AL5: Customer Compensation/Recoupment | AM5: Delivery Charges Recovery | AN5: Amount received in cash (on self delivery orders) | AO5: Credit note/(Debit Note) adjustment | AP5: Promo recovery adjustment | AQ5: Extra Inventory Ads and Misc. (order level deduction) | AR5: Brand loyalty points redemption | AS5: Express Order Fee | AT5: Other order-level deductions [(21) + (22) + (23) + (24) + (25) + (26) + (27) + (28)] | AU5: Net Deductions (B) + (C) + (D) | AV5: Net Additions (cancellation refund for cancelled orders/Tip for Kitchen Staff for delivered orders) | AW5: Order level Payout (A) - (E) + (F) | AX5: Settlement status | AY5: Settlement date | AZ5: Bank UTR | BA5: Unsettled Amount | BB5: Customer ID
A6: 116 | B6: 7636581212 | C6: 2026-01-01 00:13:33 | D6: 1 | E6: Sha Sha - Shandaar Shawarma | F6: 18557902 | G6: 30% off upto ₹75 (2025-06-25 - 2031-01-01) | H6: ONLINE | I6: DELIVERED | J6: NA | K6: NA | L6: NA | M6: O2 | N6: 36 | O6: 438 | P6: 3.5 | Q6: 0 | R6: 75 | S6: 0 | T6: 0 | U6: 0 | V6: 18.33 | W6: 384.83 | X6: 366.5 | Y6: 19 | Z6: 69.64 | AA6: 7.08 | AB6: 76.72 | AC6: 13.81 | AD6: 0 | AE6: 366.5 | AF6: 0 | AG6: 0 | AH6: 0.37 | AI6: 18.33 | AJ6: 0 | AK6: 32.51 | AL6: 0 | AM6: 0 | AN6: 0 | AO6: 0 | AP6: 0 | AQ6: 0 | AR6: 0 | AS6: 0 | AT6: 0 | AU6: 109.23 | AV6: 0 | AW6: 275.6 | AX6: settled | AY6: 2026-01-07 05:30:00 | AZ6: CITIN26602720826 | BA6: 0 | BB6: 28b3b09010f4a8f77527842f05ce8bd0f08a2773bedf9f6e521ea848662b8191
A7: 117 | B7: 7636469807 | C7: 2026-01-01 00:22:53 | D7: 1 | E7: Sha Sha - Shandaar Shawarma | F7: 18557902 | G7: 30% off upto ₹75 (2025-06-25 - 2031-01-01) | H7: ONLINE | I7: DELIVERED | J7: NA | K7: NA | L7: NA | M7: O2 | N7: 36 | O7: 1095 | P7: 3.5 | Q7: 0 | R7: 75 | S7: 0 | T7: 0 | U7: 0 | V7: 51.18 | W7: 1074.68 | X7: 1023.5 | Y7: 19 | Z7: 194.46 | AA7: 19.77 | AB7: 214.23 | AC7: 38.56 | AD7: 0 | AE7: 1023.5 | AF7: 0 | AG7: 0 | AH7: 1.02 | AI7: 51.18 | AJ7: 0 | AK7: 90.76 | AL7: 0 | AM7: 0 | AN7: 0 | AO7: 0 | AP7: 0 | AQ7: 0 | AR7: 0 | AS7: 0 | AT7: 0 | AU7: 304.99 | AV7: 0 | AW7: 769.69 | AX7: settled | AY7: 2026-01-07 05:30:00 | AZ7: CITIN26602720826 | BA7: 0 | BB7: 98b20de171436a8ef0dc0b7acb5f8633e0d254f6f7bcaa79955455a59f36f367
A8: 118 | B8: 7642503764 | C8: 2026-01-01 00:23:35 | D8: 1 | E8: Sha Sha - Shandaar Shawarma | F8: 18557902 | G8: 30% off upto ₹75 (2025-06-25 - 2031-01-01) | H8: ONLINE | I8: DELIVERED | J8: NA | K8: NA | L8: NA | M8: O2 | N8: 36 | O8: 229 | P8: 3.5 | Q8: 0 | R8: 68.7 | S8: 0 | T8: 0 | U8: 0 | V8: 8.19 | W8: 171.99 | X8: 163.8 | Y8: 19 | Z8: 31.12 | AA8: 3.16 | AB8: 34.28 | AC8: 6.17 | AD8: 0 | AE8: 163.8 | AF8: 0 | AG8: 0 | AH8: 0.16 | AI8: 8.2 | AJ8: -0.01 | AK8: 14.53 | AL8: 0 | AM8: 0 | AN8: 0 | AO8: 0 | AP8: 0 | AQ8: 0 | AR8: 0 | AS8: 0 | AT8: 0 | AU8: 48.81 | AV8: 0 | AW8: 123.18 | AX8: settled | AY8: 2026-01-07 05:30:00 | AZ8: CITIN26602720826 | BA8: 0 | BB8: f965c705b5c4cac429aaa12fa644d2d6b611f69f55ef841ad3fea42d208be5e0
A9: 119 | B9: 7643675925 | C9: 2026-01-01 00:24:39 | D9: 1 | E9: Sha Sha - Shandaar Shawarma | F9: 18557902 | G9: 30% off upto ₹75 (2025-06-25 - 2031-01-01) | H9: ONLINE | I9: DELIVERED | J9: NA | K9: NA | L9: NA | M9: O2 | N9: 36 | O9: 229 | P9: 3.5 | Q9: 0 | R9: 68.7 | S9: 0 | T9: 0 | U9: 0 | V9: 8.19 | W9: 171.99 | X9: 163.8 | Y9: 19 | Z9: 31.12 | AA9: 3.16 | AB9: 34.28 | AC9: 6.17 | AD9: 0 | AE9: 163.8 | AF9: 0 | AG9: 0 | AH9: 0.16 | AI9: 8.2 | AJ9: -0.01 | AK9: 14.53 | AL9: 0 | AM9: 0 | AN9: 0 | AO9: 0 | AP9: 0 | AQ9: 0 | AR9: 0 | AS9: 0 | AT9: 0 | AU9: 48.81 | AV9: 0 | AW9: 123.18 | AX9: settled | AY9: 2026-01-07 05:30:00 | AZ9: CITIN26602720826 | BA9: 0 | BB9: 698ff2c4622ac1d05c0f630119941426046847ccc4a3c36bb5411a963a35b80c
A10: 120 | B10: 7636876354 | C10: 2026-01-01 01:10:10 | D10: 1 | E10: Sha Sha - Shandaar Shawarma | F10: 18557902 | G10: 30% off upto ₹75 (2025-06-25 - 2031-01-01) | H10: ONLINE | I10: DELIVERED | J10: NA | K10: NA | L10: NA | M10: O2 | N10: 36 | O10: 229 | P10: 3.5 | Q10: 0 | R10: 68.7 | S10: 0 | T10: 0 | U10: 0 | V10: 8.19 | W10: 171.99 | X10: 163.8 | Y10: 19 | Z10: 31.12 | AA10: 3.16 | AB10: 34.28 | AC10: 6.17 | AD10: 0 | AE10: 163.8 | AF10: 0 | AG10: 0 | AH10: 0.16 | AI10: 8.2 | AJ10: -0.01 | AK10: 14.53 | AL10: 0 | AM10: 0 | AN10: 0 | AO10: 0 | AP10: 0 | AQ10: 0 | AR10: 0 | AS10: 0 | AT10: 0 | AU10: 48.81 | AV10: 0 | AW10: 123.18 | AX10: settled | AY10: 2026-01-07 05:30:00 | AZ10: CITIN26602720826 | BA10: 0 | BB10: 2bbc31bbec3c0a4ea4e924d4aa7ad19ddbf6c65db21b0eb4fe8b54287e1a55ad
A11: 121 | B11: 7634837780 | C11: 2026-01-01 01:20:52 | D11: 1 | E11: Sha Sha - Shandaar Shawarma | F11: 18557902 | G11: NA | H11: ONLINE | I11: DELIVERED | J11: NA | K11: NA | L11: NA | M11: O2 | N11: 36 | O11: 229 | P11: 3.5 | Q11: 0 | R11: 0 | S11: 0 | T11: 0 | U11: 0 | V11: 11.63 | W11: 244.13 | X11: 232.5 | Y11: 19 | Z11: 44.18 | AA11: 4.49 | AB11: 48.67 | AC11: 8.76 | AD11: 0 | AE11: 232.5 | AF11: 0 | AG11: 0 | AH11: 0.23 | AI11: 11.63 | AJ11: 0 | AK11: 20.62 | AL11: 0 | AM11: 0 | AN11: 0 | AO11: 0 | AP11: 0 | AQ11: 0 | AR11: 0 | AS11: 0 | AT11: 0 | AU11: 69.29 | AV11: 0 | AW11: 174.84 | AX11: settled | AY11: 2026-01-07 05:30:00 | AZ11: CITIN26602720826 | BA11: 0 | BB11: aca3ea8829f35f32eeb9c617b1f572fd528973fe5d98cd8653b3eae979a66190
A12: 122 | B12: 7643032364 | C12: 2026-01-01 01:31:38 | D12: 1 | E12: Sha Sha - Shandaar Shawarma | F12: 18557902 | G12: 30% off upto ₹75 (2025-06-25 - 2031-01-01) | H12: ONLINE | I12: DELIVERED | J12: NA | K12: NA | L12: NA | M12: O2 | N12: 36 | O12: 229 | P12: 3.5 | Q12: 0 | R12: 68.7 | S12: 0 | T12: 0 | U12: 0 | V12: 8.19 | W12: 171.99 | X12: 163.8 | Y12: 19 | Z12: 31.12 | AA12: 3.16 | AB12: 34.28 | AC12: 6.17 | AD12: 0 | AE12: 163.8 | AF12: 0 | AG12: 0 | AH12: 0.16 | AI12: 8.2 | AJ12: -0.01 | AK12: 14.53 | AL12: 0 | AM12: 0 | AN12: 0 | AO12: 0 | AP12: 0 | AQ12: 0 | AR12: 0 | AS12: 0 | AT12: 0 | AU12: 48.81 | AV12: 0 | AW12: 123.18 | AX12: settled | AY12: 2026-01-07 05:30:00 | AZ12: CITIN26602720826 | BA12: 0 | BB12: 4a90e5febf5308624328dc5953e96680f5d19bd804096e4db488689d65222ea4
A13: 123 | B13: 7642127182 | C13: 2026-01-01 02:18:03 | D13: 1 | E13: Sha Sha - Shandaar Shawarma | F13: 18557902 | G13: 30% off upto ₹75 (2025-06-25 - 2031-01-01) | H13: ONLINE | I13: DELIVERED | J13: NA | K13: NA | L13: NA | M13: O2 | N13: 36 | O13: 229 | P13: 3.5 | Q13: 0 | R13: 68.7 | S13: 0 | T13: 0 | U13: 0 | V13: 8.19 | W13: 171.99 | X13: 163.8 | Y13: 19 | Z13: 31.12 | AA13: 3.16 | AB13: 34.28 | AC13: 6.17 | AD13: 0 | AE13: 163.8 | AF13: 0 | AG13: 0 | AH13: 0.16 | AI13: 8.2 | AJ13: -0.01 | AK13: 14.53 | AL13: 0 | AM13: 0 | AN13: 0 | AO13: 0 | AP13: 0 | AQ13: 0 | AR13: 0 | AS13: 0 | AT13: 0 | AU13: 48.81 | AV13: 0 | AW13: 123.18 | AX13: settled | AY13: 2026-01-07 05:30:00 | AZ13: CITIN26602720826 | BA13: 0 | BB13: f59205a6412cd5d8fe633658ae0da95767dd06ef0e84e3115f815110c4b1996e
A14: 124 | B14: 7642671036 | C14: 2026-01-01 02:26:35 | D14: 1 | E14: Sha Sha - Shandaar Shawarma | F14: 18557902 | G14: 30% off upto ₹75 (2025-06-25 - 2031-01-01) | H14: ONLINE | I14: DELIVERED | J14: NA | K14: NA | L14: NA | M14: O2 | N14: 36 | O14: 229 | P14: 3.5 | Q14: 0 | R14: 68.7 | S14: 0 | T14: 0 | U14: 0 | V14: 8.19 | W14: 171.99 | X14: 163.8 | Y14: 19 | Z14: 31.12 | AA14: 3.16 | AB14: 34.28 | AC14: 6.17 | AD14: 0 | AE14: 163.8 | AF14: 0 | AG14: 0 | AH14: 0.16 | AI14: 8.2 | AJ14: -0.01 | AK14: 14.53 | AL14: 0 | AM14: 0 | AN14: 0 | AO14: 0 | AP14: 0 | AQ14: 0 | AR14: 0 | AS14: 0 | AT14: 0 | AU14: 48.81 | AV14: 0 | AW14: 123.18 | AX14: settled | AY14: 2026-01-07 05:30:00 | AZ14: CITIN26602720826 | BA14: 0 | BB14: be5d8cc3809e3a403f69fb51edd5960c0ebef3179b956e6e42dc1e48f6364453
A15: 125 | B15: 7637410325 | C15: 2026-01-01 02:35:33 | D15: 1 | E15: Sha Sha - Shandaar Shawarma | F15: 18557902 | G15: 30% off upto ₹75 (2025-06-25 - 2031-01-01) | H15: ONLINE | I15: DELIVERED | J15: NA | K15: NA | L15: NA | M15: O2 | N15: 36 | O15: 458 | P15: 3.5 | Q15: 0 | R15: 75 | S15: 0 | T15: 0 | U15: 0 | V15: 19.33 | W15: 405.83 | X15: 386.5 | Y15: 19 | Z15: 73.44 | AA15: 7.47 | AB15: 80.91 | AC15: 14.56 | AD15: 0 | AE15: 386.5 | AF15: 0 | AG15: 0 | AH15: 0.39 | AI15: 19.33 | AJ15: 0 | AK15: 34.28 | AL15: 0 | AM15: 0 | AN15: 0 | AO15: 0 | AP15: 0 | AQ15: 0 | AR15: 0 | AS15: 0 | AT15: 0 | AU15: 115.19 | AV15: 0 | AW15: 290.64 | AX15: settled | AY15: 2026-01-07 05:30:00 | AZ15: CITIN26602720826 | BA15: 0 | BB15: cff90805a595d623387bdcd500670cf0610c8c1bd791104906f3ed2c1be1ac15
A16: 126 | B16: 7641307016 | C16: 2026-01-01 02:42:19 | D16: 1 | E16: Sha Sha - Shandaar Shawarma | F16: 18557902 | G16: 30% off upto ₹75 (2025-06-25 - 2031-01-01) | H16: ONLINE | I16: DELIVERED | J16: NA | K16: NA | L16: NA | M16: O2 | N16: 36 | O16: 229 | P16: 3.5 | Q16: 0 | R16: 68.7 | S16: 0 | T16: 0 | U16: 0 | V16: 8.19 | W16: 171.99 | X16: 163.8 | Y16: 19 | Z16: 31.12 | AA16: 3.16 | AB16: 34.28 | AC16: 6.17 | AD16: 0 | AE16: 163.8 | AF16: 0 | AG16: 0 | AH16: 0.16 | AI16: 8.2 | AJ16: -0.01 | AK16: 14.53 | AL16: 0 | AM16: 0 | AN16: 0 | AO16: 0 | AP16: 0 | AQ16: 0 | AR16: 0 | AS16: 0 | AT16: 0 | AU16: 48.81 | AV16: 0 | AW16: 123.18 | AX16: settled | AY16: 2026-01-07 05:30:00 | AZ16: CITIN26602720826 | BA16: 0 | BB16: 00b3c8429cb17175c902e66ea0782526c8a257bc581dc08b3ff67067e0f8a377
A17: 127 | B17: 7638216436 | C17: 2026-01-01 03:02:18 | D17: 1 | E17: Sha Sha - Shandaar Shawarma | F17: 18557902 | G17: 30% off upto ₹75 (2025-06-25 - 2031-01-01) | H17: ONLINE | I17: DELIVERED | J17: NA | K17: NA | L17: NA | M17: O2 | N17: 36 | O17: 219 | P17: 3.5 | Q17: 0 | R17: 65.7 | S17: 0 | T17: 0 | U17: 0 | V17: 7.84 | W17: 164.64 | X17: 156.8 | Y17: 19 | Z17: 29.79 | AA17: 3.03 | AB17: 32.82 | AC17: 5.91 | AD17: 0 | AE17: 156.8 | AF17: 0 | AG17: 0 | AH17: 0.16 | AI17: 7.85 | AJ17: -0.01 | AK17: 13.92 | AL17: 0 | AM17: 0 | AN17: 0 | AO17: 0 | AP17: 0 | AQ17: 0 | AR17: 0 | AS17: 0 | AT17: 0 | AU17: 46.74 | AV17: 0 | AW17: 117.9 | AX17: settled | AY17: 2026-01-07 05:30:00 | AZ17: CITIN26602720826 | BA17: 0 | BB17: 5579837ef747f9228f83ec97b51876253cf4ce7ab0293c2342f4cf67c01214bc
... A201: 311 | B201: 7654486597 | C201: 2026-01-04 23:27:34 | D201: 1 | E201: Sha Sha - Shandaar Shawarma | F201: 18557902 | G201: 30% off upto ₹75 (2025-06-25 - 2031-01-01) | H201: ONLINE | I201: DELIVERED | J201: NA | K201: NA | L201: NA | M201: O2 | N201: 36 | O201: 229 | P201: 3.5 | Q201: 0 | R201: 68.7 | S201: 0 | T201: 0 | U201: 0 | V201: 8.19 | W201: 171.99 | X201: 163.8 | Y201: 19 | Z201: 31.12 | AA201: 3.16 | AB201: 34.28 | AC201: 6.17 | AD201: 0 | AE201: 163.8 | AF201: 0 | AG201: 0 | AH201: 0.16 | AI201: 8.2 | AJ201: -0.01 | AK201: 14.53 | AL201: 0 | AM201: 0 | AN201: 0 | AO201: 0 | AP201: 0 | AQ201: 0 | AR201: 0 | AS201: 0 | AT201: 0 | AU201: 48.81 | AV201: 0 | AW201: 123.18 | AX201: settled | AY201: 2026-01-07 05:30:00 | AZ201: CITIN26602720826 | BA201: 0 | BB201: b9a618ec20a51eb66aa2da79b2ffa9af7fb5fd4fd3e999ffea40f34bfe2d107c

Sheet D2W1
B1: Addition/ Deduction Details (non-order level additions & deductions and adjustments from previous weeks)
B2: Summarized view on : 1. Res id level additions like 194 H, etc 2. Res id level deductions like pay later, etc
B5: Addition Type
B6: Type | C6: NA | D6: Invoice No/Order id | E6: Order date | F6: Settlement status | G6: Total amount | H6: Adjusted amount | I6: Outstanding amount
B7: Total Additions | G7: 0 | H7: 0 | I7: 0
B10: Deduction Type
B11: A) Investments in growth services
B12: Type | C12: Res id for which deduction created | D12: Invoice No/Campaign id | E12: Deduction time period | F12: Settlement Status | G12: Total amount | H12: Adjusted amount | I12: Outstanding amount
B13: ADS | C13: 18557902 | D13: 33001818 | E13: 02 January 26 - 04 January 26 | F13: settled | G13: 4065.33 | H13: 4065.33 | I13: 0
B14: ADS | C14: 18557902 | D14: 32733983 | E14: 02 January 26 - 02 January 26 | F14: settled | G14: 4537.03 | H14: 4537.03 | I14: 0
B15: Total Ads & miscellaneous services | G15: 8602.36 | H15: 8602.36 | I15: 0
B17: B) Investments in Hyperpure
B18: Type | C18: Res id for which deduction created | D18: OrderId | E18: Deduction time period | F18: Settlement Status | G18: Total amount | H18: Adjusted amount | I18: Outstanding amount
B19: Hyperpure | C19: 18557902 | D19: 22408890 | E19: 29 December 25 - 29 December 25 | F19: settled | G19: 33494.44 | H19: 33494.44 | I19: 0
B20: Total Hyperpure | G20: 33494.44 | H20: 33494.44 | I20: 0
B22: C) Other deductions
B23: D) Adjustments from previous weeks
B24: Total Deductions (A) + (B) + (C) | G24: 42096.8 | H24: 42096.8 | I24: 0

Sheet D1W2
O1: 448 | P1: 0 | Q1: 0 | R1: 0 | S1: 0 | T1: 0 | U1: 0 | V1: 0 | W1: 448 | X1: 0 | Y1: 0 | Z1: 0 | AA1: 0 | AB1: 0 | AC1: 0 | AD1: 0 | AE1: 0 | AF1: 0 | AG1: 0 | AH1: 0 | AI1: 0 | AJ1: 0 | AK1: 0 | AL1: 0 | AM1: 0 | AN1: 0 | AO1: 0 | AP1: 0 | AQ1: 0 | AR1: 0 | AS1: 0 | AT1: 0 | AU1: 0 | AV1: 117.9 | AW1: 117.9 | AX1: 0 | AY1: 0 | AZ1: 0 | BA1: 0 | BB1: 0
O2: 95656 | P2: 1130.5 | Q2: 0 | R2: 19066.8 | S2: 0 | T2: 0 | U2: 76.65 | V2: 3882.85 | W2: 81525.9 | X2: 77643.05 | Y2: 6211.34 | Z2: 14830.92 | AA2: 1499.5 | AB2: 16330.42 | AC2: 2939.41 | AD2: 0 | AE2: 77643.05 | AF2: 0 | AG2: 0 | AH2: 77.33 | AI2: 3884.69 | AJ2: -1.84 | AK2: 6901.43 | AL2: 0 | AM2: 0 | AN2: 0 | AO2: 0 | AP2: 0 | AQ2: 0 | AR2: 0 | AS2: 0 | AT2: 0 | AU2: 23231.85 | AV2: 0 | AW2: 58294.05 | AX2: 0 | AY2: 0 | AZ2: 0 | BA2: 0 | BB2: 0
O3: 112874.08 | P3: 1333.99 | Q3: 0 | R3: 22498.824 | S3: 0 | T3: 0 | U3: 90.447 | V3: 4581.763 | W3: 96200.562 | X3: 91618.799 | Y3: 7329.3812 | Z3: 17500.486 | AA3: 1769.41 | AB3: 19269.896 | AC3: 3468.5038 | AD3: 0 | AE3: 91618.799 | AF3: 0 | AG3: 0 | AH3: 91.2494 | AI3: 4583.9342 | AJ3: -2.1712 | AK3: 8143.6874 | AL3: 0 | AM3: 0 | AN3: 0 | AO3: 0 | AP3: 0 | AQ3: 0 | AR3: 0 | AS3: 0 | AT3: 0 | AU3: 27413.583 | AV3: 0 | AW3: 68786.979 | AX3: 0 | AY3: 0 | AZ3: 0 | BA3: 0 | BB3: 0
O4: 96104 | P4: 1130.5 | Q4: 0 | R4: 19066.8 | S4: 0 | T4: 0 | U4: 76.65 | V4: 3882.85 | W4: 81973.9 | X4: 77643.05 | Y4: 6211.34 | Z4: 14830.92 | AA4: 1499.5 | AB4: 16330.42 | AC4: 2939.41 | AD4: 0 | AE4: 77643.05 | AF4: 0 | AG4: 0 | AH4: 77.33 | AI4: 3884.69 | AJ4: -1.84 | AK4: 6901.43 | AL4: 0 | AM4: 0 | AN4: 0 | AO4: 0 | AP4: 0 | AQ4: 0 | AR4: 0 | AS4: 0 | AT4: 0 | AU4: 23231.85 | AV4: 117.9 | AW4: 58411.95 | AX4: 0 | AY4: 0 | AZ4: 0 | BA4: 0 | BB4: 0
A5: S.No. | B5: Order ID | C5: Order Date | D5: Week No. | E5: Res. name | F5: Res. ID | G5: Discount Construct | H5: Mode of payment | I5: Order status (Delivered/ Cancelled/ Rejected) | J5: Cancellation policy (% Amount refunded back to restaurant partner) | K5: Cancellation/ Rejection Reason | L5: Cancelled/ Rejected State (Order status at the time it was cancelled/ rejected) | M5: Order type | N5: Delivery State code | O5: Subtotal (items total) | P5: Packaging charge | Q5: Delivery charge for restaurants on self logistics | R5: Restaurant discount [Promo] | S5: Restaurant Discount [BOGO, Freebies, Gold, Brand pack & others] | T5: Brand pack subscription fee | U5: Delivery charge discount / Relisting discount | V5: Total GST collected from customers | W5: Net order value [(1) + (2) + (3) - (4) - (5) + (6) - (7) + (8)] | X5: Commissionable value (excludes customer GST) [(A) + (7) - (8) - (6) - (3)] | Y5: Service fees % | Z5: Service fee [ (9) * (10) ] | AA5: Payment mechanism fee | AB5: Service fee & payment mechanism fees [(11) + (12)] | AC5: Taxes on service & payment mechanism fees (B) * 18% | AD5: Applicable amount for TCS | AE5: Applicable amount for 9(5) | AF5: Tax collected at source | AG5: TCS IGST amount | AH5: TDS 194O amount | AI5: GST paid by Zomato on behalf of restaurant - under section 9(5) | AJ5: GST to be paid by Restaurant partner to Govt. | AK5: Government charges [(13) + (16) + (17) + (18) + (19)] | AL5: Customer Compensation/Recoupment | AM5: Delivery Charges Recovery | AN5: Amount received in cash (on self delivery orders) | AO5: Credit note/(Debit Note) adjustment | AP5: Promo recovery adjustment | AQ5: Extra Inventory Ads and Misc. (order level deduction) | AR5: Brand loyalty points redemption | AS5: Express Order Fee | AT5: Other order-level deductions [(21) + (22) + (23) + (24) + (25) + (26) + (27) + (28)] | AU5: Net Deductions (B) + (C) + (D) | AV5: Net Additions (cancellation refund for cancelled orders/Tip for Kitchen Staff for delivered orders) | AW5: Order level Payout (A) - (E) + (F) | AX5: Settlement status | AY5: Settlement date | AZ5: Bank UTR | BA5: Unsettled Amount | BB5: Customer ID
A6: 1 | B6: 7657603214 | C6: 2026-01-05 00:19:37 | D6: 2 | E6: Sha Sha - Shandaar Shawarma | F6: 18557902 | G6: 30% off upto ₹75 (2025-06-25 - 2031-01-01) | H6: ONLINE | I6: DELIVERED | J6: NA | K6: NA | L6: NA | M6: O2 | N6: 36 | O6: 219 | P6: 3.5 | Q6: 0 | R6: 65.7 | S6: 0 | T6: 0 | U6: 0 | V6: 7.84 | W6: 164.64 | X6: 156.8 | Y6: 19 | Z6: 29.79 | AA6: 3.03 | AB6: 32.82 | AC6: 5.91 | AD6: 0 | AE6: 156.8 | AF6: 0 | AG6: 0 | AH6: 0.16 | AI6: 7.85 | AJ6: -0.01 | AK6: 13.92 | AL6: 0 | AM6: 0 | AN6: 0 | AO6: 0 | AP6: 0 | AQ6: 0 | AR6: 0 | AS6: 0 | AT6: 0 | AU6: 46.74 | AV6: 0 | AW6: 117.9 | AX6: settled | AY6: 2026-01-14 05:30:00 | AZ6: CITIN26605478364 | BA6: 0 | BB6: 01eda247c91ac4cf8f27829406308b863d03f3bbf700241275c2cfc635e5f8a6
A7: 2 | B7: 7657619062 | C7: 2026-01-05 00:40:12 | D7: 2 | E7: Sha Sha - Shandaar Shawarma | F7: 18557902 | G7: 30% off upto ₹75 (2025-06-25 - 2031-01-01) | H7: ONLINE | I7: DELIVERED | J7: NA | K7: NA | L7: NA | M7: O2 | N7: 36 | O7: 219 | P7: 3.5 | Q7: 0 | R7: 65.7 | S7: 0 | T7: 0 | U7: 0 | V7: 7.84 | W7: 164.64 | X7: 156.8 | Y7: 19 | Z7: 29.79 | AA7: 3.03 | AB7: 32.82 | AC7: 5.91 | AD7: 0 | AE7: 156.8 | AF7: 0 | AG7: 0 | AH7: 0.16 | AI7: 7.85 | AJ7: -0.01 | AK7: 13.92 | AL7: 0 | AM7: 0 | AN7: 0 | AO7: 0 | AP7: 0 | AQ7: 0 | AR7: 0 | AS7: 0 | AT7: 0 | AU7: 46.74 | AV7: 0 | AW7: 117.9 | AX7: settled | AY7: 2026-01-14 05:30:00 | AZ7: CITIN26605478364 | BA7: 0 | BB7: 68743d4a0441ee782d9aa00a3be3b5a92fecae5633bd0cd7a2fb851b43fce4ee
A8: 3 | B8: 7657561046 | C8: 2026-01-05 01:15:48 | D8: 2 | E8: Sha Sha - Shandaar Shawarma | F8: 18557902 | G8: 30% off upto ₹75 (2025-06-25 - 2031-01-01) | H8: ONLINE | I8: DELIVERED | J8: NA | K8: NA | L8: NA | M8: O2 | N8: 36 | O8: 229 | P8: 3.5 | Q8: 0 | R8: 68.7 | S8: 0 | T8: 0 | U8: 0 | V8: 8.19 | W8: 171.99 | X8: 163.8 | Y8: 19 | Z8: 31.12 | AA8: 3.16 | AB8: 34.28 | AC8: 6.17 | AD8: 0 | AE8: 163.8 | AF8: 0 | AG8: 0 | AH8: 0.16 | AI8: 8.2 | AJ8: -0.01 | AK8: 14.53 | AL8: 0 | AM8: 0 | AN8: 0 | AO8: 0 | AP8: 0 | AQ8: 0 | AR8: 0 | AS8: 0 | AT8: 0 | AU8: 48.81 | AV8: 0 | AW8: 123.18 | AX8: settled | AY8: 2026-01-14 05:30:00 | AZ8: CITIN26605478364 | BA8: 0 | BB8: 0524ed78c59e8e395a74c3ad8d19e605d3bc31b30196f1ccfb68526861a6b8d0
A9: 4 | B9: 7655084808 | C9: 2026-01-05 01:33:42 | D9: 2 | E9: Sha Sha - Shandaar Shawarma | F9: 18557902 | G9: 30% off upto ₹75 (2025-06-25 - 2031-01-01) | H9: ONLINE | I9: DELIVERED | J9: NA | K9: NA | L9: NA | M9: O2 | N9: 36 | O9: 448 | P9: 3.5 | Q9: 0 | R9: 75 | S9: 0 | T9: 0 | U9: 0 | V9: 18.83 | W9: 395.33 | X9: 376.5 | Y9: 19 | Z9: 71.54 | AA9: 7.27 | AB9: 78.81 | AC9: 14.19 | AD9: 0 | AE9: 376.5 | AF9: 0 | AG9: 0 | AH9: 0.38 | AI9: 18.83 | AJ9: 0 | AK9: 33.4 | AL9: 0 | AM9: 0 | AN9: 0 | AO9: 0 | AP9: 0 | AQ9: 0 | AR9: 0 | AS9: 0 | AT9: 0 | AU9: 112.21 | AV9: 0 | AW9: 283.12 | AX9: settled | AY9: 2026-01-14 05:30:00 | AZ9: CITIN26605478364 | BA9: 0 | BB9: f0f17bcf6ca603facafc47c0dfd328fbc5a6d4a33754dd8acd09a6a25991f377
A10: 5 | B10: 7654698024 | C10: 2026-01-05 01:38:56 | D10: 2 | E10: Sha Sha - Shandaar Shawarma | F10: 18557902 | G10: 30% off upto ₹75 (2025-06-25 - 2031-01-01) | H10: ONLINE | I10: DELIVERED | J10: NA | K10: NA | L10: NA | M10: O2 | N10: 36 | O10: 407 | P10: 3.5 | Q10: 0 | R10: 75 | S10: 0 | T10: 0 | U10: 0 | V10: 16.78 | W10: 352.28 | X10: 335.5 | Y10: 19 | Z10: 63.74 | AA10: 6.48 | AB10: 70.22 | AC10: 12.64 | AD10: 0 | AE10: 335.5 | AF10: 0 | AG10: 0 | AH10: 0.34 | AI10: 16.78 | AJ10: 0 | AK10: 29.76 | AL10: 0 | AM10: 0 | AN10: 0 | AO10: 0 | AP10: 0 | AQ10: 0 | AR10: 0 | AS10: 0 | AT10: 0 | AU10: 99.98 | AV10: 0 | AW10: 252.3 | AX10: settled | AY10: 2026-01-14 05:30:00 | AZ10: CITIN26605478364 | BA10: 0 | BB10: dbd80cefdeb5f2da5f059128189ab8f47285a7cfa808eb5a16a83f163541aeed
A11: 6 | B11: 7658019089 | C11: 2026-01-05 01:55:56 | D11: 2 | E11: Sha Sha - Shandaar Shawarma | F11: 18557902 | G11: 30% off upto ₹75 (2025-06-25 - 2031-01-01) | H11: ONLINE | I11: DELIVERED | J11: NA | K11: NA | L11: NA | M11: O2 | N11: 36 | O11: 219 | P11: 3.5 | Q11: 0 | R11: 65.7 | S11: 0 | T11: 0 | U11: 0 | V11: 7.84 | W11: 164.64 | X11: 156.8 | Y11: 19 | Z11: 29.79 | AA11: 3.03 | AB11: 32.82 | AC11: 5.91 | AD11: 0 | AE11: 156.8 | AF11: 0 | AG11: 0 | AH11: 0.16 | AI11: 7.85 | AJ11: -0.01 | AK11: 13.92 | AL11: 0 | AM11: 0 | AN11: 0 | AO11: 0 | AP11: 0 | AQ11: 0 | AR11: 0 | AS11: 0 | AT11: 0 | AU11: 46.74 | AV11: 0 | AW11: 117.9 | AX11: settled | AY11: 2026-01-14 05:30:00 | AZ11: CITIN26605478364 | BA11: 0 | BB11: 3958f504484044e07c5b9b184ef6fac4fc52a41c65e7355772eb73ff02d58fba
A12: 7 | B12: 7655438186 | C12: 2026-01-05 02:04:45 | D12: 2 | E12: Sha Sha - Shandaar Shawarma | F12: 18557902 | G12: NA | H12: ONLINE | I12: DELIVERED | J12: NA | K12: NA | L12: NA | M12: O2 | N12: 36 | O12: 229 | P12: 3.5 | Q12: 0 | R12: 0 | S12: 0 | T12: 0 | U12: 0 | V12: 11.63 | W12: 244.13 | X12: 232.5 | Y12: 19 | Z12: 44.18 | AA12: 4.49 | AB12: 48.67 | AC12: 8.76 | AD12: 0 | AE12: 232.5 | AF12: 0 | AG12: 0 | AH12: 0.23 | AI12: 11.63 | AJ12: 0 | AK12: 20.62 | AL12: 0 | AM12: 0 | AN12: 0 | AO12: 0 | AP12: 0 | AQ12: 0 | AR12: 0 | AS12: 0 | AT12: 0 | AU12: 69.29 | AV12: 0 | AW12: 174.84 | AX12: settled | AY12: 2026-01-14 05:30:00 | AZ12: CITIN26605478364 | BA12: 0 | BB12: 047f9570e5ca0b39ca277e4fe8265b2590f14c34430672b43ffff400d369a324
A13: 8 | B13: 7650988873 | C13: 2026-01-05 02:25:14 | D13: 2 | E13: Sha Sha - Shandaar Shawarma | F13: 18557902 | G13: 30% off upto ₹75 (2025-06-25 - 2031-01-01) | H13: ONLINE | I13: DELIVERED | J13: NA | K13: NA | L13: NA | M13: O2 | N13: 36 | O13: 219 | P13: 3.5 | Q13: 0 | R13: 65.7 | S13: 0 | T13: 0 | U13: 0 | V13: 7.84 | W13: 164.64 | X13: 156.8 | Y13: 19 | Z13: 29.79 | AA13: 3.03 | AB13: 32.82 | AC13: 5.91 | AD13: 0 | AE13: 156.8 | AF13: 0 | AG13: 0 | AH13: 0.16 | AI13: 7.85 | AJ13: -0.01 | AK13: 13.92 | AL13: 0 | AM13: 0 | AN13: 0 | AO13: 0 | AP13: 0 | AQ13: 0 | AR13: 0 | AS13: 0 | AT13: 0 | AU13: 46.74 | AV13: 0 | AW13: 117.9 | AX13: settled | AY13: 2026-01-14 05:30:00 | AZ13: CITIN26605478364 | BA13: 0 | BB13: cf4e82bbc041c0b2270c64de5571ce343e8a3ff2d9c5d9737136939f49c59b72
A14: 9 | B14: 7654388859 | C14: 2026-01-05 02:27:42 | D14: 2 | E14: Sha Sha - Shandaar Shawarma | F14: 18557902 | G14: 30% off upto ₹75 (2025-06-25 - 2031-01-01) | H14: ONLINE | I14: DELIVERED | J14: NA | K14: NA | L14: NA | M14: O2 | N14: 36 | O14: 229 | P14: 3.5 | Q14: 0 | R14: 68.7 | S14: 0 | T14: 0 | U14: 0 | V14: 8.19 | W14: 171.99 | X14: 163.8 | Y14: 19 | Z14: 31.12 | AA14: 3.16 | AB14: 34.28 | AC14: 6.17 | AD14: 0 | AE14: 163.8 | AF14: 0 | AG14: 0 | AH14: 0.16 | AI14: 8.2 | AJ14: -0.01 | AK14: 14.53 | AL14: 0 | AM14: 0 | AN14: 0 | AO14: 0 | AP14: 0 | AQ14: 0 | AR14: 0 | AS14: 0 | AT14: 0 | AU14: 48.81 | AV14: 0 | AW14: 123.18 | AX14: settled | AY14: 2026-01-14 05:30:00 | AZ14: CITIN26605478364 | BA14: 0 | BB14: 283295ca7113c41973cf12fa3a4a16efd65bcad191f9a4688318d79ad577295a
A15: 10 | B15: 7651882840 | C15: 2026-01-05 03:21:41 | D15: 2 | E15: Sha Sha - Shandaar Shawarma | F15: 18557902 | G15: 30% off upto ₹75 (2025-06-25 - 2031-01-01) | H15: ONLINE | I15: DELIVERED | J15: NA | K15: NA | L15: NA | M15: O2 | N15: 36 | O15: 268 | P15: 3.5 | Q15: 0 | R15: 75 | S15: 0 | T15: 0 | U15: 0 | V15: 9.83 | W15: 206.33 | X15: 196.5 | Y15: 19 | Z15: 37.34 | AA15: 3.8 | AB15: 41.14 | AC15: 7.4 | AD15: 0 | AE15: 196.5 | AF15: 0 | AG15: 0 | AH15: 0.2 | AI15: 9.83 | AJ15: 0 | AK15: 17.43 | AL15: 0 | AM15: 0 | AN15: 0 | AO15: 0 | AP15: 0 | AQ15: 0 | AR15: 0 | AS15: 0 | AT15: 0 | AU15: 58.57 | AV15: 0 | AW15: 147.76 | AX15: settled | AY15: 2026-01-14 05:30:00 | AZ15: CITIN26605478364 | BA15: 0 | BB15: 471e44d7671e66b504536185091a2e71f7e277da399310243ad4cde959a881c8
A16: 11 | B16: 7655255352 | C16: 2026-01-05 03:24:47 | D16: 2 | E16: Sha Sha - Shandaar Shawarma | F16: 18557902 | G16: 30% off upto ₹75 (2025-06-25 - 2031-01-01) | H16: ONLINE | I16: DELIVERED | J16: NA | K16: NA | L16: NA | M16: O2 | N16: 36 | O16: 219 | P16: 3.5 | Q16: 0 | R16: 65.7 | S16: 0 | T16: 0 | U16: 0 | V16: 7.84 | W16: 164.64 | X16: 156.8 | Y16: 19 | Z16: 29.79 | AA16: 3.03 | AB16: 32.82 | AC16: 5.91 | AD16: 0 | AE16: 156.8 | AF16: 0 | AG16: 0 | AH16: 0.16 | AI16: 7.85 | AJ16: -0.01 | AK16: 13.92 | AL16: 0 | AM16: 0 | AN16: 0 | AO16: 0 | AP16: 0 | AQ16: 0 | AR16: 0 | AS16: 0 | AT16: 0 | AU16: 46.74 | AV16: 0 | AW16: 117.9 | AX16: settled | AY16: 2026-01-14 05:30:00 | AZ16: CITIN26605478364 | BA16: 0 | BB16: 262e921dd159c062df7876d77e41d5cbd90a0b3eddebbbb26b147cf99f9ccbb7
A17: 12 | B17: 7653935930 | C17: 2026-01-05 03:44:03 | D17: 2 | E17: Sha Sha - Shandaar Shawarma | F17: 18557902 | G17: 30% off upto ₹75 (2025-06-25 - 2031-01-01) | H17: ONLINE | I17: DELIVERED | J17: NA | K17: NA | L17: NA | M17: O2 | N17: 36 | O17: 229 | P17: 3.5 | Q17: 0 | R17: 68.7 | S17: 0 | T17: 0 | U17: 0 | V17: 8.19 | W17: 171.99 | X17: 163.8 | Y17: 19 | Z17: 31.12 | AA17: 3.16 | AB17: 34.28 | AC17: 6.17 | AD17: 0 | AE17: 163.8 | AF17: 0 | AG17: 0 | AH17: 0.16 | AI17: 8.2 | AJ17: -0.01 | AK17: 14.53 | AL17: 0 | AM17: 0 | AN17: 0 | AO17: 0 | AP17: 0 | AQ17: 0 | AR17: 0 | AS17: 0 | AT17: 0 | AU17: 48.81 | AV17: 0 | AW17: 123.18 | AX17: settled | AY17: 2026-01-14 05:30:00 | AZ17: CITIN26605478364 | BA17: 0 | BB17: 42ba7bcede19cb228ac1b9b7f3a6410a78610aaae747ae2731c6c66fb6709154
... A331: 326 | B331: 7682180091 | C331: 2026-01-11 23:55:21 | D331: 2 | E331: Sha Sha - Shandaar Shawarma | F331: 18557902 | G331: 30% off upto ₹75 (2025-06-25 - 2031-01-01) | H331: ONLINE | I331: DELIVERED | J331: NA | K331: NA | L331: NA | M331: O2 | N331: 36 | O331: 458 | P331: 3.5 | Q331: 0 | R331: 75 | S331: 0 | T331: 0 | U331: 0 | V331: 19.33 | W331: 405.83 | X331: 386.5 | Y331: 19 | Z331: 73.44 | AA331: 7.47 | AB331: 80.91 | AC331: 14.56 | AD331: 0 | AE331: 386.5 | AF331: 0 | AG331: 0 | AH331: 0.39 | AI331: 19.33 | AJ331: 0 | AK331: 34.28 | AL331: 0 | AM331: 0 | AN331: 0 | AO331: 0 | AP331: 0 | AQ331: 0 | AR331: 0 | AS331: 0 | AT331: 0 | AU331: 115.19 | AV331: 0 | AW331: 290.64 | AX331: settled | AY331: 2026-01-14 05:30:00 | AZ331: CITIN26605478364 | BA331: 0 | BB331: f2331c06fce7437b2ae7836284653b4167b86b7c5a15f679b9ac72ee4b572167

Sheet D2W2
B1: Addition/ Deduction Details (non-order level additions & deductions and adjustments from previous weeks)
B2: Summarized view on : 1. Res id level additions like 194 H, etc 2. Res id level deductions like pay later, etc
B5: Addition Type
B6: Type | C6: NA | D6: Invoice No/Order id | E6: Order date | F6: Settlement status | G6: Total amount | H6: Adjusted amount | I6: Outstanding amount
B7: Total Additions | G7: 0 | H7: 0 | I7: 0
B10: Deduction Type
B11: A) Investments in growth services
B12: Type | C12: Res id for which deduction created | D12: Invoice No/Campaign id | E12: Deduction time period | F12: Settlement Status | G12: Total amount | H12: Adjusted amount | I12: Outstanding amount
B13: ADS | C13: 18557902 | D13: 33168698 | E13: 07 January 26 - 11 January 26 | F13: settled | G13: 4001.61 | H13: 4001.61 | I13: 0
B14: ADS | C14: 18557902 | D14: 33001818 | E14: 05 January 26 - 06 January 26 | F14: settled | G14: 892.08 | H14: 892.08 | I14: 0
B15: Total Ads & miscellaneous services | G15: 4893.69 | H15: 4893.69 | I15: 0
B17: B) Investments in Hyperpure
B18: Type | C18: Res id for which deduction created | D18: OrderId | E18: Deduction time period | F18: Settlement Status | G18: Total amount | H18: Adjusted amount | I18: Outstanding amount
B19: Total Hyperpure | G19: 0 | H19: 0 | I19: 0
B21: C) Other deductions
B22: D) Adjustments from previous weeks
B23: Total Deductions (A) + (B) + (C) | G23: 4893.69 | H23: 4893.69 | I23: 0

Sheet D1W3
O1: 219 | P1: 0 | Q1: 0 | R1: 0 | S1: 0 | T1: 0 | U1: 0 | V1: 0 | W1: 219 | X1: 0 | Y1: 0 | Z1: 0 | AA1: 0 | AB1: 0 | AC1: 0 | AD1: 0 | AE1: 0 | AF1: 0 | AG1: 0 | AH1: 0 | AI1: 0 | AJ1: 0 | AK1: 0 | AL1: 0 | AM1: 0 | AN1: 0 | AO1: 0 | AP1: 0 | AQ1: 0 | AR1: 0 | AS1: 0 | AT1: 0 | AU1: 0 | AV1: 167.32 | AW1: 167.32 | AX1: 0 | AY1: 0 | AZ1: 0 | BA1: 0 | BB1: 0
O2: 83250 | P2: 983.5 | Q2: 0 | R2: 16044.9 | S2: 0 | T2: 0 | U2: 76.65 | V2: 3406.18 | W2: 71518.13 | X2: 68111.95 | Y2: 5413.34 | Z2: 13020.02 | AA2: 1315.46 | AB2: 14335.48 | AC2: 2580.41 | AD2: 0 | AE2: 68111.95 | AF2: 0 | AG2: 0 | AH2: 67.89 | AI2: 3407.83 | AJ2: -1.65 | AK2: 6056.13 | AL2: 0 | AM2: 0 | AN2: 0 | AO2: 0 | AP2: 0 | AQ2: 0 | AR2: 0 | AS2: 0 | AT2: 0 | AU2: 20391.61 | AV2: 0 | AW2: 51126.52 | AX2: 0 | AY2: 0 | AZ2: 0 | BA2: 0 | BB2: 0
O3: 98235 | P3: 1160.53 | Q3: 0 | R3: 18932.982 | S3: 0 | T3: 0 | U3: 90.447 | V3: 4019.2924 | W3: 84391.393 | X3: 80372.101 | Y3: 6387.7412 | Z3: 15363.624 | AA3: 1552.2428 | AB3: 16915.866 | AC3: 3044.8838 | AD3: 0 | AE3: 80372.101 | AF3: 0 | AG3: 0 | AH3: 80.1102 | AI3: 4021.2394 | AJ3: -1.947 | AK3: 7146.2334 | AL3: 0 | AM3: 0 | AN3: 0 | AO3: 0 | AP3: 0 | AQ3: 0 | AR3: 0 | AS3: 0 | AT3: 0 | AU3: 24062.1 | AV3: 0 | AW3: 60329.294 | AX3: 0 | AY3: 0 | AZ3: 0 | BA3: 0 | BB3: 0
O4: 83469 | P4: 983.5 | Q4: 0 | R4: 16044.9 | S4: 0 | T4: 0 | U4: 76.65 | V4: 3406.18 | W4: 71737.13 | X4: 68111.95 | Y4: 5413.34 | Z4: 13020.02 | AA4: 1315.46 | AB4: 14335.48 | AC4: 2580.41 | AD4: 0 | AE4: 68111.95 | AF4: 0 | AG4: 0 | AH4: 67.89 | AI4: 3407.83 | AJ4: -1.65 | AK4: 6056.13 | AL4: 0 | AM4: 0 | AN4: 0 | AO4: 0 | AP4: 0 | AQ4: 0 | AR4: 0 | AS4: 0 | AT4: 0 | AU4: 20391.61 | AV4: 167.32 | AW4: 51293.84 | AX4: 0 | AY4: 0 | AZ4: 0 | BA4: 0 | BB4: 0
A5: S.No. | B5: Order ID | C5: Order Date | D5: Week No. | E5: Res. name | F5: Res. ID | G5: Discount Construct | H5: Mode of payment | I5: Order status (Delivered/ Cancelled/ Rejected) | J5: Cancellation policy (% Amount refunded back to restaurant partner) | K5: Cancellation/ Rejection Reason | L5: Cancelled/ Rejected State (Order status at the time it was cancelled/ rejected) | M5: Order type | N5: Delivery State code | O5: Subtotal (items total) | P5: Packaging charge | Q5: Delivery charge for restaurants on self logistics | R5: Restaurant discount [Promo] | S5: Restaurant Discount [BOGO, Freebies, Gold, Brand pack & others] | T5: Brand pack subscription fee | U5: Delivery charge discount / Relisting discount | V5: Total GST collected from customers | W5: Net order value [(1) + (2) + (3) - (4) - (5) + (6) - (7) + (8)] | X5: Commissionable value (excludes customer GST) [(A) + (7) - (8) - (6) - (3)] | Y5: Service fees % | Z5: Service fee [ (9) * (10) ] | AA5: Payment mechanism fee | AB5: Service fee & payment mechanism fees [(11) + (12)] | AC5: Taxes on service & payment mechanism fees (B) * 18% | AD5: Applicable amount for TCS | AE5: Applicable amount for 9(5) | AF5: Tax collected at source | AG5: TCS IGST amount | AH5: TDS 194O amount | AI5: GST paid by Zomato on behalf of restaurant - under section 9(5) | AJ5: GST to be paid by Restaurant partner to Govt. | AK5: Government charges [(13) + (16) + (17) + (18) + (19)] | AL5: Customer Compensation/Recoupment | AM5: Delivery Charges Recovery | AN5: Amount received in cash (on self delivery orders) | AO5: Credit note/(Debit Note) adjustment | AP5: Promo recovery adjustment | AQ5: Extra Inventory Ads and Misc. (order level deduction) | AR5: Brand loyalty points redemption | AS5: Express Order Fee | AT5: Other order-level deductions [(21) + (22) + (23) + (24) + (25) + (26) + (27) + (28)] | AU5: Net Deductions (B) + (C) + (D) | AV5: Net Additions (cancellation refund for cancelled orders/Tip for Kitchen Staff for delivered orders) | AW5: Order level Payout (A) - (E) + (F) | AX5: Settlement status | AY5: Settlement date | AZ5: Bank UTR | BA5: Unsettled Amount | BB5: Customer ID
A6: 1 | B6: 7682376457 | C6: 2026-01-12 00:08:40 | D6: 3 | E6: Sha Sha - Shandaar Shawarma | F6: 18557902 | G6: 30% off upto ₹75 (2025-06-25 - 2031-01-01) | H6: ONLINE | I6: DELIVERED | J6: NA | K6: NA | L6: NA | M6: O2 | N6: 36 | O6: 219 | P6: 3.5 | Q6: 0 | R6: 65.7 | S6: 0 | T6: 0 | U6: 0 | V6: 7.84 | W6: 164.64 | X6: 156.8 | Y6: 19 | Z6: 29.79 | AA6: 3.03 | AB6: 32.82 | AC6: 5.91 | AD6: 0 | AE6: 156.8 | AF6: 0 | AG6: 0 | AH6: 0.16 | AI6: 7.85 | AJ6: -0.01 | AK6: 13.92 | AL6: 0 | AM6: 0 | AN6: 0 | AO6: 0 | AP6: 0 | AQ6: 0 | AR6: 0 | AS6: 0 | AT6: 0 | AU6: 46.74 | AV6: 0 | AW6: 117.9 | AX6: settled | AY6: 2026-01-21 05:30:00 | AZ6: CITIN26608218588 | BA6: 0 | BB6: f5c9e83f465cca4cb652242402e9c88f2b5e870713999fb09c705218687db987
A7: 2 | B7: 7679626720 | C7: 2026-01-12 00:39:47 | D7: 3 | E7: Sha Sha - Shandaar Shawarma | F7: 18557902 | G7: NA | H7: ONLINE | I7: DELIVERED | J7: NA | K7: NA | L7: NA | M7: O2 | N7: 36 | O7: 219 | P7: 3.5 | Q7: 0 | R7: 0 | S7: 0 | T7: 0 | U7: 0 | V7: 11.13 | W7: 233.63 | X7: 222.5 | Y7: 19 | Z7: 42.28 | AA7: 4.3 | AB7: 46.58 | AC7: 8.38 | AD7: 0 | AE7: 222.5 | AF7: 0 | AG7: 0 | AH7: 0.22 | AI7: 11.13 | AJ7: 0 | AK7: 19.73 | AL7: 0 | AM7: 0 | AN7: 0 | AO7: 0 | AP7: 0 | AQ7: 0 | AR7: 0 | AS7: 0 | AT7: 0 | AU7: 66.31 | AV7: 0 | AW7: 167.32 | AX7: settled | AY7: 2026-01-21 05:30:00 | AZ7: CITIN26608218588 | BA7: 0 | BB7: 03b0f369757d36a84dd6be03dc85ab3d45803f6e2228b7325b95cf4412b13a22
A8: 3 | B8: 7676201056 | C8: 2026-01-12 00:41:16 | D8: 3 | E8: Sha Sha - Shandaar Shawarma | F8: 18557902 | G8: NA | H8: ONLINE | I8: DELIVERED | J8: NA | K8: NA | L8: NA | M8: O2 | N8: 36 | O8: 219 | P8: 3.5 | Q8: 0 | R8: 0 | S8: 0 | T8: 0 | U8: 0 | V8: 11.13 | W8: 233.63 | X8: 222.5 | Y8: 19 | Z8: 42.28 | AA8: 4.3 | AB8: 46.58 | AC8: 8.38 | AD8: 0 | AE8: 222.5 | AF8: 0 | AG8: 0 | AH8: 0.22 | AI8: 11.13 | AJ8: 0 | AK8: 19.73 | AL8: 0 | AM8: 0 | AN8: 0 | AO8: 0 | AP8: 0 | AQ8: 0 | AR8: 0 | AS8: 0 | AT8: 0 | AU8: 66.31 | AV8: 0 | AW8: 167.32 | AX8: settled | AY8: 2026-01-21 05:30:00 | AZ8: CITIN26608218588 | BA8: 0 | BB8: 03b0f369757d36a84dd6be03dc85ab3d45803f6e2228b7325b95cf4412b13a22
A9: 4 | B9: 7682261671 | C9: 2026-01-12 01:16:20 | D9: 3 | E9: Sha Sha - Shandaar Shawarma | F9: 18557902 | G9: 30% off upto ₹75 (2025-06-25 - 2031-01-01) | H9: ONLINE | I9: DELIVERED | J9: NA | K9: NA | L9: NA | M9: O2 | N9: 36 | O9: 229 | P9: 3.5 | Q9: 0 | R9: 68.7 | S9: 0 | T9: 0 | U9: 0 | V9: 8.19 | W9: 171.99 | X9: 163.8 | Y9: 19 | Z9: 31.12 | AA9: 3.16 | AB9: 34.28 | AC9: 6.17 | AD9: 0 | AE9: 163.8 | AF9: 0 | AG9: 0 | AH9: 0.16 | AI9: 8.2 | AJ9: -0.01 | AK9: 14.53 | AL9: 0 | AM9: 0 | AN9: 0 | AO9: 0 | AP9: 0 | AQ9: 0 | AR9: 0 | AS9: 0 | AT9: 0 | AU9: 48.81 | AV9: 0 | AW9: 123.18 | AX9: settled | AY9: 2026-01-21 05:30:00 | AZ9: CITIN26608218588 | BA9: 0 | BB9: 42ba7bcede19cb228ac1b9b7f3a6410a78610aaae747ae2731c6c66fb6709154
A10: 5 | B10: 7680525293 | C10: 2026-01-12 01:34:25 | D10: 3 | E10: Sha Sha - Shandaar Shawarma | F10: 18557902 | G10: 30% off upto ₹75 (2025-06-25 - 2031-01-01) | H10: ONLINE | I10: DELIVERED | J10: NA | K10: NA | L10: NA | M10: O2 | N10: 36 | O10: 229 | P10: 3.5 | Q10: 0 | R10: 68.7 | S10: 0 | T10: 0 | U10: 0 | V10: 8.19 | W10: 171.99 | X10: 163.8 | Y10: 19 | Z10: 31.12 | AA10: 3.16 | AB10: 34.28 | AC10: 6.17 | AD10: 0 | AE10: 163.8 | AF10: 0 | AG10: 0 | AH10: 0.16 | AI10: 8.2 | AJ10: -0.01 | AK10: 14.53 | AL10: 0 | AM10: 0 | AN10: 0 | AO10: 0 | AP10: 0 | AQ10: 0 | AR10: 0 | AS10: 0 | AT10: 0 | AU10: 48.81 | AV10: 0 | AW10: 123.18 | AX10: settled | AY10: 2026-01-21 05:30:00 | AZ10: CITIN26608218588 | BA10: 0 | BB10: 85681b30793b69fe38fddafcb9592a5130df6220a573056c642f0af64f18c080
A11: 6 | B11: 7680748388 | C11: 2026-01-12 01:34:50 | D11: 3 | E11: Sha Sha - Shandaar Shawarma | F11: 18557902 | G11: NA | H11: ONLINE | I11: CANCELLED | J11: 100% | K11: Customer cancellation because they do not require order anymore | L11: Order picked up by rider | M11: O2 | N11: NA | O11: 219 | P11: 0 | Q11: 0 | R11: 0 | S11: 0 | T11: 0 | U11: 0 | V11: 0 | W11: 219 | X11: 0 | Y11: 0 | Z11: 0 | AA11: 0 | AB11: 0 | AC11: 0 | AD11: 0 | AE11: 0 | AF11: 0 | AG11: 0 | AH11: 0 | AI11: 0 | AJ11: 0 | AK11: 0 | AL11: 0 | AM11: 0 | AN11: 0 | AO11: 0 | AP11: 0 | AQ11: 0 | AR11: 0 | AS11: 0 | AT11: 0 | AU11: 0 | AV11: 167.32 | AW11: 167.32 | AX11: settled | AY11: 2026-01-21 05:30:00 | AZ11: CITIN26608218588 | BA11: 0 | BB11: NA
A12: 7 | B12: 7676944403 | C12: 2026-01-12 02:21:25 | D12: 3 | E12: Sha Sha - Shandaar Shawarma | F12: 18557902 | G12: NA | H12: ONLINE | I12: DELIVERED | J12: NA | K12: NA | L12: NA | M12: RELISTING | N12: 36 | O12: 219 | P12: 0 | Q12: 0 | R12: 0 | S12: 0 | T12: 0 | U12: 76.65 | V12: 7.12 | W12: 149.47 | X12: 142.35 | Y12: 74.34 | Z12: 105.82 | AA12: 2.75 | AB12: 108.57 | AC12: 19.55 | AD12: 0 | AE12: 142.35 | AF12: 0 | AG12: 0 | AH12: 0.14 | AI12: 7.12 | AJ12: 0 | AK12: 26.81 | AL12: 0 | AM12: 0 | AN12: 0 | AO12: 0 | AP12: 0 | AQ12: 0 | AR12: 0 | AS12: 0 | AT12: 0 | AU12: 135.38 | AV12: 0 | AW12: 14.09 | AX12: settled | AY12: 2026-01-21 05:30:00 | AZ12: CITIN26608218588 | BA12: 0 | BB12: 3250297d4d034fec2592f1d04508bbee63452cff5c8486784adc4eadea919bbc
A13: 8 | B13: 7679370738 | C13: 2026-01-12 02:35:21 | D13: 3 | E13: Sha Sha - Shandaar Shawarma | F13: 18557902 | G13: 30% off upto ₹75 (2025-06-25 - 2031-01-01) | H13: ONLINE | I13: DELIVERED | J13: NA | K13: NA | L13: NA | M13: O2 | N13: 36 | O13: 229 | P13: 3.5 | Q13: 0 | R13: 68.7 | S13: 0 | T13: 0 | U13: 0 | V13: 8.19 | W13: 171.99 | X13: 163.8 | Y13: 19 | Z13: 31.12 | AA13: 3.16 | AB13: 34.28 | AC13: 6.17 | AD13: 0 | AE13: 163.8 | AF13: 0 | AG13: 0 | AH13: 0.16 | AI13: 8.2 | AJ13: -0.01 | AK13: 14.53 | AL13: 0 | AM13: 0 | AN13: 0 | AO13: 0 | AP13: 0 | AQ13: 0 | AR13: 0 | AS13: 0 | AT13: 0 | AU13: 48.81 | AV13: 0 | AW13: 123.18 | AX13: settled | AY13: 2026-01-21 05:30:00 | AZ13: CITIN26608218588 | BA13: 0 | BB13: c864cabf967482366bc1c469efc09862e44310c384611918b958675dd5273767
