Workbook

Sheet Summary
B1: Royal Dhaba (Greater Noida West)
B2: Zomato Summary - December - 2026
B4: Details | C4: 1st to 7th | D4: 8th to 14th | E4: 15th to 21st | F4: 22nd to 28th | G4: 29th to 31st | H4: Total
B6: No.of orders | C6: 33 | D6: 32 | E6: 32 | F6: 20 | G6: 11 | H6: =SUM(C6:G6)
B8: Total Income (Number that you see on Zomato dashboard) | C8: =Cashflow!C10 | D8: =Cashflow!D10 | E8: =Cashflow!E10 | F8: =Cashflow!F10 | G8: =Cashflow!G10 | H8: =SUM(C8:G8)
B10: Avg. order value | C10: =IFERROR(C8/C6,) | D10: =IFERROR(D8/D6,) | E10: =IFERROR(E8/E6,) | F10: =IFERROR(F8/F6,) | G10: =IFERROR(G8/G6,) | H10: =IFERROR(H8/H6,)
B12: No of disputed orders | C12: 0 | D12: 0 | E12: 0 | F12: 0 | G12: 0 | H12: =SUM(C12:G12)
B14: Refund amount for disputed orders | C14: =Cashflow!C18 | D14: =Cashflow!D18 | E14: =Cashflow!E18 | F14: =Cashflow!F18 | G14: =Cashflow!G18 | H14: =SUM(C14:G14)
B16: Discounts | C16: =Cashflow!C8 | D16: =Cashflow!D8 | E16: =Cashflow!E8 | F16: =Cashflow!F8 | G16: =Cashflow!G8 | H16: =SUM(C16:G16)
C17: =IFERROR(C16/C8,) | D17: =IFERROR(D16/D8,) | E17: =IFERROR(E16/E8,) | F17: =IFERROR(F16/F8,) | G17: =IFERROR(G16/G8,) | H17: =IFERROR(H16/H8,)
B19: Commisonable Amount | C19: 11617.25 | D19: 14097.8 | E19: 11948 | F19: 6796.56 | G19: 4066.8 | H19: =SUM(C19:G19)
B20: Commission | C20: =Cashflow!C11 | D20: =Cashflow!D11 | E20: =Cashflow!E11 | F20: =Cashflow!F11 | G20: =Cashflow!G11 | H20: =SUM(C20:G20)
B21: (Calculated on Sales + GST) | C21: =IFERROR(C20/C19,) | D21: =IFERROR(D20/D19,) | E21: =IFERROR(E20/E19,) | F21: =IFERROR(F20/F19,) | G21: =IFERROR(G20/G19,) | H21: =IFERROR(H20/H19,)
B23: Marketing & Ads | C23: =Cashflow!C21 | D23: =Cashflow!D21 | E23: =Cashflow!E21 | F23: =Cashflow!F21 | G23: =Cashflow!G21 | H23: =SUM(C23:G23)
C24: =IFERROR(C23/C8,) | D24: =IFERROR(D23/D8,) | E24: =IFERROR(E23/E8,) | F24: =IFERROR(F23/F8,) | G24: =IFERROR(G23/G8,) | H24: =IFERROR(H23/H8,)
B27: Other charges & Tax Adjustments | C27: =Cashflow!C13+Cashflow!C26 | D27: =Cashflow!D13+Cashflow!D26 | E27: =Cashflow!E13+Cashflow!E26 | F27: =Cashflow!F13+Cashflow!F26 | G27: =Cashflow!G13+Cashflow!G26 | H27: =SUM(C27:G27)
C28: =IFERROR(C27/C8,) | D28: =IFERROR(D27/D8,) | E28: =IFERROR(E27/E8,) | F28: =IFERROR(F27/F8,) | G28: =IFERROR(G27/G8,) | H28: =IFERROR(H27/H8,)
B32: Zomato Hyperpure Adjustments | C32: =Cashflow!C36 | D32: =Cashflow!D36 | E32: =Cashflow!E36 | F32: =Cashflow!F36 | G32: =Cashflow!G36 | H32: =SUM(C32:G32)
B35: Money received | C35: =C8-C14-C20-C23-C27-C32 | D35: =D8-D14-D20-D23-D27-D32 | E35: =E8-E14-E20-E23-E27-E32 | F35: =F8-F14-F20-F23-F27-F32+Cashflow!F31 | G35: =G8-G14-G20-G23-G27-G32 | H35: =SUM(C35:G35)
C36: =IFERROR(C35/$C$8,) | D36: =IFERROR(D35/$D$8,) | E36: =IFERROR(E35/$E$8,) | F36: =IFERROR(F35/F8,) | G36: =IFERROR(G35/G8,) | H36: =IFERROR(H35/H8,)

Sheet Cashflow
A1: =Summary!B1
A2: Zomato Cash Flow - December - 2026
A4: S.No | B4: Details | C4: =Summary!C4 | D4: =Summary!D4 | E4: =Summary!E4 | F4: =Summary!F4 | G4: =Summary!G4 | H4: Total
A5: 1 | B5: Item sales (Delivered orders) | C5: ='D1W1'!O2 | D5: ='D1W2'!O2 | E5: ='D1W3'!O2 | F5: ='D1W4'!O2 | G5: ='D1W5'!O2 | H5: =SUM(C5:G5)
B6: Add:- Packing charges | C6: ='D1W1'!P2 | D6: ='D1W2'!P2 | E6: ='D1W3'!P2 | F6: ='D1W4'!P2 | G6: ='D1W5'!P2 | H6: =SUM(C6:G6)
B7: Add:- Compensation paid for cancelled orders | C7: ='D1W1'!BC1 | D7: ='D1W2'!BC1 | E7: ='D1W3'!BC1 | F7: ='D1W4'!BC1 | G7: ='D1W5'!BC1 | H7: =SUM(C7:G7)
B8: Less:- Discount | C8: ='D1W1'!R2+'D1W1'!S2+'D1W1'!U2 | D8: ='D1W2'!R2+'D1W2'!S2+'D1W2'!U2 | E8: ='D1W3'!R2+'D1W3'!S2+'D1W3'!U2 | F8: ='D1W4'!R2+'D1W4'!S2+'D1W4'!U2 | G8: ='D1W5'!R2+'D1W5'!S2+'D1W5'!U2 | H8: =SUM(C8:G8)
B9: Add:- GST | C9: ='D1W1'!V2 | D9: ='D1W2'!V2 | E9: ='D1W3'!V2 | F9: ='D1W4'!V2 | G9: ='D1W5'!V2 | H9: =SUM(C9:G9) | M9: Gst | N9: Tds
B10: Net Sales | C10: =C5+C6+C9+C7-C8 | D10: =D5+D6+D9+D7-D8 | E10: =E5+E6+E9+E7-E8 | F10: =F5+F6+F9+F7-F8 | G10: =G5+G6+G9+G7-G8 | H10: =H5+H6+H9+H7-H8 | M10: =H10-H29 | N10: =H12*100/118
A11: 2 | B11: Less:- Commission | C11: =C12 | D11: =D12 | E11: =E12 | F11: =F12 | G11: =G12 | H11: =H12
B12: Platform Fee | C12: ='D1W1'!AC3 | D12: ='D1W2'!AC3 | E12: ='D1W3'!AC3 | F12: ='D1W4'!AC3 | G12: ='D1W5'!AC3 | H12: =SUM(C12:G12)
A13: 3 | B13: Less:- Other Charges | C13: =C14+C16-C15+C17 | D13: =D14+D16-D15+D17 | E13: =E14+E16-E15+E17 | F13: =F14+F16-F15+F17 | G13: =G14+G16-G15+G17 | H13: =H14+H16-H15+H17
B14: Convenience Fee | C14: ='D1W1'!AH3 | D14: ='D1W2'!AH3 | E14: ='D1W3'!AH3 | F14: ='D1W4'!AH3 | G14: ='D1W5'!AH3 | H14: =SUM(C14:G14)
B15: Discount on Service Fee | C15: ='D1W1'!AG3 | D15: ='D1W2'!AG3 | E15: ='D1W3'!AG3 | F15: ='D1W4'!AG3 | G15: ='D1W5'!AG3 | H15: =SUM(C15:G15) | L15: netsales | M15: =C10+C8-C29 | N15: =D10+D8-D29 | O15: =E10+E8-E29 | P15: =F10+F8-F29 | Q15: =G10+G8-G29
B16: Long Distance Fee | C16: ='D1W1'!AE3-'D1W1'!AF3 | D16: ='D1W2'!AE3-'D1W2'!AF3 | E16: ='D1W3'!AE3-'D1W3'!AF3 | F16: ='D1W4'!AE3-'D1W4'!AF3 | G16: ='D1W5'!AE3-'D1W5'!AF3 | H16: =SUM(C16:G16) | L16: disc | M16: =C8 | N16: =D8 | O16: =E8 | P16: =F8 | Q16: =G8
A17: 4 | B17: Merchant Cancellation Charges | C17: 0 | D17: 0 | E17: 0 | F17: 0 | G17: 0 | H17: =SUM(C17:G17) | L17: comm | M17: =C12-C15 | N17: =D12-D15 | O17: =E12-E15 | P17: =F12-F15 | Q17: =G12-G15
B18: Less:- Refunds | C18: =SUM(C19:C20) | D18: =SUM(D19:D20) | E18: =SUM(E19:E20) | F18: =SUM(F19:F20) | G18: =SUM(G19:G20) | H18: =H19+H20 | L18: tds ecom | M18: =C27 | N18: =D27 | O18: =E27 | P18: =F27 | Q18: =G27
B19: Paid by Restaurant | C19: ='D1W1'!AS4 | D19: ='D1W2'!AS4 | E19: ='D1W3'!AS4 | F19: ='D1W4'!AS4 | G19: ='D1W5'!AS4 | H19: =SUM(C19:G19) | L19: conve | M19: =C14 | N19: =D14 | O19: =E14 | P19: =F14 | Q19: =G14
A20: 5 | B20: Received by Restaurant | C20: 0 | D20: 0 | E20: 0 | F20: 0 | G20: 0 | H20: =SUM(C20:G20) | L20: othe cha | M20: =C16 | N20: =D16 | O20: =E16 | P20: =F16 | Q20: =G16
B21: Less:- Marketing Charges | C21: =C22+C23+C24 | D21: =D22+D23+D24 | E21: =E22+E23+E24 | F21: =F22+F23+F24 | G21: =G22+G23+G24 | H21: =H22+H23+H24 | L21: tds | M21: =(C12*100/118)*2% | N21: =(D12*100/118)*2% | O21: =(E12*100/118)*2% | P21: =(F12*100/118)*2% | Q21: =(G12*100/118)*2%
B22: High Priority | C22: ='D2W1'!G15-'D2W1'!G7 + 'D1W1'!AX4 | D22: ='D2W2'!G14-'D2W2'!G7 + 'D1W2'!AX4 | E22: ='D2W3'!G15-'D2W3'!G7 + 'D1W3'!AX4 | F22: ='D2W4'!G15-'D2W4'!G7 + 'D1W4'!AX4 | G22: ='D2W5'!G15-'D2W5'!G7 + 'D1W5'!AX4 | H22: =SUM(C22:G22)
B23: Call Center Service Fees | C23: 0 | D23: 0 | E23: 0 | F23: 0 | G23: 0 | H23: =SUM(C23:G23)
B24: PocketHero Fee | C24: 0 | D24: 0 | E24: 0 | F24: 0 | G24: 0 | H24: =SUM(C24:G24)
A25: 6 | B25: Profit from Zomato | C25: =C10-C11-C18-C21-C13-C29 | D25: =D10-D11-D18-D21-D13-D29 | E25: =E10-E11-E18-E21-E13-E29 | F25: =F10-F11-F18-F21-F13-F29 | G25: =G10-G11-G18-G21-G13-G29 | H25: =H10-H11-H18-H21-H13-H29
B26: Less:- Tax Adjustments | C26: =SUM(C27:C29) | D26: =SUM(D27:D29) | E26: =SUM(E27:E29) | F26: =SUM(F27:F29) | G26: =SUM(G27:G29) | H26: =SUM(H27:H29)
B27: TDS deduction for aggrigators | C27: ='D1W1'!AO4 | D27: ='D1W2'!AO4 | E27: ='D1W3'!AO4 | F27: ='D1W4'!AO4 | G27: ='D1W5'!AO4 | H27: =SUM(C27:G27)
B28: TCS | C28: ='D1W1'!AN4+'D1W1'!AM4 | D28: ='D1W2'!AN4+'D1W2'!AM4 | E28: ='D1W3'!AN4+'D1W3'!AM4 | F28: ='D1W4'!AN4+'D1W4'!AM4 | G28: ='D1W5'!AN4+'D1W5'!AM4 | H28: =SUM(C28:G28)
A29: 7 | B29: GST collected and paid by Zomato | C29: ='D1W1'!AP4 | D29: ='D1W2'!AP4 | E29: ='D1W3'!AP4 | F29: ='D1W4'!AP4 | G29: ='D1W5'!AP4 | H29: =SUM(C29:G29)
B30: Expected Receipts | C30: =C25-C27-C28-C34 | D30: =D25-D27-D28-D34 | E30: =E25-E27-E28-E34 | F30: =F25-F27-F28-F34 | G30: =G25-G27-G28-G34 | H30: =H25-H27-H28-H34
B31: Service Fee Reversal | C31: 0 | D31: 0 | E31: 0 | F31: 0 | G31: 0 | H31: =SUM(C31:G31)
B32: Interim payments | C32: 0 | D32: 0 | E32: 0 | F32: 0 | G32: 0 | H32: =SUM(C32:G32)
B33: Opening Week Adjustments | C33: 0 | D33: 0 | E33: 0 | F33: 0 | G33: 0 | H33: =SUM(C33:G33)
B34: Following Week Adjustments | C34: 0 | D34: 0 | E34: 0 | F34: 0 | G34: 0 | H34: =SUM(C34:G34)
B35: Closing Week Adjustments | C35: 0 | D35: 0 | E35: 0 | F35: 0 | G35: 3165.99 | H35: =SUM(C35:G35)
B36: Zomato hyperpure Payment Adjustments | C36: ='D2W1'!G19 | D36: ='D2W2'!G18 | E36: ='D2W3'!G19 | F36: ='D2W4'!G19 | G36: ='D2W5'!G19 | H36: =SUM(C36:G36)
B37: EMI Loan deductions | C37: 0 | D37: 0 | E37: 0 | F37: 0 | G37: 0 | H37: =SUM(C37:G37)
A38: 8 | B38: Actual receipts | C38: 0 | D38: 0 | E38: 0 | F38: 0 | G38: 0 | H38: =SUM(C38:G38)
B39: Difference | C39: =C30-C38-C36+C33+C35 | D39: =D30-D38-D36-D33+D35 | E39: =E30-E38-E36-E33+E35 | F39: =F30-F38-F36-F33+F35-F34-F32 | G39: =G30-G38-G36-G33+G35 | H39: =H30-H38-H36+H33+H35-H34-H32
B41: Note :

Sheet Profit statement
A1: =Summary!B1
A2: Zomato Profit Statement - December - 2026
A4: Details | B4: =Summary!C4 | C4: =Summary!D4 | D4: =Summary!E4 | E4: =Summary!F4 | F4: =Summary!G4 | G4: =Summary!H4
A5: A. Net Sales
A6: Total Income | B6: =Cashflow!C5+Cashflow!C6+Cashflow!C9-Cashflow!C8-Cashflow!C29 | C6: =Cashflow!D5+Cashflow!D6+Cashflow!D9-Cashflow!D8-Cashflow!D29 | D6: =Cashflow!E5+Cashflow!E6+Cashflow!E9-Cashflow!E8-Cashflow!E29 | E6: =Cashflow!F5+Cashflow!F6+Cashflow!F9-Cashflow!F8-Cashflow!F29 | F6: =Cashflow!G5+Cashflow!G6+Cashflow!G9-Cashflow!G8-Cashflow!G29 | G6: =SUM(B6:F6)
A7: Add- Adjust: Cancelled orders (By Zomato) | B7: =Cashflow!C7 | C7: =Cashflow!D7 | D7: =Cashflow!E7 | E7: =Cashflow!F7 | F7: =Cashflow!G7 | G7: =SUM(B7:F7)
A8: Net Sales (Number that you see on Numerize app) | B8: =B6+B7 | C8: =C6+C7 | D8: =D6+D7 | E8: =E6+E7 | F8: =F6+F7 | G8: =G6+G7
A10: B. Less:- Commission | B10: =Cashflow!C11 | C10: =Cashflow!D11 | D10: =Cashflow!E11 | E10: =Cashflow!F11 | F10: =Cashflow!G11 | G10: =SUM(B10:F10)
A12: C. Less:- Marketing & Ads | B12: =Cashflow!C21 | C12: =Cashflow!D21 | D12: =Cashflow!E21 | E12: =Cashflow!F21 | F12: =Cashflow!G21 | G12: =SUM(B12:F12)
A14: D. Less:- Refund on disputed orders | B14: =Cashflow!C18 | C14: =Cashflow!D18 | D14: =Cashflow!E18 | E14: =Cashflow!F18 | F14: =Cashflow!G18 | G14: =SUM(B14:F14)
A16: E. Other charges | B16: =Cashflow!C13 | C16: =Cashflow!D13 | D16: =Cashflow!E13 | E16: =Cashflow!F13 | F16: =Cashflow!G13 | G16: =SUM(B16:F16)
A18: F. Profit | B18: =B8-B10-B12-B14-B16 | C18: =C8-C10-C12-C14-C16 | D18: =D8-D10-D12-D14-D16 | E18: =E8-E10-E12-E14-E16 | F18: =F8-F10-F12-F14-F16 | G18: =G8-G10-G12-G14-G16
A19: Percentage | B19: =IFERROR(B18/B8,0) | C19: =IFERROR(C18/C8,0) | D19: =IFERROR(D18/D8,0) | E19: =IFERROR(E18/E8,0) | F19: =IFERROR(F18/F8,0) | G19: =G18/G8

Sheet Discrepancies
A1: =Summary!B1
A2: Zomato Discrepancies - December - 2026
A4: Details | B4: =Summary!C4 | C4: =Summary!D4 | D4: =Summary!E4 | E4: =Summary!F4 | F4: =Summary!G4 | G4: =Summary!H4
A5: A. POS discrepancies
A6: Sales as per Zomato | B6: =Cashflow!C10 | C6: =Cashflow!D10 | D6: =Cashflow!E10 | E6: =Cashflow!F10 | F6: =Cashflow!G10 | G6: =SUM(B6:F6)
A7: Sale as per POS | G7: =SUM(B7:F7)
A8: Difference | B8: =B7-B6 | C8: =C7-C6 | D8: =D7-D6 | E8: =E7-E6 | F8: =F7-F6 | G8: =G7-G6
B9: =IFERROR(B8/B6,) | C9: =IFERROR(C8/C6,0) | D9: =IFERROR(D8/D6,0) | E9: =IFERROR(E8/E6,0) | F9: =IFERROR(F8/F6,0) | G9: =IFERROR(G8/G6,0)
A11: B. Order discrepancies
A12: No.of delivered orders for which payment isn't received | B12: 0 | C12: 0 | D12: 0 | E12: 0 | F12: 0 | G12: =SUM(B12:F12)
A13: Value of such orders | B13: 0 | C13: 0 | D13: 0 | E13: 0 | F13: 0 | G13: =SUM(B13:F13)
A16: C. Payment discrepancies
A17: Expected receipts in the bank account | B17: =Cashflow!C30 | C17: =Cashflow!D30 | D17: =Cashflow!E30 | E17: =Cashflow!F30 | F17: =Cashflow!G30 | G17: =SUM(B17:F17)
A18: Investment in Hyperpure | B18: =Cashflow!C36 | C18: =Cashflow!D36 | D18: =Cashflow!E36 | E18: =Cashflow!F36 | F18: =Cashflow!G36 | G18: =SUM(B18:F18)
A19: Following Week Adjustment | B19: =Cashflow!C34 | C19: =Cashflow!D34 | D19: =Cashflow!E34 | E19: =Cashflow!F34 | F19: =Cashflow!G34 | G19: =SUM(B19:F19)
A20: Opening Week Adjustment | B20: =Cashflow!C33 | C20: =Cashflow!D33 | D20: =Cashflow!E33 | E20: =Cashflow!F33 | F20: 0 | G20: =SUM(B20:F20)
A21: Closing Week Adjustment | B21: =Cashflow!C35 | C21: =Cashflow!D35 | D21: =Cashflow!E35 | E21: =Cashflow!F35 | F21: =Cashflow!G35 | G21: =SUM(B21:F21)
A22: Actual receipts in the bank | B22: =Cashflow!C38 | C22: =Cashflow!D38 | D22: =Cashflow!E38 | E22: =Cashflow!F38 | F22: =Cashflow!G38 | G22: =SUM(B22:F22)
A23: Difference | B23: =B17-B22-B18+B20 | C23: =C17-C22-C18 | D23: =D17-D22-D18 | E23: =E17-E22-E18-E19 | F23: =F17-F22-F18+F21 | G23: =G17-G22-G18+G20-G19
A25: Note:

Sheet POS

Sheet BANK
B5: 1 | C5: 2 | D5: 3 | E5: 4 | F5: 5
A10: Date | B10: Narration | C10: Chq./Ref.No. | D10: Value Dt | E10: Withdrawal Amt. | F10: Deposit Amt. | G10: Closing Balance
A11: 01/10/25 | B11: NEFT CR-YESB0000001-ONE 97 COMMUNICATIONS LIMITED SETTL-ROCKTAIL HOSPITALITY SERVICES-YESBN12025100101816795 | C11: YESBN12025100101816795 | D11: 01/10/25 | F11: 28308.11 | G11: 369938.81
A12: 01/10/25 | B12: NEFT CR-RATN0000999-PINE LABS LIMITED-ROCKTAIL HOSPITALITY SERVICES-RATNN52025100142548753 | C12: RATNN52025100142548753 | D12: 01/10/25 | F12: 988.02 | G12: 370926.83
A13: 01/10/25 | B13: 42552394TERMINAL 1 CARDS SETTL. 01/10/25 | C13: 000000000000000 | D13: 01/10/25 | F13: 4135.06 | G13: 375061.89
A14: 01/10/25 | B14: UPI-8978287178PTYES-8978287178@PTYES-UBIN0813567-564035906635-UPI | C14: 0000564035906635 | D14: 01/10/25 | E14: 165 | G14: 374896.89
A15: 01/10/25 | B15: 50200069817641-TPT-NBLCVTK6KLDPDJXS-WOLFFPACK VENTURES PRIVATE LIMITED | C15: 0000000223256296 | D15: 01/10/25 | F15: 200000 | G15: 574896.89
A16: 01/10/25 | B16: VENDOR PAYMENTS - ROCKTAIL HOSPITALITY DR - 57500000326520 - NEFT TRANSITORY ACCOUNT | C16: 0000000000000188 | D16: 01/10/25 | E16: 390734 | G16: 184162.89
A17: 01/10/25 | B17: UPI-SHREY SINGH-SHREYSINGH0501-1@OKHDFCBANK-HDFC0004216-564012927870-REGISTRATION | C17: 0000564012927870 | D17: 01/10/25 | E17: 8700 | G17: 175462.89
A18: 01/10/25 | B18: NEFT RETURN-INCORRECT ACCOUNT NUMBER-LAXMI AGENCIES-IBKLN92025100194760959 | C18: HDFCN52025100104276617 | D18: 01/10/25 | F18: 8322 | G18: 183784.89
A19: 01/10/25 | B19: NEFT RETURN-INCORRECT ACCOUNT NUMBER-LAXMI AGENCIES-IBKLN92025100194760962 | C19: HDFCN52025100104276606 | D19: 01/10/25 | F19: 8316 | G19: 192100.89
A20: 01/10/25 | B20: NEFT CR-CITI0000002-ETERNAL LIMITED-ROCKTAIL HOSPITALITY SERVICES-CITIN52025100134584901 | C20: CITIN52025100134584901 | D20: 01/10/25 | F20: 22470.51 | G20: 214571.4
A21: 01/10/25 | B21: NEFT CR-UTIB0000052-BUNDL TECHNOLOGIES PRIVATE LIMITED-ROCKTAIL HOSPITALITY SERVICES-UTIBN62025100172850989 | C21: UTIBN62025100172850989 | D21: 01/10/25 | F21: 28624.05 | G21: 243195.45
A22: 01/10/25 | B22: FT - DR - 50200086201346 - SRI CHAKRA ENTERPRISES | C22: 0000000000000187 | D22: 01/10/25 | E22: 68400 | G22: 174795.45
A23: 01/10/25 | B23: CQ NO-000187 AMOUNT-100323 TRANSFERS 4 DR - 50200088485779 - NSP ENTERPRISES | C23: 000000000000000 | D23: 01/10/25 | E23: 12843 | G23: 161952.45
A24: 01/10/25 | B24: CQ NO-000187 AMOUNT-100323 TRANSFERS 4 DR - 50200082063860 - AAMODHA ENTERPRISES | C24: 000000000000000 | D24: 01/10/25 | E24: 16560 | G24: 145392.45
A25: 01/10/25 | B25: CQ NO-000187 AMOUNT-100323 TRANSFERS 4 DR - 50200034371828 - SRIHITHA DISTRIBUTORS | C25: 000000000000000 | D25: 01/10/25 | E25: 2520 | G25: 142872.45
A26: 01/10/25 | B26: UPI-SRI LAXMI CHENNAKESA-Q560982817@YBL-YESB0YBLUPI-112039563850-POOJA | C26: 0000112039563850 | D26: 01/10/25 | E26: 1651 | G26: 141221.45
A27: 01/10/25 | B27: NEFT CR-YESB0000001-SWIGGY LIMITED-ROCKTAIL HOSPITALITY SERVICES-YESBN12025100106534132 | C27: YESBN12025100106534132 | D27: 01/10/25 | F27: 37494.72 | G27: 178716.17
A28: 02/10/25 | B28: NEFT CR-YESB0000001-ONE 97 COMMUNICATIONS LIMITED SETTL-ROCKTAIL HOSPITALITY SERVICES-YESBN12025100202440556 | C28: YESBN12025100202440556 | D28: 02/10/25 | F28: 28924.86 | G28: 207641.03
A29: 02/10/25 | B29: 42552394TERMINAL 1 CARDS SETTL. 02/10/25 | C29: 000000000000000 | D29: 02/10/25 | F29: 6676.28 | G29: 214317.31
A30: 03/10/25 | B30: NEFT CR-YESB0000001-ONE 97 COMMUNICATIONS LIMITED SETTL-ROCKTAIL HOSPITALITY SERVICES-YESBN12025100302342936 | C30: YESBN12025100302342936 | D30: 03/10/25 | F30: 38471.91 | G30: 252789.22
A31: 03/10/25 | B31: 42552394TERMINAL 1 CARDS SETTL. 03/10/25 | C31: 000000000000000 | D31: 03/10/25 | F31: 13411.99 | G31: 266201.21
A32: 03/10/25 | B32: UPI-BHANWRA RAM-BHANWARJATCHOUDHARY251@OKSBI-SBIN0011306-564239417166-FURNITURE | C32: 0000564239417166 | D32: 03/10/25 | E32: 35000 | G32: 231201.21
A33: 03/10/25 | B33: NEFT CR-UTIB0000052-BUNDL TECHNOLOGIES PRIVATE LIMITED-ROCKTAIL HOSPITALITY SERVICES-UTIBN62025100395892591 | C33: UTIBN62025100395892591 | D33: 03/10/25 | F33: 13038.51 | G33: 244239.72
A34: 04/10/25 | B34: NEFT CR-YESB0000001-ONE 97 COMMUNICATIONS LIMITED SETTL-ROCKTAIL HOSPITALITY SERVICES-YESBN12025100403632181 | C34: YESBN12025100403632181 | D34: 04/10/25 | F34: 53035 | G34: 297274.72
A35: 04/10/25 | B35: 42552394TERMINAL 1 CARDS SETTL. 04/10/25 | C35: 000000000000000 | D35: 04/10/25 | F35: 10812.69 | G35: 308087.41
A36: 04/10/25 | B36: UPI-SWIGGY LIMITED-SWIGGY.STORES@AXB-UTIB0000100-527751059928-PAY FOR INTENT | C36: 0000527751059928 | D36: 04/10/25 | E36: 856 | G36: 307231.41
A37: 05/10/25 | B37: NEFT CR-YESB0000001-ONE 97 COMMUNICATIONS LIMITED SETTL-ROCKTAIL HOSPITALITY SERVICES-YESBN12025100501829191 | C37: YESBN12025100501829191 | D37: 05/10/25 | F37: 72645.73 | G37: 379877.14
A38: 05/10/25 | B38: 42552394TERMINAL 1 CARDS SETTL. 05/10/25 | C38: 000000000000000 | D38: 05/10/25 | F38: 17370.83 | G38: 397247.97
A39: 05/10/25 | B39: SETTLEMENT CHARGE-SEP25-CPY597 | C39: 000000000000000 | D39: 05/10/25 | E39: 37.76 | G39: 397210.21
A40: 06/10/25 | B40: NEFT CR-YESB0000001-ONE 97 COMMUNICATIONS LIMITED SETTL-ROCKTAIL HOSPITALITY SERVICES-YESBN12025100601953902 | C40: YESBN12025100601953902 | D40: 06/10/25 | F40: 65856.98 | G40: 463067.19
A41: 06/10/25 | B41: EMI 162047443 CHQ S16204744314 1025162047443 | C41: 000000000000000 | D41: 06/10/25 | E41: 70666 | G41: 392401.19
A42: 06/10/25 | B42: 42552394TERMINAL 1 CARDS SETTL. 06/10/25 | C42: 000000000000000 | D42: 06/10/25 | F42: 1635.17 | G42: 394036.36
A43: 06/10/25 | B43: NEFT CR-CITI0000002-ETERNAL LIMITED-ROCKTAIL HOSPITALITY SERVICES-CITIN52025100636240957 | C43: CITIN52025100636240957 | D43: 06/10/25 | F43: 61201.16 | G43: 455237.52
A44: 07/10/25 | B44: NEFT CR-YESB0000001-ONE 97 COMMUNICATIONS LIMITED SETTL-ROCKTAIL HOSPITALITY SERVICES-YESBN12025100701113506 | C44: YESBN12025100701113506 | D44: 07/10/25 | F44: 24613.36 | G44: 479850.88
A45: 07/10/25 | B45: 42552394TERMINAL 1 CARDS SETTL. 07/10/25 | C45: 000000000000000 | D45: 07/10/25 | F45: 9641.79 | G45: 489492.67
A46: 07/10/25 | B46: NEFT CR-YESB0000001-SWIGGY LIMITED-ROCKTAIL HOSPITALITY SERVICES-YESBN12025100705709842 | C46: YESBN12025100705709842 | D46: 07/10/25 | F46: 83057.26 | G46: 572549.93
A47: 08/10/25 | B47: NEFT CR-YESB0000001-ONE 97 COMMUNICATIONS LIMITED SETTL-ROCKTAIL HOSPITALITY SERVICES-YESBN12025100800862936 | C47: YESBN12025100800862936 | D47: 08/10/25 | F47: 17786 | G47: 590335.93
A48: 08/10/25 | B48: 42552394TERMINAL 1 CARDS SETTL. 08/10/25 | C48: 000000000000000 | D48: 08/10/25 | F48: 5938.15 | G48: 596274.08
...

Sheet D1W1
O1: 0 | P1: 0 | Q1: 0 | R1: 0 | S1: 0 | T1: 0 | U1: 0 | V1: 0 | W1: 0 | X1: 0 | Y1: 0 | Z1: 0 | AA1: 0 | AB1: 0 | AC1: 0 | AD1: 0 | AE1: 0 | AF1: 0 | AG1: 0 | AH1: 0 | AI1: 0 | AJ1: 0 | AK1: 0 | AL1: 0 | AM1: 0 | AN1: 0 | AO1: 0 | AP1: 0 | AQ1: 0 | AR1: 0 | AS1: 0 | AT1: 0 | AU1: 0 | AV1: 0 | AW1: 0 | AX1: 0 | AY1: 0 | AZ1: 0 | BA1: 0 | BB1: 0 | BC1: 0 | BD1: 0 | BE1: 0 | BF1: 0 | BG1: 0 | BH1: 0 | BI1: 0
O2: 16332 | P2: 0 | Q2: 0 | R2: 3521.5 | S2: 1193.25 | T2: 0 | U2: 0 | V2: 580.94 | W2: 12198.19 | X2: 11617.25 | Y2: 0 | Z2: 0 | AA2: 11617.25 | AB2: 759 | AC2: 2671.99 | AD2: 119.14 | AE2: 300 | AF2: 0 | AG2: 40.86 | AH2: 224.47 | AI2: 3155.6 | AJ2: 568.03 | AK2: 0 | AL2: 11617.25 | AM2: 0 | AN2: 0 | AO2: 11.63 | AP2: 580.91 | AQ2: 0.03 | AR2: 1160.57 | AS2: 0 | AT2: 0 | AU2: 0 | AV2: 0 | AW2: 0 | AX2: 0 | AY2: 0 | AZ2: 0 | BA2: 0 | BB2: 4316.17 | BC2: 0 | BD2: 7882.02 | BE2: 0 | BF2: 0 | BG2: 0 | BH2: 0 | BI2: 0
O3: 19271.76 | P3: 0 | Q3: 0 | R3: 4155.37 | S3: 1408.035 | T3: 0 | U3: 0 | V3: 685.5092 | W3: 14393.864 | X3: 13708.355 | Y3: 0 | Z3: 0 | AA3: 13708.355 | AB3: 895.62 | AC3: 3152.9482 | AD3: 140.5852 | AE3: 354 | AF3: 0 | AG3: 48.2148 | AH3: 264.8746 | AI3: 3723.608 | AJ3: 670.2754 | AK3: 0 | AL3: 13708.355 | AM3: 0 | AN3: 0 | AO3: 13.7234 | AP3: 685.4738 | AQ3: 0.0354 | AR3: 1369.4726 | AS3: 0 | AT3: 0 | AU3: 0 | AV3: 0 | AW3: 0 | AX3: 0 | AY3: 0 | AZ3: 0 | BA3: 0 | BB3: 5093.0806 | BC3: 0 | BD3: 9300.7836 | BE3: 0 | BF3: 0 | BG3: 0 | BH3: 0 | BI3: 0
O4: 16332 | P4: 0 | Q4: 0 | R4: 3521.5 | S4: 1193.25 | T4: 0 | U4: 0 | V4: 580.94 | W4: 12198.19 | X4: 11617.25 | Y4: 0 | Z4: 0 | AA4: 11617.25 | AB4: 759 | AC4: 2671.99 | AD4: 119.14 | AE4: 300 | AF4: 0 | AG4: 40.86 | AH4: 224.47 | AI4: 3155.6 | AJ4: 568.03 | AK4: 0 | AL4: 11617.25 | AM4: 0 | AN4: 0 | AO4: 11.63 | AP4: 580.91 | AQ4: 0.03 | AR4: 1160.57 | AS4: 0 | AT4: 0 | AU4: 0 | AV4: 0 | AW4: 0 | AX4: 0 | AY4: 0 | AZ4: 0 | BA4: 0 | BB4: 4316.17 | BC4: 0 | BD4: 7882.02 | BE4: 0 | BF4: 0 | BG4: 0 | BH4: 0 | BI4: 0
A5: S.no. | B5: Order ID | C5: Order date | D5: Week no. | E5: Res. name | F5: Res. ID | G5: Discount construct | H5: Mode of payment | I5: Order status (Delivered/ Cancelled/ Rejected) | J5: Cancellation policy (% Amount refunded back to restaurant partner) | K5: Cancellation/ Rejection reason | L5: Cancelled/ Rejected state (Order status at the time it was cancelled/ rejected) | M5: Order type | N5: Delivery state code | O5: Subtotal (items total) | P5: Packaging charge | Q5: Delivery charge for restaurants on self logistics | R5: Restaurant discount (Promo) | S5: Restaurant discount (BOGO, Freebies, Gold, Brand pack & others) | T5: Brand pack subscription fee | U5: Delivery charge discount/ Relisting discount | V5: Total GST collected from customers | W5: Net order value [(1) + (2) + (3) - (4) - (5) + (6) - (7) + (8)] | X5: Commissionable value of Subtotal, excluding restuarant discounts [(1) - (4) - (5)] | Y5: Commissionable value of Packaging charge | Z5: Commissionable value of Total GST collected from customers | AA5: Total commissionable value [(9) + (10) + (11)] | AB5: Base service fee % | AC5: Base service fee [(12)% * (B)] | AD5: Actual order distance (km) | AE5: Long distance enablement fee | AF5: Discount on long distance enablement fee | AG5: Discount on service fee due to 30% capping Service fees capped at 30% of commissionable value (B) | AH5: Payment mechanism fee | AI5: Service fee & payment mechanism fee [(13) + (15) - (16) - (17) + (18)] | AJ5: Taxes on service fee & payment mechanism fee [(C) * 18%] | AK5: Applicable amount for TCS | AL5: Applicable amount for 9(5) | AM5: Tax collected at source | AN5: TCS IGST amount | AO5: TDS 194O amount | AP5: GST paid by Zomato on behalf of restaurant - under section 9(5) | AQ5: GST to be paid by Restaurant partner to Govt. | AR5: Government charges [(19) + (22) + (23) + (24) + (25)] | AS5: Customer compensation/ recoupment | AT5: Delivery charges recovery | AU5: Amount received in cash (on self delivery orders) | AV5: Credit note/ (Debit note) adjustment | AW5: Promo recovery adjustment | AX5: Extra inventory ads (order level deduction) | AY5: Brand loyalty points redemption | AZ5: Express order fee | BA5: Other order-level deductions [(27) + (28) + (29) + (30) + (31) + (32) + (33) + (34)] | BB5: Net Deductions [(C) + (D) + (E)] | BC5: Net Additions (cancellation refund for cancelled orders/ tip for kitchen staff for delivered orders) | BD5: Order level Payout (A) - (F) + (G) | BE5: Settlement status | BF5: Settlement date | BG5: Bank UTR | BH5: Unsettled amount | BI5: Customer ID
A6: 1 | B6: 7526529302 | C6: 2025-12-01 12:44:04 | D6: 49 | E6: Royal Dhaba Since 1922 - By Posh Foods | F6: 19617842 | G6: NA | H6: ONLINE | I6: DELIVERED | J6: NA | K6: NA | L6: NA | M6: O2 | N6: 9 | O6: 254 | P6: 0 | Q6: 0 | R6: 0 | S6: 120 | T6: 0 | U6: 0 | V6: 6.7 | W6: 140.7 | X6: 134 | Y6: 0 | Z6: 0 | AA6: 134 | AB6: 23 | AC6: 30.82 | AD6: 4.46 | AE6: 0 | AF6: 0 | AG6: 0 | AH6: 2.59 | AI6: 33.41 | AJ6: 6.02 | AK6: 0 | AL6: 134 | AM6: 0 | AN6: 0 | AO6: 0.13 | AP6: 6.7 | AQ6: 0 | AR6: 12.85 | AS6: 0 | AT6: 0 | AU6: 0 | AV6: 0 | AW6: 0 | AX6: 0 | AY6: 0 | AZ6: 0 | BA6: 0 | BB6: 46.26 | BC6: 0 | BD6: 94.44 | BE6: settled | BF6: 2025-12-10 05:30:00 | BG6: CITIN25668310562 | BH6: 0 | BI6: e0aab47b5be27c12601c20459168180b632524b8282f865e8fa173fef629b186
A7: 2 | B7: 7537807475 | C7: 2025-12-01 19:04:15 | D7: 49 | E7: Royal Dhaba Since 1922 - By Posh Foods | F7: 19617842 | G7: Flat ₹125 off (2025-11-26 - 2031-01-01) | H7: ONLINE | I7: DELIVERED | J7: NA | K7: NA | L7: NA | M7: O2 | N7: 9 | O7: 442 | P7: 0 | Q7: 0 | R7: 125 | S7: 31.7 | T7: 0 | U7: 0 | V7: 14.27 | W7: 299.57 | X7: 285.3 | Y7: 0 | Z7: 0 | AA7: 285.3 | AB7: 23 | AC7: 65.62 | AD7: 1.68 | AE7: 0 | AF7: 0 | AG7: 0 | AH7: 5.51 | AI7: 71.13 | AJ7: 12.8 | AK7: 0 | AL7: 285.3 | AM7: 0 | AN7: 0 | AO7: 0.29 | AP7: 14.26 | AQ7: 0.01 | AR7: 27.35 | AS7: 0 | AT7: 0 | AU7: 0 | AV7: 0 | AW7: 0 | AX7: 0 | AY7: 0 | AZ7: 0 | BA7: 0 | BB7: 98.48 | BC7: 0 | BD7: 201.09 | BE7: settled | BF7: 2025-12-10 05:30:00 | BG7: CITIN25668310562 | BH7: 0 | BI7: 6155c100278a6d14270e2549cb94227fa522c39b6926c5d334e1bb2d387488b9
A8: 3 | B8: 7540054634 | C8: 2025-12-01 21:28:11 | D8: 49 | E8: Royal Dhaba Since 1922 - By Posh Foods | F8: 19617842 | G8: Flat ₹125 off (2025-11-26 - 2031-01-01) | H8: ONLINE | I8: DELIVERED | J8: NA | K8: NA | L8: NA | M8: O2 | N8: 9 | O8: 475 | P8: 0 | Q8: 0 | R8: 125 | S8: 35 | T8: 0 | U8: 0 | V8: 15.75 | W8: 330.75 | X8: 315 | Y8: 0 | Z8: 0 | AA8: 315 | AB8: 23 | AC8: 72.45 | AD8: 5.66 | AE8: 20 | AF8: 0 | AG8: 0 | AH8: 6.09 | AI8: 98.54 | AJ8: 17.74 | AK8: 0 | AL8: 315 | AM8: 0 | AN8: 0 | AO8: 0.32 | AP8: 15.75 | AQ8: 0 | AR8: 33.81 | AS8: 0 | AT8: 0 | AU8: 0 | AV8: 0 | AW8: 0 | AX8: 0 | AY8: 0 | AZ8: 0 | BA8: 0 | BB8: 132.35 | BC8: 0 | BD8: 198.4 | BE8: settled | BF8: 2025-12-10 05:30:00 | BG8: CITIN25668310562 | BH8: 0 | BI8: 91cafdb3c03303079ec806af030762f6a4d7e0825a65456638a012614be954e3
A9: 4 | B9: 7528659322 | C9: 2025-12-01 21:28:45 | D9: 49 | E9: Royal Dhaba Since 1922 - By Posh Foods | F9: 19617842 | G9: Flat ₹125 off (2025-11-26 - 2031-01-01) | H9: ONLINE | I9: DELIVERED | J9: NA | K9: NA | L9: NA | M9: O2 | N9: 9 | O9: 425 | P9: 0 | Q9: 0 | R9: 87 | S9: 30 | T9: 0 | U9: 0 | V9: 15.4 | W9: 323.4 | X9: 308 | Y9: 0 | Z9: 0 | AA9: 308 | AB9: 23 | AC9: 70.84 | AD9: 6.45 | AE9: 40 | AF9: 0 | AG9: 18.44 | AH9: 5.95 | AI9: 98.35 | AJ9: 17.7 | AK9: 0 | AL9: 308 | AM9: 0 | AN9: 0 | AO9: 0.31 | AP9: 15.4 | AQ9: 0 | AR9: 33.41 | AS9: 0 | AT9: 0 | AU9: 0 | AV9: 0 | AW9: 0 | AX9: 0 | AY9: 0 | AZ9: 0 | BA9: 0 | BB9: 131.76 | BC9: 0 | BD9: 191.64 | BE9: settled | BF9: 2025-12-10 05:30:00 | BG9: CITIN25668310562 | BH9: 0 | BI9: 05a2a340e921e58d9e8687b74e93cc841087beab20f371c72e7cf2f5e54fa3a5
A10: 5 | B10: 7540679995 | C10: 2025-12-01 23:24:17 | D10: 49 | E10: Royal Dhaba Since 1922 - By Posh Foods | F10: 19617842 | G10: Flat ₹125 off (2025-11-26 - 2031-01-01) | H10: ONLINE | I10: DELIVERED | J10: NA | K10: NA | L10: NA | M10: O2 | N10: 9 | O10: 512 | P10: 0 | Q10: 0 | R10: 125 | S10: 38.7 | T10: 0 | U10: 0 | V10: 17.42 | W10: 365.72 | X10: 348.3 | Y10: 0 | Z10: 0 | AA10: 348.3 | AB10: 23 | AC10: 80.11 | AD10: 2.3 | AE10: 0 | AF10: 0 | AG10: 0 | AH10: 6.73 | AI10: 86.84 | AJ10: 15.63 | AK10: 0 | AL10: 348.3 | AM10: 0 | AN10: 0 | AO10: 0.35 | AP10: 17.41 | AQ10: 0.01 | AR10: 33.39 | AS10: 0 | AT10: 0 | AU10: 0 | AV10: 0 | AW10: 0 | AX10: 0 | AY10: 0 | AZ10: 0 | BA10: 0 | BB10: 120.23 | BC10: 0 | BD10: 245.49 | BE10: settled | BF10: 2025-12-10 05:30:00 | BG10: CITIN25668310562 | BH10: 0 | BI10: d59554851c85aa923644c39e4ba4aa42bb54e0c1e519940d85aa687a92fc7939
A11: 6 | B11: 7544092583 | C11: 2025-12-03 09:13:21 | D11: 49 | E11: Royal Dhaba Since 1922 - By Posh Foods | F11: 19617842 | G11: Flat ₹80 off (2025-12-03 - 2031-01-01) | H11: ONLINE | I11: DELIVERED | J11: NA | K11: NA | L11: NA | M11: O2 | N11: 9 | O11: 298 | P11: 0 | Q11: 0 | R11: 56 | S11: 0 | T11: 0 | U11: 0 | V11: 12.1 | W11: 254.1 | X11: 242 | Y11: 0 | Z11: 0 | AA11: 242 | AB11: 23 | AC11: 55.66 | AD11: 5.1 | AE11: 20 | AF11: 0 | AG11: 3.06 | AH11: 4.68 | AI11: 77.28 | AJ11: 13.91 | AK11: 0 | AL11: 242 | AM11: 0 | AN11: 0 | AO11: 0.24 | AP11: 12.1 | AQ11: 0 | AR11: 26.25 | AS11: 0 | AT11: 0 | AU11: 0 | AV11: 0 | AW11: 0 | AX11: 0 | AY11: 0 | AZ11: 0 | BA11: 0 | BB11: 103.53 | BC11: 0 | BD11: 150.57 | BE11: settled | BF11: 2025-12-10 05:30:00 | BG11: CITIN25668310562 | BH11: 0 | BI11: a47bbd560212a8c024e29ea9f1a04dbf6fbdb79fa8b7df987af872ca4fa57a22
A12: 7 | B12: 7546157969 | C12: 2025-12-03 21:23:59 | D12: 49 | E12: Royal Dhaba Since 1922 - By Posh Foods | F12: 19617842 | G12: Flat ₹175 off (2025-12-03 - 2031-01-01) | H12: ONLINE | I12: DELIVERED | J12: NA | K12: NA | L12: NA | M12: O2 | N12: 9 | O12: 780 | P12: 0 | Q12: 0 | R12: 175 | S12: 60.5 | T12: 0 | U12: 0 | V12: 27.23 | W12: 571.73 | X12: 544.5 | Y12: 0 | Z12: 0 | AA12: 544.5 | AB12: 23 | AC12: 125.24 | AD12: 2.3 | AE12: 0 | AF12: 0 | AG12: 0 | AH12: 10.52 | AI12: 135.76 | AJ12: 24.43 | AK12: 0 | AL12: 544.5 | AM12: 0 | AN12: 0 | AO12: 0.54 | AP12: 27.23 | AQ12: 0 | AR12: 52.2 | AS12: 0 | AT12: 0 | AU12: 0 | AV12: 0 | AW12: 0 | AX12: 0 | AY12: 0 | AZ12: 0 | BA12: 0 | BB12: 187.96 | BC12: 0 | BD12: 383.77 | BE12: settled | BF12: 2025-12-10 05:30:00 | BG12: CITIN25668310562 | BH12: 0 | BI12: d59554851c85aa923644c39e4ba4aa42bb54e0c1e519940d85aa687a92fc7939
A13: 8 | B13: 7541206081 | C13: 2025-12-03 22:04:57 | D13: 49 | E13: Royal Dhaba Since 1922 - By Posh Foods | F13: 19617842 | G13: Flat ₹125 off (2025-12-03 - 2031-01-01) | H13: ONLINE | I13: DELIVERED | J13: NA | K13: NA | L13: NA | M13: O2 | N13: 9 | O13: 445 | P13: 0 | Q13: 0 | R13: 87 | S13: 32 | T13: 0 | U13: 0 | V13: 16.3 | W13: 342.3 | X13: 326 | Y13: 0 | Z13: 0 | AA13: 326 | AB13: 23 | AC13: 74.98 | AD13: 2.62 | AE13: 0 | AF13: 0 | AG13: 0 | AH13: 6.3 | AI13: 81.28 | AJ13: 14.63 | AK13: 0 | AL13: 326 | AM13: 0 | AN13: 0 | AO13: 0.33 | AP13: 16.3 | AQ13: 0 | AR13: 31.26 | AS13: 0 | AT13: 0 | AU13: 0 | AV13: 0 | AW13: 0 | AX13: 0 | AY13: 0 | AZ13: 0 | BA13: 0 | BB13: 112.54 | BC13: 0 | BD13: 229.76 | BE13: settled | BF13: 2025-12-10 05:30:00 | BG13: CITIN25668310562 | BH13: 0 | BI13: 783753e82b6777b465c7f9096766615d4ccb830b8d6369d30a8a8ea34dd8d2b9
A14: 9 | B14: 7545047792 | C14: 2025-12-03 22:20:27 | D14: 49 | E14: Royal Dhaba Since 1922 - By Posh Foods | F14: 19617842 | G14: Flat ₹175 off (2025-12-03 - 2031-01-01) | H14: ONLINE | I14: DELIVERED | J14: NA | K14: NA | L14: NA | M14: O2 | N14: 9 | O14: 850 | P14: 0 | Q14: 0 | R14: 122 | S14: 67.5 | T14: 0 | U14: 0 | V14: 33.03 | W14: 693.53 | X14: 660.5 | Y14: 0 | Z14: 0 | AA14: 660.5 | AB14: 23 | AC14: 151.92 | AD14: 2.24 | AE14: 0 | AF14: 0 | AG14: 0 | AH14: 12.76 | AI14: 164.68 | AJ14: 29.65 | AK14: 0 | AL14: 660.5 | AM14: 0 | AN14: 0 | AO14: 0.66 | AP14: 33.03 | AQ14: 0 | AR14: 63.34 | AS14: 0 | AT14: 0 | AU14: 0 | AV14: 0 | AW14: 0 | AX14: 0 | AY14: 0 | AZ14: 0 | BA14: 0 | BB14: 228.02 | BC14: 0 | BD14: 465.51 | BE14: settled | BF14: 2025-12-10 05:30:00 | BG14: CITIN25668310562 | BH14: 0 | BI14: d4565a7788092597bc3f19d7bff82d57ceaefb0fd217e1ca3507726ca19c213f
A15: 10 | B15: 7546110686 | C15: 2025-12-03 22:30:52 | D15: 49 | E15: Royal Dhaba Since 1922 - By Posh Foods | F15: 19617842 | G15: NA | H15: ONLINE | I15: DELIVERED | J15: NA | K15: NA | L15: NA | M15: O2 | N15: 9 | O15: 35 | P15: 0 | Q15: 0 | R15: 0 | S15: 0 | T15: 0 | U15: 0 | V15: 1.75 | W15: 36.75 | X15: 35 | Y15: 0 | Z15: 0 | AA15: 35 | AB15: 23 | AC15: 8.05 | AD15: 2.24 | AE15: 0 | AF15: 0 | AG15: 0 | AH15: 0.68 | AI15: 8.73 | AJ15: 1.57 | AK15: 0 | AL15: 35 | AM15: 0 | AN15: 0 | AO15: 0.04 | AP15: 1.75 | AQ15: 0 | AR15: 3.36 | AS15: 0 | AT15: 0 | AU15: 0 | AV15: 0 | AW15: 0 | AX15: 0 | AY15: 0 | AZ15: 0 | BA15: 0 | BB15: 12.09 | BC15: 0 | BD15: 24.66 | BE15: settled | BF15: 2025-12-10 05:30:00 | BG15: CITIN25668310562 | BH15: 0 | BI15: d4565a7788092597bc3f19d7bff82d57ceaefb0fd217e1ca3507726ca19c213f
A16: 11 | B16: 7546977445 | C16: 2025-12-04 00:33:01 | D16: 49 | E16: Royal Dhaba Since 1922 - By Posh Foods | F16: 19617842 | G16: NA | H16: ONLINE | I16: DELIVERED | J16: NA | K16: NA | L16: NA | M16: O2 | N16: 9 | O16: 375 | P16: 0 | Q16: 0 | R16: 0 | S16: 37.5 | T16: 0 | U16: 0 | V16: 16.88 | W16: 354.38 | X16: 337.5 | Y16: 0 | Z16: 0 | AA16: 337.5 | AB16: 23 | AC16: 77.62 | AD16: 2.03 | AE16: 0 | AF16: 0 | AG16: 0 | AH16: 6.52 | AI16: 84.14 | AJ16: 15.14 | AK16: 0 | AL16: 337.5 | AM16: 0 | AN16: 0 | AO16: 0.34 | AP16: 16.88 | AQ16: 0 | AR16: 32.36 | AS16: 0 | AT16: 0 | AU16: 0 | AV16: 0 | AW16: 0 | AX16: 0 | AY16: 0 | AZ16: 0 | BA16: 0 | BB16: 116.5 | BC16: 0 | BD16: 237.88 | BE16: settled | BF16: 2025-12-10 05:30:00 | BG16: CITIN25668310562 | BH16: 0 | BI16: 84f0e8e0612f128f46dbf6add5088879185b1fa454858203a7931fded6256ef7
A17: 12 | B17: 7538352810 | C17: 2025-12-04 09:12:17 | D17: 49 | E17: Royal Dhaba Since 1922 - By Posh Foods | F17: 19617842 | G17: Flat ₹100 off (2025-12-03 - 2031-01-01) | H17: ONLINE | I17: DELIVERED | J17: NA | K17: NA | L17: NA | M17: O2 | N17: 9 | O17: 224 | P17: 0 | Q17: 0 | R17: 70 | S17: 0 | T17: 0 | U17: 0 | V17: 7.7 | W17: 161.7 | X17: 154 | Y17: 0 | Z17: 0 | AA17: 154 | AB17: 23 | AC17: 35.42 | AD17: 1.1 | AE17: 0 | AF17: 0 | AG17: 0 | AH17: 2.98 | AI17: 38.4 | AJ17: 6.92 | AK17: 0 | AL17: 154 | AM17: 0 | AN17: 0 | AO17: 0.15 | AP17: 7.7 | AQ17: 0 | AR17: 14.77 | AS17: 0 | AT17: 0 | AU17: 0 | AV17: 0 | AW17: 0 | AX17: 0 | AY17: 0 | AZ17: 0 | BA17: 0 | BB17: 53.17 | BC17: 0 | BD17: 108.53 | BE17: settled | BF17: 2025-12-10 05:30:00 | BG17: CITIN25668310562 | BH17: 0 | BI17: a9902821358a11bb33e3ebe7e672b5e367c584258c1050a83bdf1e1fdf81c63a
... A38: 33 | B38: 7559817936 | C38: 2025-12-07 22:16:35 | D38: 49 | E38: Royal Dhaba Since 1922 - By Posh Foods | F38: 19617842 | G38: Flat ₹100 off (2025-12-03 - 2031-01-01) | H38: ONLINE | I38: DELIVERED | J38: NA | K38: NA | L38: NA | M38: O2 | N38: 9 | O38: 325 | P38: 0 | Q38: 0 | R38: 70 | S38: 22.5 | T38: 0 | U38: 0 | V38: 11.63 | W38: 244.13 | X38: 232.5 | Y38: 0 | Z38: 0 | AA38: 232.5 | AB38: 23 | AC38: 53.48 | AD38: 2.33 | AE38: 0 | AF38: 0 | AG38: 0 | AH38: 4.49 | AI38: 57.97 | AJ38: 10.44 | AK38: 0 | AL38: 232.5 | AM38: 0 | AN38: 0 | AO38: 0.23 | AP38: 11.63 | AQ38: 0 | AR38: 22.3 | AS38: 0 | AT38: 0 | AU38: 0 | AV38: 0 | AW38: 0 | AX38: 0 | AY38: 0 | AZ38: 0 | BA38: 0 | BB38: 80.27 | BC38: 0 | BD38: 163.86 | BE38: settled | BF38: 2025-12-10 05:30:00 | BG38: CITIN25668310562 | BH38: 0 | BI38: a9480ac8067c5e1ed61cd8cd87ab970ed4e7448cd82ce83bcf3f988204c0f379

Sheet D2W1
B1: Addition/ Deduction details (non order-level additions & deductions and adjustments from previous weeks)
B2: Summarized view on : 1. Res id level additions like 194 H, etc 2. Res id level deductions like pay later, etc
B5: Addition Type
B6: Type | C6: NA | D6: Invoice No/Order id | E6: Order date | F6: Settlement status | G6: Total amount | H6: Adjusted amount | I6: Outstanding amount
B7: Total Additions | G7: 0 | H7: 0 | I7: 0
B10: Deduction Type
B11: A) Investments in growth services
B12: Type | C12: Res id for which deduction created | D12: Invoice No/Campaign id | E12: Deduction time period | F12: Settlement Status | G12: Total amount | H12: Adjusted amount | I12: Outstanding amount
B13: ADS | C13: 19617842 | D13: 31800084 | E13: 01 December 25 - 07 December 25 | F13: settled | G13: 3201.93 | H13: 3201.93 | I13: 0
B14: ADS | C14: 21552679 | D14: 31786480 | E14: 02 December 25 - 02 December 25 | F14: settled | G14: 10.62 | H14: 10.62 | I14: 0
B15: Total Ads & miscellaneous services | G15: 3212.55 | H15: 3212.55 | I15: 0
B17: B) Investments in Hyperpure
B18: Type | C18: Res id for which deduction created | D18: OrderId | E18: Deduction time period | F18: Settlement Status | G18: Total amount | H18: Adjusted amount | I18: Outstanding amount
B19: Total Hyperpure | G19: 0 | H19: 0 | I19: 0
B21: C) Other deductions
B22: D) Adjustments from previous weeks
B23: Total Deductions (A) + (B) + (C) | G23: 3212.55 | H23: 3212.55 | I23: 0

Sheet D1W2
O1: 565 | P1: 0 | Q1: 0 | R1: 0 | S1: 0 | T1: 0 | U1: 0 | V1: 0 | W1: 565 | X1: 0 | Y1: 0 | Z1: 0 | AA1: 0 | AB1: 0 | AC1: 0 | AD1: 0 | AE1: 0 | AF1: 0 | AG1: 0 | AH1: 0 | AI1: 0 | AJ1: 0 | AK1: 0 | AL1: 0 | AM1: 0 | AN1: 0 | AO1: 0 | AP1: 0 | AQ1: 0 | AR1: 0 | AS1: 0 | AT1: 0 | AU1: 0 | AV1: 0 | AW1: 0 | AX1: 0 | AY1: 0 | AZ1: 0 | BA1: 0 | BB1: 0 | BC1: 358.39 | BD1: 358.39 | BE1: 0 | BF1: 0 | BG1: 0 | BH1: 0 | BI1: 0
O2: 18569 | P2: 0 | Q2: 0 | R2: 3026 | S2: 1162.7 | T2: 0 | U2: 282.5 | V2: 704.97 | W2: 14802.77 | X2: 14097.8 | Y2: 0 | Z2: 0 | AA2: 14097.8 | AB2: 764.34 | AC2: 3387.56 | AD2: 121.98 | AE2: 300 | AF2: 0 | AG2: 76.96 | AH2: 272.38 | AI2: 3882.98 | AJ2: 698.96 | AK2: 0 | AL2: 14097.8 | AM2: 0 | AN2: 0 | AO2: 14.06 | AP2: 704.92 | AQ2: 0.05 | AR2: 1417.94 | AS2: 0 | AT2: 0 | AU2: 0 | AV2: 0 | AW2: 0 | AX2: 0 | AY2: 0 | AZ2: 0 | BA2: 0 | BB2: 5300.92 | BC2: 0 | BD2: 9501.85 | BE2: 0 | BF2: 0 | BG2: 0 | BH2: 0 | BI2: 0
O3: 21911.42 | P3: 0 | Q3: 0 | R3: 3570.68 | S3: 1371.986 | T3: 0 | U3: 333.35 | V3: 831.8646 | W3: 17467.269 | X3: 16635.404 | Y3: 0 | Z3: 0 | AA3: 16635.404 | AB3: 901.9212 | AC3: 3997.3208 | AD3: 143.9364 | AE3: 354 | AF3: 0 | AG3: 90.8128 | AH3: 321.4084 | AI3: 4581.9164 | AJ3: 824.7728 | AK3: 0 | AL3: 16635.404 | AM3: 0 | AN3: 0 | AO3: 16.5908 | AP3: 831.8056 | AQ3: 0.059 | AR3: 1673.1692 | AS3: 0 | AT3: 0 | AU3: 0 | AV3: 0 | AW3: 0 | AX3: 0 | AY3: 0 | AZ3: 0 | BA3: 0 | BB3: 6255.0856 | BC3: 0 | BD3: 11212.183 | BE3: 0 | BF3: 0 | BG3: 0 | BH3: 0 | BI3: 0
O4: 19134 | P4: 0 | Q4: 0 | R4: 3026 | S4: 1162.7 | T4: 0 | U4: 282.5 | V4: 704.97 | W4: 15367.77 | X4: 14097.8 | Y4: 0 | Z4: 0 | AA4: 14097.8 | AB4: 764.34 | AC4: 3387.56 | AD4: 121.98 | AE4: 300 | AF4: 0 | AG4: 76.96 | AH4: 272.38 | AI4: 3882.98 | AJ4: 698.96 | AK4: 0 | AL4: 14097.8 | AM4: 0 | AN4: 0 | AO4: 14.06 | AP4: 704.92 | AQ4: 0.05 | AR4: 1417.94 | AS4: 0 | AT4: 0 | AU4: 0 | AV4: 0 | AW4: 0 | AX4: 0 | AY4: 0 | AZ4: 0 | BA4: 0 | BB4: 5300.92 | BC4: 358.39 | BD4: 9860.24 | BE4: 0 | BF4: 0 | BG4: 0 | BH4: 0 | BI4: 0
A5: S.no. | B5: Order ID | C5: Order date | D5: Week no. | E5: Res. name | F5: Res. ID | G5: Discount construct | H5: Mode of payment | I5: Order status (Delivered/ Cancelled/ Rejected) | J5: Cancellation policy (% Amount refunded back to restaurant partner) | K5: Cancellation/ Rejection reason | L5: Cancelled/ Rejected state (Order status at the time it was cancelled/ rejected) | M5: Order type | N5: Delivery state code | O5: Subtotal (items total) | P5: Packaging charge | Q5: Delivery charge for restaurants on self logistics | R5: Restaurant discount (Promo) | S5: Restaurant discount (BOGO, Freebies, Gold, Brand pack & others) | T5: Brand pack subscription fee | U5: Delivery charge discount/ Relisting discount | V5: Total GST collected from customers | W5: Net order value [(1) + (2) + (3) - (4) - (5) + (6) - (7) + (8)] | X5: Commissionable value of Subtotal, excluding restuarant discounts [(1) - (4) - (5)] | Y5: Commissionable value of Packaging charge | Z5: Commissionable value of Total GST collected from customers | AA5: Total commissionable value [(9) + (10) + (11)] | AB5: Base service fee % | AC5: Base service fee [(12)% * (B)] | AD5: Actual order distance (km) | AE5: Long distance enablement fee | AF5: Discount on long distance enablement fee | AG5: Discount on service fee due to 30% capping Service fees capped at 30% of commissionable value (B) | AH5: Payment mechanism fee | AI5: Service fee & payment mechanism fee [(13) + (15) - (16) - (17) + (18)] | AJ5: Taxes on service fee & payment mechanism fee [(C) * 18%] | AK5: Applicable amount for TCS | AL5: Applicable amount for 9(5) | AM5: Tax collected at source | AN5: TCS IGST amount | AO5: TDS 194O amount | AP5: GST paid by Zomato on behalf of restaurant - under section 9(5) | AQ5: GST to be paid by Restaurant partner to Govt. | AR5: Government charges [(19) + (22) + (23) + (24) + (25)] | AS5: Customer compensation/ recoupment | AT5: Delivery charges recovery | AU5: Amount received in cash (on self delivery orders) | AV5: Credit note/ (Debit note) adjustment | AW5: Promo recovery adjustment | AX5: Extra inventory ads (order level deduction) | AY5: Brand loyalty points redemption | AZ5: Express order fee | BA5: Other order-level deductions [(27) + (28) + (29) + (30) + (31) + (32) + (33) + (34)] | BB5: Net Deductions [(C) + (D) + (E)] | BC5: Net Additions (cancellation refund for cancelled orders/ tip for kitchen staff for delivered orders) | BD5: Order level Payout (A) - (F) + (G) | BE5: Settlement status | BF5: Settlement date | BG5: Bank UTR | BH5: Unsettled amount | BI5: Customer ID
A6: 1 | B6: 7561244013 | C6: 2025-12-08 22:35:37 | D6: 50 | E6: Royal Dhaba Since 1922 - By Posh Foods | F6: 19617842 | G6: Flat ₹175 off (2025-12-08 - 2031-01-01) | H6: ONLINE | I6: DELIVERED | J6: NA | K6: NA | L6: NA | M6: O2 | N6: 9 | O6: 850 | P6: 0 | Q6: 0 | R6: 122 | S6: 67.5 | T6: 0 | U6: 0 | V6: 33.03 | W6: 693.53 | X6: 660.5 | Y6: 0 | Z6: 0 | AA6: 660.5 | AB6: 23 | AC6: 151.92 | AD6: 1.23 | AE6: 0 | AF6: 0 | AG6: 0 | AH6: 12.76 | AI6: 164.68 | AJ6: 29.65 | AK6: 0 | AL6: 660.5 | AM6: 0 | AN6: 0 | AO6: 0.66 | AP6: 33.03 | AQ6: 0 | AR6: 63.34 | AS6: 0 | AT6: 0 | AU6: 0 | AV6: 0 | AW6: 0 | AX6: 0 | AY6: 0 | AZ6: 0 | BA6: 0 | BB6: 228.02 | BC6: 0 | BD6: 465.51 | BE6: settled | BF6: 2025-12-17 05:30:00 | BG6: CITIN25671254712 | BH6: 0 | BI6: e68c53c98418816858c6a86f4d4193059e8a8ee315630f75389871bbd6022455
A7: 2 | B7: 7557452254 | C7: 2025-12-08 23:29:26 | D7: 50 | E7: Royal Dhaba Since 1922 - By Posh Foods | F7: 19617842 | G7: Flat 30% off (2025-10-19 - 2031-01-01) | H7: ONLINE | I7: DELIVERED | J7: NA | K7: NA | L7: NA | M7: O2 | N7: 9 | O7: 1510 | P7: 0 | Q7: 0 | R7: 453 | S7: 0 | T7: 0 | U7: 0 | V7: 52.85 | W7: 1109.85 | X7: 1057 | Y7: 0 | Z7: 0 | AA7: 1057 | AB7: 23 | AC7: 243.11 | AD7: 3.29 | AE7: 0 | AF7: 0 | AG7: 0 | AH7: 20.42 | AI7: 263.53 | AJ7: 47.44 | AK7: 0 | AL7: 1057 | AM7: 0 | AN7: 0 | AO7: 1.06 | AP7: 52.85 | AQ7: 0 | AR7: 101.35 | AS7: 0 | AT7: 0 | AU7: 0 | AV7: 0 | AW7: 0 | AX7: 0 | AY7: 0 | AZ7: 0 | BA7: 0 | BB7: 364.88 | BC7: 0 | BD7: 744.97 | BE7: settled | BF7: 2025-12-17 05:30:00 | BG7: CITIN25671254712 | BH7: 0 | BI7: 2d909ebfc10e0821a556a2650aa96d316696044fcbaffb8af47ffcdbdd580260
A8: 3 | B8: 7554540213 | C8: 2025-12-09 00:26:09 | D8: 50 | E8: Royal Dhaba Since 1922 - By Posh Foods | F8: 19617842 | G8: NA | H8: ONLINE | I8: CANCELLED | J8: 100% | K8: Customer cancellation because they do not require order anymore | L8: Order picked up by rider | M8: O2 | N8: NA | O8: 565 | P8: 0 | Q8: 0 | R8: 0 | S8: 0 | T8: 0 | U8: 0 | V8: 0 | W8: 565 | X8: 0 | Y8: 0 | Z8: 0 | AA8: 0 | AB8: 0 | AC8: 0 | AD8: 0 | AE8: 0 | AF8: 0 | AG8: 0 | AH8: 0 | AI8: 0 | AJ8: 0 | AK8: 0 | AL8: 0 | AM8: 0 | AN8: 0 | AO8: 0 | AP8: 0 | AQ8: 0 | AR8: 0 | AS8: 0 | AT8: 0 | AU8: 0 | AV8: 0 | AW8: 0 | AX8: 0 | AY8: 0 | AZ8: 0 | BA8: 0 | BB8: 0 | BC8: 358.39 | BD8: 358.39 | BE8: settled | BF8: 2025-12-17 05:30:00 | BG8: CITIN25671254712 | BH8: 0 | BI8: NA
A9: 4 | B9: 7563338761 | C9: 2025-12-09 01:34:11 | D9: 50 | E9: Royal Dhaba Since 1922 - By Posh Foods | F9: 19617842 | G9: NA | H9: ONLINE | I9: DELIVERED | J9: NA | K9: NA | L9: NA | M9: RELISTING | N9: 9 | O9: 565 | P9: 0 | Q9: 0 | R9: 0 | S9: 0 | T9: 0 | U9: 282.5 | V9: 14.13 | W9: 296.63 | X9: 282.5 | Y9: 0 | Z9: 0 | AA9: 282.5 | AB9: 74.34 | AC9: 210.01 | AD9: 3.65 | AE9: 0 | AF9: 0 | AG9: 0 | AH9: 5.46 | AI9: 215.47 | AJ9: 38.78 | AK9: 0 | AL9: 282.5 | AM9: 0 | AN9: 0 | AO9: 0.28 | AP9: 14.13 | AQ9: 0 | AR9: 53.19 | AS9: 0 | AT9: 0 | AU9: 0 | AV9: 0 | AW9: 0 | AX9: 0 | AY9: 0 | AZ9: 0 | BA9: 0 | BB9: 268.66 | BC9: 0 | BD9: 27.97 | BE9: settled | BF9: 2025-12-17 05:30:00 | BG9: CITIN25671254712 | BH9: 0 | BI9: 6ef909a4284ab6aaef6bcb927d4da473c03d56fc4524e39f723fd4a6ff77d4f8
A10: 5 | B10: 7562207507 | C10: 2025-12-09 11:12:05 | D10: 50 | E10: Royal Dhaba Since 1922 - By Posh Foods | F10: 19617842 | G10: Flat ₹100 off (2025-12-08 - 2031-01-01) | H10: ONLINE | I10: DELIVERED | J10: NA | K10: NA | L10: NA | M10: O2 | N10: 9 | O10: 300 | P10: 0 | Q10: 0 | R10: 70 | S10: 0 | T10: 0 | U10: 0 | V10: 11.5 | W10: 241.5 | X10: 230 | Y10: 0 | Z10: 0 | AA10: 230 | AB10: 23 | AC10: 52.9 | AD10: 2.47 | AE10: 0 | AF10: 0 | AG10: 0 | AH10: 4.44 | AI10: 57.34 | AJ10: 10.32 | AK10: 0 | AL10: 230 | AM10: 0 | AN10: 0 | AO10: 0.23 | AP10: 11.5 | AQ10: 0 | AR10: 22.05 | AS10: 0 | AT10: 0 | AU10: 0 | AV10: 0 | AW10: 0 | AX10: 0 | AY10: 0 | AZ10: 0 | BA10: 0 | BB10: 79.39 | BC10: 0 | BD10: 162.11 | BE10: settled | BF10: 2025-12-17 05:30:00 | BG10: CITIN25671254712 | BH10: 0 | BI10: 474a10b459e82a074207f8333cbd2a5dfb52baf06c60fd0e43f7329bd177e6b2
A11: 6 | B11: 7565374206 | C11: 2025-12-09 20:47:15 | D11: 50 | E11: Royal Dhaba Since 1922 - By Posh Foods | F11: 19617842 | G11: Flat ₹175 off (2025-12-08 - 2031-01-01) | H11: ONLINE | I11: DELIVERED | J11: NA | K11: NA | L11: NA | M11: O2 | N11: 9 | O11: 710 | P11: 0 | Q11: 0 | R11: 122 | S11: 53.5 | T11: 0 | U11: 0 | V11: 26.73 | W11: 561.23 | X11: 534.5 | Y11: 0 | Z11: 0 | AA11: 534.5 | AB11: 23 | AC11: 122.94 | AD11: 3.34 | AE11: 0 | AF11: 0 | AG11: 0 | AH11: 10.33 | AI11: 133.27 | AJ11: 23.99 | AK11: 0 | AL11: 534.5 | AM11: 0 | AN11: 0 | AO11: 0.53 | AP11: 26.72 | AQ11: 0.01 | AR11: 51.24 | AS11: 0 | AT11: 0 | AU11: 0 | AV11: 0 | AW11: 0 | AX11: 0 | AY11: 0 | AZ11: 0 | BA11: 0 | BB11: 184.51 | BC11: 0 | BD11: 376.72 | BE11: settled | BF11: 2025-12-17 05:30:00 | BG11: CITIN25671254712 | BH11: 0 | BI11: 8c234406d68a66228b9ae7eaa7028bad5f2e406664b2e4f8500918fc4f111f8b
A12: 7 | B12: 7563961083 | C12: 2025-12-09 23:52:34 | D12: 50 | E12: Royal Dhaba Since 1922 - By Posh Foods | F12: 19617842 | G12: Flat ₹175 off (2025-12-08 - 2031-01-01) | H12: ONLINE | I12: DELIVERED | J12: NA | K12: NA | L12: NA | M12: O2 | N12: 9 | O12: 820 | P12: 0 | Q12: 0 | R12: 122 | S12: 64.5 | T12: 0 | U12: 0 | V12: 31.68 | W12: 665.18 | X12: 633.5 | Y12: 0 | Z12: 0 | AA12: 633.5 | AB12: 23 | AC12: 145.7 | AD12: 5.95 | AE12: 20 | AF12: 0 | AG12: 0 | AH12: 12.24 | AI12: 177.94 | AJ12: 32.03 | AK12: 0 | AL12: 633.5 | AM12: 0 | AN12: 0 | AO12: 0.63 | AP12: 31.68 | AQ12: 0 | AR12: 64.34 | AS12: 0 | AT12: 0 | AU12: 0 | AV12: 0 | AW12: 0 | AX12: 0 | AY12: 0 | AZ12: 0 | BA12: 0 | BB12: 242.28 | BC12: 0 | BD12: 422.9 | BE12: settled | BF12: 2025-12-17 05:30:00 | BG12: CITIN25671254712 | BH12: 0 | BI12: 59b68d6f8af35ba02d22ded17d877ba2ecfa9322b5f48b534e6fceb511f268a0
A13: 8 | B13: 7553140024 | C13: 2025-12-10 00:44:24 | D13: 50 | E13: Royal Dhaba Since 1922 - By Posh Foods | F13: 19617842 | G13: Flat ₹125 off (2025-12-08 - 2031-01-01) | H13: ONLINE | I13: DELIVERED | J13: NA | K13: NA | L13: NA | M13: O2 | N13: 9 | O13: 350 | P13: 0 | Q13: 0 | R13: 87 | S13: 22.5 | T13: 0 | U13: 0 | V13: 12.03 | W13: 252.53 | X13: 240.5 | Y13: 0 | Z13: 0 | AA13: 240.5 | AB13: 23 | AC13: 55.32 | AD13: 6.9 | AE13: 40 | AF13: 0 | AG13: 23.17 | AH13: 4.65 | AI13: 76.8 | AJ13: 13.83 | AK13: 0 | AL13: 240.5 | AM13: 0 | AN13: 0 | AO13: 0.24 | AP13: 12.02 | AQ13: 0.01 | AR13: 26.09 | AS13: 0 | AT13: 0 | AU13: 0 | AV13: 0 | AW13: 0 | AX13: 0 | AY13: 0 | AZ13: 0 | BA13: 0 | BB13: 102.89 | BC13: 0 | BD13: 149.64 | BE13: settled | BF13: 2025-12-17 05:30:00 | BG13: CITIN25671254712 | BH13: 0 | BI13: 7ad4ed00f6474a584c2df1a88462c01fefcf6243ea8834eda5b3db274d7dcf29
A14: 9 | B14: 7563782735 | C14: 2025-12-10 15:01:56 | D14: 50 | E14: Royal Dhaba Since 1922 - By Posh Foods | F14: 19617842 | G14: Flat ₹125 off (2025-12-05 - 2031-01-01) | H14: ONLINE | I14: DELIVERED | J14: NA | K14: NA | L14: NA | M14: O2 | N14: 9 | O14: 492 | P14: 0 | Q14: 0 | R14: 87 | S14: 36.7 | T14: 0 | U14: 0 | V14: 18.42 | W14: 386.72 | X14: 368.3 | Y14: 0 | Z14: 0 | AA14: 368.3 | AB14: 23 | AC14: 84.71 | AD14: 1.23 | AE14: 0 | AF14: 0 | AG14: 0 | AH14: 7.12 | AI14: 91.83 | AJ14: 16.53 | AK14: 0 | AL14: 368.3 | AM14: 0 | AN14: 0 | AO14: 0.37 | AP14: 18.42 | AQ14: 0 | AR14: 35.32 | AS14: 0 | AT14: 0 | AU14: 0 | AV14: 0 | AW14: 0 | AX14: 0 | AY14: 0 | AZ14: 0 | BA14: 0 | BB14: 127.15 | BC14: 0 | BD14: 259.57 | BE14: settled | BF14: 2025-12-17 05:30:00 | BG14: CITIN25671254712 | BH14: 0 | BI14: e68c53c98418816858c6a86f4d4193059e8a8ee315630f75389871bbd6022455
A15: 10 | B15: 7564068148 | C15: 2025-12-10 18:01:09 | D15: 50 | E15: Royal Dhaba Since 1922 - By Posh Foods | F15: 19617842 | G15: Flat ₹100 off (2025-12-08 - 2031-01-01) | H15: ONLINE | I15: DELIVERED | J15: NA | K15: NA | L15: NA | M15: O2 | N15: 9 | O15: 295 | P15: 0 | Q15: 0 | R15: 70 | S15: 0 | T15: 0 | U15: 0 | V15: 11.25 | W15: 236.25 | X15: 225 | Y15: 0 | Z15: 0 | AA15: 225 | AB15: 23 | AC15: 51.75 | AD15: 5.61 | AE15: 20 | AF15: 0 | AG15: 4.25 | AH15: 4.35 | AI15: 71.85 | AJ15: 12.94 | AK15: 0 | AL15: 225 | AM15: 0 | AN15: 0 | AO15: 0.22 | AP15: 11.25 | AQ15: 0 | AR15: 24.41 | AS15: 0 | AT15: 0 | AU15: 0 | AV15: 0 | AW15: 0 | AX15: 0 | AY15: 0 | AZ15: 0 | BA15: 0 | BB15: 96.26 | BC15: 0 | BD15: 139.99 | BE15: settled | BF15: 2025-12-17 05:30:00 | BG15: CITIN25671254712 | BH15: 0 | BI15: edf7dc8394c75e0bd20dc7080fbb83009dc70103141b19b24af3464051f5735d
A16: 11 | B16: 7549388240 | C16: 2025-12-10 18:47:20 | D16: 50 | E16: Royal Dhaba Since 1922 - By Posh Foods | F16: 19617842 | G16: Flat ₹100 off (2025-12-08 - 2031-01-01) | H16: ONLINE | I16: DELIVERED | J16: NA | K16: NA | L16: NA | M16: O2 | N16: 9 | O16: 295 | P16: 0 | Q16: 0 | R16: 70 | S16: 0 | T16: 0 | U16: 0 | V16: 11.25 | W16: 236.25 | X16: 225 | Y16: 0 | Z16: 0 | AA16: 225 | AB16: 23 | AC16: 51.75 | AD16: 2.33 | AE16: 0 | AF16: 0 | AG16: 0 | AH16: 4.35 | AI16: 56.1 | AJ16: 10.1 | AK16: 0 | AL16: 225 | AM16: 0 | AN16: 0 | AO16: 0.22 | AP16: 11.25 | AQ16: 0 | AR16: 21.57 | AS16: 0 | AT16: 0 | AU16: 0 | AV16: 0 | AW16: 0 | AX16: 0 | AY16: 0 | AZ16: 0 | BA16: 0 | BB16: 77.67 | BC16: 0 | BD16: 158.58 | BE16: settled | BF16: 2025-12-17 05:30:00 | BG16: CITIN25671254712 | BH16: 0 | BI16: a39d03fe403b7584e9c608a84da71519960ba1775fd8f748118db78af23af51e
A17: 12 | B17: 7560781818 | C17: 2025-12-10 21:27:22 | D17: 50 | E17: Royal Dhaba Since 1922 - By Posh Foods | F17: 19617842 | G17: Flat ₹175 off (2025-12-08 - 2031-01-01) | H17: ONLINE | I17: DELIVERED | J17: NA | K17: NA | L17: NA | M17: O2 | N17: 9 | O17: 780 | P17: 0 | Q17: 0 | R17: 175 | S17: 60.5 | T17: 0 | U17: 0 | V17: 27.23 | W17: 571.73 | X17: 544.5 | Y17: 0 | Z17: 0 | AA17: 544.5 | AB17: 23 | AC17: 125.24 | AD17: 2.3 | AE17: 0 | AF17: 0 | AG17: 0 | AH17: 10.52 | AI17: 135.76 | AJ17: 24.43 | AK17: 0 | AL17: 544.5 | AM17: 0 | AN17: 0 | AO17: 0.54 | AP17: 27.23 | AQ17: 0 | AR17: 52.2 | AS17: 0 | AT17: 0 | AU17: 0 | AV17: 0 | AW17: 0 | AX17: 0 | AY17: 0 | AZ17: 0 | BA17: 0 | BB17: 187.96 | BC17: 0 | BD17: 383.77 | BE17: settled | BF17: 2025-12-17 05:30:00 | BG17: CITIN25671254712 | BH17: 0 | BI17: d59554851c85aa923644c39e4ba4aa42bb54e0c1e519940d85aa687a92fc7939
... A37: 32 | B37: 7580171044 | C37: 2025-12-14 22:12:04 | D37: 50 | E37: Royal Dhaba Since 1922 - By Posh Foods | F37: 19617842 | G37: Flat ₹125 off (2025-12-05 - 2031-01-01) | H37: ONLINE | I37: DELIVERED | J37: NA | K37: NA | L37: NA | M37: O2 | N37: 9 | O37: 460 | P37: 0 | Q37: 0 | R37: 87 | S37: 33.5 | T37: 0 | U37: 0 | V37: 16.98 | W37: 356.48 | X37: 339.5 | Y37: 0 | Z37: 0 | AA37: 339.5 | AB37: 23 | AC37: 78.08 | AD37: 3.62 | AE37: 0 | AF37: 0 | AG37: 0 | AH37: 6.56 | AI37: 84.64 | AJ37: 15.23 | AK37: 0 | AL37: 339.5 | AM37: 0 | AN37: 0 | AO37: 0.34 | AP37: 16.98 | AQ37: 0 | AR37: 32.55 | AS37: 0 | AT37: 0 | AU37: 0 | AV37: 0 | AW37: 0 | AX37: 0 | AY37: 0 | AZ37: 0 | BA37: 0 | BB37: 117.19 | BC37: 0 | BD37: 239.29 | BE37: settled | BF37: 2025-12-17 05:30:00 | BG37: CITIN25671254712 | BH37: 0 | BI37: f9064711e234ca8dbe97229d03d94132706c9d3f1595191fbd569894b1e2c0e9

Sheet D2W2
B1: Addition/ Deduction details (non order-level additions & deductions and adjustments from previous weeks)
B2: Summarized view on : 1. Res id level additions like 194 H, etc 2. Res id level deductions like pay later, etc
B5: Addition Type
B6: Type | C6: NA | D6: Invoice No/Order id | E6: Order date | F6: Settlement status | G6: Total amount | H6: Adjusted amount | I6: Outstanding amount
B7: Total Additions | G7: 0 | H7: 0 | I7: 0
B10: Deduction Type
B11: A) Investments in growth services
B12: Type | C12: Res id for which deduction created | D12: Invoice No/Campaign id | E12: Deduction time period | F12: Settlement Status | G12: Total amount | H12: Adjusted amount | I12: Outstanding amount
B13: ADS | C13: 19617842 | D13: 31800084 | E13: 08 December 25 - 14 December 25 | F13: settled | G13: 3409.02 | H13: 3409.02 | I13: 0
B14: Total Ads & miscellaneous services | G14: 3409.02 | H14: 3409.02 | I14: 0
B16: B) Investments in Hyperpure
B17: Type | C17: Res id for which deduction created | D17: OrderId | E17: Deduction time period | F17: Settlement Status | G17: Total amount | H17: Adjusted amount | I17: Outstanding amount
B18: Total Hyperpure | G18: 0 | H18: 0 | I18: 0
B20: C) Other deductions
B21: D) Adjustments from previous weeks
B22: Total Deductions (A) + (B) + (C) | G22: 3409.02 | H22: 3409.02 | I22: 0

Sheet D1W3
O1: 0 | P1: 0 | Q1: 0 | R1: 0 | S1: 0 | T1: 0 | U1: 0 | V1: 0 | W1: 0 | X1: 0 | Y1: 0 | Z1: 0 | AA1: 0 | AB1: 0 | AC1: 0 | AD1: 0 | AE1: 0 | AF1: 0 | AG1: 0 | AH1: 0 | AI1: 0 | AJ1: 0 | AK1: 0 | AL1: 0 | AM1: 0 | AN1: 0 | AO1: 0 | AP1: 0 | AQ1: 0 | AR1: 0 | AS1: 0 | AT1: 0 | AU1: 0 | AV1: 0 | AW1: 0 | AX1: 0 | AY1: 0 | AZ1: 0 | BA1: 0 | BB1: 0 | BC1: 0 | BD1: 0 | BE1: 0 | BF1: 0 | BG1: 0 | BH1: 0 | BI1: 0
O2: 15741 | P2: 0 | Q2: 0 | R2: 2438 | S2: 1355 | T2: 0 | U2: 0 | V2: 597.45 | W2: 12545.45 | X2: 11948 | Y2: 0 | Z2: 0 | AA2: 11948 | AB2: 736 | AC2: 2748.04 | AD2: 134.53 | AE2: 400 | AF2: 0 | AG2: 109.72 | AH2: 230.83 | AI2: 3269.15 | AJ2: 588.46 | AK2: 0 | AL2: 11948 | AM2: 0 | AN2: 0 | AO2: 11.94 | AP2: 597.44 | AQ2: 0.01 | AR2: 1197.84 | AS2: 0 | AT2: 0 | AU2: 0 | AV2: 0 | AW2: 0 | AX2: 0 | AY2: 0 | AZ2: 0 | BA2: 0 | BB2: 4466.99 | BC2: 0 | BD2: 8078.46 | BE2: 0 | BF2: 0 | BG2: 0 | BH2: 0 | BI2: 0
O3: 18574.38 | P3: 0 | Q3: 0 | R3: 2876.84 | S3: 1598.9 | T3: 0 | U3: 0 | V3: 704.991 | W3: 14803.631 | X3: 14098.64 | Y3: 0 | Z3: 0 | AA3: 14098.64 | AB3: 868.48 | AC3: 3242.6872 | AD3: 158.7454 | AE3: 472 | AF3: 0 | AG3: 129.4696 | AH3: 272.3794 | AI3: 3857.597 | AJ3: 694.3828 | AK3: 0 | AL3: 14098.64 | AM3: 0 | AN3: 0 | AO3: 14.0892 | AP3: 704.9792 | AQ3: 0.0118 | AR3: 1413.4512 | AS3: 0 | AT3: 0 | AU3: 0 | AV3: 0 | AW3: 0 | AX3: 0 | AY3: 0 | AZ3: 0 | BA3: 0 | BB3: 5271.0482 | BC3: 0 | BD3: 9532.5828 | BE3: 0 | BF3: 0 | BG3: 0 | BH3: 0 | BI3: 0
O4: 15741 | P4: 0 | Q4: 0 | R4: 2438 | S4: 1355 | T4: 0 | U4: 0 | V4: 597.45 | W4: 12545.45 | X4: 11948 | Y4: 0 | Z4: 0 | AA4: 11948 | AB4: 736 | AC4: 2748.04 | AD4: 134.53 | AE4: 400 | AF4: 0 | AG4: 109.72 | AH4: 230.83 | AI4: 3269.15 | AJ4: 588.46 | AK4: 0 | AL4: 11948 | AM4: 0 | AN4: 0 | AO4: 11.94 | AP4: 597.44 | AQ4: 0.01 | AR4: 1197.84 | AS4: 0 | AT4: 0 | AU4: 0 | AV4: 0 | AW4: 0 | AX4: 0 | AY4: 0 | AZ4: 0 | BA4: 0 | BB4: 4466.99 | BC4: 0 | BD4: 8078.46 | BE4: 0 | BF4: 0 | BG4: 0 | BH4: 0 | BI4: 0
A5: S.no. | B5: Order ID | C5: Order date | D5: Week no. | E5: Res. name | F5: Res. ID | G5: Discount construct | H5: Mode of payment | I5: Order status (Delivered/ Cancelled/ Rejected) | J5: Cancellation policy (% Amount refunded back to restaurant partner) | K5: Cancellation/ Rejection reason | L5: Cancelled/ Rejected state (Order status at the time it was cancelled/ rejected) | M5: Order type | N5: Delivery state code | O5: Subtotal (items total) | P5: Packaging charge | Q5: Delivery charge for restaurants on self logistics | R5: Restaurant discount (Promo) | S5: Restaurant discount (BOGO, Freebies, Gold, Brand pack & others) | T5: Brand pack subscription fee | U5: Delivery charge discount/ Relisting discount | V5: Total GST collected from customers | W5: Net order value [(1) + (2) + (3) - (4) - (5) + (6) - (7) + (8)] | X5: Commissionable value of Subtotal, excluding restuarant discounts [(1) - (4) - (5)] | Y5: Commissionable value of Packaging charge | Z5: Commissionable value of Total GST collected from customers | AA5: Total commissionable value [(9) + (10) + (11)] | AB5: Base service fee % | AC5: Base service fee [(12)% * (B)] | AD5: Actual order distance (km) | AE5: Long distance enablement fee | AF5: Discount on long distance enablement fee | AG5: Discount on service fee due to 30% capping Service fees capped at 30% of commissionable value (B) | AH5: Payment mechanism fee | AI5: Service fee & payment mechanism fee [(13) + (15) - (16) - (17) + (18)] | AJ5: Taxes on service fee & payment mechanism fee [(C) * 18%] | AK5: Applicable amount for TCS | AL5: Applicable amount for 9(5) | AM5: Tax collected at source | AN5: TCS IGST amount | AO5: TDS 194O amount | AP5: GST paid by Zomato on behalf of restaurant - under section 9(5) | AQ5: GST to be paid by Restaurant partner to Govt. | AR5: Government charges [(19) + (22) + (23) + (24) + (25)] | AS5: Customer compensation/ recoupment | AT5: Delivery charges recovery | AU5: Amount received in cash (on self delivery orders) | AV5: Credit note/ (Debit note) adjustment | AW5: Promo recovery adjustment | AX5: Extra inventory ads (order level deduction) | AY5: Brand loyalty points redemption | AZ5: Express order fee | BA5: Other order-level deductions [(27) + (28) + (29) + (30) + (31) + (32) + (33) + (34)] | BB5: Net Deductions [(C) + (D) + (E)] | BC5: Net Additions (cancellation refund for cancelled orders/ tip for kitchen staff for delivered orders) | BD5: Order level Payout (A) - (F) + (G) | BE5: Settlement status | BF5: Settlement date | BG5: Bank UTR | BH5: Unsettled amount | BI5: Customer ID
A6: 1 | B6: 7579846676 | C6: 2025-12-15 07:25:21 | D6: 51 | E6: Royal Dhaba Since 1922 - By Posh Foods | F6: 19617842 | G6: Flat ₹100 off (2025-12-08 - 2031-01-01) | H6: ONLINE | I6: DELIVERED | J6: NA | K6: NA | L6: NA | M6: O2 | N6: 9 | O6: 224 | P6: 0 | Q6: 0 | R6: 70 | S6: 0 | T6: 0 | U6: 0 | V6: 7.7 | W6: 161.7 | X6: 154 | Y6: 0 | Z6: 0 | AA6: 154 | AB6: 23 | AC6: 35.42 | AD6: 8.35 | AE6: 40 | AF6: 0 | AG6: 29.22 | AH6: 2.98 | AI6: 49.18 | AJ6: 8.86 | AK6: 0 | AL6: 154 | AM6: 0 | AN6: 0 | AO6: 0.15 | AP6: 7.7 | AQ6: 0 | AR6: 16.71 | AS6: 0 | AT6: 0 | AU6: 0 | AV6: 0 | AW6: 0 | AX6: 0 | AY6: 0 | AZ6: 0 | BA6: 0 | BB6: 65.89 | BC6: 0 | BD6: 95.81 | BE6: settled | BF6: 2025-12-24 05:30:00 | BG6: CITIN25674256745 | BH6: 0 | BI6: d91e8b8599ebbdbb79058d9db18c785d97da98862255b7f4af639a7ffbd28a65
A7: 2 | B7: 7585483411 | C7: 2025-12-15 09:40:58 | D7: 51 | E7: Royal Dhaba Since 1922 - By Posh Foods | F7: 19617842 | G7: Flat ₹100 off (2025-12-08 - 2031-01-01) | H7: ONLINE | I7: DELIVERED | J7: NA | K7: NA | L7: NA | M7: O2 | N7: 9 | O7: 224 | P7: 0 | Q7: 0 | R7: 70 | S7: 0 | T7: 0 | U7: 0 | V7: 7.7 | W7: 161.7 | X7: 154 | Y7: 0 | Z7: 0 | AA7: 154 | AB7: 23 | AC7: 35.42 | AD7: 1.17 | AE7: 0 | AF7: 0 | AG7: 0 | AH7: 2.98 | AI7: 38.4 | AJ7: 6.92 | AK7: 0 | AL7: 154 | AM7: 0 | AN7: 0 | AO7: 0.15 | AP7: 7.7 | AQ7: 0 | AR7: 14.77 | AS7: 0 | AT7: 0 | AU7: 0 | AV7: 0 | AW7: 0 | AX7: 0 | AY7: 0 | AZ7: 0 | BA7: 0 | BB7: 53.17 | BC7: 0 | BD7: 108.53 | BE7: settled | BF7: 2025-12-24 05:30:00 | BG7: CITIN25674256745 | BH7: 0 | BI7: 837a413c8ff0bda32bec7cc85db4f983fa70c085605d1530e191b6a27dd9caac
