Workbook
Name Summary: #REF!

Sheet Paytm Reconciliation
A1: Sumadhura Shandaar Foods
A2: Paytm Reconciliation - December - 2026
A4: S. No | B4: Particulars | C4: Amount (₹) | I4: Percentage (%)
C5: 1st to 7th | D5: 8th to 14th | E5: 15th to 21st | F5: 22nd to 28th | G5: 29th to 31st | H5: Total
A6: 1 | B6: Sales (exclusive of GST) before failed and reversed transactions | C6: ='Paytm Calculations'!G2 | D6: ='Paytm Calculations'!H2 | E6: ='Paytm Calculations'!I2 | F6: ='Paytm Calculations'!J2 | G6: ='Paytm Calculations'!K2 | H6: =SUM(C6:G6) | I6: =H6/$H$10 | K6: =J6*100/105
B7: Failed transctions | C7: 0 | D7: 0 | E7: 0 | F7: 0 | G7: 0 | H7: =SUM(C7:G7) | I7: =H7/$H$10
B8: Sales (Exclucive of GST) after failed and reversed transactions | C8: =C6-C7 | D8: =D6-D7 | E8: =E6-E7 | F8: =F6-F7 | G8: =G6-G7 | H8: =H6-H7 | I8: =H8/$H$10
B9: add: GST @5% | C9: =C8*5% | D9: =D8*5% | E9: =E8*5% | F9: =F8*5% | G9: =G8*5% | H9: =SUM(C9:G9) | I9: =H9/$H$10
B10: Sales (inclusive of GST) | C10: =C8+C9 | D10: =D8+D9 | E10: =E8+E9 | F10: =F8+F9 | G10: =G8+G9 | H10: =SUM(C10:G10) | I10: =H10/$H$10
B11: Sales as per POS (Inclusive of GST) | H11: =SUM(C11:G11) | I11: =H11/$H$10
B12: Difference in POS | C12: =C11-C10 | D12: =D11-D10 | E12: =E11-E10 | F12: =F11-F10 | G12: =G11-G10 | H12: =SUM(C12:G12) | I12: =H12/$H$10
A14: 2 | B14: Commission & other charges
B15: Commission (Inclusive of GST) | C15: ='Paytm Calculations'!G3 | D15: ='Paytm Calculations'!H3 | E15: ='Paytm Calculations'!I3 | F15: ='Paytm Calculations'!J3 | G15: ='Paytm Calculations'!K3 | H15: =SUM(C15:G15) | I15: =H15/$H$10
B16: Total Commission & other charges | C16: =C15 | D16: =D15 | E16: =E15 | F16: =F15 | G16: =G15 | H16: =SUM(C16:G16) | I16: =H16/$H$10
A18: 3 | B18: Expected receipt in Bank Statement | C18: =C10-C16 | D18: =D10-D16 | E18: =E10-E16 | F18: =F10-F16 | G18: =G10-G16 | H18: =SUM(C18:G18) | I18: =H18/$H$10
B19: Actual Receipt in Bank Statement | H19: =SUM(C19:G19) | I19: =H19/$H$10
B20: Difference | C20: =C19-C18 | D20: =D19-D18 | E20: =E19-E18 | F20: =F19-F18 | G20: =G19-G18 | H20: =SUM(C20:G20) | I20: =H20/$H$10
A22: Note:
A23: 1. Due to the absence of source for last week considered from bank.
A24: 3. There is a difference between Amex Actual receipts and Expected receipts.Rs. 1,572.71/- is more in expected receipts
A25: 4. There is a difference in Paytm Actual receipts and Expected receipts, Rs. 99/- is more in expected receipts.

Sheet Paytm Calculations
G1: Week 1 | H1: Week 2 | I1: Week 3 | J1: Week 4 | K1: Week 5
G2: 92680.952 | H2: 85201.905 | I2: 78261.905 | J2: 87553.333 | K2: 16800.952
G3: 208.7538 | H3: 197.4612 | I3: 298.717 | J3: 247.2926 | K3: 25.9836
A10: Transaction_ID | B10: Order_ID | C10: Merchant_Unique_Ref | D10: Merchant_Request_Id | E10: Transaction_Date | F10: Updated_Date | G10: Transaction_Type | H10: Status | I10: MID | J10: Merchant_Name | K10: Customer_ID | L10: Customer_Nickname | M10: Payment_Mobile_Number | N10: Payment_Email_Id | O10: Amount | P10: Commission | Q10: GST | R10: Merchant_Order_ID | S10: Payout_ID | T10: Channel | U10: UTR_No. | V10: Payout_Date | W10: Settled_Date | X10: Payment_Mode | Y10: Issuing_Bank | Z10: Reference_Transaction_ID | AA10: POS_ID | AB10: Merchant_Ref_ID | AC10: External_Serial_No | AD10: Commission_Rate | AE10: Product_Code | AF10: GMV_Tier | AG10: Transaction_Slab | AH10: Request_Type | AI10: Refund_Type | AJ10: Refund_Actor | AK10: Split_Flag | AL10: Split_MID | AM10: Split_Id | AN10: Is_Split_Refund | AO10: Link_Description | AP10: Payment_Reference_Number | AQ10: Is_PRN_Validated | AR10: PRN_Validate_Time | AS10: Credit/Debit_Card_Last_4_Digits | AT10: Bank_Transaction_ID | AU10: Promo_Code | AV10: Promo_Response | AW10: Settled_Amount | AX10: PCF | AY10: PCF_GST | AZ10: FS_Offer_Fee | BA10: FS_Offer_GST | BB10: Response_code | BC10: Customer_VPA | BD10: Card_BIN | BE10: Customer_Details | BF10: Link_Name | BG10: Link_Notes | BH10: Response_message | BI10: Promo_discount_type | BJ10: Promo_Amount | BK10: Original_txn_value_before_promo | BL10: Total_Bill_Amount | BM10: Instant_Discount | BN10: MLV_Amount | BO10: Auth_Code | BP10: RRN | BQ10: Prepaid_Card | BR10: AdditionalComments | BS10: Charge_Target | BT10: Fee_Factor | BU10: Bank/Gateway | BV10: Card_Scheme | BW10: ACQUIRING_SERVICE_FEE | BX10: ACQUIRING_SERVICE_TAX | BY10: PLATFORM_SERVICE_FEE | BZ10: PLATFORM_SERVICE_TAX | CA10: Promo_Cart_Amount | CB10: Reseller_ID | CC10: Reseller_Name | CD10: Employee_Id | CE10: Employee_Name | CF10: Employee_PhoneNo | CG10: Employee_Email | CH10: User_Expected_Credit_Date | CI10: Order_Reason | CJ10: Customer_Account_Number | CK10: Customer_BANK_IFSC | CL10: TEMPLATE_ID | CM10: TEMPLATE_NAME | CN10: Foreign_Currency | CO10: Foreign_Currency_Name | CP10: Foreign_Amount | CQ10: Exchange_Rate | CR10: User_Markup_Rate | CS10: Refund_Source | CT10: Sub_Order_Status | CU10: Refund_Reversal_Id | CV10: Refund_Reversal_Status | CW10: Refund_Reversal_TimeStamp | CX10: Capture_Id | CY10: Pos_Date | CZ10: Pos_Time | DA10: Add_Money_Type | DB10: ARN | DC10: Gateway_Response_Code | DD10: Gateway_Response_Message | DE10: ARN_AVAILABILITY | DF10: Split_Reference_Id | DG10: UDF2 | DH10: UDF3 | DI10: IS_REVERSAL | DJ10: Settle_Type | DK10: Merchant_Payment_Detail_1 | DL10: Settlement_Bundle_Id | DM10: Settle_Factors | DN10: Is_Dqr_True | DO10: Customer_Convenience_Fee
A11: '20251201111030000202045111744948209' | B11: 'PTM50153de570c845648d55547c97ec2ceb' | E11: '2025-12-01 00:18:07' | F11: '2025-12-01 00:18:08' | G11: 'ACQUIRING' | H11: 'SUCCESS' | I11: 'TYXysH23627954956290' | J11: 'SHA SHA SHANDAAR SHAWARMA' | O11: 130 | P11: 0 | Q11: 0 | S11: 'AWSPG202512010001216820000806612997973' | T11: 'WAP' | U11: 'YESAP53363716979' | V11: '2025-12-01 00:01:00' | W11: '2025-12-02 04:36:23' | X11: 'UPI' | AA11: 'POS23985176461' | AC11: '5120120077791047681' | AE11: '51051000100000000001' | AH11: 'SEAMLESS_3D_FORM' | AO11: 'POS23985176461' | AT11: '533591462832' | AW11: 130 | AX11: 0 | AY11: 0 | BB11: '01' | BC11: '6300374561@pthdfc' | BH11: 'Txn Success' | BK11: 130 | BP11: '533591462832' | BQ11: 'false' | BR11: 'NA' | BS11: 'RECEIVER' | BT11: 'UPI|UPIPUSH|QR|PPBL' | BU11: 'PPBL' | BW11: 0 | BX11: 0 | CH11: 'UPI:null' | DJ11: 'BW'
A12: '20251201011000000202044341028631625' | B12: 'ICI6d5c9a1d44144ae7a96ee928c5af4edb' | E12: '2025-12-01 00:15:03' | F12: '2025-12-01 00:15:04' | G12: 'ACQUIRING' | H12: 'SUCCESS' | I12: 'TYXysH23627954956290' | J12: 'SHA SHA SHANDAAR SHAWARMA' | O12: 150 | P12: 0 | Q12: 0 | S12: 'AWSPG202512010001216820000806612997973' | T12: 'WAP' | U12: 'YESAP53363716979' | V12: '2025-12-01 00:01:00' | W12: '2025-12-02 04:36:23' | X12: 'UPI' | AA12: 'POS23985176461' | AC12: '5120120064635003913' | AE12: '51051000100000000001' | AH12: 'SEAMLESS_3D_FORM' | AT12: '570153307474' | AW12: 150 | AX12: 0 | AY12: 0 | BB12: '01' | BC12: 'mirzaakbarbaig231-3@okicici' | BH12: 'Txn Success' | BK12: 150 | BP12: '570153307474' | BQ12: 'false' | BR12: 'UPI' | BS12: 'RECEIVER' | BT12: 'UPI|UPIPUSH|QR|PPBL' | BU12: 'PPBL' | BW12: 0 | BX12: 0 | CH12: 'UPI:null' | DJ12: 'BW'
A13: '20251201010810000202044249534505180' | B13: 'APLAP4fd87161aa087a960178420847df76' | E13: '2025-12-01 00:14:41' | F13: '2025-12-01 00:14:42' | G13: 'ACQUIRING' | H13: 'SUCCESS' | I13: 'TYXysH23627954956290' | J13: 'SHA SHA SHANDAAR SHAWARMA' | O13: 190 | P13: 0 | Q13: 0 | S13: 'AWSPG202512010001216820000806612997973' | T13: 'WAP' | U13: 'YESAP53363716979' | V13: '2025-12-01 00:01:00' | W13: '2025-12-02 04:36:23' | X13: 'UPI' | AA13: 'POS23985176461' | AC13: '5120120062959237121' | AE13: '51051000100000000001' | AH13: 'SEAMLESS_3D_FORM' | AO13: 'POS23985176461' | AT13: '533502396913' | AW13: 190 | AX13: 0 | AY13: 0 | BB13: '01' | BC13: '7995232555@apl' | BH13: 'Txn Success' | BK13: 190 | BP13: '533502396913' | BQ13: 'false' | BR13: 'UPI' | BS13: 'RECEIVER' | BT13: 'UPI|UPIPUSH|QR|PPBL' | BU13: 'PPBL' | BW13: 0 | BX13: 0 | CH13: 'UPI:null' | DJ13: 'BW'
A14: '20251201011070000202084585476095638' | B14: 'SBI53e2e8921ce2436b88fdda87c18e86f8' | E14: '2025-12-01 02:54:58' | F14: '2025-12-01 02:55:00' | G14: 'ACQUIRING' | H14: 'SUCCESS' | I14: 'TYXysH23627954956290' | J14: 'SHA SHA SHANDAAR SHAWARMA' | O14: 130 | P14: 0 | Q14: 0 | S14: 'AWSPG202512010001216820000806612997973' | T14: 'WAP' | U14: 'YESAP53363716979' | V14: '2025-12-01 00:01:00' | W14: '2025-12-02 04:36:23' | X14: 'UPI' | AA14: 'POS23985176461' | AC14: '5120120785588296713' | AE14: '51051000100000000001' | AH14: 'SEAMLESS_3D_FORM' | AT14: '533598369432' | AW14: 130 | AX14: 0 | AY14: 0 | BB14: '01' | BC14: 'krishna202014@oksbi' | BH14: 'Txn Success' | BK14: 130 | BP14: '533598369432' | BQ14: 'false' | BR14: 'UPI' | BS14: 'RECEIVER' | BT14: 'UPI|UPIPUSH|QR|PPBL' | BU14: 'PPBL' | BW14: 0 | BX14: 0 | CH14: 'UPI:null' | DJ14: 'BW'
A15: '20251201010800000202081385591031189' | B15: 'T2512010242128663702126' | E15: '2025-12-01 02:42:15' | F15: '2025-12-01 02:42:16' | G15: 'ACQUIRING' | H15: 'SUCCESS' | I15: 'TYXysH23627954956290' | J15: 'SHA SHA SHANDAAR SHAWARMA' | O15: 80 | P15: 0 | Q15: 0 | S15: 'AWSPG202512010001216820000806612997973' | T15: 'WAP' | U15: 'YESAP53363716979' | V15: '2025-12-01 00:01:00' | W15: '2025-12-02 04:36:23' | X15: 'UPI' | AA15: 'POS23985176461' | AC15: '5120120731229848577' | AE15: '51051000100000000001' | AH15: 'SEAMLESS_3D_FORM' | AT15: '099501640518' | AW15: 80 | AX15: 0 | AY15: 0 | BB15: '01' | BC15: '7760037134@axl' | BH15: 'Txn Success' | BK15: 80 | BP15: '099501640518' | BQ15: 'false' | BR15: 'Payment from PhonePe' | BS15: 'RECEIVER' | BT15: 'UPI|UPIPUSH|QR|PPBL' | BU15: 'PPBL' | BW15: 0 | BX15: 0 | CH15: 'UPI:null' | DJ15: 'BW'
A16: '20251201010930000202079816158738527' | B16: 'T2512010235589711857234' | E16: '2025-12-01 02:36:01' | F16: '2025-12-01 02:36:02' | G16: 'ACQUIRING' | H16: 'SUCCESS' | I16: 'TYXysH23627954956290' | J16: 'SHA SHA SHANDAAR SHAWARMA' | O16: 600 | P16: 0 | Q16: 0 | S16: 'AWSPG202512010001216820000806612997973' | T16: 'WAP' | U16: 'YESAP53363716979' | V16: '2025-12-01 00:01:00' | W16: '2025-12-02 04:36:23' | X16: 'UPI' | AA16: 'POS23985176461' | AC16: '5120120704450280453' | AE16: '51051000100000000001' | AH16: 'SEAMLESS_3D_FORM' | AT16: '265456750126' | AW16: 600 | AX16: 0 | AY16: 0 | BB16: '01' | BC16: '7760037134@ybl' | BH16: 'Txn Success' | BK16: 600 | BP16: '265456750126' | BQ16: 'false' | BR16: 'Payment from PhonePe' | BS16: 'RECEIVER' | BT16: 'UPI|UPIPUSH|QR|PPBL' | BU16: 'PPBL' | BW16: 0 | BX16: 0 | CH16: 'UPI:null' | DJ16: 'BW'
A17: '20251201111110000202079126387765020' | B17: 'T2512010233088017497476' | E17: '2025-12-01 02:33:17' | F17: '2025-12-01 02:33:18' | G17: 'ACQUIRING' | H17: 'SUCCESS' | I17: 'TYXysH23627954956290' | J17: 'SHA SHA SHANDAAR SHAWARMA' | O17: 160 | P17: 0 | Q17: 0 | S17: 'AWSPG202512010001216820000806612997973' | T17: 'WAP' | U17: 'YESAP53363716979' | V17: '2025-12-01 00:01:00' | W17: '2025-12-02 04:36:23' | X17: 'UPI' | AA17: 'POS23985176461' | AC17: '5120120692639733765' | AE17: '51051000100000000001' | AH17: 'SEAMLESS_3D_FORM' | AT17: '871135800951' | AW17: 160 | AX17: 0 | AY17: 0 | BB17: '01' | BC17: 'saicrazy9871@axl' | BH17: 'Txn Success' | BK17: 160 | BP17: '871135800951' | BQ17: 'false' | BR17: 'Payment from PhonePe' | BS17: 'RECEIVER' | BT17: 'UPI|UPIPUSH|QR|PPBL' | BU17: 'PPBL' | BW17: 0 | BX17: 0 | CH17: 'UPI:null' | DJ17: 'BW'
A18: '20251201110810000202076593653131174' | B18: 'SBIb149b0de4e754a308a82a5e450f71ac7' | E18: '2025-12-01 02:23:13' | F18: '2025-12-01 02:23:14' | G18: 'ACQUIRING' | H18: 'SUCCESS' | I18: 'TYXysH23627954956290' | J18: 'SHA SHA SHANDAAR SHAWARMA' | O18: 130 | P18: 0 | Q18: 0 | S18: 'AWSPG202512010001216820000806612997973' | T18: 'WAP' | U18: 'YESAP53363716979' | V18: '2025-12-01 00:01:00' | W18: '2025-12-02 04:36:23' | X18: 'UPI' | AA18: 'POS23985176461' | AC18: '5120120649424143381' | AE18: '51051000100000000001' | AH18: 'SEAMLESS_3D_FORM' | AT18: '533598337683' | AW18: 130 | AX18: 0 | AY18: 0 | BB18: '01' | BC18: 'atishkumardas695@oksbi' | BH18: 'Txn Success' | BK18: 130 | BP18: '533598337683' | BQ18: 'false' | BR18: 'UPI' | BS18: 'RECEIVER' | BT18: 'UPI|UPIPUSH|QR|PPBL' | BU18: 'PPBL' | BW18: 0 | BX18: 0 | CH18: 'UPI:null' | DJ18: 'BW'
A19: '20251201110930000202074859158293906' | B19: 'SMTXA7DOX3CTL1YUUB4PNU88CPTEPLN1XSL' | E19: '2025-12-01 02:16:19' | F19: '2025-12-01 02:16:20' | G19: 'ACQUIRING' | H19: 'SUCCESS' | I19: 'TYXysH23627954956290' | J19: 'SHA SHA SHANDAAR SHAWARMA' | O19: 260 | P19: 0 | Q19: 0 | S19: 'AWSPG202512010001216820000806612997973' | T19: 'WAP' | U19: 'YESAP53363716979' | V19: '2025-12-01 00:01:00' | W19: '2025-12-02 04:36:23' | X19: 'UPI' | AA19: 'POS23985176461' | AC19: '5120120619825860609' | AE19: '51051000100000000001' | AH19: 'SEAMLESS_3D_FORM' | AO19: 'POS23985176461' | AT19: '533516033492' | AW19: 260 | AX19: 0 | AY19: 0 | BB19: '01' | BC19: '9381813984@superyes' | BH19: 'Txn Success' | BK19: 260 | BP19: '533516033492' | BQ19: 'false' | BR19: 'Paid via SuperMoney UPI' | BS19: 'RECEIVER' | BT19: 'UPI|UPIPUSH|QR|PPBL' | BU19: 'PPBL' | BW19: 0 | BX19: 0 | CH19: 'UPI:null' | DJ19: 'BW'
A20: '20251201111000000202074763364020221' | B20: 'ICI5c260f42b603471dadf8a76d1a0fad54' | E20: '2025-12-01 02:15:57' | F20: '2025-12-01 02:15:57' | G20: 'ACQUIRING' | H20: 'SUCCESS' | I20: 'TYXysH23627954956290' | J20: 'SHA SHA SHANDAAR SHAWARMA' | O20: 130 | P20: 0 | Q20: 0 | S20: 'AWSPG202512010001216820000806612997973' | T20: 'WAP' | U20: 'YESAP53363716979' | V20: '2025-12-01 00:01:00' | W20: '2025-12-02 04:36:23' | X20: 'UPI' | AA20: 'POS23985176461' | AC20: '5120120618014133253' | AE20: '51051000100000000001' | AH20: 'SEAMLESS_3D_FORM' | AT20: '570129807603' | AW20: 130 | AX20: 0 | AY20: 0 | BB20: '01' | BC20: 'abbusher56@okicici' | BH20: 'Txn Success' | BK20: 130 | BP20: '570129807603' | BQ20: 'false' | BR20: 'UPI' | BS20: 'RECEIVER' | BT20: 'UPI|UPIPUSH|QR|PPBL' | BU20: 'PPBL' | BW20: 0 | BX20: 0 | CH20: 'UPI:null' | DJ20: 'BW'
A21: '20251201110900000202072296136376046' | B21: '533502752219' | E21: '2025-12-01 02:06:08' | F21: '2025-12-01 02:06:09' | G21: 'ACQUIRING' | H21: 'SUCCESS' | I21: 'TYXysH23627954956290' | J21: 'SHA SHA SHANDAAR SHAWARMA' | O21: 150 | P21: 0 | Q21: 0 | S21: 'AWSPG202512010001216820000806612997973' | T21: 'WAP' | U21: 'YESAP53363716979' | V21: '2025-12-01 00:01:00' | W21: '2025-12-02 04:36:23' | X21: 'UPI' | AA21: 'POS23985176461' | AC21: '5120120576074257433' | AE21: '51051000100000000001' | AH21: 'SEAMLESS_3D_FORM' | AO21: 'POS23985176461' | AT21: '533502752219' | AW21: 150 | AX21: 0 | AY21: 0 | BB21: '01' | BC21: '9676173003@kotak811' | BH21: 'Txn Success' | BK21: 150 | BP21: '533502752219' | BQ21: 'false' | BR21: 'UPI' | BS21: 'RECEIVER' | BT21: 'UPI|UPIPUSH|QR|PPBL' | BU21: 'PPBL' | BW21: 0 | BX21: 0 | CH21: 'UPI:null' | DJ21: 'BW'
A22: '20251201111020000202071006827746874' | B22: 'T2512010200579249516858' | E22: '2025-12-01 02:01:01' | F22: '2025-12-01 02:01:02' | G22: 'ACQUIRING' | H22: 'SUCCESS' | I22: 'TYXysH23627954956290' | J22: 'SHA SHA SHANDAAR SHAWARMA' | O22: 130 | P22: 0 | Q22: 0 | S22: 'AWSPG202512010001216820000806612997973' | T22: 'WAP' | U22: 'YESAP53363716979' | V22: '2025-12-01 00:01:00' | W22: '2025-12-02 04:36:23' | X22: 'UPI' | AA22: 'POS23985176461' | AC22: '5120120554129852421' | AE22: '51051000100000000001' | AH22: 'SEAMLESS_3D_FORM' | AT22: '448241477611' | AW22: 130 | AX22: 0 | AY22: 0 | BB22: '01' | BC22: '8184898815@ybl' | BH22: 'Txn Success' | BK22: 130 | BP22: '448241477611' | BQ22: 'false' | BR22: 'Payment from PhonePe' | BS22: 'RECEIVER' | BT22: 'UPI|UPIPUSH|QR|PPBL' | BU22: 'PPBL' | BW22: 0 | BX22: 0 | CH22: 'UPI:null' | DJ22: 'BW'
A23: '20251201010930000202067321951452168' | B23: 'PTM6bd74fe6f0c04cfbb5d33dcbe68a2e0b' | E23: '2025-12-01 01:46:22' | F23: '2025-12-01 01:46:24' | G23: 'ACQUIRING' | H23: 'SUCCESS' | I23: 'TYXysH23627954956290' | J23: 'SHA SHA SHANDAAR SHAWARMA' | O23: 130 | P23: 0 | Q23: 0 | S23: 'AWSPG202512010001216820000806612997973' | T23: 'WAP' | U23: 'YESAP53363716979' | V23: '2025-12-01 00:01:00' | W23: '2025-12-02 04:36:23' | X23: 'UPI' | AA23: 'POS23985176461' | AC23: '5120130473932899333' | AE23: '51051000100000000001' | AH23: 'SEAMLESS_3D_FORM' | AO23: 'POS23985176461' | AT23: '393092296018' | AW23: 130 | AX23: 0 | AY23: 0 | BB23: '01' | BC23: '9392032356@ptyes' | BH23: 'Txn Success' | BK23: 130 | BP23: '393092296018' | BQ23: 'false' | BR23: 'NA' | BS23: 'RECEIVER' | BT23: 'UPI|UPIPUSH|QR|PPBL' | BU23: 'PPBL' | BW23: 0 | BX23: 0 | CH23: 'UPI:null' | DJ23: 'BW'
A24: '20251201010930000202061357303047348' | B24: 'APYAP2818fdc815727fa8adff5758ebb573' | E24: '2025-12-01 01:22:40' | F24: '2025-12-01 01:22:41' | G24: 'ACQUIRING' | H24: 'SUCCESS' | I24: 'TYXysH23627954956290' | J24: 'SHA SHA SHANDAAR SHAWARMA' | O24: 560 | P24: 0 | Q24: 0 | S24: 'AWSPG202512010001216820000806612997973' | T24: 'WAP' | U24: 'YESAP53363716979' | V24: '2025-12-01 00:01:00' | W24: '2025-12-02 04:36:23' | X24: 'UPI' | AA24: 'POS23985176461' | AC24: '5120120372062494729' | AE24: '51051000100000000001' | AH24: 'SEAMLESS_3D_FORM' | AO24: 'POS23985176461' | AT24: '533532976604' | AW24: 560 | AX24: 0 | AY24: 0 | BB24: '01' | BC24: '9553675243@yapl' | BH24: 'Txn Success' | BK24: 560 | BP24: '533532976604' | BQ24: 'false' | BR24: 'UPI' | BS24: 'RECEIVER' | BT24: 'UPI|UPIPUSH|QR|PPBL' | BU24: 'PPBL' | BW24: 0 | BX24: 0 | CH24: 'UPI:null' | DJ24: 'BW'
A25: '20251201110980000202059987229568166' | B25: 'ICI08d5aa7dd0684d95925838802331df58' | E25: '2025-12-01 01:17:14' | F25: '2025-12-01 01:17:15' | G25: 'ACQUIRING' | H25: 'SUCCESS' | I25: 'TYXysH23627954956290' | J25: 'SHA SHA SHANDAAR SHAWARMA' | O25: 130 | P25: 0 | Q25: 0 | S25: 'AWSPG202512010001216820000806612997973' | T25: 'WAP' | U25: 'YESAP53363716979' | V25: '2025-12-01 00:01:00' | W25: '2025-12-02 04:36:23' | X25: 'UPI' | AA25: 'POS23985176461' | AC25: '5120120348841217025' | AE25: '51051000100000000001' | AH25: 'SEAMLESS_3D_FORM' | AT25: '533577494409' | AW25: 130 | AX25: 0 | AY25: 0 | BB25: '01' | BC25: 'swastikdudiwar04-1@okicici' | BH25: 'Txn Success' | BK25: 130 | BP25: '533577494409' | BQ25: 'false' | BR25: 'UPI' | BS25: 'RECEIVER' | BT25: 'UPI|UPIPUSH|QR|PPBL' | BU25: 'PPBL' | BW25: 0 | BX25: 0 | CH25: 'UPI:null' | DJ25: 'BW'
A26: '20251201111020000202059795113450612' | B26: 'T2512010116247364989867' | E26: '2025-12-01 01:16:28' | F26: '2025-12-01 01:16:29' | G26: 'ACQUIRING' | H26: 'SUCCESS' | I26: 'TYXysH23627954956290' | J26: 'SHA SHA SHANDAAR SHAWARMA' | O26: 150 | P26: 0 | Q26: 0 | S26: 'AWSPG202512010001216820000806612997973' | T26: 'WAP' | U26: 'YESAP53363716979' | V26: '2025-12-01 00:01:00' | W26: '2025-12-02 04:36:23' | X26: 'UPI' | AA26: 'POS23985176461' | AC26: '5120120345487832065' | AE26: '51051000100000000001' | AH26: 'SEAMLESS_3D_FORM' | AT26: '145783564866' | AW26: 150 | AX26: 0 | AY26: 0 | BB26: '01' | BC26: 'rakeshrao16@ybl' | BH26: 'Txn Success' | BK26: 150 | BP26: '145783564866' | BQ26: 'false' | BR26: 'Payment from PhonePe' | BS26: 'RECEIVER' | BT26: 'UPI|UPIPUSH|QR|PPBL' | BU26: 'PPBL' | BW26: 0 | BX26: 0 | CH26: 'UPI:null' | DJ26: 'BW'
A27: '20251201110930000202056517306916738' | B27: 'T2512010103234044989730' | E27: '2025-12-01 01:03:26' | F27: '2025-12-01 01:03:28' | G27: 'ACQUIRING' | H27: 'SUCCESS' | I27: 'TYXysH23627954956290' | J27: 'SHA SHA SHANDAAR SHAWARMA' | O27: 150 | P27: 0 | Q27: 0 | S27: 'AWSPG202512010001216820000806612997973' | T27: 'WAP' | U27: 'YESAP53363716979' | V27: '2025-12-01 00:01:00' | W27: '2025-12-02 04:36:23' | X27: 'UPI' | AA27: 'POS23985176461' | AC27: '5120130289518796825' | AE27: '51051000100000000001' | AH27: 'SEAMLESS_3D_FORM' | AT27: '206785215579' | AW27: 150 | AX27: 0 | AY27: 0 | BB27: '01' | BC27: 'lokeshrocky007@axl' | BH27: 'Txn Success' | BK27: 150 | BP27: '206785215579' | BQ27: 'false' | BR27: 'Payment from PhonePe' | BS27: 'RECEIVER' | BT27: 'UPI|UPIPUSH|QR|PPBL' | BU27: 'PPBL' | BW27: 0 | BX27: 0 | CH27: 'UPI:null' | DJ27: 'BW'
A28: '20251201111070000202056514530740086' | B28: 'SBId42358f9a120414e90714a8a9f3befed' | E28: '2025-12-01 01:03:26' | F28: '2025-12-01 01:03:27' | G28: 'ACQUIRING' | H28: 'SUCCESS' | I28: 'TYXysH23627954956290' | J28: 'SHA SHA SHANDAAR SHAWARMA' | O28: 250 | P28: 0 | Q28: 0 | S28: 'AWSPG202512010001216820000806612997973' | T28: 'WAP' | U28: 'YESAP53363716979' | V28: '2025-12-01 00:01:00' | W28: '2025-12-02 04:36:23' | X28: 'UPI' | AA28: 'POS23985176461' | AC28: '5120120289518154753' | AE28: '51051000100000000001' | AH28: 'SEAMLESS_3D_FORM' | AT28: '533598112288' | AW28: 250 | AX28: 0 | AY28: 0 | BB28: '01' | BC28: 'shaikomer70977@oksbi' | BH28: 'Txn Success' | BK28: 250 | BP28: '533598112288' | BQ28: 'false' | BR28: 'UPI' | BS28: 'RECEIVER' | BT28: 'UPI|UPIPUSH|QR|PPBL' | BU28: 'PPBL' | BW28: 0 | BX28: 0 | CH28: 'UPI:null' | DJ28: 'BW'
A29: '20251201010800000202055686167673128' | B29: 'T2512010100053809720941' | E29: '2025-12-01 01:00:08' | F29: '2025-12-01 01:00:09' | G29: 'ACQUIRING' | H29: 'SUCCESS' | I29: 'TYXysH23627954956290' | J29: 'SHA SHA SHANDAAR SHAWARMA' | O29: 120 | P29: 0 | Q29: 0 | S29: 'AWSPG202512010001216820000806612997973' | T29: 'WAP' | U29: 'YESAP53363716979' | V29: '2025-12-01 00:01:00' | W29: '2025-12-02 04:36:23' | X29: 'UPI' | AA29: 'POS23985176461' | AC29: '5120120275427011585' | AE29: '51051000100000000001' | AH29: 'SEAMLESS_3D_FORM' | AT29: '384415721810' | AW29: 120 | AX29: 0 | AY29: 0 | BB29: '01' | BC29: 'ashraygolu@axl' | BH29: 'Txn Success' | BK29: 120 | BP29: '384415721810' | BQ29: 'false' | BR29: 'Payment from PhonePe' | BS29: 'RECEIVER' | BT29: 'UPI|UPIPUSH|QR|PPBL' | BU29: 'PPBL' | BW29: 0 | BX29: 0 | CH29: 'UPI:null' | DJ29: 'BW'
A30: '20251201110870000202051238309956537' | B30: 'PTM398e4c0a5bb54ac0aebfd8b114f8b71c' | E30: '2025-12-01 00:42:28' | F30: '2025-12-01 00:42:29' | G30: 'ACQUIRING' | H30: 'SUCCESS' | I30: 'TYXysH23627954956290' | J30: 'SHA SHA SHANDAAR SHAWARMA' | O30: 130 | P30: 0 | Q30: 0 | S30: 'AWSPG202512010001216820000806612997973' | T30: 'WAP' | U30: 'YESAP53363716979' | V30: '2025-12-01 00:01:00' | W30: '2025-12-02 04:36:23' | X30: 'UPI_LITE' | AA30: 'POS23985176461' | AC30: '5120120182277944325' | AE30: '51051000100000000001' | AH30: 'SEAMLESS_3D_FORM' | AO30: 'POS23985176461' | AT30: '393092069508' | AW30: 130 | AX30: 0 | AY30: 0 | BB30: '01' | BC30: '9553850189@ptyes' | BH30: 'Txn Success' | BK30: 130 | BP30: '393092069508' | BQ30: 'false' | BR30: 'NA' | BS30: 'RECEIVER' | BT30: 'UPI|UPIPUSH|QR|UPI_LITE|PPBL' | BU30: 'PPBL' | BW30: 0 | BX30: 0 | CH30: 'UPI:null' | DJ30: 'BW'
A31: '20251201110980000202048066783087738' | B31: 'T2512010029488609291803' | E31: '2025-12-01 00:29:52' | F31: '2025-12-01 00:29:53' | G31: 'ACQUIRING' | H31: 'SUCCESS' | I31: 'TYXysH23627954956290' | J31: 'SHA SHA SHANDAAR SHAWARMA' | O31: 150 | P31: 0 | Q31: 0 | S31: 'AWSPG202512010001216820000806612997973' | T31: 'WAP' | U31: 'YESAP53363716979' | V31: '2025-12-01 00:01:00' | W31: '2025-12-02 04:36:23' | X31: 'UPI' | AA31: 'POS23985176461' | AC31: '5120120128053679105' | AE31: '51051000100000000001' | AH31: 'SEAMLESS_3D_FORM' | AT31: '732375943494' | AW31: 150 | AX31: 0 | AY31: 0 | BB31: '01' | BC31: '8475800314-4@ybl' | BH31: 'Txn Success' | BK31: 150 | BP31: '732375943494' | BQ31: 'false' | BR31: 'Payment from PhonePe' | BS31: 'RECEIVER' | BT31: 'UPI|UPIPUSH|QR|PPBL' | BU31: 'PPBL' | BW31: 0 | BX31: 0 | CH31: 'UPI:null' | DJ31: 'BW'
A32: '20251201110930000202048019151860293' | B32: 'PTM8a5044a515fc43299dc6bbfeefb7cbcd' | E32: '2025-12-01 00:29:40' | F32: '2025-12-01 00:29:43' | G32: 'ACQUIRING' | H32: 'SUCCESS' | I32: 'TYXysH23627954956290' | J32: 'SHA SHA SHANDAAR SHAWARMA' | O32: 130 | P32: 2.95 | Q32: 0.53 | S32: 'AWSPG202512010001216820000806612997973' | T32: 'WAP' | U32: 'YESAP53363716979' | V32: '2025-12-01 00:01:00' | W32: '2025-12-02 04:36:23' | X32: 'UPI_CREDIT_CARD' | AA32: 'POS23985176461' | AC32: '5120120127248055297' | AE32: '51051000100000000001' | AH32: 'SEAMLESS_3D_FORM' | AO32: 'POS23985176461' | AT32: '393092001067' | AW32: 126.52 | AX32: 0 | AY32: 0 | BB32: '01' | BC32: 'vinaytejauppada@ptyes' | BH32: 'Txn Success' | BK32: 130 | BP32: '393092001067' | BQ32: 'false' | BR32: 'NA' | BS32: 'RECEIVER' | BT32: 'UPI|UPIPUSH|QR|UPI_CREDIT_CARD|PPBL|Platinum|upiCc' | BU32: 'PPBL' | BW32: 2.95 | BX32: 0.53 | CH32: 'UPI:null' | DJ32: 'BW'
A33: '20251201110890000202047677421673281' | B33: 'T2512010028163267996878' | E33: '2025-12-01 00:28:19' | F33: '2025-12-01 00:28:20' | G33: 'ACQUIRING' | H33: 'SUCCESS' | I33: 'TYXysH23627954956290' | J33: 'SHA SHA SHANDAAR SHAWARMA' | O33: 150 | P33: 3.41 | Q33: 0.61 | S33: 'AWSPG202512010001216820000806612997973' | T33: 'WAP' | U33: 'YESAP53363716979' | V33: '2025-12-01 00:01:00' | W33: '2025-12-02 04:36:23' | X33: 'UPI_CREDIT_CARD' | AA33: 'POS23985176461' | AC33: '5120120121544119301' | AE33: '51051000100000000001' | AH33: 'SEAMLESS_3D_FORM' | AO33: 'POS23985176461' | AT33: '862735782198' | AW33: 145.98 | AX33: 0 | AY33: 0 | BB33: '01' | BC33: '7396916992-5@axl' | BH33: 'Txn Success' | BK33: 150 | BP33: '862735782198' | BQ33: 'false' | BR33: 'Payment from PhonePe' | BS33: 'RECEIVER' | BT33: 'UPI|UPIPUSH|QR|UPI_CREDIT_CARD|PPBL|JCB Platinum|upiCc' | BU33: 'PPBL' | BW33: 3.41 | BX33: 0.61 | CH33: 'UPI:null' | DJ33: 'BW'
A34: '20251201011070000202111174763109551' | B34: 'T2512010440323444241629' | E34: '2025-12-01 04:40:38' | F34: '2025-12-01 04:40:39' | G34: 'ACQUIRING' | H34: 'SUCCESS' | I34: 'TYXysH23627954956290' | J34: 'SHA SHA SHANDAAR SHAWARMA' | O34: 300 | P34: 0 | Q34: 0 | S34: 'AWSPG202512010001216820000806612997973' | T34: 'WAP' | U34: 'YESAP53363716979' | V34: '2025-12-01 00:01:00' | W34: '2025-12-02 04:36:23' | X34: 'UPI' | AA34: 'POS23985176461' | AC34: '5120131273870057473' | AE34: '51051000100000000001' | AH34: 'SEAMLESS_3D_FORM' | AT34: '615599481708' | AW34: 300 | AX34: 0 | AY34: 0 | BB34: '01' | BC34: '60021725120@ybl' | BH34: 'Txn Success' | BK34: 300 | BP34: '615599481708' | BQ34: 'false' | BR34: 'Payment from PhonePe' | BS34: 'RECEIVER' | BT34: 'UPI|UPIPUSH|QR|PPBL' | BU34: 'PPBL' | BW34: 0 | BX34: 0 | CH34: 'UPI:null' | DJ34: 'BW'
A35: '20251201011020000202106274964062649' | B35: 'SBI5308a2aeb94f4644857ca0ef42b1b4c8' | E35: '2025-12-01 04:21:09' | F35: '2025-12-01 04:21:11' | G35: 'ACQUIRING' | H35: 'SUCCESS' | I35: 'TYXysH23627954956290' | J35: 'SHA SHA SHANDAAR SHAWARMA' | O35: 520 | P35: 0 | Q35: 0 | S35: 'AWSPG202512010001216820000806612997973' | T35: 'WAP' | U35: 'YESAP53363716979' | V35: '2025-12-01 00:01:00' | W35: '2025-12-02 04:36:23' | X35: 'UPI' | AA35: 'POS23985176461' | AC35: '5120121190388898817' | AE35: '51051000100000000001' | AH35: 'SEAMLESS_3D_FORM' | AT35: '533598469718' | AW35: 520 | AX35: 0 | AY35: 0 | BB35: '01' | BC35: 'www.mohds9824@oksbi' | BH35: 'Txn Success' | BK35: 520 | BP35: '533598469718' | BQ35: 'false' | BR35: 'UPI' | BS35: 'RECEIVER' | BT35: 'UPI|UPIPUSH|QR|PPBL' | BU35: 'PPBL' | BW35: 0 | BX35: 0 | CH35: 'UPI:null' | DJ35: 'BW'
A36: '20251201110990000202256898070617275' | B36: 'ICI99b143cda7514aad98b1af3baa7596ca' | E36: '2025-12-01 14:19:41' | F36: '2025-12-01 14:19:42' | G36: 'ACQUIRING' | H36: 'SUCCESS' | I36: 'TYXysH23627954956290' | J36: 'SHA SHA SHANDAAR SHAWARMA' | O36: 180 | P36: 0 | Q36: 0 | S36: 'AWSPG202512010001216820000806612997973' | T36: 'WAP' | U36: 'YESAP53363716979' | V36: '2025-12-01 00:01:00' | W36: '2025-12-02 04:36:23' | X36: 'UPI' | AA36: 'POS23985176461' | AC36: '5120123932655588365' | AE36: '51051000100000000001' | AH36: 'SEAMLESS_3D_FORM' | AT36: '570176430602' | AW36: 180 | AX36: 0 | AY36: 0 | BB36: '01' | BC36: 'nandaandrajula@okicici' | BH36: 'Txn Success' | BK36: 180 | BP36: '570176430602' | BQ36: 'false' | BR36: 'UPI' | BS36: 'RECEIVER' | BT36: 'UPI|UPIPUSH|QR|PPBL' | BU36: 'PPBL' | BW36: 0 | BX36: 0 | CH36: 'UPI:null' | DJ36: 'BW'
A37: '20251201110950000202250950132980344' | B37: 'HDFff1520f87c5340749e6b743a7d7466d4' | E37: '2025-12-01 13:56:03' | F37: '2025-12-01 13:56:04' | G37: 'ACQUIRING' | H37: 'SUCCESS' | I37: 'TYXysH23627954956290' | J37: 'SHA SHA SHANDAAR SHAWARMA' | O37: 20 | P37: 0 | Q37: 0 | S37: 'AWSPG202512010001216820000806612997973' | T37: 'WAP' | U37: 'YESAP53363716979' | V37: '2025-12-01 00:01:00' | W37: '2025-12-02 04:36:23' | X37: 'UPI' | AA37: 'POS23985176461' | AC37: '5120123814140744729' | AE37: '51051000100000000001' | AH37: 'SEAMLESS_3D_FORM' | AT37: '114956415119' | AW37: 20 | AX37: 0 | AY37: 0 | BB37: '01' | BC37: 'finearttattoos8@okhdfcbank' | BH37: 'Txn Success' | BK37: 20 | BP37: '114956415119' | BQ37: 'false' | BR37: 'UPI' | BS37: 'RECEIVER' | BT37: 'UPI|UPIPUSH|QR|PPBL' | BU37: 'PPBL' | BW37: 0 | BX37: 0 | CH37: 'UPI:null' | DJ37: 'BW'
A38: '20251201011060000202250828543927587' | B38: 'HDF36f01acfb1864a45be2fbd9871642a7f' | E38: '2025-12-01 13:55:34' | F38: '2025-12-01 13:55:35' | G38: 'ACQUIRING' | H38: 'SUCCESS' | I38: 'TYXysH23627954956290' | J38: 'SHA SHA SHANDAAR SHAWARMA' | O38: 20 | P38: 0 | Q38: 0 | S38: 'AWSPG202512010001216820000806612997973' | T38: 'WAP' | U38: 'YESAP53363716979' | V38: '2025-12-01 00:01:00' | W38: '2025-12-02 04:36:23' | X38: 'UPI' | AA38: 'POS23985176461' | AC38: '5120123811929758738' | AE38: '51051000100000000001' | AH38: 'SEAMLESS_3D_FORM' | AT38: '114956384701' | AW38: 20 | AX38: 0 | AY38: 0 | BB38: '01' | BC38: 'finearttattoos8@okhdfcbank' | BH38: 'Txn Success' | BK38: 20 | BP38: '114956384701' | BQ38: 'false' | BR38: 'UPI' | BS38: 'RECEIVER' | BT38: 'UPI|UPIPUSH|QR|PPBL' | BU38: 'PPBL' | BW38: 0 | BX38: 0 | CH38: 'UPI:null' | DJ38: 'BW'
A39: '20251201111080000202250591414773655' | B39: 'HDFdee66926140e4e36abb782c3c5729e07' | E39: '2025-12-01 13:54:37' | F39: '2025-12-01 13:54:39' | G39: 'ACQUIRING' | H39: 'SUCCESS' | I39: 'TYXysH23627954956290' | J39: 'SHA SHA SHANDAAR SHAWARMA' | O39: 130 | P39: 0 | Q39: 0 | S39: 'AWSPG202512010001216820000806612997973' | T39: 'WAP' | U39: 'YESAP53363716979' | V39: '2025-12-01 00:01:00' | W39: '2025-12-02 04:36:23' | X39: 'UPI' | AA39: 'POS23985176461' | AC39: '5120123807834018873' | AE39: '51051000100000000001' | AH39: 'SEAMLESS_3D_FORM' | AT39: '114956337713' | AW39: 130 | AX39: 0 | AY39: 0 | BB39: '01' | BC39: 'finearttattoos8@okhdfcbank' | BH39: 'Txn Success' | BK39: 130 | BP39: '114956337713' | BQ39: 'false' | BR39: 'UPI' | BS39: 'RECEIVER' | BT39: 'UPI|UPIPUSH|QR|PPBL' | BU39: 'PPBL' | BW39: 0 | BX39: 0 | CH39: 'UPI:null' | DJ39: 'BW'
A40: '20251201010940000202250515963526313' | B40: 'PTM8df609a8c84a4f6dac029e9a8389e5df' | E40: '2025-12-01 13:54:19' | F40: '2025-12-01 13:54:20' | G40: 'ACQUIRING' | H40: 'SUCCESS' | I40: 'TYXysH23627954956290' | J40: 'SHA SHA SHANDAAR SHAWARMA' | O40: 300 | P40: 0 | Q40: 0 | S40: 'AWSPG202512010001216820000806612997973' | T40: 'WAP' | U40: 'YESAP53363716979' | V40: '2025-12-01 00:01:00' | W40: '2025-12-02 04:36:23' | X40: 'UPI' | AA40: 'POS23985176461' | AC40: '5120133806628014153' | AE40: '51051000100000000001' | AH40: 'SEAMLESS_3D_FORM' | AO40: 'POS23985176461' | AT40: '533596813615' | AW40: 300 | AX40: 0 | AY40: 0 | BB40: '01' | BC40: '9949457971@pthdfc' | BH40: 'Txn Success' | BK40: 300 | BP40: '533596813615' | BQ40: 'false' | BR40: 'NA' | BS40: 'RECEIVER' | BT40: 'UPI|UPIPUSH|QR|PPBL' | BU40: 'PPBL' | BW40: 0 | BX40: 0 | CH40: 'UPI:null' | DJ40: 'BW'
A41: '20251201110840000202249374894762661' | B41: 'HDF1d3b1d3e6a6d48f68ed4aebe6d110759' | E41: '2025-12-01 13:49:47' | F41: '2025-12-01 13:49:48' | G41: 'ACQUIRING' | H41: 'SUCCESS' | I41: 'TYXysH23627954956290' | J41: 'SHA SHA SHANDAAR SHAWARMA' | O41: 260 | P41: 0 | Q41: 0 | S41: 'AWSPG202512010001216820000806612997973' | T41: 'WAP' | U41: 'YESAP53363716979' | V41: '2025-12-01 00:01:00' | W41: '2025-12-02 04:36:23' | X41: 'UPI' | AA41: 'POS23985176461' | AC41: '5120123787031363649' | AE41: '51051000100000000001' | AH41: 'SEAMLESS_3D_FORM' | AT41: '114956051003' | AW41: 260 | AX41: 0 | AY41: 0 | BB41: '01' | BC41: 'finearttattoos8@okhdfcbank' | BH41: 'Txn Success' | BK41: 260 | BP41: '114956051003' | BQ41: 'false' | BR41: 'UPI' | BS41: 'RECEIVER' | BT41: 'UPI|UPIPUSH|QR|PPBL' | BU41: 'PPBL' | BW41: 0 | BX41: 0 | CH41: 'UPI:null' | DJ41: 'BW'
A42: '20251201110850000202367679483534279' | B42: 'SBI9caf6a0b073449a2b50d086f709ed944' | E42: '2025-12-01 21:39:53' | F42: '2025-12-01 21:39:54' | G42: 'ACQUIRING' | H42: 'SUCCESS' | I42: 'TYXysH23627954956290' | J42: 'SHA SHA SHANDAAR SHAWARMA' | O42: 870 | P42: 0 | Q42: 0 | S42: 'AWSPG202512010001216820000806612997973' | T42: 'WAP' | U42: 'YESAP53363716979' | V42: '2025-12-01 00:01:00' | W42: '2025-12-02 04:36:23' | X42: 'UPI' | AA42: 'POS23985176461' | AC42: '5120125943507969057' | AE42: '51051000100000000001' | AH42: 'SEAMLESS_3D_FORM' | AT42: '533533452465' | AW42: 870 | AX42: 0 | AY42: 0 | BB42: '01' | BC42: 'raveena.nandipati@oksbi' | BH42: 'Txn Success' | BK42: 870 | BP42: '533533452465' | BQ42: 'false' | BR42: 'UPI' | BS42: 'RECEIVER' | BT42: 'UPI|UPIPUSH|QR|PPBL' | BU42: 'PPBL' | BW42: 0 | BX42: 0 | CH42: 'UPI:null' | DJ42: 'BW'
A43: '20251201011060000202366822855773400' | B43: 'PTM9be65b3df9524b6ba4f019acee8d1809' | E43: '2025-12-01 21:36:29' | F43: '2025-12-01 21:36:30' | G43: 'ACQUIRING' | H43: 'SUCCESS' | I43: 'TYXysH23627954956290' | J43: 'SHA SHA SHANDAAR SHAWARMA' | O43: 220 | P43: 0 | Q43: 0 | S43: 'AWSPG202512010001216820000806612997973' | T43: 'WAP' | U43: 'YESAP53363716979' | V43: '2025-12-01 00:01:00' | W43: '2025-12-02 04:36:23' | X43: 'UPI' | AA43: 'POS23985176461' | AC43: '5120125929012923397' | AE43: '51051000100000000001' | AH43: 'SEAMLESS_3D_FORM' | AO43: 'POS23985176461' | AT43: '533551777081' | AW43: 220 | AX43: 0 | AY43: 0 | BB43: '01' | BC43: '9392032356@ptsbi' | BH43: 'Txn Success' | BK43: 220 | BP43: '533551777081' | BQ43: 'false' | BR43: 'NA' | BS43: 'RECEIVER' | BT43: 'UPI|UPIPUSH|QR|PPBL' | BU43: 'PPBL' | BW43: 0 | BX43: 0 | CH43: 'UPI:null' | DJ43: 'BW'
A44: '20251201111010000202366016429302701' | B44: 'T2512012133135608517748' | E44: '2025-12-01 21:33:17' | F44: '2025-12-01 21:33:18' | G44: 'ACQUIRING' | H44: 'SUCCESS' | I44: 'TYXysH23627954956290' | J44: 'SHA SHA SHANDAAR SHAWARMA' | O44: 170 | P44: 0 | Q44: 0 | S44: 'AWSPG202512010001216820000806612997973' | T44: 'WAP' | U44: 'YESAP53363716979' | V44: '2025-12-01 00:01:00' | W44: '2025-12-02 04:36:23' | X44: 'UPI' | AA44: 'POS23985176461' | AC44: '5120125915321282577' | AE44: '51051000100000000001' | AH44: 'SEAMLESS_3D_FORM' | AT44: '842712541093' | AW44: 170 | AX44: 0 | AY44: 0 | BB44: '01' | BC44: '9963961381-2@ybl' | BH44: 'Txn Success' | BK44: 170 | BP44: '842712541093' | BQ44: 'false' | BR44: 'Payment from PhonePe' | BS44: 'RECEIVER' | BT44: 'UPI|UPIPUSH|QR|PPBL' | BU44: 'PPBL' | BW44: 0 | BX44: 0 | CH44: 'UPI:null' | DJ44: 'BW'
A45: '20251201111090000202364159174831000' | B45: 'T2512012125507018484107' | E45: '2025-12-01 21:25:54' | F45: '2025-12-01 21:25:55' | G45: 'ACQUIRING' | H45: 'SUCCESS' | I45: 'TYXysH23627954956290' | J45: 'SHA SHA SHANDAAR SHAWARMA' | O45: 300 | P45: 0 | Q45: 0 | S45: 'AWSPG202512010001216820000806612997973' | T45: 'WAP' | U45: 'YESAP53363716979' | V45: '2025-12-01 00:01:00' | W45: '2025-12-02 04:36:23' | X45: 'UPI' | AA45: 'POS23985176461' | AC45: '5120125883443510293' | AE45: '51051000100000000001' | AH45: 'SEAMLESS_3D_FORM' | AT45: '135999309800' | AW45: 300 | AX45: 0 | AY45: 0 | BB45: '01' | BC45: 'mohammedsalman235@ybl' | BH45: 'Txn Success' | BK45: 300 | BP45: '135999309800' | BQ45: 'false' | BR45: 'Payment from PhonePe' | BS45: 'RECEIVER' | BT45: 'UPI|UPIPUSH|QR|PPBL' | BU45: 'PPBL' | BW45: 0 | BX45: 0 | CH45: 'UPI:null' | DJ45: 'BW'
A46: '20251201111070000202358331537649002' | B46: 'T2512012102396411246783' | E46: '2025-12-01 21:02:44' | F46: '2025-12-01 21:02:47' | G46: 'ACQUIRING' | H46: 'SUCCESS' | I46: 'TYXysH23627954956290' | J46: 'SHA SHA SHANDAAR SHAWARMA' | O46: 530 | P46: 0 | Q46: 0 | S46: 'AWSPG202512010001216820000806612997973' | T46: 'WAP' | U46: 'YESAP53363716979' | V46: '2025-12-01 00:01:00' | W46: '2025-12-02 04:36:23' | X46: 'UPI' | AA46: 'POS23985176461' | AC46: '5120135784056313869' | AE46: '51051000100000000001' | AH46: 'SEAMLESS_3D_FORM' | AT46: '856173107371' | AW46: 530 | AX46: 0 | AY46: 0 | BB46: '01' | BC46: '9634634534-2@axl' | BH46: 'Txn Success' | BK46: 530 | BP46: '856173107371' | BQ46: 'false' | BR46: 'Payment from PhonePe' | BS46: 'RECEIVER' | BT46: 'UPI|UPIPUSH|QR|PPBL' | BU46: 'PPBL' | BW46: 0 | BX46: 0 | CH46: 'UPI:null' | DJ46: 'BW'
...
