Workbook

Sheet Summary
B2: Zomato Summary - July - 2026
B4: Details | H4: Total
B6: No.of orders | H6: =SUM(C6:G6) -> 0
B8: Total Income (Number that you see on Zomato dashboard) | C8: =Cashflow!C10 -> 0 | D8: =Cashflow!D10 -> 0 | E8: =Cashflow!E10 -> 0 | F8: =Cashflow!F10 -> 0 | G8: =Cashflow!G10 -> 0 | H8: =SUM(C8:G8) -> 0
B10: Avg. order value | C10: =IFERROR(C8/C6,) -> 0 | D10: =IFERROR(D8/D6,) -> 0 | E10: =IFERROR(E8/E6,) -> 0 | F10: =IFERROR(F8/F6,) -> 0 | G10: =IFERROR(G8/G6,) -> 0 | H10: =IFERROR(H8/H6,) -> 0
B12: No of disputed orders | C12: 0 | D12: 0 | E12: 0 | F12: 0 | G12: 0 | H12: =SUM(C12:G12) -> 0
B14: Refund amount for disputed orders | C14: =Cashflow!C18 -> 0 | D14: =Cashflow!D18 -> 0 | E14: =Cashflow!E18 -> 0 | F14: =Cashflow!F18 -> 0 | G14: =Cashflow!G18 -> 0 | H14: =SUM(C14:G14) -> 0
B16: Discounts | C16: =Cashflow!C8 -> 0 | D16: =Cashflow!D8 -> 0 | E16: =Cashflow!E8 -> 0 | F16: =Cashflow!F8 -> 0 | G16: =Cashflow!G8 -> 0 | H16: =SUM(C16:G16) -> 0
C17: =IFERROR(C16/C8,) -> 0 | D17: =IFERROR(D16/D8,) -> 0 | E17: =IFERROR(E16/E8,) -> 0 | F17: =IFERROR(F16/F8,) -> 0 | G17: =IFERROR(G16/G8,) -> 0 | H17: =IFERROR(H16/H8,) -> 0
B19: Commisonable Amount | H19: =SUM(C19:G19) -> 0
B20: Commission | C20: =Cashflow!C11 -> 0 | D20: =Cashflow!D11 -> 0 | E20: =Cashflow!E11 -> 0 | F20: =Cashflow!F11 -> 0 | G20: =Cashflow!G11 -> 0 | H20: =SUM(C20:G20) -> 0
B21: (Calculated on Sales + GST) | C21: =IFERROR(C20/C19,) -> 0 | D21: =IFERROR(D20/D19,) -> 0 | E21: =IFERROR(E20/E19,) -> 0 | F21: =IFERROR(F20/F19,) -> 0 | G21: =IFERROR(G20/G19,) -> 0 | H21: =IFERROR(H20/H19,) -> 0
B23: Marketing & Ads | C23: =Cashflow!C21 -> 0 | D23: =Cashflow!D21 -> 0 | E23: =Cashflow!E21 -> 0 | F23: =Cashflow!F21 -> 0 | G23: =Cashflow!G21 -> 0 | H23: =SUM(C23:G23) -> 0
C24: =IFERROR(C23/C8,) -> 0 | D24: =IFERROR(D23/D8,) -> 0 | E24: =IFERROR(E23/E8,) -> 0 | F24: =IFERROR(F23/F8,) -> 0 | G24: =IFERROR(G23/G8,) -> 0 | H24: =IFERROR(H23/H8,) -> 0
B27: Other charges & Tax Adjustments | C27: =Cashflow!C13+Cashflow!C26 -> 0 | D27: =Cashflow!D13+Cashflow!D26 -> 0 | E27: =Cashflow!E13+Cashflow!E26 -> 0 | F27: =Cashflow!F13+Cashflow!F26 -> 0 | G27: =Cashflow!G13+Cashflow!G26 -> 0 | H27: =SUM(C27:G27) -> 0
C28: =IFERROR(C27/C8,) -> 0 | D28: =IFERROR(D27/D8,) -> 0 | E28: =IFERROR(E27/E8,) -> 0 | F28: =IFERROR(F27/F8,) -> 0 | G28: =IFERROR(G27/G8,) -> 0 | H28: =IFERROR(H27/H8,) -> 0
B32: Zomato Hyperpure Adjustments | C32: =Cashflow!C36 -> 0 | D32: =Cashflow!D36 -> 0 | E32: =Cashflow!E36 -> 0 | F32: =Cashflow!F36 -> 0 | G32: =Cashflow!G36 -> 0 | H32: =SUM(C32:G32) -> 0
B35: Money received | C35: =C8-C14-C20-C23-C27-C32 -> 0 | D35: =D8-D14-D20-D23-D27-D32 -> 0 | E35: =E8-E14-E20-E23-E27-E32 -> 0 | F35: =F8-F14-F20-F23-F27-F32+Cashflow!F31 -> 0 | G35: =G8-G14-G20-G23-G27-G32 -> 0 | H35: =SUM(C35:G35) -> 0
C36: =IFERROR(C35/$C$8,) -> 0 | D36: =IFERROR(D35/$D$8,) -> 0 | E36: =IFERROR(E35/$E$8,) -> 0 | F36: =IFERROR(F35/F8,) -> 0 | G36: =IFERROR(G35/G8,) -> 0 | H36: =IFERROR(H35/H8,) -> 0

Sheet Cashflow
A1: =Summary!B1 -> 0
A2: Zomato Cash Flow - July - 2026
A4: S.No | B4: Details | C4: =Summary!C4 -> 0 | D4: =Summary!D4 -> 0 | E4: =Summary!E4 -> 0 | F4: =Summary!F4 -> 0 | G4: =Summary!G4 -> 0 | H4: Total
A5: 1 | B5: Item sales (Delivered orders) | H5: =SUM(C5:G5) -> 0
B6: Add:- Packing charges | H6: =SUM(C6:G6) -> 0
B7: Add:- Compensation paid for cancelled orders | H7: =SUM(C7:G7) -> 0
B8: Less:- Discount | H8: =SUM(C8:G8) -> 0
B9: Add:- GST | H9: =SUM(C9:G9) -> 0 | M9: Gst | N9: Tds
B10: Net Sales | C10: =C5+C6+C9+C7-C8 -> 0 | D10: =D5+D6+D9+D7-D8 -> 0 | E10: =E5+E6+E9+E7-E8 -> 0 | F10: =F5+F6+F9+F7-F8 -> 0 | G10: =G5+G6+G9+G7-G8 -> 0 | H10: =H5+H6+H9+H7-H8 -> 0 | M10: =H10-H29 -> 0 | N10: =H12*100/118 -> 0
A11: 2 | B11: Less:- Commission | C11: =C12 -> 0 | D11: =D12 -> 0 | E11: =E12 -> 0 | F11: =F12 -> 0 | G11: =G12 -> 0 | H11: =H12 -> 0
B12: Platform Fee | H12: =SUM(C12:G12) -> 0
A13: 3 | B13: Less:- Other Charges | C13: =C14+C16-C15+C17 -> 0 | D13: =D14+D16-D15+D17 -> 0 | E13: =E14+E16-E15+E17 -> 0 | F13: =F14+F16-F15+F17 -> 0 | G13: =G14+G16-G15+G17 -> 0 | H13: =H14+H16-H15+H17 -> 0
B14: Convenience Fee | H14: =SUM(C14:G14) -> 0
B15: Discount on Service Fee | H15: =SUM(C15:G15) -> 0 | L15: netsales | M15: =C10+C8-C29 -> 0 | N15: =D10+D8-D29 -> 0 | O15: =E10+E8-E29 -> 0 | P15: =F10+F8-F29 -> 0 | Q15: =G10+G8-G29 -> 0
B16: Long Distance Fee | H16: =SUM(C16:G16) -> 0 | L16: disc | M16: =C8 -> 0 | N16: =D8 -> 0 | O16: =E8 -> 0 | P16: =F8 -> 0 | Q16: =G8 -> 0
A17: 4 | B17: Merchant Cancellation Charges | C17: 0 | D17: 0 | E17: 0 | F17: 0 | G17: 0 | H17: =SUM(C17:G17) -> 0 | L17: comm | M17: =C12-C15 -> 0 | N17: =D12-D15 -> 0 | O17: =E12-E15 -> 0 | P17: =F12-F15 -> 0 | Q17: =G12-G15 -> 0
B18: Less:- Refunds | C18: =SUM(C19:C20) -> 0 | D18: =SUM(D19:D20) -> 0 | E18: =SUM(E19:E20) -> 0 | F18: =SUM(F19:F20) -> 0 | G18: =SUM(G19:G20) -> 0 | H18: =H19+H20 -> 0 | L18: tds ecom | M18: =C27 -> 0 | N18: =D27 -> 0 | O18: =E27 -> 0 | P18: =F27 -> 0 | Q18: =G27 -> 0
B19: Paid by Restaurant | H19: =SUM(C19:G19) -> 0 | L19: conve | M19: =C14 -> 0 | N19: =D14 -> 0 | O19: =E14 -> 0 | P19: =F14 -> 0 | Q19: =G14 -> 0
A20: 5 | B20: Received by Restaurant | C20: 0 | D20: 0 | E20: 0 | F20: 0 | G20: 0 | H20: =SUM(C20:G20) -> 0 | L20: othe cha | M20: =C16 -> 0 | N20: =D16 -> 0 | O20: =E16 -> 0 | P20: =F16 -> 0 | Q20: =G16 -> 0
B21: Less:- Marketing Charges | C21: =C22+C23+C24 -> 0 | D21: =D22+D23+D24 -> 0 | E21: =E22+E23+E24 -> 0 | F21: =F22+F23+F24 -> 0 | G21: =G22+G23+G24 -> 0 | H21: =H22+H23+H24 -> 0 | L21: tds | M21: =(C12*100/118)*2% -> 0 | N21: =(D12*100/118)*2% -> 0 | O21: =(E12*100/118)*2% -> 0 | P21: =(F12*100/118)*2% -> 0 | Q21: =(G12*100/118)*2% -> 0
B22: High Priority | C22: 0 | D22: 0 | E22: 0 | F22: 0 | G22: 0 | H22: =SUM(C22:G22) -> 0
B23: Call Center Service Fees | C23: 0 | D23: 0 | E23: 0 | F23: 0 | G23: 0 | H23: =SUM(C23:G23) -> 0
B24: PocketHero Fee | C24: 0 | D24: 0 | E24: 0 | F24: 0 | G24: 0 | H24: =SUM(C24:G24) -> 0
A25: 6 | B25: Profit from Zomato | C25: =C10-C11-C18-C21-C13-C29 -> 0 | D25: =D10-D11-D18-D21-D13-D29 -> 0 | E25: =E10-E11-E18-E21-E13-E29 -> 0 | F25: =F10-F11-F18-F21-F13-F29 -> 0 | G25: =G10-G11-G18-G21-G13-G29 -> 0 | H25: =H10-H11-H18-H21-H13-H29 -> 0
B26: Less:- Tax Adjustments | C26: =SUM(C27:C29) -> 0 | D26: =SUM(D27:D29) -> 0 | E26: =SUM(E27:E29) -> 0 | F26: =SUM(F27:F29) -> 0 | G26: =SUM(G27:G29) -> 0 | H26: =SUM(H27:H29) -> 0
B27: TDS deduction for aggrigators | H27: =SUM(C27:G27) -> 0
B28: TCS | H28: =SUM(C28:G28) -> 0
A29: 7 | B29: GST collected and paid by Zomato | H29: =SUM(C29:G29) -> 0
B30: Expected Receipts | C30: =C25-C27-C28-C34 -> 0 | D30: =D25-D27-D28-D34 -> 0 | E30: =E25-E27-E28-E34 -> 0 | F30: =F25-F27-F28-F34 -> 0 | G30: =G25-G27-G28-G34 -> 0 | H30: =H25-H27-H28-H34 -> 0
B31: Service Fee Reversal | C31: 0 | D31: 0 | E31: 0 | F31: 0 | G31: 0 | H31: =SUM(C31:G31) -> 0
B32: Interim payments | C32: 0 | D32: 0 | E32: 0 | F32: 0 | G32: 0 | H32: =SUM(C32:G32) -> 0
B33: Opening Week Adjustments | C33: 0 | D33: 0 | E33: 0 | F33: 0 | G33: 0 | H33: =SUM(C33:G33) -> 0
B34: Following Week Adjustments | C34: 0 | D34: 0 | E34: 0 | F34: 0 | G34: 0 | H34: =SUM(C34:G34) -> 0
B35: Closing Week Adjustments | C35: 0 | D35: 0 | E35: 0 | F35: 0 | G35: 0 | H35: =SUM(C35:G35) -> 0
B36: Zomato hyperpure Payment Adjustments | C36: 0 | D36: 0 | E36: 0 | F36: 0 | G36: 0 | H36: =SUM(C36:G36) -> 0
B37: EMI Loan deductions | C37: 0 | D37: 0 | E37: 0 | F37: 0 | G37: 0 | H37: =SUM(C37:G37) -> 0
A38: 8 | B38: Actual receipts | C38: 0 | D38: 0 | E38: 0 | F38: 0 | G38: 0 | H38: =SUM(C38:G38) -> 0
B39: Difference | C39: =C30-C38-C36+C33+C35 -> 0 | D39: =D30-D38-D36-D33+D35 -> 0 | E39: =E30-E38-E36-E33+E35 -> 0 | F39: =F30-F38-F36-F33+F35-F34-F32 -> 0 | G39: =G30-G38-G36-G33+G35 -> 0 | H39: =H30-H38-H36+H33+H35-H34-H32 -> 0
B41: Note :

Sheet Profit statement
A1: =Summary!B1 -> 0
A2: Zomato Profit Statement - July - 2026
A4: Details | B4: =Summary!C4 -> 0 | C4: =Summary!D4 -> 0 | D4: =Summary!E4 -> 0 | E4: =Summary!F4 -> 0 | F4: =Summary!G4 -> 0 | G4: =Summary!H4 -> Total
A5: A. Net Sales
A6: Total Income | B6: =Cashflow!C5+Cashflow!C6+Cashflow!C9-Cashflow!C8-Cashflow!C29 -> 0 | C6: =Cashflow!D5+Cashflow!D6+Cashflow!D9-Cashflow!D8-Cashflow!D29 -> 0 | D6: =Cashflow!E5+Cashflow!E6+Cashflow!E9-Cashflow!E8-Cashflow!E29 -> 0 | E6: =Cashflow!F5+Cashflow!F6+Cashflow!F9-Cashflow!F8-Cashflow!F29 -> 0 | F6: =Cashflow!G5+Cashflow!G6+Cashflow!G9-Cashflow!G8-Cashflow!G29 -> 0 | G6: =SUM(B6:F6) -> 0
A7: Add- Adjust: Cancelled orders (By Zomato) | B7: =Cashflow!C7 -> 0 | C7: =Cashflow!D7 -> 0 | D7: =Cashflow!E7 -> 0 | E7: =Cashflow!F7 -> 0 | F7: =Cashflow!G7 -> 0 | G7: =SUM(B7:F7) -> 0
A8: Net Sales (Number that you see on Numerize app) | B8: =B6+B7 -> 0 | C8: =C6+C7 -> 0 | D8: =D6+D7 -> 0 | E8: =E6+E7 -> 0 | F8: =F6+F7 -> 0 | G8: =G6+G7 -> 0
A10: B. Less:- Commission | B10: =Cashflow!C11 -> 0 | C10: =Cashflow!D11 -> 0 | D10: =Cashflow!E11 -> 0 | E10: =Cashflow!F11 -> 0 | F10: =Cashflow!G11 -> 0 | G10: =SUM(B10:F10) -> 0
A12: C. Less:- Marketing & Ads | B12: =Cashflow!C21 -> 0 | C12: =Cashflow!D21 -> 0 | D12: =Cashflow!E21 -> 0 | E12: =Cashflow!F21 -> 0 | F12: =Cashflow!G21 -> 0 | G12: =SUM(B12:F12) -> 0
A14: D. Less:- Refund on disputed orders | B14: =Cashflow!C18 -> 0 | C14: =Cashflow!D18 -> 0 | D14: =Cashflow!E18 -> 0 | E14: =Cashflow!F18 -> 0 | F14: =Cashflow!G18 -> 0 | G14: =SUM(B14:F14) -> 0
A16: E. Other charges | B16: =Cashflow!C13 -> 0 | C16: =Cashflow!D13 -> 0 | D16: =Cashflow!E13 -> 0 | E16: =Cashflow!F13 -> 0 | F16: =Cashflow!G13 -> 0 | G16: =SUM(B16:F16) -> 0
A18: F. Profit | B18: =B8-B10-B12-B14-B16 -> 0 | C18: =C8-C10-C12-C14-C16 -> 0 | D18: =D8-D10-D12-D14-D16 -> 0 | E18: =E8-E10-E12-E14-E16 -> 0 | F18: =F8-F10-F12-F14-F16 -> 0 | G18: =G8-G10-G12-G14-G16 -> 0
A19: Percentage | B19: =IFERROR(B18/B8,0) -> 0 | C19: =IFERROR(C18/C8,0) -> 0 | D19: =IFERROR(D18/D8,0) -> 0 | E19: =IFERROR(E18/E8,0) -> 0 | F19: =IFERROR(F18/F8,0) -> 0 | G19: =G18/G8 -> #DIV/0!

Sheet Discrepancies
A1: =Summary!B1 -> 0
A2: Zomato Discrepancies - July - 2026
A4: Details | B4: =Summary!C4 -> 0 | C4: =Summary!D4 -> 0 | D4: =Summary!E4 -> 0 | E4: =Summary!F4 -> 0 | F4: =Summary!G4 -> 0 | G4: =Summary!H4 -> Total
A5: A. POS discrepancies
A6: Sales as per Zomato | B6: =Cashflow!C10 -> 0 | C6: =Cashflow!D10 -> 0 | D6: =Cashflow!E10 -> 0 | E6: =Cashflow!F10 -> 0 | F6: =Cashflow!G10 -> 0 | G6: =SUM(B6:F6) -> 0
A7: Sale as per POS | G7: =SUM(B7:F7) -> 0
A8: Difference | B8: =B7-B6 -> 0 | C8: =C7-C6 -> 0 | D8: =D7-D6 -> 0 | E8: =E7-E6 -> 0 | F8: =F7-F6 -> 0 | G8: =G7-G6 -> 0
B9: =IFERROR(B8/B6,) -> 0 | C9: =IFERROR(C8/C6,0) -> 0 | D9: =IFERROR(D8/D6,0) -> 0 | E9: =IFERROR(E8/E6,0) -> 0 | F9: =IFERROR(F8/F6,0) -> 0 | G9: =IFERROR(G8/G6,0) -> 0
A11: B. Order discrepancies
A12: No.of delivered orders for which payment isn't received | B12: 0 | C12: 0 | D12: 0 | E12: 0 | F12: 0 | G12: =SUM(B12:F12) -> 0
A13: Value of such orders | B13: 0 | C13: 0 | D13: 0 | E13: 0 | F13: 0 | G13: =SUM(B13:F13) -> 0
A16: C. Payment discrepancies
A17: Expected receipts in the bank account | B17: =Cashflow!C30 -> 0 | C17: =Cashflow!D30 -> 0 | D17: =Cashflow!E30 -> 0 | E17: =Cashflow!F30 -> 0 | F17: =Cashflow!G30 -> 0 | G17: =SUM(B17:F17) -> 0
A18: Investment in Hyperpure | B18: =Cashflow!C36 -> 0 | C18: =Cashflow!D36 -> 0 | D18: =Cashflow!E36 -> 0 | E18: =Cashflow!F36 -> 0 | F18: =Cashflow!G36 -> 0 | G18: =SUM(B18:F18) -> 0
A19: Following Week Adjustment | B19: =Cashflow!C34 -> 0 | C19: =Cashflow!D34 -> 0 | D19: =Cashflow!E34 -> 0 | E19: =Cashflow!F34 -> 0 | F19: =Cashflow!G34 -> 0 | G19: =SUM(B19:F19) -> 0
A20: Opening Week Adjustment | B20: =Cashflow!C33 -> 0 | C20: =Cashflow!D33 -> 0 | D20: =Cashflow!E33 -> 0 | E20: =Cashflow!F33 -> 0 | F20: 0 | G20: =SUM(B20:F20) -> 0
A21: Closing Week Adjustment | B21: =Cashflow!C35 -> 0 | C21: =Cashflow!D35 -> 0 | D21: =Cashflow!E35 -> 0 | E21: =Cashflow!F35 -> 0 | F21: =Cashflow!G35 -> 0 | G21: =SUM(B21:F21) -> 0
A22: Actual receipts in the bank | B22: =Cashflow!C38 -> 0 | C22: =Cashflow!D38 -> 0 | D22: =Cashflow!E38 -> 0 | E22: =Cashflow!F38 -> 0 | F22: =Cashflow!G38 -> 0 | G22: =SUM(B22:F22) -> 0
A23: Difference | B23: =B17-B22-B18+B20 -> 0 | C23: =C17-C22-C18 -> 0 | D23: =D17-D22-D18 -> 0 | E23: =E17-E22-E18-E19 -> 0 | F23: =F17-F22-F18+F21 -> 0 | G23: =G17-G22-G18+G20-G19 -> 0
A25: Note:

Sheet POS

Sheet BANK
B5: 1 | C5: 2 | D5: 3 | E5: 4 | F5: 5
A10: Date | B10: Narration | C10: Chq./Ref.No. | D10: Value Dt | E10: Withdrawal Amt. | F10: Deposit Amt. | G10: Closing Balance
A11: 01/10/25 | B11: NEFT CR-YESB0000001-ONE 97 COMMUNICATIONS LIMITED SETTL-ROCKTAIL HOSPITALITY SERVICES-YESBN12025100101816795 | C11: YESBN12025100101816795 | D11: 01/10/25 | F11: 28308.11 | G11: 369938.81
A12: 01/10/25 | B12: NEFT CR-RATN0000999-PINE LABS LIMITED-ROCKTAIL HOSPITALITY SERVICES-RATNN52025100142548753 | C12: RATNN52025100142548753 | D12: 01/10/25 | F12: 988.02 | G12: 370926.83
A13: 01/10/25 | B13: 42552394TERMINAL 1 CARDS SETTL. 01/10/25 | C13: 000000000000000 | D13: 01/10/25 | F13: 4135.06 | G13: 375061.89
A14: 01/10/25 | B14: UPI-8978287178PTYES-8978287178@PTYES-UBIN0813567-564035906635-UPI | C14: 0000564035906635 | D14: 01/10/25 | E14: 165 | G14: 374896.89
A15: 01/10/25 | B15: 50200069817641-TPT-NBLCVTK6KLDPDJXS-WOLFFPACK VENTURES PRIVATE LIMITED | C15: 0000000223256296 | D15: 01/10/25 | F15: 200000 | G15: 574896.89
A16: 01/10/25 | B16: VENDOR PAYMENTS - ROCKTAIL HOSPITALITY DR - 57500000326520 - NEFT TRANSITORY ACCOUNT | C16: 0000000000000188 | D16: 01/10/25 | E16: 390734 | G16: 184162.89
A17: 01/10/25 | B17: UPI-SHREY SINGH-SHREYSINGH0501-1@OKHDFCBANK-HDFC0004216-564012927870-REGISTRATION | C17: 0000564012927870 | D17: 01/10/25 | E17: 8700 | G17: 175462.89
A18: 01/10/25 | B18: NEFT RETURN-INCORRECT ACCOUNT NUMBER-LAXMI AGENCIES-IBKLN92025100194760959 | C18: HDFCN52025100104276617 | D18: 01/10/25 | F18: 8322 | G18: 183784.89
A19: 01/10/25 | B19: NEFT RETURN-INCORRECT ACCOUNT NUMBER-LAXMI AGENCIES-IBKLN92025100194760962 | C19: HDFCN52025100104276606 | D19: 01/10/25 | F19: 8316 | G19: 192100.89
A20: 01/10/25 | B20: NEFT CR-CITI0000002-ETERNAL LIMITED-ROCKTAIL HOSPITALITY SERVICES-CITIN52025100134584901 | C20: CITIN52025100134584901 | D20: 01/10/25 | F20: 22470.51 | G20: 214571.4
A21: 01/10/25 | B21: NEFT CR-UTIB0000052-BUNDL TECHNOLOGIES PRIVATE LIMITED-ROCKTAIL HOSPITALITY SERVICES-UTIBN62025100172850989 | C21: UTIBN62025100172850989 | D21: 01/10/25 | F21: 28624.05 | G21: 243195.45
A22: 01/10/25 | B22: FT - DR - 50200086201346 - SRI CHAKRA ENTERPRISES | C22: 0000000000000187 | D22: 01/10/25 | E22: 68400 | G22: 174795.45
A23: 01/10/25 | B23: CQ NO-000187 AMOUNT-100323 TRANSFERS 4 DR - 50200088485779 - NSP ENTERPRISES | C23: 000000000000000 | D23: 01/10/25 | E23: 12843 | G23: 161952.45
A24: 01/10/25 | B24: CQ NO-000187 AMOUNT-100323 TRANSFERS 4 DR - 50200082063860 - AAMODHA ENTERPRISES | C24: 000000000000000 | D24: 01/10/25 | E24: 16560 | G24: 145392.45
A25: 01/10/25 | B25: CQ NO-000187 AMOUNT-100323 TRANSFERS 4 DR - 50200034371828 - SRIHITHA DISTRIBUTORS | C25: 000000000000000 | D25: 01/10/25 | E25: 2520 | G25: 142872.45
A26: 01/10/25 | B26: UPI-SRI LAXMI CHENNAKESA-Q560982817@YBL-YESB0YBLUPI-112039563850-POOJA | C26: 0000112039563850 | D26: 01/10/25 | E26: 1651 | G26: 141221.45
A27: 01/10/25 | B27: NEFT CR-YESB0000001-SWIGGY LIMITED-ROCKTAIL HOSPITALITY SERVICES-YESBN12025100106534132 | C27: YESBN12025100106534132 | D27: 01/10/25 | F27: 37494.72 | G27: 178716.17
A28: 02/10/25 | B28: NEFT CR-YESB0000001-ONE 97 COMMUNICATIONS LIMITED SETTL-ROCKTAIL HOSPITALITY SERVICES-YESBN12025100202440556 | C28: YESBN12025100202440556 | D28: 02/10/25 | F28: 28924.86 | G28: 207641.03
A29: 02/10/25 | B29: 42552394TERMINAL 1 CARDS SETTL. 02/10/25 | C29: 000000000000000 | D29: 02/10/25 | F29: 6676.28 | G29: 214317.31
A30: 03/10/25 | B30: NEFT CR-YESB0000001-ONE 97 COMMUNICATIONS LIMITED SETTL-ROCKTAIL HOSPITALITY SERVICES-YESBN12025100302342936 | C30: YESBN12025100302342936 | D30: 03/10/25 | F30: 38471.91 | G30: 252789.22
A31: 03/10/25 | B31: 42552394TERMINAL 1 CARDS SETTL. 03/10/25 | C31: 000000000000000 | D31: 03/10/25 | F31: 13411.99 | G31: 266201.21
A32: 03/10/25 | B32: UPI-BHANWRA RAM-BHANWARJATCHOUDHARY251@OKSBI-SBIN0011306-564239417166-FURNITURE | C32: 0000564239417166 | D32: 03/10/25 | E32: 35000 | G32: 231201.21
A33: 03/10/25 | B33: NEFT CR-UTIB0000052-BUNDL TECHNOLOGIES PRIVATE LIMITED-ROCKTAIL HOSPITALITY SERVICES-UTIBN62025100395892591 | C33: UTIBN62025100395892591 | D33: 03/10/25 | F33: 13038.51 | G33: 244239.72
A34: 04/10/25 | B34: NEFT CR-YESB0000001-ONE 97 COMMUNICATIONS LIMITED SETTL-ROCKTAIL HOSPITALITY SERVICES-YESBN12025100403632181 | C34: YESBN12025100403632181 | D34: 04/10/25 | F34: 53035 | G34: 297274.72
A35: 04/10/25 | B35: 42552394TERMINAL 1 CARDS SETTL. 04/10/25 | C35: 000000000000000 | D35: 04/10/25 | F35: 10812.69 | G35: 308087.41
A36: 04/10/25 | B36: UPI-SWIGGY LIMITED-SWIGGY.STORES@AXB-UTIB0000100-527751059928-PAY FOR INTENT | C36: 0000527751059928 | D36: 04/10/25 | E36: 856 | G36: 307231.41
A37: 05/10/25 | B37: NEFT CR-YESB0000001-ONE 97 COMMUNICATIONS LIMITED SETTL-ROCKTAIL HOSPITALITY SERVICES-YESBN12025100501829191 | C37: YESBN12025100501829191 | D37: 05/10/25 | F37: 72645.73 | G37: 379877.14
A38: 05/10/25 | B38: 42552394TERMINAL 1 CARDS SETTL. 05/10/25 | C38: 000000000000000 | D38: 05/10/25 | F38: 17370.83 | G38: 397247.97
A39: 05/10/25 | B39: SETTLEMENT CHARGE-SEP25-CPY597 | C39: 000000000000000 | D39: 05/10/25 | E39: 37.76 | G39: 397210.21
A40: 06/10/25 | B40: NEFT CR-YESB0000001-ONE 97 COMMUNICATIONS LIMITED SETTL-ROCKTAIL HOSPITALITY SERVICES-YESBN12025100601953902 | C40: YESBN12025100601953902 | D40: 06/10/25 | F40: 65856.98 | G40: 463067.19
A41: 06/10/25 | B41: EMI 162047443 CHQ S16204744314 1025162047443 | C41: 000000000000000 | D41: 06/10/25 | E41: 70666 | G41: 392401.19
A42: 06/10/25 | B42: 42552394TERMINAL 1 CARDS SETTL. 06/10/25 | C42: 000000000000000 | D42: 06/10/25 | F42: 1635.17 | G42: 394036.36
A43: 06/10/25 | B43: NEFT CR-CITI0000002-ETERNAL LIMITED-ROCKTAIL HOSPITALITY SERVICES-CITIN52025100636240957 | C43: CITIN52025100636240957 | D43: 06/10/25 | F43: 61201.16 | G43: 455237.52
A44: 07/10/25 | B44: NEFT CR-YESB0000001-ONE 97 COMMUNICATIONS LIMITED SETTL-ROCKTAIL HOSPITALITY SERVICES-YESBN12025100701113506 | C44: YESBN12025100701113506 | D44: 07/10/25 | F44: 24613.36 | G44: 479850.88
A45: 07/10/25 | B45: 42552394TERMINAL 1 CARDS SETTL. 07/10/25 | C45: 000000000000000 | D45: 07/10/25 | F45: 9641.79 | G45: 489492.67
A46: 07/10/25 | B46: NEFT CR-YESB0000001-SWIGGY LIMITED-ROCKTAIL HOSPITALITY SERVICES-YESBN12025100705709842 | C46: YESBN12025100705709842 | D46: 07/10/25 | F46: 83057.26 | G46: 572549.93
A47: 08/10/25 | B47: NEFT CR-YESB0000001-ONE 97 COMMUNICATIONS LIMITED SETTL-ROCKTAIL HOSPITALITY SERVICES-YESBN12025100800862936 | C47: YESBN12025100800862936 | D47: 08/10/25 | F47: 17786 | G47: 590335.93
A48: 08/10/25 | B48: 42552394TERMINAL 1 CARDS SETTL. 08/10/25 | C48: 000000000000000 | D48: 08/10/25 | F48: 5938.15 | G48: 596274.08
...
