Workbook

Sheet Summary
B1: asdf
B2: Zomato Summary - November - 2026
B4: Details | C4: 1st to 2nd | D4: 3rd to 9th | E4: 10th to 16th | F4: 17th to 23rd | G4: 24th to 30th | H4: Total
B6: No.of orders | C6: 34 | D6: 75 | E6: 69 | F6: 67 | G6: 82 | H6: =SUM(C6:G6)
B8: Total Income (Number that you see on Zomato dashboard) | C8: =Cashflow!C10 | D8: =Cashflow!D10 | E8: =Cashflow!E10 | F8: =Cashflow!F10 | G8: =Cashflow!G10 | H8: =SUM(C8:G8)
B10: Avg. order value | C10: =IFERROR(C8/C6,) | D10: =IFERROR(D8/D6,) | E10: =IFERROR(E8/E6,) | F10: =IFERROR(F8/F6,) | G10: =IFERROR(G8/G6,) | H10: =IFERROR(H8/H6,)
B12: No of disputed orders | C12: 0 | D12: 0 | E12: 0 | F12: 0 | G12: 0 | H12: =SUM(C12:G12)
B14: Refund amount for disputed orders | C14: =Cashflow!C18 | D14: =Cashflow!D18 | E14: =Cashflow!E18 | F14: =Cashflow!F18 | G14: =Cashflow!G18 | H14: =SUM(C14:G14)
B16: Discounts | C16: =Cashflow!C8 | D16: =Cashflow!D8 | E16: =Cashflow!E8 | F16: =Cashflow!F8 | G16: =Cashflow!G8 | H16: =SUM(C16:G16)
C17: =IFERROR(C16/C8,) | D17: =IFERROR(D16/D8,) | E17: =IFERROR(E16/E8,) | F17: =IFERROR(F16/F8,) | G17: =IFERROR(G16/G8,) | H17: =IFERROR(H16/H8,)
B19: Commisonable Amount | C19: 19443 | D19: 43110 | E19: 36462 | F19: 37712 | G19: 52237 | H19: =SUM(C19:G19)
B20: Commission | C20: =Cashflow!C11 | D20: =Cashflow!D11 | E20: =Cashflow!E11 | F20: =Cashflow!F11 | G20: =Cashflow!G11 | H20: =SUM(C20:G20)
B21: (Calculated on Sales + GST) | C21: =IFERROR(C20/C19,) | D21: =IFERROR(D20/D19,) | E21: =IFERROR(E20/E19,) | F21: =IFERROR(F20/F19,) | G21: =IFERROR(G20/G19,) | H21: =IFERROR(H20/H19,)
B23: Marketing & Ads | C23: =Cashflow!C21 | D23: =Cashflow!D21 | E23: =Cashflow!E21 | F23: =Cashflow!F21 | G23: =Cashflow!G21 | H23: =SUM(C23:G23)
C24: =IFERROR(C23/C8,) | D24: =IFERROR(D23/D8,) | E24: =IFERROR(E23/E8,) | F24: =IFERROR(F23/F8,) | G24: =IFERROR(G23/G8,) | H24: =IFERROR(H23/H8,)
B27: Other charges & Tax Adjustments | C27: =Cashflow!C13+Cashflow!C26 | D27: =Cashflow!D13+Cashflow!D26 | E27: =Cashflow!E13+Cashflow!E26 | F27: =Cashflow!F13+Cashflow!F26 | G27: =Cashflow!G13+Cashflow!G26 | H27: =SUM(C27:G27)
C28: =IFERROR(C27/C8,) | D28: =IFERROR(D27/D8,) | E28: =IFERROR(E27/E8,) | F28: =IFERROR(F27/F8,) | G28: =IFERROR(G27/G8,) | H28: =IFERROR(H27/H8,)
B32: Zomato Hyperpure Adjustments | C32: =Cashflow!C36 | D32: =Cashflow!D36 | E32: =Cashflow!E36 | F32: =Cashflow!F36 | G32: =Cashflow!G36 | H32: =SUM(C32:G32)
B35: Money received | C35: =C8-C14-C20-C23-C27-C32 | D35: =D8-D14-D20-D23-D27-D32 | E35: =E8-E14-E20-E23-E27-E32 | F35: =F8-F14-F20-F23-F27-F32+Cashflow!F31 | G35: =G8-G14-G20-G23-G27-G32 | H35: =SUM(C35:G35)
C36: =IFERROR(C35/$C$8,) | D36: =IFERROR(D35/$D$8,) | E36: =IFERROR(E35/$E$8,) | F36: =IFERROR(F35/F8,) | G36: =IFERROR(G35/G8,) | H36: =IFERROR(H35/H8,)

Sheet Cashflow
A1: =Summary!B1
A2: Zomato Cash Flow - November - 2026
A4: S.No | B4: Details | C4: =Summary!C4 | D4: =Summary!D4 | E4: =Summary!E4 | F4: =Summary!F4 | G4: =Summary!G4 | H4: Total
A5: 1 | B5: Item sales (Delivered orders) | C5: ='D1W1'!O2 | D5: ='D1W2'!O2 | E5: ='D1W3'!O2 | F5: ='D1W4'!O2 | G5: ='D1W5'!O2 | H5: =SUM(C5:G5)
B6: Add:- Packing charges | C6: ='D1W1'!P2 | D6: ='D1W2'!P2 | E6: ='D1W3'!P2 | F6: ='D1W4'!P2 | G6: ='D1W5'!P2 | H6: =SUM(C6:G6)
B7: Add:- Compensation paid for cancelled orders | C7: ='D1W1'!BC1 | D7: ='D1W2'!BC1 | E7: ='D1W3'!BC1 | F7: ='D1W4'!BC1 | G7: ='D1W5'!BC1 | H7: =SUM(C7:G7)
B8: Less:- Discount | C8: ='D1W1'!R2+'D1W1'!S2+'D1W1'!U2 | D8: ='D1W2'!R2+'D1W2'!S2+'D1W2'!U2 | E8: ='D1W3'!R2+'D1W3'!S2+'D1W3'!U2 | F8: ='D1W4'!R2+'D1W4'!S2+'D1W4'!U2 | G8: ='D1W5'!R2+'D1W5'!S2+'D1W5'!U2 | H8: =SUM(C8:G8)
B9: Add:- GST | C9: ='D1W1'!V2 | D9: ='D1W2'!V2 | E9: ='D1W3'!V2 | F9: ='D1W4'!V2 | G9: ='D1W5'!V2 | H9: =SUM(C9:G9) | M9: Gst | N9: Tds
B10: Net Sales | C10: =C5+C6+C9+C7-C8 | D10: =D5+D6+D9+D7-D8 | E10: =E5+E6+E9+E7-E8 | F10: =F5+F6+F9+F7-F8 | G10: =G5+G6+G9+G7-G8 | H10: =H5+H6+H9+H7-H8 | M10: =H10-H29 | N10: =H12*100/118
A11: 2 | B11: Less:- Commission | C11: =C12 | D11: =D12 | E11: =E12 | F11: =F12 | G11: =G12 | H11: =H12
B12: Platform Fee | C12: ='D1W1'!AC3 | D12: ='D1W2'!AC3 | E12: ='D1W3'!AC3 | F12: ='D1W4'!AC3 | G12: ='D1W5'!AC3 | H12: =SUM(C12:G12)
A13: 3 | B13: Less:- Other Charges | C13: =C14+C16-C15+C17 | D13: =D14+D16-D15+D17 | E13: =E14+E16-E15+E17 | F13: =F14+F16-F15+F17 | G13: =G14+G16-G15+G17 | H13: =H14+H16-H15+H17
B14: Convenience Fee | C14: ='D1W1'!AH3 | D14: ='D1W2'!AH3 | E14: ='D1W3'!AH3 | F14: ='D1W4'!AH3 | G14: ='D1W5'!AH3 | H14: =SUM(C14:G14)
B15: Discount on Service Fee | C15: ='D1W1'!AG3 | D15: ='D1W2'!AG3 | E15: ='D1W3'!AG3 | F15: ='D1W4'!AG3 | G15: ='D1W5'!AG3 | H15: =SUM(C15:G15) | L15: netsales | M15: =C10+C8-C29 | N15: =D10+D8-D29 | O15: =E10+E8-E29 | P15: =F10+F8-F29 | Q15: =G10+G8-G29
B16: Long Distance Fee | C16: ='D1W1'!AE3-'D1W1'!AF3 | D16: ='D1W2'!AE3-'D1W2'!AF3 | E16: ='D1W3'!AE3-'D1W3'!AF3 | F16: ='D1W4'!AE3-'D1W4'!AF3 | G16: ='D1W5'!AE3-'D1W5'!AF3 | H16: =SUM(C16:G16) | L16: disc | M16: =C8 | N16: =D8 | O16: =E8 | P16: =F8 | Q16: =G8
A17: 4 | B17: Merchant Cancellation Charges | C17: 0 | D17: 0 | E17: 0 | F17: 0 | G17: 0 | H17: =SUM(C17:G17) | L17: comm | M17: =C12-C15 | N17: =D12-D15 | O17: =E12-E15 | P17: =F12-F15 | Q17: =G12-G15
B18: Less:- Refunds | C18: =SUM(C19:C20) | D18: =SUM(D19:D20) | E18: =SUM(E19:E20) | F18: =SUM(F19:F20) | G18: =SUM(G19:G20) | H18: =H19+H20 | L18: tds ecom | M18: =C27 | N18: =D27 | O18: =E27 | P18: =F27 | Q18: =G27
B19: Paid by Restaurant | C19: ='D1W1'!AS4 | D19: ='D1W2'!AS4 | E19: ='D1W3'!AS4 | F19: ='D1W4'!AS4 | G19: ='D1W5'!AS4 | H19: =SUM(C19:G19) | L19: conve | M19: =C14 | N19: =D14 | O19: =E14 | P19: =F14 | Q19: =G14
A20: 5 | B20: Received by Restaurant | C20: 0 | D20: 0 | E20: 0 | F20: 0 | G20: 0 | H20: =SUM(C20:G20) | L20: othe cha | M20: =C16 | N20: =D16 | O20: =E16 | P20: =F16 | Q20: =G16
B21: Less:- Marketing Charges | C21: =C22+C23+C24 | D21: =D22+D23+D24 | E21: =E22+E23+E24 | F21: =F22+F23+F24 | G21: =G22+G23+G24 | H21: =H22+H23+H24 | L21: tds | M21: =(C12*100/118)*2% | N21: =(D12*100/118)*2% | O21: =(E12*100/118)*2% | P21: =(F12*100/118)*2% | Q21: =(G12*100/118)*2%
B22: High Priority | C22: 0 | D22: 0 | E22: 0 | F22: 0 | G22: 0 | H22: =SUM(C22:G22)
B23: Call Center Service Fees | C23: 0 | D23: 0 | E23: 0 | F23: 0 | G23: 0 | H23: =SUM(C23:G23)
B24: PocketHero Fee | C24: 0 | D24: 0 | E24: 0 | F24: 0 | G24: 0 | H24: =SUM(C24:G24)
A25: 6 | B25: Profit from Zomato | C25: =C10-C11-C18-C21-C13-C29 | D25: =D10-D11-D18-D21-D13-D29 | E25: =E10-E11-E18-E21-E13-E29 | F25: =F10-F11-F18-F21-F13-F29 | G25: =G10-G11-G18-G21-G13-G29 | H25: =H10-H11-H18-H21-H13-H29
B26: Less:- Tax Adjustments | C26: =SUM(C27:C29) | D26: =SUM(D27:D29) | E26: =SUM(E27:E29) | F26: =SUM(F27:F29) | G26: =SUM(G27:G29) | H26: =SUM(H27:H29)
B27: TDS deduction for aggrigators | C27: ='D1W1'!AO4 | D27: ='D1W2'!AO4 | E27: ='D1W3'!AO4 | F27: ='D1W4'!AO4 | G27: ='D1W5'!AO4 | H27: =SUM(C27:G27)
B28: TCS | C28: ='D1W1'!AN4+'D1W1'!AM4 | D28: ='D1W2'!AN4+'D1W2'!AM4 | E28: ='D1W3'!AN4+'D1W3'!AM4 | F28: ='D1W4'!AN4+'D1W4'!AM4 | G28: ='D1W5'!AN4+'D1W5'!AM4 | H28: =SUM(C28:G28)
A29: 7 | B29: GST collected and paid by Zomato | C29: ='D1W1'!AP4 | D29: ='D1W2'!AP4 | E29: ='D1W3'!AP4 | F29: ='D1W4'!AP4 | G29: ='D1W5'!AP4 | H29: =SUM(C29:G29)
B30: Expected Receipts | C30: =C25-C27-C28-C34 | D30: =D25-D27-D28-D34 | E30: =E25-E27-E28-E34 | F30: =F25-F27-F28-F34 | G30: =G25-G27-G28-G34 | H30: =H25-H27-H28-H34
B31: Service Fee Reversal | C31: 0 | D31: 0 | E31: 0 | F31: 0 | G31: 0 | H31: =SUM(C31:G31)
B32: Interim payments | C32: 0 | D32: 0 | E32: 0 | F32: 0 | G32: 0 | H32: =SUM(C32:G32)
B33: Opening Week Adjustments | C33: 23776.85 | D33: 0 | E33: 0 | F33: 0 | G33: 0 | H33: =SUM(C33:G33)
B34: Following Week Adjustments | C34: 0 | D34: 0 | E34: 0 | F34: 0 | G34: 0 | H34: =SUM(C34:G34)
B35: Closing Week Adjustments | C35: 0 | D35: 0 | E35: 0 | F35: 0 | G35: 0 | H35: =SUM(C35:G35)
B36: Zomato hyperpure Payment Adjustments | C36: ='D2W1'!G21 | D36: ='D2W2'!G21 | E36: ='D2W3'!G21 | F36: ='D2W4'!G22 | G36: ='D2W5'!G22 | H36: =SUM(C36:G36)
B37: EMI Loan deductions | C37: 0 | D37: 0 | E37: 0 | F37: 0 | G37: 0 | H37: =SUM(C37:G37)
A38: 8 | B38: Actual receipts | C38: 0 | D38: 0 | E38: 0 | F38: 0 | G38: 0 | H38: =SUM(C38:G38)
B39: Difference | C39: =C30-C38-C36+C33+C35 | D39: =D30-D38-D36-D33+D35 | E39: =E30-E38-E36-E33+E35 | F39: =F30-F38-F36-F33+F35-F34-F32 | G39: =G30-G38-G36-G33+G35 | H39: =H30-H38-H36+H33+H35-H34-H32
B41: Note :

Sheet Profit statement
A1: =Summary!B1
A2: Zomato Profit Statement - November - 2026
A4: Details | B4: =Summary!C4 | C4: =Summary!D4 | D4: =Summary!E4 | E4: =Summary!F4 | F4: =Summary!G4 | G4: =Summary!H4
A5: A. Net Sales
A6: Total Income | B6: =Cashflow!C5+Cashflow!C6+Cashflow!C9-Cashflow!C8-Cashflow!C29 | C6: =Cashflow!D5+Cashflow!D6+Cashflow!D9-Cashflow!D8-Cashflow!D29 | D6: =Cashflow!E5+Cashflow!E6+Cashflow!E9-Cashflow!E8-Cashflow!E29 | E6: =Cashflow!F5+Cashflow!F6+Cashflow!F9-Cashflow!F8-Cashflow!F29 | F6: =Cashflow!G5+Cashflow!G6+Cashflow!G9-Cashflow!G8-Cashflow!G29 | G6: =SUM(B6:F6)
A7: Add- Adjust: Cancelled orders (By Zomato) | B7: =Cashflow!C7 | C7: =Cashflow!D7 | D7: =Cashflow!E7 | E7: =Cashflow!F7 | F7: =Cashflow!G7 | G7: =SUM(B7:F7)
A8: Net Sales (Number that you see on Numerize app) | B8: =B6+B7 | C8: =C6+C7 | D8: =D6+D7 | E8: =E6+E7 | F8: =F6+F7 | G8: =G6+G7
A10: B. Less:- Commission | B10: =Cashflow!C11 | C10: =Cashflow!D11 | D10: =Cashflow!E11 | E10: =Cashflow!F11 | F10: =Cashflow!G11 | G10: =SUM(B10:F10)
A12: C. Less:- Marketing & Ads | B12: =Cashflow!C21 | C12: =Cashflow!D21 | D12: =Cashflow!E21 | E12: =Cashflow!F21 | F12: =Cashflow!G21 | G12: =SUM(B12:F12)
A14: D. Less:- Refund on disputed orders | B14: =Cashflow!C18 | C14: =Cashflow!D18 | D14: =Cashflow!E18 | E14: =Cashflow!F18 | F14: =Cashflow!G18 | G14: =SUM(B14:F14)
A16: E. Other charges | B16: =Cashflow!C13 | C16: =Cashflow!D13 | D16: =Cashflow!E13 | E16: =Cashflow!F13 | F16: =Cashflow!G13 | G16: =SUM(B16:F16)
A18: F. Profit | B18: =B8-B10-B12-B14-B16 | C18: =C8-C10-C12-C14-C16 | D18: =D8-D10-D12-D14-D16 | E18: =E8-E10-E12-E14-E16 | F18: =F8-F10-F12-F14-F16 | G18: =G8-G10-G12-G14-G16
A19: Percentage | B19: =IFERROR(B18/B8,0) | C19: =IFERROR(C18/C8,0) | D19: =IFERROR(D18/D8,0) | E19: =IFERROR(E18/E8,0) | F19: =IFERROR(F18/F8,0) | G19: =G18/G8

Sheet Discrepancies
A1: =Summary!B1
A2: Zomato Discrepancies - November - 2026
A4: Details | B4: =Summary!C4 | C4: =Summary!D4 | D4: =Summary!E4 | E4: =Summary!F4 | F4: =Summary!G4 | G4: =Summary!H4
A5: A. POS discrepancies
A6: Sales as per Zomato | B6: =Cashflow!C10 | C6: =Cashflow!D10 | D6: =Cashflow!E10 | E6: =Cashflow!F10 | F6: =Cashflow!G10 | G6: =SUM(B6:F6)
A7: Sale as per POS | G7: =SUM(B7:F7)
A8: Difference | B8: =B7-B6 | C8: =C7-C6 | D8: =D7-D6 | E8: =E7-E6 | F8: =F7-F6 | G8: =G7-G6
B9: =IFERROR(B8/B6,) | C9: =IFERROR(C8/C6,0) | D9: =IFERROR(D8/D6,0) | E9: =IFERROR(E8/E6,0) | F9: =IFERROR(F8/F6,0) | G9: =IFERROR(G8/G6,0)
A11: B. Order discrepancies
A12: No.of delivered orders for which payment isn't received | B12: 0 | C12: 0 | D12: 0 | E12: 0 | F12: 0 | G12: =SUM(B12:F12)
A13: Value of such orders | B13: 0 | C13: 0 | D13: 0 | E13: 0 | F13: 0 | G13: =SUM(B13:F13)
A16: C. Payment discrepancies
A17: Expected receipts in the bank account | B17: =Cashflow!C30 | C17: =Cashflow!D30 | D17: =Cashflow!E30 | E17: =Cashflow!F30 | F17: =Cashflow!G30 | G17: =SUM(B17:F17)
A18: Investment in Hyperpure | B18: =Cashflow!C36 | C18: =Cashflow!D36 | D18: =Cashflow!E36 | E18: =Cashflow!F36 | F18: =Cashflow!G36 | G18: =SUM(B18:F18)
A19: Following Week Adjustment | B19: =Cashflow!C34 | C19: =Cashflow!D34 | D19: =Cashflow!E34 | E19: =Cashflow!F34 | F19: =Cashflow!G34 | G19: =SUM(B19:F19)
A20: Opening Week Adjustment | B20: =Cashflow!C33 | C20: =Cashflow!D33 | D20: =Cashflow!E33 | E20: =Cashflow!F33 | F20: 0 | G20: =SUM(B20:F20)
A21: Closing Week Adjustment | B21: =Cashflow!C35 | C21: =Cashflow!D35 | D21: =Cashflow!E35 | E21: =Cashflow!F35 | F21: =Cashflow!G35 | G21: =SUM(B21:F21)
A22: Actual receipts in the bank | B22: =Cashflow!C38 | C22: =Cashflow!D38 | D22: =Cashflow!E38 | E22: =Cashflow!F38 | F22: =Cashflow!G38 | G22: =SUM(B22:F22)
A23: Difference | B23: =B17-B22-B18+B20 | C23: =C17-C22-C18 | D23: =D17-D22-D18 | E23: =E17-E22-E18-E19 | F23: =F17-F22-F18+F21 | G23: =G17-G22-G18+G20-G19
A25: Note:

Sheet POS

Sheet BANK
B5: 1 | C5: 2 | D5: 3 | E5: 4 | F5: 5
A10: Date | B10: Narration | C10: Chq./Ref.No. | D10: Value Dt | E10: Withdrawal Amt. | F10: Deposit Amt. | G10: Closing Balance
A11: 01/10/25 | B11: NEFT CR-YESB0000001-ONE 97 COMMUNICATIONS LIMITED SETTL-ROCKTAIL HOSPITALITY SERVICES-YESBN12025100101816795 | C11: YESBN12025100101816795 | D11: 01/10/25 | F11: 28308.11 | G11: 369938.81
A12: 01/10/25 | B12: NEFT CR-RATN0000999-PINE LABS LIMITED-ROCKTAIL HOSPITALITY SERVICES-RATNN52025100142548753 | C12: RATNN52025100142548753 | D12: 01/10/25 | F12: 988.02 | G12: 370926.83
A13: 01/10/25 | B13: 42552394TERMINAL 1 CARDS SETTL. 01/10/25 | C13: 000000000000000 | D13: 01/10/25 | F13: 4135.06 | G13: 375061.89
A14: 01/10/25 | B14: UPI-8978287178PTYES-8978287178@PTYES-UBIN0813567-564035906635-UPI | C14: 0000564035906635 | D14: 01/10/25 | E14: 165 | G14: 374896.89
A15: 01/10/25 | B15: 50200069817641-TPT-NBLCVTK6KLDPDJXS-WOLFFPACK VENTURES PRIVATE LIMITED | C15: 0000000223256296 | D15: 01/10/25 | F15: 200000 | G15: 574896.89
A16: 01/10/25 | B16: VENDOR PAYMENTS - ROCKTAIL HOSPITALITY DR - 57500000326520 - NEFT TRANSITORY ACCOUNT | C16: 0000000000000188 | D16: 01/10/25 | E16: 390734 | G16: 184162.89
A17: 01/10/25 | B17: UPI-SHREY SINGH-SHREYSINGH0501-1@OKHDFCBANK-HDFC0004216-564012927870-REGISTRATION | C17: 0000564012927870 | D17: 01/10/25 | E17: 8700 | G17: 175462.89
A18: 01/10/25 | B18: NEFT RETURN-INCORRECT ACCOUNT NUMBER-LAXMI AGENCIES-IBKLN92025100194760959 | C18: HDFCN52025100104276617 | D18: 01/10/25 | F18: 8322 | G18: 183784.89
A19: 01/10/25 | B19: NEFT RETURN-INCORRECT ACCOUNT NUMBER-LAXMI AGENCIES-IBKLN92025100194760962 | C19: HDFCN52025100104276606 | D19: 01/10/25 | F19: 8316 | G19: 192100.89
A20: 01/10/25 | B20: NEFT CR-CITI0000002-ETERNAL LIMITED-ROCKTAIL HOSPITALITY SERVICES-CITIN52025100134584901 | C20: CITIN52025100134584901 | D20: 01/10/25 | F20: 22470.51 | G20: 214571.4
A21: 01/10/25 | B21: NEFT CR-UTIB0000052-BUNDL TECHNOLOGIES PRIVATE LIMITED-ROCKTAIL HOSPITALITY SERVICES-UTIBN62025100172850989 | C21: UTIBN62025100172850989 | D21: 01/10/25 | F21: 28624.05 | G21: 243195.45
A22: 01/10/25 | B22: FT - DR - 50200086201346 - SRI CHAKRA ENTERPRISES | C22: 0000000000000187 | D22: 01/10/25 | E22: 68400 | G22: 174795.45
A23: 01/10/25 | B23: CQ NO-000187 AMOUNT-100323 TRANSFERS 4 DR - 50200088485779 - NSP ENTERPRISES | C23: 000000000000000 | D23: 01/10/25 | E23: 12843 | G23: 161952.45
A24: 01/10/25 | B24: CQ NO-000187 AMOUNT-100323 TRANSFERS 4 DR - 50200082063860 - AAMODHA ENTERPRISES | C24: 000000000000000 | D24: 01/10/25 | E24: 16560 | G24: 145392.45
A25: 01/10/25 | B25: CQ NO-000187 AMOUNT-100323 TRANSFERS 4 DR - 50200034371828 - SRIHITHA DISTRIBUTORS | C25: 000000000000000 | D25: 01/10/25 | E25: 2520 | G25: 142872.45
A26: 01/10/25 | B26: UPI-SRI LAXMI CHENNAKESA-Q560982817@YBL-YESB0YBLUPI-112039563850-POOJA | C26: 0000112039563850 | D26: 01/10/25 | E26: 1651 | G26: 141221.45
A27: 01/10/25 | B27: NEFT CR-YESB0000001-SWIGGY LIMITED-ROCKTAIL HOSPITALITY SERVICES-YESBN12025100106534132 | C27: YESBN12025100106534132 | D27: 01/10/25 | F27: 37494.72 | G27: 178716.17
A28: 02/10/25 | B28: NEFT CR-YESB0000001-ONE 97 COMMUNICATIONS LIMITED SETTL-ROCKTAIL HOSPITALITY SERVICES-YESBN12025100202440556 | C28: YESBN12025100202440556 | D28: 02/10/25 | F28: 28924.86 | G28: 207641.03
A29: 02/10/25 | B29: 42552394TERMINAL 1 CARDS SETTL. 02/10/25 | C29: 000000000000000 | D29: 02/10/25 | F29: 6676.28 | G29: 214317.31
A30: 03/10/25 | B30: NEFT CR-YESB0000001-ONE 97 COMMUNICATIONS LIMITED SETTL-ROCKTAIL HOSPITALITY SERVICES-YESBN12025100302342936 | C30: YESBN12025100302342936 | D30: 03/10/25 | F30: 38471.91 | G30: 252789.22
A31: 03/10/25 | B31: 42552394TERMINAL 1 CARDS SETTL. 03/10/25 | C31: 000000000000000 | D31: 03/10/25 | F31: 13411.99 | G31: 266201.21
A32: 03/10/25 | B32: UPI-BHANWRA RAM-BHANWARJATCHOUDHARY251@OKSBI-SBIN0011306-564239417166-FURNITURE | C32: 0000564239417166 | D32: 03/10/25 | E32: 35000 | G32: 231201.21
A33: 03/10/25 | B33: NEFT CR-UTIB0000052-BUNDL TECHNOLOGIES PRIVATE LIMITED-ROCKTAIL HOSPITALITY SERVICES-UTIBN62025100395892591 | C33: UTIBN62025100395892591 | D33: 03/10/25 | F33: 13038.51 | G33: 244239.72
A34: 04/10/25 | B34: NEFT CR-YESB0000001-ONE 97 COMMUNICATIONS LIMITED SETTL-ROCKTAIL HOSPITALITY SERVICES-YESBN12025100403632181 | C34: YESBN12025100403632181 | D34: 04/10/25 | F34: 53035 | G34: 297274.72
A35: 04/10/25 | B35: 42552394TERMINAL 1 CARDS SETTL. 04/10/25 | C35: 000000000000000 | D35: 04/10/25 | F35: 10812.69 | G35: 308087.41
A36: 04/10/25 | B36: UPI-SWIGGY LIMITED-SWIGGY.STORES@AXB-UTIB0000100-527751059928-PAY FOR INTENT | C36: 0000527751059928 | D36: 04/10/25 | E36: 856 | G36: 307231.41
A37: 05/10/25 | B37: NEFT CR-YESB0000001-ONE 97 COMMUNICATIONS LIMITED SETTL-ROCKTAIL HOSPITALITY SERVICES-YESBN12025100501829191 | C37: YESBN12025100501829191 | D37: 05/10/25 | F37: 72645.73 | G37: 379877.14
A38: 05/10/25 | B38: 42552394TERMINAL 1 CARDS SETTL. 05/10/25 | C38: 000000000000000 | D38: 05/10/25 | F38: 17370.83 | G38: 397247.97
A39: 05/10/25 | B39: SETTLEMENT CHARGE-SEP25-CPY597 | C39: 000000000000000 | D39: 05/10/25 | E39: 37.76 | G39: 397210.21
A40: 06/10/25 | B40: NEFT CR-YESB0000001-ONE 97 COMMUNICATIONS LIMITED SETTL-ROCKTAIL HOSPITALITY SERVICES-YESBN12025100601953902 | C40: YESBN12025100601953902 | D40: 06/10/25 | F40: 65856.98 | G40: 463067.19
A41: 06/10/25 | B41: EMI 162047443 CHQ S16204744314 1025162047443 | C41: 000000000000000 | D41: 06/10/25 | E41: 70666 | G41: 392401.19
A42: 06/10/25 | B42: 42552394TERMINAL 1 CARDS SETTL. 06/10/25 | C42: 000000000000000 | D42: 06/10/25 | F42: 1635.17 | G42: 394036.36
A43: 06/10/25 | B43: NEFT CR-CITI0000002-ETERNAL LIMITED-ROCKTAIL HOSPITALITY SERVICES-CITIN52025100636240957 | C43: CITIN52025100636240957 | D43: 06/10/25 | F43: 61201.16 | G43: 455237.52
A44: 07/10/25 | B44: NEFT CR-YESB0000001-ONE 97 COMMUNICATIONS LIMITED SETTL-ROCKTAIL HOSPITALITY SERVICES-YESBN12025100701113506 | C44: YESBN12025100701113506 | D44: 07/10/25 | F44: 24613.36 | G44: 479850.88
A45: 07/10/25 | B45: 42552394TERMINAL 1 CARDS SETTL. 07/10/25 | C45: 000000000000000 | D45: 07/10/25 | F45: 9641.79 | G45: 489492.67
A46: 07/10/25 | B46: NEFT CR-YESB0000001-SWIGGY LIMITED-ROCKTAIL HOSPITALITY SERVICES-YESBN12025100705709842 | C46: YESBN12025100705709842 | D46: 07/10/25 | F46: 83057.26 | G46: 572549.93
A47: 08/10/25 | B47: NEFT CR-YESB0000001-ONE 97 COMMUNICATIONS LIMITED SETTL-ROCKTAIL HOSPITALITY SERVICES-YESBN12025100800862936 | C47: YESBN12025100800862936 | D47: 08/10/25 | F47: 17786 | G47: 590335.93
A48: 08/10/25 | B48: 42552394TERMINAL 1 CARDS SETTL. 08/10/25 | C48: 000000000000000 | D48: 08/10/25 | F48: 5938.15 | G48: 596274.08
...

Sheet D1W1
O1: 0 | P1: 0 | Q1: 0 | R1: 0 | S1: 0 | T1: 0 | U1: 0 | V1: 0 | W1: 0 | X1: 0 | Y1: 0 | Z1: 0 | AA1: 0 | AB1: 0 | AC1: 0 | AD1: 0 | AE1: 0 | AF1: 0 | AG1: 0 | AH1: 0 | AI1: 0 | AJ1: 0 | AK1: 0 | AL1: 0 | AM1: 0 | AN1: 0 | AO1: 0 | AP1: 0 | AQ1: 0 | AR1: 0 | AS1: 0 | AT1: 0 | AU1: 0 | AV1: 0 | AW1: 0 | AX1: 0 | AY1: 0 | AZ1: 0 | BA1: 0 | BB1: 0 | BC1: 0 | BD1: 0 | BE1: 0 | BF1: 0 | BG1: 0 | BH1: 0 | BI1: 0
O2: 20793 | P2: 825 | Q2: 0 | R2: 1350 | S2: 0 | T2: 0 | U2: 0 | V2: 1013.4 | W2: 21281.4 | X2: 19443 | Y2: 825 | Z2: 1013.4 | AA2: 21281.4 | AB2: 782 | AC2: 4894.76 | AD2: 151.3 | AE2: 380 | AF2: 0 | AG2: 8.86 | AH2: 391.57 | AI2: 5657.47 | AJ2: 1018.43 | AK2: 0 | AL2: 20268 | AM2: 0 | AN2: 0 | AO2: 20.21 | AP2: 1013.4 | AQ2: 0 | AR2: 2052.04 | AS2: 0 | AT2: 0 | AU2: 0 | AV2: 0 | AW2: 0 | AX2: 0 | AY2: 0 | AZ2: 0 | BA2: 0 | BB2: 7709.51 | BC2: 0 | BD2: 13571.89 | BE2: 0 | BF2: 0 | BG2: 0 | BH2: 0 | BI2: 0
O3: 24535.74 | P3: 973.5 | Q3: 0 | R3: 1593 | S3: 0 | T3: 0 | U3: 0 | V3: 1195.812 | W3: 25112.052 | X3: 22942.74 | Y3: 973.5 | Z3: 1195.812 | AA3: 25112.052 | AB3: 922.76 | AC3: 5775.8168 | AD3: 178.534 | AE3: 448.4 | AF3: 0 | AG3: 10.4548 | AH3: 462.0526 | AI3: 6675.8146 | AJ3: 1201.7474 | AK3: 0 | AL3: 23916.24 | AM3: 0 | AN3: 0 | AO3: 23.8478 | AP3: 1195.812 | AQ3: 0 | AR3: 2421.4072 | AS3: 0 | AT3: 0 | AU3: 0 | AV3: 0 | AW3: 0 | AX3: 0 | AY3: 0 | AZ3: 0 | BA3: 0 | BB3: 9097.2218 | BC3: 0 | BD3: 16014.83 | BE3: 0 | BF3: 0 | BG3: 0 | BH3: 0 | BI3: 0
O4: 20793 | P4: 825 | Q4: 0 | R4: 1350 | S4: 0 | T4: 0 | U4: 0 | V4: 1013.4 | W4: 21281.4 | X4: 19443 | Y4: 825 | Z4: 1013.4 | AA4: 21281.4 | AB4: 782 | AC4: 4894.76 | AD4: 151.3 | AE4: 380 | AF4: 0 | AG4: 8.86 | AH4: 391.57 | AI4: 5657.47 | AJ4: 1018.43 | AK4: 0 | AL4: 20268 | AM4: 0 | AN4: 0 | AO4: 20.21 | AP4: 1013.4 | AQ4: 0 | AR4: 2052.04 | AS4: 0 | AT4: 0 | AU4: 0 | AV4: 0 | AW4: 0 | AX4: 0 | AY4: 0 | AZ4: 0 | BA4: 0 | BB4: 7709.51 | BC4: 0 | BD4: 13571.89 | BE4: 0 | BF4: 0 | BG4: 0 | BH4: 0 | BI4: 0
A5: S.no. | B5: Order ID | C5: Order date | D5: Week no. | E5: Res. name | F5: Res. ID | G5: Discount construct | H5: Mode of payment | I5: Order status (Delivered/ Cancelled/ Rejected) | J5: Cancellation policy (% Amount refunded back to restaurant partner) | K5: Cancellation/ Rejection reason | L5: Cancelled/ Rejected state (Order status at the time it was cancelled/ rejected) | M5: Order type | N5: Delivery state code | O5: Subtotal (items total) | P5: Packaging charge | Q5: Delivery charge for restaurants on self logistics | R5: Restaurant discount (Promo) | S5: Restaurant discount (BOGO, Freebies, Gold, Brand pack & others) | T5: Brand pack subscription fee | U5: Delivery charge discount/ Relisting discount | V5: Total GST collected from customers | W5: Net order value [(1) + (2) + (3) - (4) - (5) + (6) - (7) + (8)] | X5: Commissionable value of Subtotal, excluding restuarant discounts [(1) - (4) - (5)] | Y5: Commissionable value of Packaging charge | Z5: Commissionable value of Total GST collected from customers | AA5: Total commissionable value [(9) + (10) + (11)] | AB5: Base service fee % | AC5: Base service fee [(12)% * (B)] | AD5: Actual order distance (km) | AE5: Long distance enablement fee | AF5: Discount on long distance enablement fee | AG5: Discount on service fee due to 30% capping Service fees capped at 30% of commissionable value (B) | AH5: Payment mechanism fee | AI5: Service fee & payment mechanism fee [(13) + (15) - (16) - (17) + (18)] | AJ5: Taxes on service fee & payment mechanism fee [(C) * 18%] | AK5: Applicable amount for TCS | AL5: Applicable amount for 9(5) | AM5: Tax collected at source | AN5: TCS IGST amount | AO5: TDS 194O amount | AP5: GST paid by Zomato on behalf of restaurant - under section 9(5) | AQ5: GST to be paid by Restaurant partner to Govt. | AR5: Government charges [(19) + (22) + (23) + (24) + (25)] | AS5: Customer compensation/ recoupment | AT5: Delivery charges recovery | AU5: Amount received in cash (on self delivery orders) | AV5: Credit note/ (Debit note) adjustment | AW5: Promo recovery adjustment | AX5: Extra inventory ads (order level deduction) | AY5: Brand loyalty points redemption | AZ5: Express order fee | BA5: Other order-level deductions [(27) + (28) + (29) + (30) + (31) + (32) + (33) + (34)] | BB5: Net Deductions [(C) + (D) + (E)] | BC5: Net Additions (cancellation refund for cancelled orders/ tip for kitchen staff for delivered orders) | BD5: Order level Payout (A) - (F) + (G) | BE5: Settlement status | BF5: Settlement date | BG5: Bank UTR | BH5: Unsettled amount | BI5: Customer ID
A6: 61 | B6: 7428480973 | C6: 2025-11-01 10:08:55 | D6: 44 | E6: This Is It | F6: 20802097 | G6: Flat ₹50 off (2025-09-15 - 2031-01-01) | H6: ONLINE | I6: DELIVERED | J6: NA | K6: NA | L6: NA | M6: O2 | N6: 36 | O6: 737 | P6: 30 | Q6: 0 | R6: 50 | S6: 0 | T6: 0 | U6: 0 | V6: 35.85 | W6: 752.85 | X6: 687 | Y6: 30 | Z6: 35.85 | AA6: 752.85 | AB6: 23 | AC6: 173.16 | AD6: 4.64 | AE6: 20 | AF6: 0 | AG6: 0 | AH6: 13.85 | AI6: 207.01 | AJ6: 37.25 | AK6: 0 | AL6: 717 | AM6: 0 | AN6: 0 | AO6: 0.72 | AP6: 35.85 | AQ6: 0 | AR6: 73.82 | AS6: 0 | AT6: 0 | AU6: 0 | AV6: 0 | AW6: 0 | AX6: 0 | AY6: 0 | AZ6: 0 | BA6: 0 | BB6: 280.83 | BC6: 0 | BD6: 472.02 | BE6: settled | BF6: NA | BG6: NA | BH6: 0 | BI6: c12ab30d0a914b8918d2e3bccd839f31c7918fb24e876fc72b10fa8ec8f63336
A7: 62 | B7: 7430062031 | C7: 2025-11-01 12:32:12 | D7: 44 | E7: This Is It | F7: 20802097 | G7: NA | H7: ONLINE | I7: DELIVERED | J7: NA | K7: NA | L7: NA | M7: O2 | N7: 36 | O7: 389 | P7: 15 | Q7: 0 | R7: 0 | S7: 0 | T7: 0 | U7: 0 | V7: 20.2 | W7: 424.2 | X7: 389 | Y7: 15 | Z7: 20.2 | AA7: 424.2 | AB7: 23 | AC7: 97.57 | AD7: 1 | AE7: 0 | AF7: 0 | AG7: 0 | AH7: 7.81 | AI7: 105.38 | AJ7: 18.98 | AK7: 0 | AL7: 404 | AM7: 0 | AN7: 0 | AO7: 0.4 | AP7: 20.2 | AQ7: 0 | AR7: 39.58 | AS7: 0 | AT7: 0 | AU7: 0 | AV7: 0 | AW7: 0 | AX7: 0 | AY7: 0 | AZ7: 0 | BA7: 0 | BB7: 144.96 | BC7: 0 | BD7: 279.24 | BE7: settled | BF7: NA | BG7: NA | BH7: 0 | BI7: e84eab5b7a806737644d747e648ac6c923ab6d373cdf40526b60cfb7b3135aae
A8: 63 | B8: 7432104357 | C8: 2025-11-01 13:35:24 | D8: 44 | E8: This Is It | F8: 20802097 | G8: Flat ₹50 off (2025-09-15 - 2031-01-01) | H8: ONLINE | I8: DELIVERED | J8: NA | K8: NA | L8: NA | M8: O2 | N8: 36 | O8: 828 | P8: 30 | Q8: 0 | R8: 50 | S8: 0 | T8: 0 | U8: 0 | V8: 40.4 | W8: 848.4 | X8: 778 | Y8: 30 | Z8: 40.4 | AA8: 848.4 | AB8: 23 | AC8: 195.13 | AD8: 13.03 | AE8: 40 | AF8: 0 | AG8: 0 | AH8: 15.61 | AI8: 250.74 | AJ8: 45.13 | AK8: 0 | AL8: 808 | AM8: 0 | AN8: 0 | AO8: 0.81 | AP8: 40.4 | AQ8: 0 | AR8: 86.34 | AS8: 0 | AT8: 0 | AU8: 0 | AV8: 0 | AW8: 0 | AX8: 0 | AY8: 0 | AZ8: 0 | BA8: 0 | BB8: 337.08 | BC8: 0 | BD8: 511.32 | BE8: settled | BF8: NA | BG8: NA | BH8: 0 | BI8: 4483bee4fb3dad8635bef2fd71774c45b1c38a7a5643dd20062360bfe15a54d2
A9: 64 | B9: 7437487425 | C9: 2025-11-01 14:13:38 | D9: 44 | E9: This Is It | F9: 20802097 | G9: NA | H9: ONLINE | I9: DELIVERED | J9: NA | K9: NA | L9: NA | M9: O2 | N9: 36 | O9: 429 | P9: 15 | Q9: 0 | R9: 0 | S9: 0 | T9: 0 | U9: 0 | V9: 22.2 | W9: 466.2 | X9: 429 | Y9: 15 | Z9: 22.2 | AA9: 466.2 | AB9: 23 | AC9: 107.23 | AD9: 4.77 | AE9: 20 | AF9: 0 | AG9: 0 | AH9: 8.58 | AI9: 135.81 | AJ9: 24.44 | AK9: 0 | AL9: 444 | AM9: 0 | AN9: 0 | AO9: 0.44 | AP9: 22.2 | AQ9: 0 | AR9: 47.08 | AS9: 0 | AT9: 0 | AU9: 0 | AV9: 0 | AW9: 0 | AX9: 0 | AY9: 0 | AZ9: 0 | BA9: 0 | BB9: 182.89 | BC9: 0 | BD9: 283.31 | BE9: settled | BF9: NA | BG9: NA | BH9: 0 | BI9: ecb245cdcc7206c37c77de64752537989c55c8162bdb386c5af5224d96f360f1
A10: 65 | B10: 7433709411 | C10: 2025-11-01 15:42:02 | D10: 44 | E10: This Is It | F10: 20802097 | G10: Flat ₹50 off (2025-09-15 - 2031-01-01) | H10: ONLINE | I10: DELIVERED | J10: NA | K10: NA | L10: NA | M10: O2 | N10: 36 | O10: 1047 | P10: 45 | Q10: 0 | R10: 50 | S10: 0 | T10: 0 | U10: 0 | V10: 52.1 | W10: 1094.1 | X10: 997 | Y10: 45 | Z10: 52.1 | AA10: 1094.1 | AB10: 23 | AC10: 251.64 | AD10: 19.75 | AE10: 40 | AF10: 0 | AG10: 0 | AH10: 20.13 | AI10: 311.77 | AJ10: 56.12 | AK10: 0 | AL10: 1042 | AM10: 0 | AN10: 0 | AO10: 1.04 | AP10: 52.1 | AQ10: 0 | AR10: 109.26 | AS10: 0 | AT10: 0 | AU10: 0 | AV10: 0 | AW10: 0 | AX10: 0 | AY10: 0 | AZ10: 0 | BA10: 0 | BB10: 421.03 | BC10: 0 | BD10: 673.07 | BE10: settled | BF10: NA | BG10: NA | BH10: 0 | BI10: 8eed8ee36b11a78b60c8f3ba8585ffc79853992891d72f04a2c1d463cb880c06
A11: 66 | B11: 7434255747 | C11: 2025-11-01 17:20:25 | D11: 44 | E11: This Is It | F11: 20802097 | G11: Flat ₹50 off (2025-09-15 - 2031-01-01) | H11: ONLINE | I11: DELIVERED | J11: NA | K11: NA | L11: NA | M11: O2 | N11: 36 | O11: 778 | P11: 30 | Q11: 0 | R11: 50 | S11: 0 | T11: 0 | U11: 0 | V11: 37.9 | W11: 795.9 | X11: 728 | Y11: 30 | Z11: 37.9 | AA11: 795.9 | AB11: 23 | AC11: 183.06 | AD11: 5.04 | AE11: 20 | AF11: 0 | AG11: 0 | AH11: 14.64 | AI11: 217.7 | AJ11: 39.19 | AK11: 0 | AL11: 758 | AM11: 0 | AN11: 0 | AO11: 0.76 | AP11: 37.9 | AQ11: 0 | AR11: 77.85 | AS11: 0 | AT11: 0 | AU11: 0 | AV11: 0 | AW11: 0 | AX11: 0 | AY11: 0 | AZ11: 0 | BA11: 0 | BB11: 295.55 | BC11: 0 | BD11: 500.35 | BE11: settled | BF11: NA | BG11: NA | BH11: 0 | BI11: 45da20ed7f1445f8e2514b5a61b25bf8b9543f1c9d927ce9390e3db6641ba995
A12: 67 | B12: 7428034558 | C12: 2025-11-01 17:25:36 | D12: 44 | E12: This Is It | F12: 20802097 | G12: Flat ₹200 off (2025-09-10 - 2031-01-01) | H12: ONLINE | I12: DELIVERED | J12: NA | K12: NA | L12: NA | M12: O2 | N12: 36 | O12: 1047 | P12: 45 | Q12: 0 | R12: 200 | S12: 0 | T12: 0 | U12: 0 | V12: 44.6 | W12: 936.6 | X12: 847 | Y12: 45 | Z12: 44.6 | AA12: 936.6 | AB12: 23 | AC12: 215.42 | AD12: 19.69 | AE12: 40 | AF12: 0 | AG12: 0 | AH12: 17.23 | AI12: 272.65 | AJ12: 49.08 | AK12: 0 | AL12: 892 | AM12: 0 | AN12: 0 | AO12: 0.89 | AP12: 44.6 | AQ12: 0 | AR12: 94.57 | AS12: 0 | AT12: 0 | AU12: 0 | AV12: 0 | AW12: 0 | AX12: 0 | AY12: 0 | AZ12: 0 | BA12: 0 | BB12: 367.22 | BC12: 0 | BD12: 569.38 | BE12: settled | BF12: NA | BG12: NA | BH12: 0 | BI12: fa6bea29a7fe9b551c1e7f2ace09cbb65f963e5eec891c4067fbbb5be2c0f546
A13: 68 | B13: 7431600871 | C13: 2025-11-01 18:49:39 | D13: 44 | E13: This Is It | F13: 20802097 | G13: NA | H13: ONLINE | I13: DELIVERED | J13: NA | K13: NA | L13: NA | M13: O2 | N13: 36 | O13: 628 | P13: 15 | Q13: 0 | R13: 0 | S13: 0 | T13: 0 | U13: 0 | V13: 32.15 | W13: 675.15 | X13: 628 | Y13: 15 | Z13: 32.15 | AA13: 675.15 | AB13: 23 | AC13: 155.28 | AD13: 2.09 | AE13: 0 | AF13: 0 | AG13: 0 | AH13: 12.42 | AI13: 167.7 | AJ13: 30.19 | AK13: 0 | AL13: 643 | AM13: 0 | AN13: 0 | AO13: 0.64 | AP13: 32.15 | AQ13: 0 | AR13: 62.98 | AS13: 0 | AT13: 0 | AU13: 0 | AV13: 0 | AW13: 0 | AX13: 0 | AY13: 0 | AZ13: 0 | BA13: 0 | BB13: 230.68 | BC13: 0 | BD13: 444.47 | BE13: settled | BF13: NA | BG13: NA | BH13: 0 | BI13: 02fd79895a16f60367992ec04d264cdebb59110aabf837f4fa3fea05451378b4
A14: 69 | B14: 7430810490 | C14: 2025-11-01 19:00:41 | D14: 44 | E14: This Is It | F14: 20802097 | G14: NA | H14: ONLINE | I14: DELIVERED | J14: NA | K14: NA | L14: NA | M14: O2 | N14: 36 | O14: 429 | P14: 15 | Q14: 0 | R14: 0 | S14: 0 | T14: 0 | U14: 0 | V14: 22.2 | W14: 466.2 | X14: 429 | Y14: 15 | Z14: 22.2 | AA14: 466.2 | AB14: 23 | AC14: 107.23 | AD14: 2.89 | AE14: 0 | AF14: 0 | AG14: 0 | AH14: 8.58 | AI14: 115.81 | AJ14: 20.84 | AK14: 0 | AL14: 444 | AM14: 0 | AN14: 0 | AO14: 0.44 | AP14: 22.2 | AQ14: 0 | AR14: 43.48 | AS14: 0 | AT14: 0 | AU14: 0 | AV14: 0 | AW14: 0 | AX14: 0 | AY14: 0 | AZ14: 0 | BA14: 0 | BB14: 159.29 | BC14: 0 | BD14: 306.91 | BE14: settled | BF14: NA | BG14: NA | BH14: 0 | BI14: 82661b76abf5b90285fa5ba06ac71ecf2872e4883fa8c3f0e6cc3fd5d3e898f9
A15: 70 | B15: 7436444422 | C15: 2025-11-01 19:22:54 | D15: 44 | E15: This Is It | F15: 20802097 | G15: Flat ₹50 off (2025-09-15 - 2031-01-01) | H15: ONLINE | I15: DELIVERED | J15: NA | K15: NA | L15: NA | M15: O2 | N15: 36 | O15: 539 | P15: 15 | Q15: 0 | R15: 50 | S15: 0 | T15: 0 | U15: 0 | V15: 25.2 | W15: 529.2 | X15: 489 | Y15: 15 | Z15: 25.2 | AA15: 529.2 | AB15: 23 | AC15: 121.72 | AD15: 7.3 | AE15: 40 | AF15: 0 | AG15: 2.96 | AH15: 9.74 | AI15: 168.5 | AJ15: 30.33 | AK15: 0 | AL15: 504 | AM15: 0 | AN15: 0 | AO15: 0.5 | AP15: 25.2 | AQ15: 0 | AR15: 56.03 | AS15: 0 | AT15: 0 | AU15: 0 | AV15: 0 | AW15: 0 | AX15: 0 | AY15: 0 | AZ15: 0 | BA15: 0 | BB15: 224.53 | BC15: 0 | BD15: 304.67 | BE15: settled | BF15: NA | BG15: NA | BH15: 0 | BI15: 4652c36f78d13a00bec5518c940ca966495a95b495a2c5d8939a3b102058dfe2
A16: 71 | B16: 7438754605 | C16: 2025-11-01 19:51:16 | D16: 44 | E16: This Is It | F16: 20802097 | G16: Flat ₹50 off (2025-09-15 - 2031-01-01) | H16: ONLINE | I16: DELIVERED | J16: NA | K16: NA | L16: NA | M16: O2 | N16: 36 | O16: 519 | P16: 15 | Q16: 0 | R16: 50 | S16: 0 | T16: 0 | U16: 0 | V16: 24.2 | W16: 508.2 | X16: 469 | Y16: 15 | Z16: 24.2 | AA16: 508.2 | AB16: 23 | AC16: 116.89 | AD16: 4.48 | AE16: 20 | AF16: 0 | AG16: 0 | AH16: 9.35 | AI16: 146.24 | AJ16: 26.32 | AK16: 0 | AL16: 484 | AM16: 0 | AN16: 0 | AO16: 0.48 | AP16: 24.2 | AQ16: 0 | AR16: 51 | AS16: 0 | AT16: 0 | AU16: 0 | AV16: 0 | AW16: 0 | AX16: 0 | AY16: 0 | AZ16: 0 | BA16: 0 | BB16: 197.24 | BC16: 0 | BD16: 310.96 | BE16: settled | BF16: NA | BG16: NA | BH16: 0 | BI16: f245a05dfeb24ea278a3ec97f545e77ce73f1773042f865a024ebb205fbba082
A17: 72 | B17: 7438252664 | C17: 2025-11-01 20:09:50 | D17: 44 | E17: This Is It | F17: 20802097 | G17: Flat ₹200 off (2025-09-10 - 2031-01-01) | H17: ONLINE | I17: DELIVERED | J17: NA | K17: NA | L17: NA | M17: O2 | N17: 36 | O17: 918 | P17: 30 | Q17: 0 | R17: 100 | S17: 0 | T17: 0 | U17: 0 | V17: 42.4 | W17: 890.4 | X17: 818 | Y17: 30 | Z17: 42.4 | AA17: 890.4 | AB17: 23 | AC17: 204.79 | AD17: 3.87 | AE17: 0 | AF17: 0 | AG17: 0 | AH17: 16.38 | AI17: 221.17 | AJ17: 39.82 | AK17: 0 | AL17: 848 | AM17: 0 | AN17: 0 | AO17: 0.85 | AP17: 42.4 | AQ17: 0 | AR17: 83.07 | AS17: 0 | AT17: 0 | AU17: 0 | AV17: 0 | AW17: 0 | AX17: 0 | AY17: 0 | AZ17: 0 | BA17: 0 | BB17: 304.24 | BC17: 0 | BD17: 586.16 | BE17: settled | BF17: NA | BG17: NA | BH17: 0 | BI17: 64c73f212c2fba4f2880d72325ff4c13fb42716b076e87e7425cdd87a92c25e7
... A39: 94 | B39: 7438747837 | C39: 2025-11-02 23:27:22 | D39: 44 | E39: This Is It | F39: 20802097 | G39: Flat ₹50 off (2025-09-15 - 2031-01-01) | H39: ONLINE | I39: DELIVERED | J39: NA | K39: NA | L39: NA | M39: O2 | N39: 36 | O39: 1067 | P39: 45 | Q39: 0 | R39: 50 | S39: 0 | T39: 0 | U39: 0 | V39: 53.1 | W39: 1115.1 | X39: 1017 | Y39: 45 | Z39: 53.1 | AA39: 1115.1 | AB39: 23 | AC39: 256.47 | AD39: 5.64 | AE39: 20 | AF39: 0 | AG39: 0 | AH39: 20.52 | AI39: 296.99 | AJ39: 53.46 | AK39: 0 | AL39: 1062 | AM39: 0 | AN39: 0 | AO39: 1.06 | AP39: 53.1 | AQ39: 0 | AR39: 107.62 | AS39: 0 | AT39: 0 | AU39: 0 | AV39: 0 | AW39: 0 | AX39: 0 | AY39: 0 | AZ39: 0 | BA39: 0 | BB39: 404.61 | BC39: 0 | BD39: 710.49 | BE39: settled | BF39: NA | BG39: NA | BH39: 0 | BI39: f33579e39cffa6d0150fffcdeffab1a4099b17b87b9274cc1e5c38a7b8900ce6

Sheet D2W1
B1: Addition/ Deduction details (non order-level additions & deductions and adjustments from previous weeks)
B2: Summarized view on : 1. Res id level additions like 194 H, etc 2. Res id level deductions like pay later, etc
B5: Addition Type
B6: Type | C6: NA | D6: Invoice No/Order id | E6: Order date | F6: Settlement status | G6: Total amount | H6: Adjusted amount | I6: Outstanding amount
B7: Total Additions | G7: 0 | H7: 0 | I7: 0
B10: Deduction Type
B11: A) Investments in growth services
B12: Type | C12: Res id for which deduction created | D12: Invoice No/Campaign id | E12: Deduction time period | F12: Settlement Status | G12: Total amount | H12: Adjusted amount | I12: Outstanding amount
B13: Total Ads & miscellaneous services | G13: 0 | H13: 0 | I13: 0
B15: B) Investments in Hyperpure
B16: Type | C16: Res id for which deduction created | D16: OrderId | E16: Deduction time period | F16: Settlement Status | G16: Total amount | H16: Adjusted amount | I16: Outstanding amount
B17: Hyperpure | C17: NA | D17: NA | E17: 27 October 25 - 27 October 25 | F17: settled | G17: 9429.74 | H17: 9429.74 | I17: 0
B18: Hyperpure | C18: NA | D18: NA | E18: 30 October 25 - 30 October 25 | F18: settled | G18: 9190.25 | H18: 9190.25 | I18: 0
B19: Hyperpure | C19: NA | D19: NA | E19: 31 October 25 - 02 November 25 | F19: settled | G19: 11063.45 | H19: 11063.45 | I19: 0
B20: Hyperpure | C20: NA | D20: NA | E20: 02 November 25 - 02 November 25 | F20: settled | G20: 7665.3 | H20: 7665.3 | I20: 0
B21: Total Hyperpure | G21: 37348.74 | H21: 37348.74 | I21: 0
B23: C) Other deductions
B24: D) Adjustments from previous weeks
B25: Total Deductions (A) + (B) + (C) | G25: 37348.74 | H25: 37348.74 | I25: 0

Sheet D1W2
O1: 0 | P1: 0 | Q1: 0 | R1: 0 | S1: 0 | T1: 0 | U1: 0 | V1: 0 | W1: 0 | X1: 0 | Y1: 0 | Z1: 0 | AA1: 0 | AB1: 0 | AC1: 0 | AD1: 0 | AE1: 0 | AF1: 0 | AG1: 0 | AH1: 0 | AI1: 0 | AJ1: 0 | AK1: 0 | AL1: 0 | AM1: 0 | AN1: 0 | AO1: 0 | AP1: 0 | AQ1: 0 | AR1: 0 | AS1: 0 | AT1: 0 | AU1: 0 | AV1: 0 | AW1: 0 | AX1: 0 | AY1: 0 | AZ1: 0 | BA1: 0 | BB1: 0 | BC1: 0 | BD1: 0 | BE1: 0 | BF1: 0 | BG1: 0 | BH1: 0 | BI1: 0
O2: 47160 | P2: 1695 | Q2: 0 | R2: 4050 | S2: 0 | T2: 0 | U2: 0 | V2: 2240.25 | W2: 47045.25 | X2: 43110 | Y2: 1695 | Z2: 2240.25 | AA2: 47045.25 | AB2: 1725 | AC2: 10820.46 | AD2: 404.38 | AE2: 1480 | AF2: 0 | AG2: 179.19 | AH2: 865.63 | AI2: 12986.9 | AJ2: 2337.57 | AK2: 0 | AL2: 44805 | AM2: 0 | AN2: 0 | AO2: 44.68 | AP2: 2240.25 | AQ2: 0 | AR2: 4622.5 | AS2: 0 | AT2: 0 | AU2: 0 | AV2: 0 | AW2: 0 | AX2: 0 | AY2: 0 | AZ2: 0 | BA2: 0 | BB2: 17609.4 | BC2: 0 | BD2: 29435.85 | BE2: 0 | BF2: 0 | BG2: 0 | BH2: 0 | BI2: 0
O3: 55648.8 | P3: 2000.1 | Q3: 0 | R3: 4779 | S3: 0 | T3: 0 | U3: 0 | V3: 2643.495 | W3: 55513.395 | X3: 50869.8 | Y3: 2000.1 | Z3: 2643.495 | AA3: 55513.395 | AB3: 2035.5 | AC3: 12768.143 | AD3: 477.1684 | AE3: 1746.4 | AF3: 0 | AG3: 211.4442 | AH3: 1021.4434 | AI3: 15324.542 | AJ3: 2758.3326 | AK3: 0 | AL3: 52869.9 | AM3: 0 | AN3: 0 | AO3: 52.7224 | AP3: 2643.495 | AQ3: 0 | AR3: 5454.55 | AS3: 0 | AT3: 0 | AU3: 0 | AV3: 0 | AW3: 0 | AX3: 0 | AY3: 0 | AZ3: 0 | BA3: 0 | BB3: 20779.092 | BC3: 0 | BD3: 34734.303 | BE3: 0 | BF3: 0 | BG3: 0 | BH3: 0 | BI3: 0
O4: 47160 | P4: 1695 | Q4: 0 | R4: 4050 | S4: 0 | T4: 0 | U4: 0 | V4: 2240.25 | W4: 47045.25 | X4: 43110 | Y4: 1695 | Z4: 2240.25 | AA4: 47045.25 | AB4: 1725 | AC4: 10820.46 | AD4: 404.38 | AE4: 1480 | AF4: 0 | AG4: 179.19 | AH4: 865.63 | AI4: 12986.9 | AJ4: 2337.57 | AK4: 0 | AL4: 44805 | AM4: 0 | AN4: 0 | AO4: 44.68 | AP4: 2240.25 | AQ4: 0 | AR4: 4622.5 | AS4: 0 | AT4: 0 | AU4: 0 | AV4: 0 | AW4: 0 | AX4: 0 | AY4: 0 | AZ4: 0 | BA4: 0 | BB4: 17609.4 | BC4: 0 | BD4: 29435.85 | BE4: 0 | BF4: 0 | BG4: 0 | BH4: 0 | BI4: 0
A5: S.no. | B5: Order ID | C5: Order date | D5: Week no. | E5: Res. name | F5: Res. ID | G5: Discount construct | H5: Mode of payment | I5: Order status (Delivered/ Cancelled/ Rejected) | J5: Cancellation policy (% Amount refunded back to restaurant partner) | K5: Cancellation/ Rejection reason | L5: Cancelled/ Rejected state (Order status at the time it was cancelled/ rejected) | M5: Order type | N5: Delivery state code | O5: Subtotal (items total) | P5: Packaging charge | Q5: Delivery charge for restaurants on self logistics | R5: Restaurant discount (Promo) | S5: Restaurant discount (BOGO, Freebies, Gold, Brand pack & others) | T5: Brand pack subscription fee | U5: Delivery charge discount/ Relisting discount | V5: Total GST collected from customers | W5: Net order value [(1) + (2) + (3) - (4) - (5) + (6) - (7) + (8)] | X5: Commissionable value of Subtotal, excluding restuarant discounts [(1) - (4) - (5)] | Y5: Commissionable value of Packaging charge | Z5: Commissionable value of Total GST collected from customers | AA5: Total commissionable value [(9) + (10) + (11)] | AB5: Base service fee % | AC5: Base service fee [(12)% * (B)] | AD5: Actual order distance (km) | AE5: Long distance enablement fee | AF5: Discount on long distance enablement fee | AG5: Discount on service fee due to 30% capping Service fees capped at 30% of commissionable value (B) | AH5: Payment mechanism fee | AI5: Service fee & payment mechanism fee [(13) + (15) - (16) - (17) + (18)] | AJ5: Taxes on service fee & payment mechanism fee [(C) * 18%] | AK5: Applicable amount for TCS | AL5: Applicable amount for 9(5) | AM5: Tax collected at source | AN5: TCS IGST amount | AO5: TDS 194O amount | AP5: GST paid by Zomato on behalf of restaurant - under section 9(5) | AQ5: GST to be paid by Restaurant partner to Govt. | AR5: Government charges [(19) + (22) + (23) + (24) + (25)] | AS5: Customer compensation/ recoupment | AT5: Delivery charges recovery | AU5: Amount received in cash (on self delivery orders) | AV5: Credit note/ (Debit note) adjustment | AW5: Promo recovery adjustment | AX5: Extra inventory ads (order level deduction) | AY5: Brand loyalty points redemption | AZ5: Express order fee | BA5: Other order-level deductions [(27) + (28) + (29) + (30) + (31) + (32) + (33) + (34)] | BB5: Net Deductions [(C) + (D) + (E)] | BC5: Net Additions (cancellation refund for cancelled orders/ tip for kitchen staff for delivered orders) | BD5: Order level Payout (A) - (F) + (G) | BE5: Settlement status | BF5: Settlement date | BG5: Bank UTR | BH5: Unsettled amount | BI5: Customer ID
A6: 1 | B6: 7439802950 | C6: 2025-11-03 11:49:35 | D6: 45 | E6: This Is It | F6: 20802097 | G6: Flat ₹50 off (2025-09-15 - 2031-01-01) | H6: ONLINE | I6: DELIVERED | J6: NA | K6: NA | L6: NA | M6: O2 | N6: 36 | O6: 1167 | P6: 15 | Q6: 0 | R6: 50 | S6: 0 | T6: 0 | U6: 0 | V6: 56.6 | W6: 1188.6 | X6: 1117 | Y6: 15 | Z6: 56.6 | AA6: 1188.6 | AB6: 23 | AC6: 273.38 | AD6: 9.02 | AE6: 40 | AF6: 0 | AG6: 0 | AH6: 21.87 | AI6: 335.25 | AJ6: 60.34 | AK6: 0 | AL6: 1132 | AM6: 0 | AN6: 0 | AO6: 1.13 | AP6: 56.6 | AQ6: 0 | AR6: 118.07 | AS6: 0 | AT6: 0 | AU6: 0 | AV6: 0 | AW6: 0 | AX6: 0 | AY6: 0 | AZ6: 0 | BA6: 0 | BB6: 453.32 | BC6: 0 | BD6: 735.28 | BE6: settled | BF6: NA | BG6: NA | BH6: 0 | BI6: 7e0d58460e98d9a6eff94652f0863537d65481323cda6e36402611f3fb6dd4e8
A7: 2 | B7: 7444786290 | C7: 2025-11-03 12:12:01 | D7: 45 | E7: This Is It | F7: 20802097 | G7: Flat ₹50 off (2025-09-15 - 2031-01-01) | H7: ONLINE | I7: DELIVERED | J7: NA | K7: NA | L7: NA | M7: O2 | N7: 36 | O7: 399 | P7: 15 | Q7: 0 | R7: 50 | S7: 0 | T7: 0 | U7: 0 | V7: 18.2 | W7: 382.2 | X7: 349 | Y7: 15 | Z7: 18.2 | AA7: 382.2 | AB7: 23 | AC7: 87.91 | AD7: 4.84 | AE7: 20 | AF7: 0 | AG7: 0 | AH7: 7.03 | AI7: 114.94 | AJ7: 20.69 | AK7: 0 | AL7: 364 | AM7: 0 | AN7: 0 | AO7: 0.36 | AP7: 18.2 | AQ7: 0 | AR7: 39.25 | AS7: 0 | AT7: 0 | AU7: 0 | AV7: 0 | AW7: 0 | AX7: 0 | AY7: 0 | AZ7: 0 | BA7: 0 | BB7: 154.19 | BC7: 0 | BD7: 228.01 | BE7: settled | BF7: NA | BG7: NA | BH7: 0 | BI7: 65e02c63dbd46b59232623cf3f4b42f51d906af067fe72fcb0b9c63c604ed046
A8: 3 | B8: 7418498727 | C8: 2025-11-03 13:38:23 | D8: 45 | E8: This Is It | F8: 20802097 | G8: NA | H8: ONLINE | I8: DELIVERED | J8: NA | K8: NA | L8: NA | M8: O2 | N8: 36 | O8: 369 | P8: 15 | Q8: 0 | R8: 0 | S8: 0 | T8: 0 | U8: 0 | V8: 19.2 | W8: 403.2 | X8: 369 | Y8: 15 | Z8: 19.2 | AA8: 403.2 | AB8: 23 | AC8: 92.74 | AD8: 1.62 | AE8: 0 | AF8: 0 | AG8: 0 | AH8: 7.42 | AI8: 100.16 | AJ8: 18.04 | AK8: 0 | AL8: 384 | AM8: 0 | AN8: 0 | AO8: 0.38 | AP8: 19.2 | AQ8: 0 | AR8: 37.62 | AS8: 0 | AT8: 0 | AU8: 0 | AV8: 0 | AW8: 0 | AX8: 0 | AY8: 0 | AZ8: 0 | BA8: 0 | BB8: 137.78 | BC8: 0 | BD8: 265.42 | BE8: settled | BF8: NA | BG8: NA | BH8: 0 | BI8: e95fb64dc28ac124da267aa7c2ad5e235820d4c93164ace1e0adaa93bddaf5cb
A9: 4 | B9: 7441590712 | C9: 2025-11-03 13:56:30 | D9: 45 | E9: This Is It | F9: 20802097 | G9: Flat ₹200 off (2025-09-10 - 2031-01-01) | H9: ONLINE | I9: DELIVERED | J9: NA | K9: NA | L9: NA | M9: O2 | N9: 36 | O9: 1177 | P9: 45 | Q9: 0 | R9: 100 | S9: 0 | T9: 0 | U9: 0 | V9: 56.1 | W9: 1178.1 | X9: 1077 | Y9: 45 | Z9: 56.1 | AA9: 1178.1 | AB9: 23 | AC9: 270.96 | AD9: 2.65 | AE9: 0 | AF9: 0 | AG9: 0 | AH9: 21.68 | AI9: 292.64 | AJ9: 52.67 | AK9: 0 | AL9: 1122 | AM9: 0 | AN9: 0 | AO9: 1.12 | AP9: 56.1 | AQ9: 0 | AR9: 109.89 | AS9: 0 | AT9: 0 | AU9: 0 | AV9: 0 | AW9: 0 | AX9: 0 | AY9: 0 | AZ9: 0 | BA9: 0 | BB9: 402.53 | BC9: 0 | BD9: 775.57 | BE9: settled | BF9: NA | BG9: NA | BH9: 0 | BI9: 13c0834cc170bf043529ce2a614328b1c9ab2fd48a78ecbecc151441d257262a
A10: 5 | B10: 7442585364 | C10: 2025-11-03 14:33:33 | D10: 45 | E10: This Is It | F10: 20802097 | G10: Flat ₹50 off (2025-09-15 - 2031-01-01) | H10: ONLINE | I10: DELIVERED | J10: NA | K10: NA | L10: NA | M10: O2 | N10: 36 | O10: 389 | P10: 15 | Q10: 0 | R10: 50 | S10: 0 | T10: 0 | U10: 0 | V10: 17.7 | W10: 371.7 | X10: 339 | Y10: 15 | Z10: 17.7 | AA10: 371.7 | AB10: 23 | AC10: 85.49 | AD10: 3.2 | AE10: 0 | AF10: 0 | AG10: 0 | AH10: 6.84 | AI10: 92.33 | AJ10: 16.62 | AK10: 0 | AL10: 354 | AM10: 0 | AN10: 0 | AO10: 0.35 | AP10: 17.7 | AQ10: 0 | AR10: 34.67 | AS10: 0 | AT10: 0 | AU10: 0 | AV10: 0 | AW10: 0 | AX10: 0 | AY10: 0 | AZ10: 0 | BA10: 0 | BB10: 127 | BC10: 0 | BD10: 244.7 | BE10: settled | BF10: NA | BG10: NA | BH10: 0 | BI10: 1f319cd207dd3515a69a46442adc5d274ed58cfe3bbb6184c28bfd3a9808143b
A11: 6 | B11: 7428924290 | C11: 2025-11-03 18:30:32 | D11: 45 | E11: This Is It | F11: 20802097 | G11: Flat ₹50 off (2025-09-15 - 2031-01-01) | H11: ONLINE | I11: DELIVERED | J11: NA | K11: NA | L11: NA | M11: O2 | N11: 36 | O11: 369 | P11: 15 | Q11: 0 | R11: 50 | S11: 0 | T11: 0 | U11: 0 | V11: 16.7 | W11: 350.7 | X11: 319 | Y11: 15 | Z11: 16.7 | AA11: 350.7 | AB11: 23 | AC11: 80.66 | AD11: 4.28 | AE11: 20 | AF11: 0 | AG11: 0 | AH11: 6.45 | AI11: 107.11 | AJ11: 19.28 | AK11: 0 | AL11: 334 | AM11: 0 | AN11: 0 | AO11: 0.33 | AP11: 16.7 | AQ11: 0 | AR11: 36.31 | AS11: 0 | AT11: 0 | AU11: 0 | AV11: 0 | AW11: 0 | AX11: 0 | AY11: 0 | AZ11: 0 | BA11: 0 | BB11: 143.42 | BC11: 0 | BD11: 207.28 | BE11: settled | BF11: NA | BG11: NA | BH11: 0 | BI11: f318ef055cef4c5860c23fdb82d0ed16cc6d0b98da4bb36cf1cd7b8495f75038
A12: 7 | B12: 7445441349 | C12: 2025-11-03 18:56:13 | D12: 45 | E12: This Is It | F12: 20802097 | G12: Flat ₹100 off (2025-09-15 - 2031-01-01) | H12: ONLINE | I12: DELIVERED | J12: NA | K12: NA | L12: NA | M12: O2 | N12: 36 | O12: 948 | P12: 30 | Q12: 0 | R12: 100 | S12: 0 | T12: 0 | U12: 0 | V12: 43.9 | W12: 921.9 | X12: 848 | Y12: 30 | Z12: 43.9 | AA12: 921.9 | AB12: 23 | AC12: 212.04 | AD12: 4.82 | AE12: 20 | AF12: 0 | AG12: 0 | AH12: 16.96 | AI12: 249 | AJ12: 44.82 | AK12: 0 | AL12: 878 | AM12: 0 | AN12: 0 | AO12: 0.88 | AP12: 43.9 | AQ12: 0 | AR12: 89.6 | AS12: 0 | AT12: 0 | AU12: 0 | AV12: 0 | AW12: 0 | AX12: 0 | AY12: 0 | AZ12: 0 | BA12: 0 | BB12: 338.6 | BC12: 0 | BD12: 583.3 | BE12: settled | BF12: NA | BG12: NA | BH12: 0 | BI12: 597ffeee45dfed177e1acb2305310532ce6d384250b304853895c47b8ff4055f
A13: 8 | B13: 7440860326 | C13: 2025-11-03 19:26:00 | D13: 45 | E13: This Is It | F13: 20802097 | G13: Flat ₹50 off (2025-09-15 - 2031-01-01) | H13: ONLINE | I13: DELIVERED | J13: NA | K13: NA | L13: NA | M13: O2 | N13: 36 | O13: 299 | P13: 15 | Q13: 0 | R13: 50 | S13: 0 | T13: 0 | U13: 0 | V13: 13.2 | W13: 277.2 | X13: 249 | Y13: 15 | Z13: 13.2 | AA13: 277.2 | AB13: 23 | AC13: 63.76 | AD13: 1.44 | AE13: 0 | AF13: 0 | AG13: 0 | AH13: 5.1 | AI13: 68.86 | AJ13: 12.4 | AK13: 0 | AL13: 264 | AM13: 0 | AN13: 0 | AO13: 0.26 | AP13: 13.2 | AQ13: 0 | AR13: 25.86 | AS13: 0 | AT13: 0 | AU13: 0 | AV13: 0 | AW13: 0 | AX13: 0 | AY13: 0 | AZ13: 0 | BA13: 0 | BB13: 94.72 | BC13: 0 | BD13: 182.48 | BE13: settled | BF13: NA | BG13: NA | BH13: 0 | BI13: 274e67193286cb0a2a9cfef030374629552ba25ad54895dca58bbd6d55f3ebba
A14: 9 | B14: 7446235657 | C14: 2025-11-03 19:57:02 | D14: 45 | E14: This Is It | F14: 20802097 | G14: NA | H14: ONLINE | I14: DELIVERED | J14: NA | K14: NA | L14: NA | M14: O2 | N14: 36 | O14: 695 | P14: 75 | Q14: 0 | R14: 0 | S14: 0 | T14: 0 | U14: 0 | V14: 38.5 | W14: 808.5 | X14: 695 | Y14: 75 | Z14: 38.5 | AA14: 808.5 | AB14: 23 | AC14: 185.96 | AD14: 5.48 | AE14: 20 | AF14: 0 | AG14: 0 | AH14: 14.88 | AI14: 220.84 | AJ14: 39.75 | AK14: 0 | AL14: 770 | AM14: 0 | AN14: 0 | AO14: 0.77 | AP14: 38.5 | AQ14: 0 | AR14: 79.02 | AS14: 0 | AT14: 0 | AU14: 0 | AV14: 0 | AW14: 0 | AX14: 0 | AY14: 0 | AZ14: 0 | BA14: 0 | BB14: 299.86 | BC14: 0 | BD14: 508.64 | BE14: settled | BF14: NA | BG14: NA | BH14: 0 | BI14: a0a81d0b0ef5b71e335e06b436e6548ac2086cf6f068cd324de7ed68449cfb74
A15: 10 | B15: 7431030518 | C15: 2025-11-04 09:29:54 | D15: 45 | E15: This Is It | F15: 20802097 | G15: Flat ₹50 off (2025-09-15 - 2031-01-01) | H15: ONLINE | I15: DELIVERED | J15: NA | K15: NA | L15: NA | M15: O2 | N15: 36 | O15: 329 | P15: 15 | Q15: 0 | R15: 50 | S15: 0 | T15: 0 | U15: 0 | V15: 14.7 | W15: 308.7 | X15: 279 | Y15: 15 | Z15: 14.7 | AA15: 308.7 | AB15: 23 | AC15: 71 | AD15: 2.54 | AE15: 0 | AF15: 0 | AG15: 0 | AH15: 5.68 | AI15: 76.68 | AJ15: 13.8 | AK15: 0 | AL15: 294 | AM15: 0 | AN15: 0 | AO15: 0.29 | AP15: 14.7 | AQ15: 0 | AR15: 28.79 | AS15: 0 | AT15: 0 | AU15: 0 | AV15: 0 | AW15: 0 | AX15: 0 | AY15: 0 | AZ15: 0 | BA15: 0 | BB15: 105.47 | BC15: 0 | BD15: 203.23 | BE15: settled | BF15: NA | BG15: NA | BH15: 0 | BI15: 276723a8a6342bdda8b56adcb94751e7817f04ddc199fd7b52462d4251043206
A16: 11 | B16: 7443417528 | C16: 2025-11-04 12:42:36 | D16: 45 | E16: This Is It | F16: 20802097 | G16: Flat ₹50 off (2025-09-15 - 2031-01-01) | H16: ONLINE | I16: DELIVERED | J16: NA | K16: NA | L16: NA | M16: O2 | N16: 36 | O16: 429 | P16: 15 | Q16: 0 | R16: 50 | S16: 0 | T16: 0 | U16: 0 | V16: 19.7 | W16: 413.7 | X16: 379 | Y16: 15 | Z16: 19.7 | AA16: 413.7 | AB16: 23 | AC16: 95.15 | AD16: 6.37 | AE16: 40 | AF16: 0 | AG16: 11.04 | AH16: 7.61 | AI16: 131.72 | AJ16: 23.71 | AK16: 0 | AL16: 394 | AM16: 0 | AN16: 0 | AO16: 0.39 | AP16: 19.7 | AQ16: 0 | AR16: 43.8 | AS16: 0 | AT16: 0 | AU16: 0 | AV16: 0 | AW16: 0 | AX16: 0 | AY16: 0 | AZ16: 0 | BA16: 0 | BB16: 175.52 | BC16: 0 | BD16: 238.18 | BE16: settled | BF16: NA | BG16: NA | BH16: 0 | BI16: 4166dca4704569643a89ec3c36c47e02779e0dada4ea61e2c157c96fa80180ed
A17: 12 | B17: 7446718857 | C17: 2025-11-04 13:50:47 | D17: 45 | E17: This Is It | F17: 20802097 | G17: NA | H17: ONLINE | I17: DELIVERED | J17: NA | K17: NA | L17: NA | M17: O2 | N17: 36 | O17: 299 | P17: 15 | Q17: 0 | R17: 0 | S17: 0 | T17: 0 | U17: 0 | V17: 15.7 | W17: 329.7 | X17: 299 | Y17: 15 | Z17: 15.7 | AA17: 329.7 | AB17: 23 | AC17: 75.83 | AD17: 9.29 | AE17: 40 | AF17: 0 | AG17: 16.92 | AH17: 6.07 | AI17: 104.98 | AJ17: 18.89 | AK17: 0 | AL17: 314 | AM17: 0 | AN17: 0 | AO17: 0.31 | AP17: 15.7 | AQ17: 0 | AR17: 34.9 | AS17: 0 | AT17: 0 | AU17: 0 | AV17: 0 | AW17: 0 | AX17: 0 | AY17: 0 | AZ17: 0 | BA17: 0 | BB17: 139.88 | BC17: 0 | BD17: 189.82 | BE17: settled | BF17: NA | BG17: NA | BH17: 0 | BI17: a955ba3c68313473a0148731173e8b1b9b8ee34298006122c4baea09200afa57
... A80: 75 | B80: 7443493150 | C80: 2025-11-09 21:54:09 | D80: 45 | E80: This Is It | F80: 20802097 | G80: Flat ₹100 off (2025-11-05 - 2031-01-01) | H80: ONLINE | I80: DELIVERED | J80: NA | K80: NA | L80: NA | M80: O2 | N80: 36 | O80: 299 | P80: 15 | Q80: 0 | R80: 100 | S80: 0 | T80: 0 | U80: 0 | V80: 10.7 | W80: 224.7 | X80: 199 | Y80: 15 | Z80: 10.7 | AA80: 224.7 | AB80: 23 | AC80: 51.68 | AD80: 7.7 | AE80: 40 | AF80: 0 | AG80: 24.27 | AH80: 4.13 | AI80: 71.54 | AJ80: 12.87 | AK80: 0 | AL80: 214 | AM80: 0 | AN80: 0 | AO80: 0.21 | AP80: 10.7 | AQ80: 0 | AR80: 23.78 | AS80: 0 | AT80: 0 | AU80: 0 | AV80: 0 | AW80: 0 | AX80: 0 | AY80: 0 | AZ80: 0 | BA80: 0 | BB80: 95.32 | BC80: 0 | BD80: 129.38 | BE80: settled | BF80: NA | BG80: NA | BH80: 0 | BI80: d9be03e3610b2daf5733a2b49dd9e066b2f5d5326c7c901872846263ad97027b

Sheet D2W2
B1: Addition/ Deduction details (non order-level additions & deductions and adjustments from previous weeks)
B2: Summarized view on : 1. Res id level additions like 194 H, etc 2. Res id level deductions like pay later, etc
B5: Addition Type
B6: Type | C6: NA | D6: Invoice No/Order id | E6: Order date | F6: Settlement status | G6: Total amount | H6: Adjusted amount | I6: Outstanding amount
B7: Total Additions | G7: 0 | H7: 0 | I7: 0
B10: Deduction Type
B11: A) Investments in growth services
B12: Type | C12: Res id for which deduction created | D12: Invoice No/Campaign id | E12: Deduction time period | F12: Settlement Status | G12: Total amount | H12: Adjusted amount | I12: Outstanding amount
B13: Total Ads & miscellaneous services | G13: 0 | H13: 0 | I13: 0
B15: B) Investments in Hyperpure
B16: Type | C16: Res id for which deduction created | D16: OrderId | E16: Deduction time period | F16: Settlement Status | G16: Total amount | H16: Adjusted amount | I16: Outstanding amount
B17: Hyperpure | C17: NA | D17: NA | E17: 05 November 25 - 09 November 25 | F17: settled | G17: 8649.55 | H17: 8649.55 | I17: 0
B18: Hyperpure | C18: NA | D18: NA | E18: 03 November 25 - 09 November 25 | F18: settled | G18: 8014.45 | H18: 8014.45 | I18: 0
B19: Hyperpure | C19: NA | D19: NA | E19: 06 November 25 - 06 November 25 | F19: settled | G19: 6651.4 | H19: 6651.4 | I19: 0
B20: Hyperpure | C20: NA | D20: NA | E20: 06 November 25 - 06 November 25 | F20: settled | G20: 6120.45 | H20: 6120.45 | I20: 0
B21: Total Hyperpure | G21: 29435.85 | H21: 29435.85 | I21: 0
B23: C) Other deductions
B24: D) Adjustments from previous weeks
B25: Total Deductions (A) + (B) + (C) | G25: 29435.85 | H25: 29435.85 | I25: 0

Sheet D1W3
O1: 349 | P1: 0 | Q1: 0 | R1: 0 | S1: 0 | T1: 0 | U1: 0 | V1: 0 | W1: 349 | X1: 0 | Y1: 0 | Z1: 0 | AA1: 0 | AB1: 0 | AC1: 0 | AD1: 0 | AE1: 0 | AF1: 0 | AG1: 0 | AH1: 0 | AI1: 0 | AJ1: 0 | AK1: 0 | AL1: 0 | AM1: 0 | AN1: 0 | AO1: 0 | AP1: 0 | AQ1: 0 | AR1: 0 | AS1: 0 | AT1: 0 | AU1: 0 | AV1: 0 | AW1: 0 | AX1: 0 | AY1: 0 | AZ1: 0 | BA1: 0 | BB1: 0 | BC1: 182.48 | BD1: 182.48 | BE1: 0 | BF1: 0 | BG1: 0 | BH1: 0 | BI1: 0
O2: 39662 | P2: 1380 | Q2: 0 | R2: 3200 | S2: 0 | T2: 0 | U2: 0 | V2: 1892.1 | W2: 39734.1 | X2: 36462 | Y2: 1380 | Z2: 1892.1 | AA2: 39734.1 | AB2: 1564 | AC2: 9138.92 | AD2: 337.43 | AE2: 960 | AF2: 0 | AG2: 148.55 | AH2: 731.11 | AI2: 10681.48 | AJ2: 1922.73 | AK2: 0 | AL2: 37842 | AM2: 0 | AN2: 0 | AO2: 37.7 | AP2: 1892.1 | AQ2: 0 | AR2: 3852.53 | AS2: 0 | AT2: 0 | AU2: 0 | AV2: 0 | AW2: 0 | AX2: 0 | AY2: 0 | AZ2: 0 | BA2: 0 | BB2: 14534.01 | BC2: 0 | BD2: 25200.09 | BE2: 0 | BF2: 0 | BG2: 0 | BH2: 0 | BI2: 0
O3: 46801.16 | P3: 1628.4 | Q3: 0 | R3: 3776 | S3: 0 | T3: 0 | U3: 0 | V3: 2232.678 | W3: 46886.238 | X3: 43025.16 | Y3: 1628.4 | Z3: 2232.678 | AA3: 46886.238 | AB3: 1845.52 | AC3: 10783.926 | AD3: 398.1674 | AE3: 1132.8 | AF3: 0 | AG3: 175.289 | AH3: 862.7098 | AI3: 12604.146 | AJ3: 2268.8214 | AK3: 0 | AL3: 44653.56 | AM3: 0 | AN3: 0 | AO3: 44.486 | AP3: 2232.678 | AQ3: 0 | AR3: 4545.9854 | AS3: 0 | AT3: 0 | AU3: 0 | AV3: 0 | AW3: 0 | AX3: 0 | AY3: 0 | AZ3: 0 | BA3: 0 | BB3: 17150.132 | BC3: 0 | BD3: 29736.106 | BE3: 0 | BF3: 0 | BG3: 0 | BH3: 0 | BI3: 0
O4: 40011 | P4: 1380 | Q4: 0 | R4: 3200 | S4: 0 | T4: 0 | U4: 0 | V4: 1892.1 | W4: 40083.1 | X4: 36462 | Y4: 1380 | Z4: 1892.1 | AA4: 39734.1 | AB4: 1564 | AC4: 9138.92 | AD4: 337.43 | AE4: 960 | AF4: 0 | AG4: 148.55 | AH4: 731.11 | AI4: 10681.48 | AJ4: 1922.73 | AK4: 0 | AL4: 37842 | AM4: 0 | AN4: 0 | AO4: 37.7 | AP4: 1892.1 | AQ4: 0 | AR4: 3852.53 | AS4: 0 | AT4: 0 | AU4: 0 | AV4: 0 | AW4: 0 | AX4: 0 | AY4: 0 | AZ4: 0 | BA4: 0 | BB4: 14534.01 | BC4: 182.48 | BD4: 25382.57 | BE4: 0 | BF4: 0 | BG4: 0 | BH4: 0 | BI4: 0
A5: S.no. | B5: Order ID | C5: Order date | D5: Week no. | E5: Res. name | F5: Res. ID | G5: Discount construct | H5: Mode of payment | I5: Order status (Delivered/ Cancelled/ Rejected) | J5: Cancellation policy (% Amount refunded back to restaurant partner) | K5: Cancellation/ Rejection reason | L5: Cancelled/ Rejected state (Order status at the time it was cancelled/ rejected) | M5: Order type | N5: Delivery state code | O5: Subtotal (items total) | P5: Packaging charge | Q5: Delivery charge for restaurants on self logistics | R5: Restaurant discount (Promo) | S5: Restaurant discount (BOGO, Freebies, Gold, Brand pack & others) | T5: Brand pack subscription fee | U5: Delivery charge discount/ Relisting discount | V5: Total GST collected from customers | W5: Net order value [(1) + (2) + (3) - (4) - (5) + (6) - (7) + (8)] | X5: Commissionable value of Subtotal, excluding restuarant discounts [(1) - (4) - (5)] | Y5: Commissionable value of Packaging charge | Z5: Commissionable value of Total GST collected from customers | AA5: Total commissionable value [(9) + (10) + (11)] | AB5: Base service fee % | AC5: Base service fee [(12)% * (B)] | AD5: Actual order distance (km) | AE5: Long distance enablement fee | AF5: Discount on long distance enablement fee | AG5: Discount on service fee due to 30% capping Service fees capped at 30% of commissionable value (B) | AH5: Payment mechanism fee | AI5: Service fee & payment mechanism fee [(13) + (15) - (16) - (17) + (18)] | AJ5: Taxes on service fee & payment mechanism fee [(C) * 18%] | AK5: Applicable amount for TCS | AL5: Applicable amount for 9(5) | AM5: Tax collected at source | AN5: TCS IGST amount | AO5: TDS 194O amount | AP5: GST paid by Zomato on behalf of restaurant - under section 9(5) | AQ5: GST to be paid by Restaurant partner to Govt. | AR5: Government charges [(19) + (22) + (23) + (24) + (25)] | AS5: Customer compensation/ recoupment | AT5: Delivery charges recovery | AU5: Amount received in cash (on self delivery orders) | AV5: Credit note/ (Debit note) adjustment | AW5: Promo recovery adjustment | AX5: Extra inventory ads (order level deduction) | AY5: Brand loyalty points redemption | AZ5: Express order fee | BA5: Other order-level deductions [(27) + (28) + (29) + (30) + (31) + (32) + (33) + (34)] | BB5: Net Deductions [(C) + (D) + (E)] | BC5: Net Additions (cancellation refund for cancelled orders/ tip for kitchen staff for delivered orders) | BD5: Order level Payout (A) - (F) + (G) | BE5: Settlement status | BF5: Settlement date | BG5: Bank UTR | BH5: Unsettled amount | BI5: Customer ID
A6: 1 | B6: 7463005216 | C6: 2025-11-10 10:40:46 | D6: 46 | E6: This Is It | F6: 20802097 | G6: Flat ₹50 off (2025-09-15 - 2031-01-01) | H6: ONLINE | I6: DELIVERED | J6: NA | K6: NA | L6: NA | M6: O2 | N6: 36 | O6: 299 | P6: 15 | Q6: 0 | R6: 50 | S6: 0 | T6: 0 | U6: 0 | V6: 13.2 | W6: 277.2 | X6: 249 | Y6: 15 | Z6: 13.2 | AA6: 277.2 | AB6: 23 | AC6: 63.76 | AD6: 8.92 | AE6: 40 | AF6: 0 | AG6: 20.6 | AH6: 5.1 | AI6: 88.26 | AJ6: 15.89 | AK6: 0 | AL6: 264 | AM6: 0 | AN6: 0 | AO6: 0.26 | AP6: 13.2 | AQ6: 0 | AR6: 29.35 | AS6: 0 | AT6: 0 | AU6: 0 | AV6: 0 | AW6: 0 | AX6: 0 | AY6: 0 | AZ6: 0 | BA6: 0 | BB6: 117.61 | BC6: 0 | BD6: 159.59 | BE6: settled | BF6: NA | BG6: NA | BH6: 0 | BI6: 6689ffd8cb30bf0e6f91787a2911bc58d61dd78d3e0ae964403732a946d8bbe0
A7: 2 | B7: 7460175803 | C7: 2025-11-10 12:16:52 | D7: 46 | E7: This Is It | F7: 20802097 | G7: Flat ₹100 off (2025-11-05 - 2031-01-01) | H7: ONLINE | I7: DELIVERED | J7: NA | K7: NA | L7: NA | M7: O2 | N7: 36 | O7: 389 | P7: 15 | Q7: 0 | R7: 100 | S7: 0 | T7: 0 | U7: 0 | V7: 15.2 | W7: 319.2 | X7: 289 | Y7: 15 | Z7: 15.2 | AA7: 319.2 | AB7: 23 | AC7: 73.42 | AD7: 2.82 | AE7: 0 | AF7: 0 | AG7: 0 | AH7: 5.87 | AI7: 79.29 | AJ7: 14.28 | AK7: 0 | AL7: 304 | AM7: 0 | AN7: 0 | AO7: 0.3 | AP7: 15.2 | AQ7: 0 | AR7: 29.78 | AS7: 0 | AT7: 0 | AU7: 0 | AV7: 0 | AW7: 0 | AX7: 0 | AY7: 0 | AZ7: 0 | BA7: 0 | BB7: 109.07 | BC7: 0 | BD7: 210.13 | BE7: settled | BF7: NA | BG7: NA | BH7: 0 | BI7: 497137ccf88b200a579d6f611724206d84bd15320e5c7c03a058cbf4c5932d59
A8: 3 | B8: 7464955304 | C8: 2025-11-10 13:23:33 | D8: 46 | E8: This Is It | F8: 20802097 | G8: NA | H8: ONLINE | I8: DELIVERED | J8: NA | K8: NA | L8: NA | M8: O2 | N8: 36 | O8: 439 | P8: 0 | Q8: 0 | R8: 0 | S8: 0 | T8: 0 | U8: 0 | V8: 21.95 | W8: 460.95 | X8: 439 | Y8: 0 | Z8: 21.95 | AA8: 460.95 | AB8: 23 | AC8: 106.02 | AD8: 2.86 | AE8: 0 | AF8: 0 | AG8: 0 | AH8: 8.48 | AI8: 114.5 | AJ8: 20.61 | AK8: 0 | AL8: 439 | AM8: 0 | AN8: 0 | AO8: 0.44 | AP8: 21.95 | AQ8: 0 | AR8: 43 | AS8: 0 | AT8: 0 | AU8: 0 | AV8: 0 | AW8: 0 | AX8: 0 | AY8: 0 | AZ8: 0 | BA8: 0 | BB8: 157.5 | BC8: 0 | BD8: 303.45 | BE8: settled | BF8: NA | BG8: NA | BH8: 0 | BI8: 9da54fcf6463263a55b200834c379fba8647fbe9b382a026db340de28d71b259
A9: 4 | B9: 7465836520 | C9: 2025-11-10 13:25:02 | D9: 46 | E9: This Is It | F9: 20802097 | G9: Flat ₹100 off (2025-11-05 - 2031-01-01) | H9: ONLINE | I9: DELIVERED | J9: NA | K9: NA | L9: NA | M9: O2 | N9: 36 | O9: 638 | P9: 30 | Q9: 0 | R9: 100 | S9: 0 | T9: 0 | U9: 0 | V9: 28.4 | W9: 596.4 | X9: 538 | Y9: 30 | Z9: 28.4 | AA9: 596.4 | AB9: 23 | AC9: 137.17 | AD9: 9.02 | AE9: 40 | AF9: 0 | AG9: 0 | AH9: 10.97 | AI9: 188.14 | AJ9: 33.87 | AK9: 0 | AL9: 568 | AM9: 0 | AN9: 0 | AO9: 0.57 | AP9: 28.4 | AQ9: 0 | AR9: 62.84 | AS9: 0 | AT9: 0 | AU9: 0 | AV9: 0 | AW9: 0 | AX9: 0 | AY9: 0 | AZ9: 0 | BA9: 0 | BB9: 250.98 | BC9: 0 | BD9: 345.42 | BE9: settled | BF9: NA | BG9: NA | BH9: 0 | BI9: 7e0d58460e98d9a6eff94652f0863537d65481323cda6e36402611f3fb6dd4e8
